Workbook

Sheet 2026.1
A1: 大连北方热电股份有限公司生产销售月报表
H2: 表 号：JB007-1表
A3: 单位名称(盖章)： | C3: 2015年 3月 | F3: 46023 | H3: 制表单位：计划生产部
A4: 指 标 名 称 | B4: 计量单位 | C4: 代码 | D4: 月计划 | E4: 实 际 | I4: 备注
E5: 上年同期 | F5: 上年累计 | G5: 本月实际 | H5: 本年累计
A6: 发电机组容量 | B6: 万千瓦 | C6: 001 | E6: 3.28 | F6: 3.28 | G6: 3.28 | H6: 3.28
A7: 发电量 | B7: 千瓦时 | C7: 002 | E7: 12035100 | F7: 12035100 | G7: 15352900 | H7: 15352900
A8: 供电量 | B8: 千瓦时 | C8: 003 | E8: 8735760 | F8: 8735760 | G8: 11150964 | H8: 11150964
A9: 供汽量 | B9: 吨 | C9: 004 | E9: 0 | F9: 0 | G9: 0 | H9: 0
A10: 供热量 | B10: 吉焦 | C10: 005 | E10: 250183.46 | F10: 250183.46 | G10: 292094.32 | H10: 292094.32
A11: 首站热泵吸收供热量 | B11: 吉焦 | E11: 0 | F11: 0 | G11: 0 | H11: 0
A12: 售汽量(工业、非工业) | B12: 吨 | C12: 006 | E12: 0 | F12: 0 | G12: 0 | H12: 0
A13: 高温水用热(吉焦) | B13: 吉焦 | E13: 4203 | F13: 4203 | G13: 6898.5 | H13: 6898.5
A14: 期末供暖收费面积 | B14: 平方米 | C14: 007 | E14: 3170000 | F14: 3170000 | G14: 3019870.3 | H14: 3019870.3
A15: 生产耗原煤量 | B15: 吨 | C15: 008 | E15: 17767.37 | F15: 17767.37 | G15: 20654.19 | H15: 20654.19
A16: 发电耗原煤量 | B16: 吨 | C16: 009 | E16: 3749.5675 | F16: 3749.5675 | G16: 4953.189 | H16: 4953.189
A17: 供热耗原煤量 | B17: 吨 | C17: 010 | E17: 14017.803 | F17: 14017.803 | G17: 15701.001 | H17: 15701.001
A18: 锅炉耗油量 | B18: 吨 | C18: 011 | E18: 8.8 | F18: 8.8 | G18: 0.2 | H18: 0.2
A19: 发电耗油量 | B19: 吨 | C19: 012 | E19: 1.8571231 | F19: 1.8571231 | G19: 0.047963043 | H19: 0.047963043
A20: 供热耗油量 | B20: 吨 | C20: 013 | E20: 6.9428769 | F20: 6.9428769 | G20: 0.15203696 | H20: 0.15203696
A21: 耗水量 | B21: 吨 | C21: 014 | E21: 43108.9 | F21: 43108.9 | G21: 34653 | H21: 34653
A22: 其中：耗井水量 | B22: 吨 | C22: 015 | E22: 21789.9 | F22: 21789.9 | G22: 11538 | H22: 11538
A23: 耗酸量 | B23: 吨 | C23: 016 | E23: 6.72 | F23: 6.72 | G23: 2.31 | H23: 2.31
A24: 耗碱量 | B24: 吨 | C24: 017 | E24: 7.12 | F24: 7.12 | G24: 2.3 | H24: 2.3
A25: 耗石灰石量 | B25: 吨 | C25: 018 | E25: 837.04 | F25: 837.04 | G25: 601.88 | H25: 601.88
A26: 脱硫耗石灰粉 | B26: 吨 | E26: 299.42 | F26: 299.42 | G26: 364.38 | H26: 364.38
A27: 脱硫耗电量 | B27: 千瓦时 | E27: 441012 | F27: 441012 | G27: 619963 | H27: 619963
A28: 脱硫耗自备水量 | B28: 吨 | E28: 5952 | F28: 5952 | G28: 6120 | H28: 6120
A29: 脱硫耗除盐水量 | B29: 吨 | E29: 1535 | F29: 1535 | G29: 1284 | H29: 1284
A30: 耗氨水量 | B30: 吨 | C30: 019 | E30: 386.346 | F30: 386.346 | G30: 74.273 | H30: 74.273
A31: 耗阻垢剂量 | B31: 吨 | C31: 020 | E31: 0.119 | F31: 0.119 | G31: 0.05 | H31: 0.05
A32: 耗杀菌剂量 | B32: 吨 | C32: 021 | E32: 0 | F32: 0 | G32: 0 | H32: 0
A33: 锅炉房耗原煤量 | B33: 吨 | C33: 022 | E33: 0 | F33: 0 | G33: 0 | H33: 0
A34: 热网耗水量 | B34: 吨 | C34: 023 | E34: 32644 | F34: 32644 | G34: 22885 | H34: 22885
A35: 外购电量 | B35: 千瓦时 | C35: 024 | E35: 1003755 | F35: 1003755 | G35: 1027192 | H35: 1027192
A36: 其中：热网耗电量 | B36: 千瓦时 | C36: 025 | E36: 1003755 | F36: 1003755 | G36: 1027192 | H36: 1027192
A37: 综合厂用电量 | B37: 千瓦时 | C37: 026 | E37: 3299340 | F37: 3299340 | G37: 4201936 | H37: 4201936
A38: 非生产厂用电量 | B38: 千瓦时 | C38: 027 | E38: 0 | F38: 0 | G38: 0 | H38: 0
A39: 生产厂用电量 | B39: 千瓦时 | C39: 028 | E39: 3299340 | F39: 3299340 | G39: 4201936 | H39: 4201936
A40: 其中：发电厂用电量 | B40: 千瓦时 | C40: 029 | E40: 696281.89 | F40: 696281.89 | G40: 1007688.2 | H40: 1007688.2
...

Sheet 2026.2
A1: 大连北方热电股份有限公司生产销售月报表
H2: 表 号：JB007-1表
A3: 单位名称(盖章)： | C3: 2015年 3月 | F3: 46054 | H3: 制表单位：计划生产部
A4: 指 标 名 称 | B4: 计量单位 | C4: 代码 | D4: 月计划 | E4: 实 际 | I4: 备注
E5: 上年同期 | F5: 上年累计 | G5: 本月实际 | H5: 本年累计
A6: 发电机组容量 | B6: 万千瓦 | C6: 001 | E6: 3.28 | F6: 3.28 | G6: 3.28 | H6: 3.28
A7: 发电量 | B7: 千瓦时 | C7: 002 | E7: 9844900 | F7: 21880000 | G7: 8391100 | H7: =G7+'2026.1'!H7 -> 23744000
A8: 供电量 | B8: 千瓦时 | C8: 003 | E8: 7008012 | F8: 15743772 | G8: 5435100 | H8: =G8+'2026.1'!H8 -> 16586064
A9: 供汽量 | B9: 吨 | C9: 004 | E9: 0 | F9: 0 | G9: 0 | H9: =G9+'2026.1'!H9 -> 0
A10: 供热量 | B10: 吉焦 | C10: 005 | E10: 207028.94 | F10: 457212.4 | G10: 212810.38 | H10: =G10+'2026.1'!H10 -> 504904.7
A11: 首站热泵吸收供热量 | B11: 吉焦 | E11: 0 | F11: 0 | G11: 0 | H11: =G11+'2026.1'!H11 -> 0
A12: 售汽量(工业、非工业) | B12: 吨 | C12: 006 | E12: 0 | F12: 0 | G12: 0 | H12: =G12+'2026.1'!H12 -> 0
A13: 高温水用热(吉焦) | B13: 吉焦 | E13: 5850 | F13: 10053 | G13: 5144 | H13: =G13+'2026.1'!H13 -> 12042.5
A14: 期末供暖收费面积 | B14: 平方米 | C14: 007 | E14: 3170000 | F14: 3170000 | G14: 3019870.3 | H14: 3019870.3
A15: 生产耗原煤量 | B15: 吨 | C15: 008 | E15: 14194.71 | F15: 31962.08 | G15: =G16+G17 -> 13042.64 | H15: =G15+'2026.1'!H15 -> 33696.83
A16: 发电耗原煤量 | B16: 吨 | C16: 009 | E16: 2928.3933 | F16: 6677.9608 | G16: 2402.9015 | H16: =G16+'2026.1'!H16 -> 7356.0905
A17: 供热耗原煤量 | B17: 吨 | C17: 010 | E17: 11266.317 | F17: 25284.119 | G17: 10639.739 | H17: =G17+'2026.1'!H17 -> 26340.739
A18: 锅炉耗油量 | B18: 吨 | C18: 011 | E18: 0 | F18: 8.8 | G18: =G19+G20 -> 1.054 | H18: =G18+'2026.1'!H18 -> 1.254
A19: 发电耗油量 | B19: 吨 | C19: 012 | E19: 0 | F19: 1.8571231 | G19: 0.19418294 | H19: =G19+'2026.1'!H19 -> 0.24214598
A20: 供热耗油量 | B20: 吨 | C20: 013 | E20: 0 | F20: 6.9428769 | G20: 0.85981706 | H20: =G20+'2026.1'!H20 -> 1.011854
A21: 耗水量 | B21: 吨 | C21: 014 | E21: 41497.4 | F21: 84606.3 | G21: 27072.5 | H21: =G21+'2026.1'!H21 -> 61725.5
A22: 其中：耗井水量 | B22: 吨 | C22: 015 | E22: 18385.4 | F22: 40175.3 | G22: 6311.5 | H22: =G22+'2026.1'!H22 -> 17849.5
A23: 耗酸量 | B23: 吨 | C23: 016 | E23: 2.3 | F23: 9.02 | G23: 0 | H23: =G23+'2026.1'!H23 -> 2.31
A24: 耗碱量 | B24: 吨 | C24: 017 | E24: 7.36 | F24: 14.48 | G24: 2.3 | H24: =G24+'2026.1'!H24 -> 4.6
A25: 耗石灰石量 | B25: 吨 | C25: 018 | E25: 676.87 | F25: 1513.91 | G25: 448.88 | H25: =G25+'2026.1'!H25 -> 1050.76
A26: 脱硫耗石灰粉 | B26: 吨 | E26: 243.81 | F26: 543.23 | G26: 265.41 | H26: =G26+'2026.1'!H26 -> 629.79
A27: 脱硫耗电量 | B27: 千瓦时 | E27: 409424 | F27: 850436 | G27: 548313 | H27: =G27+'2026.1'!H27 -> 1168276
A28: 脱硫耗自备水量 | B28: 吨 | E28: 4305 | F28: 10257 | G28: 4120 | H28: =G28+'2026.1'!H28 -> 10240
A29: 脱硫耗除盐水量 | B29: 吨 | E29: 1499 | F29: 3034 | G29: 1021 | H29: =G29+'2026.1'!H29 -> 2305
A30: 耗氨水量 | B30: 吨 | C30: 019 | E30: 328.041 | F30: 714.387 | G30: 108.416 | H30: =G30+'2026.1'!H30 -> 182.689
A31: 耗阻垢剂量 | B31: 吨 | C31: 020 | E31: 0 | F31: 0.119 | G31: 0.04 | H31: =G31+'2026.1'!H31 -> 0.09
A32: 耗杀菌剂量 | B32: 吨 | C32: 021 | E32: 0 | F32: 0 | G32: 0 | H32: =G32+'2026.1'!H32 -> 0
A33: 锅炉房耗原煤量 | B33: 吨 | C33: 022 | E33: 0 | F33: 0 | G33: 0 | H33: =G33+'2026.1'!H33 -> 0
A34: 热网耗水量 | B34: 吨 | C34: 023 | E34: 33933 | F34: 66577 | G34: 18429 | H34: =G34+'2026.1'!H34 -> 41314
A35: 外购电量 | B35: 千瓦时 | C35: 024 | E35: 839595 | F35: 1843350 | G35: 923425 | H35: =G35+'2026.1'!H35 -> 1950617
A36: 其中：热网耗电量 | B36: 千瓦时 | C36: 025 | E36: 839595 | F36: 1843350 | G36: 923425 | H36: =G36+'2026.1'!H36 -> 1950617
A37: 综合厂用电量 | B37: 千瓦时 | C37: 026 | E37: 2836888 | F37: 6136228 | G37: 2956000 | H37: =G37+'2026.1'!H37 -> 7157936
A38: 非生产厂用电量 | B38: 千瓦时 | C38: 027 | E38: 0 | F38: 0 | G38: 0 | H38: =G38+'2026.1'!H38 -> 0
A39: 生产厂用电量 | B39: 千瓦时 | C39: 028 | E39: 2836888 | F39: 6136228 | G39: =G40+G41 -> 2956000 | H39: =G39+'2026.1'!H39 -> 7157936
A40: 其中：发电厂用电量 | B40: 千瓦时 | C40: 029 | E40: 585254.92 | F40: 1281536.8 | G40: 544596.55 | H40: =G40+'2026.1'!H40 -> 1552284.7
...

Sheet 2026.3
A1: 大连北方热电股份有限公司生产销售月报表
H2: 表 号：JB007-1表
A3: 单位名称(盖章)： | C3: 2015年 3月 | F3: 46082 | H3: 制表单位：计划生产部
A4: 指 标 名 称 | B4: 计量单位 | C4: 代码 | D4: 月计划 | E4: 实 际 | I4: 备注
E5: 上年同期 | F5: 上年累计 | G5: 本月实际 | H5: 本年累计
A6: 发电机组容量 | B6: 万千瓦 | C6: 001 | E6: 3.28 | F6: 3.28 | G6: 3.28 | H6: 3.28
A7: 发电量 | B7: 千瓦时 | C7: 002 | E7: 6079800 | F7: 27959800 | G7: 6246500 | H7: =G7+'2026.2'!H7 -> 29990500
A8: 供电量 | B8: 千瓦时 | C8: 003 | E8: 3990492 | F8: 19734264 | G8: 3407184 | H8: =G8+'2026.2'!H8 -> 19993248
A9: 供汽量 | B9: 吨 | C9: 004 | E9: 0 | F9: 0 | G9: 0 | H9: =G9+'2026.2'!H9 -> 0
A10: 供热量 | B10: 吉焦 | C10: 005 | E10: 142618.18 | F10: 599830.58 | G10: 148395 | H10: =G10+'2026.2'!H10 -> 653299.7
A11: 首站热泵吸收供热量 | B11: 吉焦 | E11: 0 | F11: 0 | G11: 0 | H11: =G11+'2026.2'!H11 -> 0
A12: 售汽量(工业、非工业) | B12: 吨 | C12: 006 | E12: 0 | F12: 0 | G12: 0 | H12: =G12+'2026.2'!H12 -> 0
A13: 高温水用热(吉焦) | B13: 吉焦 | E13: 2240 | F13: 12293 | G13: 3057 | H13: =G13+'2026.2'!H13 -> 15099.5
A14: 期末供暖收费面积 | B14: 平方米 | C14: 007 | E14: 3170000 | F14: 3170000 | G14: 3019870.3 | H14: 3019870.3
A15: 生产耗原煤量 | B15: 吨 | C15: 008 | E15: 9682.13 | F15: 41644.21 | G15: =G16+G17 -> 8907 | H15: =G15+'2026.2'!H15 -> 42603.83
A16: 发电耗原煤量 | B16: 吨 | C16: 009 | E16: 1723.2255 | F16: 8401.1862 | G16: 1760.6782 | H16: =G16+'2026.2'!H16 -> 9116.7687
A17: 供热耗原煤量 | B17: 吨 | C17: 010 | E17: 7958.9045 | F17: 33243.024 | G17: 7146.3218 | H17: =G17+'2026.2'!H17 -> 33487.061
A18: 锅炉耗油量 | B18: 吨 | C18: 011 | E18: 2.753 | F18: 11.553 | G18: =G19+G20 -> 0 | H18: =G18+'2026.2'!H18 -> 1.254
A19: 发电耗油量 | B19: 吨 | C19: 012 | E19: 0.48997893 | F19: 2.3471021 | G19: 0 | H19: =G19+'2026.2'!H19 -> 0.24214598
A20: 供热耗油量 | B20: 吨 | C20: 013 | E20: 2.2630211 | F20: 9.2058979 | G20: 0 | H20: =G20+'2026.2'!H20 -> 1.011854
A21: 耗水量 | B21: 吨 | C21: 014 | E21: 42817.4 | F21: 127423.7 | G21: 24037.3 | H21: =G21+'2026.2'!H21 -> 85762.8
A22: 其中：耗井水量 | B22: 吨 | C22: 015 | E22: 21852.4 | F22: 62027.7 | G22: 3683.3 | H22: =G22+'2026.2'!H22 -> 21532.8
A23: 耗酸量 | B23: 吨 | C23: 016 | E23: 2.1 | F23: 11.12 | G23: 0 | H23: =G23+'2026.2'!H23 -> 2.31
A24: 耗碱量 | B24: 吨 | C24: 017 | E24: 7.36 | F24: 21.84 | G24: 0 | H24: =G24+'2026.2'!H24 -> 4.6
A25: 耗石灰石量 | B25: 吨 | C25: 018 | E25: 468.07 | F25: 1981.98 | G25: 351.41 | H25: =G25+'2026.2'!H25 -> 1402.17
A26: 脱硫耗石灰粉 | B26: 吨 | E26: 122.69 | F26: 665.92 | G26: 185.1 | H26: =G26+'2026.2'!H26 -> 814.89
A27: 脱硫耗电量 | B27: 千瓦时 | E27: 391510 | F27: 1241946 | G27: 589104 | H27: =G27+'2026.2'!H27 -> 1757380
A28: 脱硫耗自备水量 | B28: 吨 | E28: 3523 | F28: 13780 | G28: 4317 | H28: =G28+'2026.2'!H28 -> 14557
A29: 脱硫耗除盐水量 | B29: 吨 | E29: 788 | F29: 3822 | G29: 994 | H29: =G29+'2026.2'!H29 -> 3299
A30: 耗氨水量 | B30: 吨 | C30: 019 | E30: 314.886 | F30: 1029.273 | G30: 35.442 | H30: =G30+'2026.2'!H30 -> 218.131
A31: 耗阻垢剂量 | B31: 吨 | C31: 020 | E31: 0.256 | F31: 0.375 | G31: 0.04 | H31: =G31+'2026.2'!H31 -> 0.13
A32: 耗杀菌剂量 | B32: 吨 | C32: 021 | E32: 0 | F32: 0 | G32: 0 | H32: =G32+'2026.2'!H32 -> 0
A33: 锅炉房耗原煤量 | B33: 吨 | C33: 022 | E33: 0 | F33: 0 | G33: 0 | H33: =G33+'2026.2'!H33 -> 0
A34: 热网耗水量 | B34: 吨 | C34: 023 | E34: 37137 | F34: 103714 | G34: 21100 | H34: =G34+'2026.2'!H34 -> 62414
A35: 外购电量 | B35: 千瓦时 | C35: 024 | E35: 820002 | F35: 2663352 | G35: 809091 | H35: =G35+'2026.2'!H35 -> 2759708
A36: 其中：热网耗电量 | B36: 千瓦时 | C36: 025 | E36: 815250 | F36: 2658600 | G36: 809091 | H36: =G36+'2026.2'!H36 -> 2759708
A37: 综合厂用电量 | B37: 千瓦时 | C37: 026 | E37: 2089308 | F37: 8225536 | G37: 2839316 | H37: =G37+'2026.2'!H37 -> 9997252
A38: 非生产厂用电量 | B38: 千瓦时 | C38: 027 | E38: 0 | F38: 0 | G38: 0 | H38: =G38+'2026.2'!H38 -> 0
A39: 生产厂用电量 | B39: 千瓦时 | C39: 028 | E39: 2089308 | F39: 8225536 | G39: =G40+G41 -> 2839316 | H39: =G39+'2026.2'!H39 -> 9997252
A40: 其中：发电厂用电量 | B40: 千瓦时 | C40: 029 | E40: 371855.03 | F40: 1653391.8 | G40: 561257.64 | H40: =G40+'2026.2'!H40 -> 2113542.4
...

Sheet Sheet3
C6: 15352900
C7: 11150964
G14: 5650128
G16: 5502420
O19: 3909
F20: 11142 | O20: 420
F21: 126
F22: 117
F23: 153
C25: 352.41 | D25: 71.66
C26: 11.97 | D26: 2.613
F28: 9627
F29: 11538
F30: 13488
C31: 5650128 | F31: 8474
F32: 307
F33: 313
F34: 303
C35: 5502420
C39: 15352900
C40: 11152548
C42: =C39-C40 -> 4200352
