Workbook

Sheet Sheet2
A1: 香海热电厂生产月报表
H2: 表 号：JB003-1表
A3: 单位名称(盖章)： | C3: 20 15 年 1 月 | D3: 46082 | H3: 制表单位：计划生产部
A4: 指 标 名 称 | B4: 计量单位 | C4: 代码 | D4: 月计划 | E4: 实 际 | I4: 备注
E5: 上年同期 | F5: 上年累计 | G5: 本月实际 | H5: 本年累计
A6: 发电机组容量 | B6: 万千瓦 | C6: 001 | E6: 10 | F6: 10 | G6: 10 | H6: 10
A7: 发电量 | B7: 千瓦时 | C7: 002 | E7: 28140480 | F7: 134408160 | G7: =Sheet1!B5 -> 23782080 | H7: =Sheet1!C5 -> 118984320
A8: 供电量 | B8: 千瓦时 | C8: 003 | E8: 19933056 | F8: 98855064 | G8: =Sheet1!B6 -> 14654376 | H8: =Sheet1!C6 -> 80890920
A9: 供汽量 | B9: 吨 | C9: 004 | E9: 43339 | F9: 165010 | G9: =Sheet1!B49 -> 45284 | H9: =Sheet1!C49 -> 181525
A10: 供热量 | B10: 吉焦 | C10: 005 | E10: 431430.47 | F10: 2009236 | G10: =Sheet1!B24 -> 494096.51 | H10: =Sheet1!C24 -> 2186932.3
A11: 其中：首站 | B11: 吉焦 | C11: 006 | E11: 184894 | F11: 1006499 | G11: =Sheet1!B57 -> 233494 | H11: =Sheet1!C57 -> 1073585
A12: 其中：低真空供热量 | B12: 吉焦 | C12: 007 | E12: 118613 | F12: 515678 | G12: =Sheet1!B26 -> 126938 | H12: =Sheet1!C26 -> 577541
A13: 生产耗原煤量 | B13: 吨 | C13: 008 | E13: 32176 | F13: 150228 | G13: =Sheet2!G14+Sheet2!G15 -> 30847 | H13: =Sheet2!H14+Sheet2!H15 -> 152260
A14: 发电耗原煤量 | B14: 吨 | C14: 009 | E14: 5778.8096 | F14: 27626.136 | G14: =Sheet1!B20 -> 4013.1947 | H14: =Sheet1!C20 -> 23799.11
A15: 供热耗原煤量 | B15: 吨 | C15: 010 | E15: 26397.19 | F15: 122601.86 | G15: =Sheet1!B34 -> 26833.805 | H15: =Sheet1!C34 -> 128460.89
A16: 锅炉耗油量 | B16: 吨 | C16: 011 | E16: 0 | F16: 18 | G16: =G17+G18 -> 0 | H16: =H17+H18 -> 33
A17: 发电耗油量 | B17: 吨 | C17: 012 | E17: 0 | F17: 3.3456 | G17: =Sheet1!B21 -> 0 | H17: =Sheet1!C21 -> 5.5734
A18: 供热耗油量 | B18: 吨 | C18: 013 | E18: 0 | F18: 14.6544 | G18: =Sheet1!B35 -> 0 | H18: =Sheet1!C35 -> 27.4266
A19: 耗水量 | B19: 吨 | C19: 014 | E19: 128686 | F19: 482272 | G19: =Sheet1!B44 -> 134851 | H19: =Sheet1!C44 -> 480607
A20: 耗酸量 | B20: 吨 | C20: 015 | E20: 27 | F20: 113 | G20: =Sheet1!B45 -> 28 | H20: =Sheet1!C45 -> 107
A21: 耗碱量 | B21: 吨 | C21: 016 | E21: 24 | F21: 90 | G21: =Sheet1!B46 -> 25 | H21: =Sheet1!C46 -> 86
A22: 耗石灰石量 | B22: 吨 | C22: 017 | E22: 435 | F22: 1811 | G22: =Sheet1!B47 -> 511 | H22: =Sheet1!C47 -> 1775
A23: 其中：耗细粉量 | B23: 吨 | C23: 018 | E23: 435 | F23: 1811 | G23: =Sheet1!B48 -> 511 | H23: =Sheet1!C48 -> 1775
A24: 耗氨水量 | B24: 吨 | C24: 019 | E24: 10 | F24: 266 | G24: =Sheet1!B50 -> 118 | H24: =Sheet1!C50 -> 597
A25: 耗阻垢剂量 | B25: 吨 | C25: 020 | E25: 1 | F25: 3 | G25: =Sheet1!B51 -> 1 | H25: =Sheet1!C51 -> 3
A26: 耗杀菌剂量 | B26: 吨 | C26: 021 | E26: 0 | F26: 0 | G26: =Sheet1!B52 -> 0 | H26: =Sheet1!C52 -> 0
A27: 外购电量 | B27: 千瓦时 | C27: 022 | E27: 0 | F27: 0 | G27: =Sheet1!B8 -> 0 | H27: =Sheet1!C8 -> 0
A28: 综合厂用电量 | B28: 千瓦时 | C28: 023 | E28: 8207424 | F28: 35553096 | G28: =Sheet1!B9 -> 9127704 | H28: =Sheet1!C9 -> 38093400
A29: 非生产厂用电量 | B29: 千瓦时 | C29: 024 | E29: 304699 | F29: 1898811 | G29: =Sheet1!B7 -> 351721 | H29: =Sheet1!C7 -> 1313983
A30: 生产厂用电量 | B30: 千瓦时 | C30: 025 | E30: 7902725 | F30: 33654285 | G30: =G31+G32 -> 8775983 | H30: =H31+H32 -> 36779417
A31: 其中：发电厂用电量 | B31: 千瓦时 | C31: 026 | E31: 1419329.4 | F31: 6185599.5 | G31: =Sheet1!B10 -> 1141755.4 | H31: =Sheet1!C10 -> 5669696.1
A32: 供热厂用电量 | B32: 千瓦时 | C32: 027 | E32: 6483395.6 | F32: 27468686 | G32: =Sheet1!B28 -> 7634227.6 | H32: =Sheet1!C28 -> 31109721
A33: 综合厂用电率 | B33: % | C33: 028 | E33: 29.165899 | F33: 26.45159 | G33: =Sheet1!B11 -> 38.380596 | H33: =Sheet1!C11 -> 32.015479
A34: 发电厂用电率 | B34: % | C34: 029 | E34: 5.0437285 | F34: 4.6021012 | G34: =Sheet1!B12 -> 4.8009063 | H34: =Sheet1!C12 -> 4.7650783
A35: 供热厂用电率 | B35: 千瓦时/吉焦 | C35: 030 | E35: 15.027672 | F35: 13.671209 | G35: =Sheet1!B29 -> 15.450883 | H35: =Sheet1!C29 -> 14.225279
A36: 耗标煤总量 | B36: 吨 | C36: 031 | E36: 21357.715 | F36: 98174.473 | G36: =Sheet2!G37+Sheet2!G40 -> 21893.287 | H36: =Sheet2!H37+Sheet2!H40 -> 102577.99
A37: 发电标准煤耗量 | B37: 吨 | C37: 032 | E37: 3835.8456 | F37: 18053.415 | G37: =Sheet1!B13 -> 2848.3166 | H37: =Sheet1!C13 -> 15970.706
A38: 其中：煤折标准煤量 | B38: 吨 | C38: 033 | E38: 3835.8456 | F38: 18048.54 | G38: =Sheet1!B14 -> 2848.3166 | H38: =Sheet1!C14 -> 15962.585
A39: 油折标准煤量 | B39: 吨 | C39: 034 | E39: 0 | F39: 4.8748738 | G39: =Sheet1!B15 -> 0 | H39: =Sheet1!C15 -> 8.1210011
A40: 供热标准煤耗量 | B40: 吨 | C40: 035 | E40: 17521.869 | F40: 80121.058 | G40: =Sheet1!B30 -> 19044.97 | H40: =Sheet1!C30 -> 86607.286
...

Sheet Sheet1
A4: 指标名称 | B4: =H4 -> 3月 | C4: 累计 | E4: 指标名称 | F4: 1月 | G4: 2月 | H4: 3月 | I4: 4月 | J4: 5月 | K4: 6月 | L4: 7月 | M4: 8月 | N4: 9月 | O4: 10月 | P4: 11月 | Q4: 12月 | R4: 累计
A5: 发电量 | B5: =H5 -> 23782080 | C5: =R5 -> 118984320 | E5: 发电量 | F5: 57676320 | G5: 37525920 | H5: 23782080 | I5: 0 | J5: 0 | K5: 0 | L5: 0 | M5: 0 | N5: 0 | O5: 0 | P5: 0 | Q5: 0 | R5: =F5+G5+H5+I5+J5+K5+L5+M5+N5+O5+P5+Q5 -> 118984320
A6: 供电量 | B6: =H6 -> 14654376 | C6: =R6 -> 80890920 | E6: 供电量 | F6: 41137272 | G6: 25099272 | H6: 14654376 | I6: 0 | J6: 0 | K6: 0 | L6: 0 | M6: 0 | N6: 0 | O6: 0 | P6: 0 | Q6: 0 | R6: =F6+G6+H6+I6+J6+K6+L6+M6+N6+O6+P6+Q6 -> 80890920
A7: 非生产用电量 | B7: =H7 -> 351721 | C7: =R7 -> 1313983 | E7: 非生产用电量 | F7: 573928 | G7: 388334 | H7: 351721 | I7: 0 | J7: 0 | K7: 0 | L7: 0 | M7: 0 | N7: 0 | O7: 0 | P7: 0 | Q7: 0 | R7: =F7+G7+H7+I7+J7+K7+L7+M7+N7+O7+P7+Q7 -> 1313983
A8: 高备变输入电量 | B8: =H8 -> 0 | C8: =R8 -> 0 | E8: 高备变输入电量 | F8: 0 | G8: 0 | H8: 0 | I8: 0 | J8: 0 | K8: 0 | L8: 0 | M8: 0 | N8: 0 | O8: 0 | P8: 0 | Q8: 0 | R8: =F8+G8+H8+I8+J8+K8+L8+M8+N8+O8+P8+Q8 -> 0
A9: 综合厂用电量 | B9: =H9 -> 9127704 | C9: =R9 -> 38093400 | E9: 综合厂用电量 | F9: =F5-F6 -> 16539048 | G9: =G5-G6 -> 12426648 | H9: =H5-H6 -> 9127704 | I9: =I5-I6 -> 0 | J9: =J5-J6 -> 0 | K9: =K5-K6 -> 0 | L9: =L5-L6 -> 0 | M9: =M5-M6 -> 0 | ... Q9: =Q5-Q6 -> 0 | R9: =F9+G9+H9+I9+J9+K9+L9+M9+N9+O9+P9+Q9 -> 38093400
A10: 发电厂用电量 | B10: =H10 -> 1141755.4 | C10: =R10 -> 5669696.1 | E10: 发电厂用电量 | F10: =(F9-F7)*(100-F41)/100 -> 2844984.4 | G10: =(G9-G7)*(100-G41)/100 -> 1682956.3 | H10: =(H9-H7)*(100-H41)/100 -> 1141755.4 | I10: =(I9-I7)*(100-I41)/100 -> 0 | J10: =(J9-J7)*(100-J41)/100 -> 0 | K10: =(K9-K7)*(100-K41)/100 -> 0 | L10: =(L9-L7)*(100-L41)/100 -> 0 | M10: =(M9-M7)*(100-M41)/100 -> 0 | ... Q10: =(Q9-Q7)*(100-Q41)/100 -> 0 | R10: =F10+G10+H10+I10+J10+K10+L10+M10+N10+O10+P10+Q10 -> 5669696.1
A11: 综合厂用电率 | B11: =H11 -> 38.380596 | C11: =R11 -> 32.015479 | E11: 综合厂用电率 | F11: =F9/F5*100 -> 28.67563 | G11: =G9/G5*100 -> 33.114839 | H11: =H9/H5*100 -> 38.380596 | I11: =I9/I5*100 -> #DIV/0! | J11: =J9/J5*100 -> #DIV/0! | K11: =K9/K5*100 -> #DIV/0! | L11: =L9/L5*100 -> #DIV/0! | M11: =M9/M5*100 -> #DIV/0! | ... R11: =R9/R5*100 -> 32.015479
A12: 发电厂用电率 | B12: =H12 -> 4.8009063 | C12: =R12 -> 4.7650783 | E12: 发电厂用电率 | F12: =F10/F5*100 -> 4.9326732 | G12: =G10/G5*100 -> 4.4847836 | H12: =H10/H5*100 -> 4.8009063 | I12: =I10/I5*100 -> #DIV/0! | J12: =J10/J5*100 -> #DIV/0! | K12: =K10/K5*100 -> #DIV/0! | L12: =L10/L5*100 -> #DIV/0! | M12: =M10/M5*100 -> #DIV/0! | ... R12: =R10/R5*100 -> 4.7650783
A13: 发电标准煤耗量 | B13: =H13 -> 2848.3166 | C13: =R13 -> 15970.706 | E13: 发电标准煤耗量 | F13: =F14+F15 -> 8551.1287 | G13: =G14+G15 -> 4571.2606 | H13: =H14+H15 -> 2848.3166 | I13: =I14+I15 -> 0 | J13: =J14+J15 -> 0 | K13: =K14+K15 -> 0 | L13: =L14+L15 -> 0 | M13: =M14+M15 -> 0 | ... R13: =R14+R15 -> 15970.706
A14: 其中：煤折标煤 | B14: =H14 -> 2848.3166 | C14: =R14 -> 15962.585 | E14: 其中：煤折标煤 | F14: =F20*F22/29308 -> 8544.6373 | G14: =G20*G22/29308 -> 4569.631 | H14: =H20*H22/29308 -> 2848.3166 | I14: =I20*I22/29308 -> 0 | J14: =J20*J22/29308 -> 0 | K14: =K20*K22/29308 -> 0 | L14: =L20*L22/29308 -> 0 | M14: =M20*M22/29308 -> 0 | ... Q14: =Q20*Q22/29308 -> 0 | R14: =F14+G14+H14+I14+J14+K14+L14+M14+N14+O14+P14+Q14 -> 15962.585
A15: 油折标煤 | B15: =H15 -> 0 | C15: =R15 -> 8.1210011 | E15: 油折标煤 | F15: =F21*1.4571 -> 6.4913805 | G15: =G21*1.4571 -> 1.6296206 | H15: =H21*1.4571 -> 0 | I15: =I21*1.4571 -> 0 | J15: =J21*1.4571 -> 0 | K15: =K21*1.4571 -> 0 | L15: =L21*1.4571 -> 0 | M15: =M21*1.4571 -> 0 | ... Q15: =Q21*1.4571 -> 0 | R15: =F15+G15+H15+I15+J15+K15+L15+M15+N15+O15+P15+Q15 -> 8.1210011
A16: 算供电煤耗的供电量 | B16: =H16 -> 22640325 | C16: =R16 -> 1.1331462e+08 | E16: 算供电煤耗的供电量 | F16: =F5-F10 -> 54831336 | G16: =G5-G10 -> 35842964 | H16: =H5-H10 -> 22640325 | I16: =I5-I10 -> 0 | J16: =J5-J10 -> 0 | K16: =K5-K10 -> 0 | L16: =L5-L10 -> 0 | M16: =M5-M10 -> 0 | ... R16: =R5-R10 -> 1.1331462e+08
A17: 发电标准煤耗率 | B17: =H17 -> 119.76735 | C17: =R17 -> 134.2253 | E17: 发电标准煤耗率 | F17: =F13/F5*1000000 -> 148.26065 | G17: =G13/G5*1000000 -> 121.81608 | H17: =H13/H5*1000000 -> 119.76735 | I17: =I13/I5*1000000 -> #DIV/0! | J17: =J13/J5*1000000 -> #DIV/0! | K17: =K13/K5*1000000 -> #DIV/0! | L17: =L13/L5*1000000 -> #DIV/0! | M17: =M13/M5*1000000 -> #DIV/0! | ... R17: =R13/R5*1000000 -> 134.2253
A18: 供电标准煤耗率 | B18: =H18 -> 125.80723 | C18: =R18 -> 140.94126 | E18: 供电标准煤耗率 | F18: =F13/F16*1000000 -> 155.95332 | G18: =G13/G16*1000000 -> 127.53579 | H18: =H13/H16*1000000 -> 125.80723 | I18: =I13/I16*1000000 -> #DIV/0! | J18: =J13/J16*1000000 -> #DIV/0! | K18: =K13/K16*1000000 -> #DIV/0! | L18: =L13/L16*1000000 -> #DIV/0! | M18: =M13/M16*1000000 -> #DIV/0! | ... R18: =R13/R16*1000000 -> 140.94126
A19: 发电设备利用小时 | B19: =H19 -> 2378208 | C19: =R19 -> 23796864 | E19: 发电设备利用小时 | F19: =F5/10 -> 5767632 | G19: =G5/10 -> 3752592 | H19: =H5/10 -> 2378208 | I19: =I5/10 -> 0 | J19: =J5/10 -> 0 | K19: =K5/10 -> 0 | L19: =L5/10 -> 0 | M19: =M5/10 -> 0 | ... Q19: =Q5/10 -> 0 | R19: =R5/5 -> 23796864
A20: 发电耗原煤量 | B20: =H20 -> 4013.1947 | C20: =R20 -> 23799.11 | E20: 发电耗原煤量 | F20: =F42*(100-F41)/100 -> 13051.19 | G20: =G42*(100-G41)/100 -> 6734.7252 | H20: =H42*(100-H41)/100 -> 4013.1947 | I20: =I42*(100-I41)/100 -> 0 | J20: =J42*(100-J41)/100 -> 0 | K20: =K42*(100-K41)/100 -> 0 | L20: =L42*(100-L41)/100 -> 0 | M20: =M42*(100-M41)/100 -> 0 | ... Q20: =Q42*(100-Q41)/100 -> 0 | R20: =F20+G20+H20+I20+J20+K20+L20+M20+N20+O20+P20+Q20 -> 23799.11
A21: 发电耗原油量 | B21: =H21 -> 0 | C21: =R21 -> 5.5734 | E21: 发电耗原油量 | F21: =F43*(100-F41)/100 -> 4.455 | G21: =G43*(100-G41)/100 -> 1.1184 | H21: =H43*(100-H41)/100 -> 0 | I21: =I43*(100-I41)/100 -> 0 | J21: =J43*(100-J41)/100 -> 0 | K21: =K43*(100-K41)/100 -> 0 | L21: =L43*(100-L41)/100 -> 0 | M21: =M43*(100-M41)/100 -> 0 | ... Q21: =Q43*(100-Q41)/100 -> 0 | R21: =F21+G21+H21+I21+J21+K21+L21+M21+N21+O21+P21+Q21 -> 5.5734
A22: 入炉煤低位发热量 | B22: =H22 -> 20801 | C22: =R22 -> 19735.627 | E22: 入炉煤低位发热量 | F22: 19188 | G22: 19886 | H22: 20801 | I22: 0 | J22: 0 | K22: 0 | L22: 0 | M22: 0 | N22: 0 | O22: 0 | P22: 0 | Q22: 0 | R22: =(R14+R31)/(R20+R34)*29308 -> 19735.627
A23: 入厂煤低位发热量 | B23: =H23 -> 21355 | C23: =R23 -> 20100.381 | E23: 入厂煤低位发热量 | F23: 19277 | G23: 20724 | H23: 21355 | I23: 0 | J23: 0 | K23: 0 | L23: 0 | M23: 0 | N23: 0 | O23: 0 | P23: 0 | Q23: 0 | R23: =(F23*F36+G23*G36+H23*H36+I23*I36+J23*J36+K23*K36+L23*L36+M23*M36+N23*N36+O23*O36+P23*P36+Q23*Q36)/R36 -> 20100.381
A24: 总供热量 | B24: =H24 -> 494096.51 | C24: =R24 -> 2186932.3 | E24: 供热量 | F24: =F25+F26+F57 -> 967138.54 | G24: =G25+G26+G57 -> 725697.2 | H24: =H25+H26+H57 -> 494096.51 | I24: =I25+I26+I57 -> 0 | J24: =J25+J26+J57 -> 0 | K24: =K25+K26+K57 -> 0 | L24: =L25+L26+L57 -> 0 | M24: =M25+M26+M57 -> 0 | ... Q24: =Q25+Q26+Q57 -> 0 | R24: =R25+R26+R53+R57 -> 2186932.3
A25: 东、西网供热量 | B25: =H25 -> 133664.51 | C25: =R25 -> 535806.25 | E25: 东、西网供热量 | F25: =F49*2.951694 -> 229901.54 | G25: =G49*2.951694 -> 172240.2 | H25: =H49*2.951694 -> 133664.51 | I25: =I49*2.951694 -> 0 | J25: =J49*2.951694 -> 0 | K25: =K49*2.951694 -> 0 | L25: =L49*2.951694 -> 0 | M25: =M49*2.951694 -> 0 | ... Q25: =Q49*2.951694 -> 0 | R25: =F25+G25+H25+I25+J25+K25+L25+M25+N25+O25+P25+Q25 -> 535806.25
A26: 低真空供热量 | B26: =H26 -> 126938 | C26: =R26 -> 577541 | E26: 低真空供热量 | F26: 264848 | G26: 185755 | H26: 126938 | I26: 0 | J26: 0 | K26: 0 | L26: 0 | M26: 0 | N26: 0 | O26: 0 | P26: 0 | Q26: 0 | R26: =F26+G26+H26+I26+J26+K26+L26+M26+N26+O26+P26+Q26 -> 577541
A27: 售热量 | B27: =H27 -> 0 | C27: =R27 -> 0 | E27: 售热量 | F27: 0 | G27: 0 | H27: 0 | I27: 0 | J27: 0 | K27: 0 | L27: 0 | M27: 0 | N27: 0 | O27: 0 | P27: 0 | Q27: 0 | R27: =F27+G27+H27+I27+J27+K27+L27+M27+N27+O27+P27+Q27 -> 0
A28: 供热厂用电量 | B28: =H28 -> 7634227.6 | C28: =R28 -> 31109721 | E28: 供热厂用电量 | F28: =(F9-F7)*F41/100 -> 13120136 | G28: =(G9-G7)*G41/100 -> 10355358 | H28: =(H9-H7)*H41/100 -> 7634227.6 | I28: =(I9-I7)*I41/100 -> 0 | J28: =(J9-J7)*J41/100 -> 0 | K28: =(K9-K7)*K41/100 -> 0 | L28: =(L9-L7)*L41/100 -> 0 | M28: =(M9-M7)*M41/100 -> 0 | ... Q28: =(Q9-Q7)*Q41/100 -> 0 | R28: =F28+G28+H28+I28+J28+K28+L28+M28+N28+O28+P28+Q28 -> 31109721
A29: 供热厂用电率 | B29: =H29 -> 15.450883 | C29: =R29 -> 14.225279 | E29: 供热厂用电率 | F29: =F28/F24 -> 13.565932 | G29: =G28/G24 -> 14.26953 | H29: =H28/H24 -> 15.450883 | I29: =I28/I24 -> #DIV/0! | J29: =J28/J24 -> #DIV/0! | K29: =K28/K24 -> #DIV/0! | L29: =L28/L24 -> #DIV/0! | M29: =M28/M24 -> #DIV/0! | ... R29: =R28/R24 -> 14.225279
A30: 供热标准煤耗量 | B30: =H30 -> 19044.97 | C30: =R30 -> 86607.286 | E30: 供热标准煤耗量 | F30: =(F31+F32) -> 39435.003 | G30: =(G31+G32) -> 28127.313 | H30: =(H31+H32) -> 19044.97 | I30: =(I31+I32) -> 0 | J30: =(J31+J32) -> 0 | K30: =(K31+K32) -> 0 | L30: =(L31+L32) -> 0 | M30: =(M31+M32) -> 0 | ... R30: =(R31+R32) -> 86607.286
A31: 其中：煤折标煤煤量 | B31: =H31 -> 19044.97 | C31: =R31 -> 86567.323 | E31: 其中：煤折标煤煤量 | F31: =F34*F22/29308 -> 39405.067 | G31: =G34*G22/29308 -> 28117.286 | H31: =H34*H22/29308 -> 19044.97 | I31: =I34*I22/29308 -> 0 | J31: =J34*J22/29308 -> 0 | K31: =K34*K22/29308 -> 0 | L31: =L34*L22/29308 -> 0 | M31: =M34*M22/29308 -> 0 | ... Q31: =Q34*Q22/29308 -> 0 | R31: =F31+G31+H31+I31+J31+K31+L31+M31+N31+O31+P31+Q31 -> 86567.323
A32: 油折标煤煤量 | B32: =H32 -> 0 | C32: =R32 -> 39.963299 | E32: 油折标煤煤量 | F32: =F35*1.4571 -> 29.93612 | G32: =G35*1.4571 -> 10.027179 | H32: =H35*1.4571 -> 0 | I32: =I35*1.4571 -> 0 | J32: =J35*1.4571 -> 0 | K32: =K35*1.4571 -> 0 | L32: =L35*1.4571 -> 0 | M32: =M35*1.4571 -> 0 | ... R32: =R35*1.4571 -> 39.963299
A33: 供热标准煤耗率 | B33: =H33 -> 38.545041 | C33: =R33 -> 39.602181 | E33: 供热标准煤耗率 | F33: =F30*1000/F24 -> 40.774927 | G33: =G30*1000/G24 -> 38.759021 | H33: =H30*1000/H24 -> 38.545041 | I33: =I30*1000/I24 -> #DIV/0! | J33: =J30*1000/J24 -> #DIV/0! | K33: =K30*1000/K24 -> #DIV/0! | L33: =L30*1000/L24 -> #DIV/0! | M33: =M30*1000/M24 -> #DIV/0! | ... R33: =R30*1000/R24 -> 39.602181
A34: 供热耗原煤量 | B34: =H34 -> 26833.805 | C34: =R34 -> 128460.89 | E34: 供热耗原煤量 | F34: =F42*F41/100 -> 60187.81 | G34: =G42*G41/100 -> 41439.275 | H34: =H42*H41/100 -> 26833.805 | I34: =I42*I41/100 -> 0 | J34: =J42*J41/100 -> 0 | K34: =K42*K41/100 -> 0 | L34: =L42*L41/100 -> 0 | M34: =M42*M41/100 -> 0 | ... Q34: =Q42*Q41/100 -> 0 | R34: =F34+G34+H34+I34+J34+K34+L34+M34+N34+O34+P34+Q34 -> 128460.89
A35: 供热耗原油量 | B35: =H35 -> 0 | C35: =R35 -> 27.4266 | E35: 供热耗原油量 | F35: =F43*F41/100 -> 20.545 | G35: =G43*G41/100 -> 6.8816 | H35: =H43*H41/100 -> 0 | I35: =I43*I41/100 -> 0 | J35: =J43*J41/100 -> 0 | K35: =K43*K41/100 -> 0 | L35: =L43*L41/100 -> 0 | M35: =M43*M41/100 -> 0 | ... Q35: =Q43*Q41/100 -> 0 | R35: =F35+G35+H35+I35+J35+K35+L35+M35+N35+O35+P35+Q35 -> 27.4266
A36: 入厂原煤量 | B36: =H36 -> 19046 | C36: =R36 -> 135281 | E36: 入厂原煤量 | F36: 66608 | G36: 49627 | H36: 19046 | I36: 0 | J36: 0 | K36: 0 | L36: 0 | M36: 0 | N36: 0 | O36: 0 | P36: 0 | Q36: 0 | R36: =F36+G36+H36+I36+J36+K36+L36+M36+N36+O36+P36+Q36 -> 135281
A37: 库存原煤量 | B37: =H37 -> 1467 | C37: =R37 -> 0 | E37: 库存原煤量 | F37: 11815 | G37: 13268 | H37: 1467 | I37: 0 | J37: 0 | K37: 0 | L37: 0 | M37: 0 | N37: 0 | O37: 0 | P37: 0 | Q37: 0
A38: 发电最高负荷 | B38: =H38 -> 50400 | C38: =R38 -> 0 | E38: 发电最高负荷 | F38: 99840 | G38: 78240 | H38: 50400 | I38: 0 | J38: 0 | K38: 0 | L38: 0 | M38: 0 | N38: 0 | O38: 0 | P38: 0 | Q38: 0 | R38: 0
A39: 供热最高负荷 | B39: =H39 -> 87 | C39: =R39 -> 0 | E39: 供热最高负荷 | F39: 120 | G39: 120 | H39: 87 | I39: 0 | J39: 0 | K39: 0 | L39: 0 | M39: 0 | N39: 0 | O39: 0 | P39: 0 | Q39: 0 | R39: 0
A40: 工业总产值 | B40: =H40 -> 1157695.7 | C40: =R40 -> 6390382.7 | E40: 工业总产值 | F40: =(F6*790+F27*4.3)/10000 -> 3249844.5 | G40: =(G6*790+G27*4.3)/10000 -> 1982842.5 | H40: =(H6*790+H27*4.3)/10000 -> 1157695.7 | I40: =(I6*790+I27*4.3)/10000 -> 0 | J40: =(J6*790+J27*4.3)/10000 -> 0 | K40: =(K6*790+K27*4.3)/10000 -> 0 | L40: =(L6*790+L27*4.3)/10000 -> 0 | M40: =(M6*790+M27*4.3)/10000 -> 0 | ... R40: =(R6*790+R27*4.3)/10000 -> 6390382.7
A41: 热分摊比 | B41: =H41 -> 86.99 | C41: =C30*100/(C13+C30) -> 84.43067 | E41: 热分摊比 | F41: 82.18 | G41: 86.02 | H41: 86.99 | I41: 0 | J41: 0 | K41: 0 | L41: 0 | M41: 0 | N41: 0 | O41: 0 | P41: 0 | Q41: 0 | R41: 0
A42: 发电供热耗原煤量 | B42: =H42 -> 30847 | C42: =R42 -> 152260 | E42: 发电供热耗原煤量 | F42: 73239 | G42: 48174 | H42: 30847 | I42: 0 | J42: 0 | K42: 0 | L42: 0 | M42: 0 | N42: 0 | O42: 0 | P42: 0 | Q42: 0 | R42: =SUM(F42:Q42) -> 152260
A43: 发电供热耗柴油量 | B43: =H43 -> 0 | C43: =R43 -> 33 | E43: 发电供热耗柴油量 | F43: 25 | G43: 8 | H43: 0 | I43: 0 | J43: 0 | K43: 0 | L43: 0 | M43: 0 | N43: 0 | O43: 0 | P43: 0 | Q43: 0 | R43: =SUM(F43:Q43) -> 33
...
