Workbook

Sheet 26.1
A1: 大连市热电集团所属热电厂生产月报表
A2: 2026 年 1 月
A3: 指 标 名 称 | B3: 计量单位 | C3: 代码 | D3: 本 月 实 际 | J3: 本 年 累 计
D4: 合 计 | E4: 其 中 | J4: 合 计 | K4: 其 中
E5: 北海热电厂 | F5: 香海热电厂 | G5: 主城区小计 | H5: 金州热电厂 | I5: 瓦房店热电厂 | K5: 北海热电厂 | L5: 香海热电厂 | M5: 主城区小计 | N5: 金州热电厂 | O5: 瓦房店热电厂
A6: 发电机组容量 | B6: 万千瓦 | C6: 001 | D6: =G6+H6+I6 -> 26.88 | E6: 10 | F6: 10 | G6: =SUM(E6:F6) -> 20 | H6: 3.6 | I6: 3.28 | J6: =M6+N6+O6 -> 26.88 | K6: 10 | L6: 10 | M6: =SUM(K6:L6) -> 20 | N6: 3.6 | O6: 3.28
A7: 发电量 | B7: 千瓦时 | C7: 002 | D7: =G7+H7+I7 -> 156424420 | E7: =[1]产量!$C$15 -> 60753600 | F7: =[1]产量!$C$19 -> 57676320 | G7: =SUM(E7:F7) -> 118429920 | H7: 22641600 | I7: 15352900 | J7: =M7+N7+O7 -> 156424420 | K7: =E7 -> 60753600 | L7: =F7 -> 57676320 | M7: =SUM(K7:L7) -> 118429920 | N7: =H7 -> 22641600 | O7: =I7 -> 15352900
A8: 供电量 | B8: 千瓦时 | C8: 003 | D8: =G8+H8+I8 -> 105076944 | E8: =[1]产量!$E$15 -> 37145916 | F8: =[1]产量!$E$19 -> 41137272 | G8: =SUM(E8:F8) -> 78283188 | H8: 15642792 | I8: 11150964 | J8: =M8+N8+O8 -> 105076944 | K8: =E8 -> 37145916 | L8: =F8 -> 41137272 | M8: =SUM(K8:L8) -> 78283188 | N8: =H8 -> 15642792 | O8: =I8 -> 11150964
A9: 供热量 | B9: 吉焦 | C9: 004 | D9: =G9+H9+I9 -> 2809586.1 | E9: =[1]产量!$G$6 -> 980229.19 | F9: =[1]产量!$G$7 -> 967138.54 | G9: =SUM(E9:F9) -> 1947367.7 | H9: 570124 | I9: 292094.32 | J9: =M9+N9+O9 -> 2809586.1 | K9: =E9 -> 980229.19 | L9: =F9 -> 967138.54 | M9: =SUM(K9:L9) -> 1947367.7 | N9: =H9 -> 570124 | O9: =I9 -> 292094.32
A10: 其中：低真空、热泵供热量 | B10: 吉焦 | C10: 005 | D10: =G10+H10+I10 -> 377963 | F10: =[1]产量!$G$29 -> 264848 | G10: =SUM(E10:F10) -> 264848 | H10: 113115 | J10: =M10+N10+O10 -> 377963 | K10: =E10 -> 0 | L10: =F10 -> 264848 | M10: =SUM(K10:L10) -> 264848 | N10: =H10 -> 113115 | O10: =I10 -> 0
A11: 高温水网供热量 | B11: 吉焦 | C11: 006 | D11: =G11+H11+I11 -> 2097098.7 | E11: =[1]产量!$G$28 -> 875606.4 | F11: =[1]产量!$G$30 -> 472389 | G11: =SUM(E11:F11) -> 1347995.4 | H11: =H9-H10 -> 457009 | I11: 292094.32 | J11: =M11+N11+O11 -> 2097098.7 | K11: =E11 -> 875606.4 | L11: =F11 -> 472389 | M11: =SUM(K11:L11) -> 1347995.4 | N11: =H11 -> 457009 | O11: =I11 -> 292094.32
A12: 供汽量 | B12: 吨 | C12: 007 | D12: =G12+H12+I12 -> 113333 | E12: =[1]产量!$G$15 -> 35445 | F12: =[1]产量!$G$19 -> 77888 | G12: =SUM(E12:F12) -> 113333 | H12: 0 | I12: 0 | J12: =M12+N12+O12 -> 113333 | K12: =E12 -> 35445 | L12: =F12 -> 77888 | M12: =SUM(K12:L12) -> 113333 | N12: =H12 -> 0 | O12: =I12 -> 0
A13: 期末供暖收费面积 | B13: 平方米 | C13: 008 | H13: 6337791.7 | I13: 2993404 | N13: =H13 -> 6337791.7 | O13: =I13 -> 2993404
A14: 生产耗原煤量 | B14: 吨 | C14: 009 | D14: =D15+D16 -> 201466.19 | E14: =E15+E16 -> 68272 | F14: =F15+F16 -> 73239 | G14: =G15+G16 -> 141511 | H14: =H15+H16 -> 39301 | I14: =I15+I16 -> 20654.19 | J14: =J15+J16 -> 201466.19 | K14: =K15+K16 -> 68272 | ... O14: =O15+O16 -> 20654.19
A15: 发电耗原煤量 | B15: 吨 | C15: 010 | D15: =G15+H15+I15 -> 40206.772 | E15: 14337.393 | F15: 13051.19 | G15: =SUM(E15:F15) -> 27388.583 | H15: 7865 | I15: 4953.189 | J15: =M15+N15+O15 -> 40206.772 | K15: =E15 -> 14337.393 | L15: =F15 -> 13051.19 | M15: =SUM(K15:L15) -> 27388.583 | N15: =H15 -> 7865 | O15: =I15 -> 4953.189
A16: 供热耗原煤量 | B16: 吨 | C16: 011 | D16: =G16+H16+I16 -> 161259.42 | E16: 53934.607 | F16: 60187.81 | G16: =SUM(E16:F16) -> 114122.42 | H16: 31436 | I16: 15701.001 | J16: =M16+N16+O16 -> 161259.42 | K16: =E16 -> 53934.607 | L16: =F16 -> 60187.81 | M16: =SUM(K16:L16) -> 114122.42 | N16: =H16 -> 31436 | O16: =I16 -> 15701.001
A17: 锅炉耗油量 | B17: 吨 | C17: 012 | D17: =D18+D19 -> 108.5 | E17: =E18+E19 -> 69.3 | F17: =F18+F19 -> 25 | G17: =G18+G19 -> 94.3 | H17: =H18+H19 -> 14 | I17: =I18+I19 -> 0.2 | J17: =J18+J19 -> 108.5 | K17: =K18+K19 -> 69.3 | ... O17: =O18+O19 -> 0.2
A18: 发电耗油量 | B18: 吨 | C18: 013 | D18: =G18+H18+I18 -> 22.05624 | E18: 14.553277 | F18: 4.455 | G18: =SUM(E18:F18) -> 19.008277 | H18: 3 | I18: 0.047963043 | J18: =M18+N18+O18 -> 22.05624 | K18: =E18 -> 14.553277 | L18: =F18 -> 4.455 | M18: =SUM(K18:L18) -> 19.008277 | N18: =H18 -> 3 | O18: =I18 -> 0.047963043
A19: 供热耗油量 | B19: 吨 | C19: 014 | D19: =G19+H19+I19 -> 86.44376 | E19: 54.746723 | F19: 20.545 | G19: =SUM(E19:F19) -> 75.291723 | H19: 11 | I19: 0.15203696 | J19: =M19+N19+O19 -> 86.44376 | K19: =E19 -> 54.746723 | L19: =F19 -> 20.545 | M19: =SUM(K19:L19) -> 75.291723 | N19: =H19 -> 11 | O19: =I19 -> 0.15203696
A20: 耗水量 | B20: 吨 | C20: 015 | D20: =G20+H20+I20 -> 501831 | E20: 177610 | F20: 194774 | G20: =SUM(E20:F20) -> 372384 | H20: 94794 | I20: 34653 | J20: =M20+N20+O20 -> 501831 | K20: =E20 -> 177610 | L20: =F20 -> 194774 | M20: =SUM(K20:L20) -> 372384 | N20: =H20 -> 94794 | O20: =I20 -> 34653
A21: 其中：耗再生水量(或井水) | B21: 吨 | C21: 016 | D21: =G21+H21+I21 -> 132751 | E21: 121213 | G21: =SUM(E21:F21) -> 121213 | I21: 11538 | J21: =M21+N21+O21 -> 132751 | K21: =E21 -> 121213 | L21: =F21 -> 0 | M21: =SUM(K21:L21) -> 121213 | N21: =H21 -> 0 | O21: =I21 -> 11538
A22: 耗酸量 | B22: 吨 | C22: 017 | D22: =G22+H22+I22 -> 63.71 | E22: 6.4 | F22: 40 | G22: =SUM(E22:F22) -> 46.4 | H22: 15 | I22: 2.31 | J22: =M22+N22+O22 -> 63.71 | K22: =E22 -> 6.4 | L22: =F22 -> 40 | M22: =SUM(K22:L22) -> 46.4 | N22: =H22 -> 15 | O22: =I22 -> 2.31
A23: 耗碱量 | B23: 吨 | C23: 018 | D23: =G23+H23+I23 -> 54 | E23: 9.7 | F23: 32 | G23: =SUM(E23:F23) -> 41.7 | H23: 10 | I23: 2.3 | J23: =M23+N23+O23 -> 54 | K23: =E23 -> 9.7 | L23: =F23 -> 32 | M23: =SUM(K23:L23) -> 41.7 | N23: =H23 -> 10 | O23: =I23 -> 2.3
A24: 耗石灰石量 | B24: 吨 | C24: 019 | D24: =G24+H24+I24 -> 601.88 | G24: =SUM(E24:F24) -> 0 | I24: 601.88 | J24: =M24+N24+O24 -> 601.88 | K24: =E24 -> 0 | L24: =F24 -> 0 | M24: =SUM(K24:L24) -> 0 | N24: =H24 -> 0 | O24: =I24 -> 601.88
A25: 耗石灰石粉量 | B25: 吨 | C25: 020 | D25: =G25+H25+I25 -> 3965.38 | E25: 2045 | F25: 854 | G25: =SUM(E25:F25) -> 2899 | H25: 702 | I25: 364.38 | J25: =M25+N25+O25 -> 3965.38 | K25: =E25 -> 2045 | L25: =F25 -> 854 | M25: =SUM(K25:L25) -> 2899 | N25: =H25 -> 702 | O25: =I25 -> 364.38
A26: 耗氨水量 | B26: 吨 | C26: 021 | D26: =G26+H26+I26 -> 972.013 | E26: 377.74 | F26: 201 | G26: =SUM(E26:F26) -> 578.74 | H26: 319 | I26: 74.273 | J26: =M26+N26+O26 -> 972.013 | K26: =E26 -> 377.74 | L26: =F26 -> 201 | M26: =SUM(K26:L26) -> 578.74 | N26: =H26 -> 319 | O26: =I26 -> 74.273
A27: 耗阻垢剂量(水质稳定剂) | B27: 吨 | C27: 022 | D27: =G27+H27+I27 -> 3.125 | E27: 1.075 | F27: 1 | G27: =SUM(E27:F27) -> 2.075 | H27: 1 | I27: 0.05 | J27: =M27+N27+O27 -> 3.125 | K27: =E27 -> 1.075 | L27: =F27 -> 1 | M27: =SUM(K27:L27) -> 2.075 | N27: =H27 -> 1 | O27: =I27 -> 0.05
A28: 耗杀菌剂量 | B28: 吨 | C28: 023 | D28: =G28+H28+I28 -> 0 | E28: 0 | F28: 0 | G28: =SUM(E28:F28) -> 0 | H28: 0 | I28: 0 | J28: =M28+N28+O28 -> 0 | K28: =E28 -> 0 | L28: =F28 -> 0 | M28: =SUM(K28:L28) -> 0 | N28: =H28 -> 0 | O28: =I28 -> 0
A29: 耗钢球量 | B29: 吨 | C29: 024 | D29: =G29+H29+I29 -> 28 | E29: 28 | G29: =SUM(E29:F29) -> 28 | J29: =M29+N29+O29 -> 28 | K29: =E29 -> 28 | L29: =F29 -> 0 | M29: =SUM(K29:L29) -> 28 | N29: =H29 -> 0 | O29: =I29 -> 0
A30: 综合厂用电量 | B30: 千瓦时 | C30: 025 | D30: =G30+H30+I30 -> 51347476 | E30: =E7-E8 -> 23607684 | F30: =F7-F8 -> 16539048 | G30: =G7-G8 -> 40146732 | H30: =H7-H8 -> 6998808 | I30: =I7-I8 -> 4201936 | J30: =M30+N30+O30 -> 51347476 | K30: =E30 -> 23607684 | L30: =F30 -> 16539048 | M30: =M7-M8 -> 40146732 | N30: =H30 -> 6998808 | O30: =I30 -> 4201936
A31: 非生产厂用电量 | B31: 千瓦时 | C31: 026 | D31: =G31+H31+I31 -> 7167192.5 | E31: 6593264.5 | F31: 573928 | G31: =SUM(E31:F31) -> 7167192.5 | H31: 0 | I31: 0 | J31: =M31+N31+O31 -> 7167192.5 | K31: =E31 -> 6593264.5 | L31: =F31 -> 573928 | M31: =SUM(K31:L31) -> 7167192.5 | N31: =H31 -> 0 | O31: =I31 -> 0
A32: 生产厂用电量 | B32: 千瓦时 | C32: 027 | D32: =D33+D34 -> 44180283 | E32: =E33+E34 -> 17014419 | F32: =F33+F34 -> 15965120 | G32: =G33+G34 -> 32979539 | H32: =H33+H34 -> 6998808 | I32: =I33+I34 -> 4201936 | J32: =J33+J34 -> 44180283 | K32: =K33+K34 -> 17014419 | ... M32: =M33+M34 -> 32979539 | N32: =H32 -> 6998808 | O32: =I32 -> 4201936
A33: 其中：发电厂用电量 | B33: 千瓦时 | C33: 028 | D33: =G33+H33+I33 -> 8826323.6 | E33: 3573096 | F33: 2844984.4 | G33: =SUM(E33:F33) -> 6418080.4 | H33: 1400555 | I33: 1007688.2 | J33: =M33+N33+O33 -> 8826323.6 | K33: =E33 -> 3573096 | L33: =F33 -> 2844984.4 | M33: =SUM(K33:L33) -> 6418080.4 | N33: =H33 -> 1400555 | O33: =I33 -> 1007688.2
A34: 供热厂用电量 | B34: 千瓦时 | C34: 029 | D34: =G34+H34+I34 -> 35353959 | E34: 13441323 | F34: 13120136 | G34: =SUM(E34:F34) -> 26561458 | H34: 5598253 | I34: 3194247.8 | J34: =M34+N34+O34 -> 35353959 | K34: =E34 -> 13441323 | L34: =F34 -> 13120136 | M34: =SUM(K34:L34) -> 26561458 | N34: =H34 -> 5598253 | O34: =I34 -> 3194247.8
A35: 综合厂用电率 | B35: % | C35: 030 | D35: =D30*100/D7 -> 32.825742 | E35: =E30*100/E7 -> 38.858082 | F35: =F30*100/F7 -> 28.67563 | G35: =G30*100/G7 -> 33.899146 | H35: =H30*100/H7 -> 30.911278 | I35: =I30*100/I7 -> 27.369005 | J35: =J30*100/J7 -> 32.825742 | K35: =K30*100/K7 -> 38.858082 | ... O35: =O30*100/O7 -> 27.369005
A36: 发电厂用电率 | B36: % | C36: 031 | D36: =D33*100/D7 -> 5.6425484 | E36: =E33*100/E7 -> 5.881291 | F36: =F33*100/F7 -> 4.9326732 | G36: =G33*100/G7 -> 5.4193065 | H36: =H33*100/H7 -> 6.1857598 | I36: =I33*100/I7 -> 6.5635039 | J36: =J33*100/J7 -> 5.6425484 | K36: =K33*100/K7 -> 5.881291 | ... O36: =O33*100/O7 -> 6.5635039
A37: 供热厂用电率 | B37: 千瓦时/吉焦 | C37: 032 | D37: =D34/D9 -> 12.583334 | E37: =E34/E9 -> 13.712429 | F37: =F34/F9 -> 13.565932 | G37: =G34/G9 -> 13.639673 | H37: =H34/H9 -> 9.8193603 | I37: =I34/I9 -> 10.935672 | J37: =J34/J9 -> 12.583334 | K37: =K34/K9 -> 13.712429 | ... O37: =O34/O9 -> 10.935672
A38: 耗标煤总量 | B38: 吨 | C38: 033 | D38: =D39+D42 -> 137897.36 | E38: =E39+E42 -> 46848.881 | F38: =F39+F42 -> 47986.132 | G38: =G39+G42 -> 94835.013 | H38: =H39+H42 -> 28210 | I38: =I39+I42 -> 14852.348 | J38: =J39+J42 -> 137897.36 | K38: =K39+K42 -> 46848.881 | ... O38: =O39+O42 -> 14852.348
A39: 发电标准煤耗量 | B39: 吨 | C39: 034 | D39: =D40+D41 -> 27596.4 | E39: =E40+E41 -> 9838.4525 | F39: =F40+F41 -> 8551.1287 | G39: =G40+G41 -> 18389.581 | H39: =H40+H41 -> 5645 | I39: =I40+I41 -> 3561.819 | J39: =J40+J41 -> 27596.4 | K39: =K40+K41 -> 9838.4525 | ... O39: =O40+O41 -> 3561.819
A40: 其中：煤折标准煤量 | B40: 吨 | C40: 035 | D40: =G40+H40+I40 -> 27564.635 | E40: 9817.2469 | F40: 8544.6373 | G40: =SUM(E40:F40) -> 18361.884 | H40: 5641 | I40: 3561.7504 | J40: =M40+N40+O40 -> 27564.635 | K40: =E40 -> 9817.2469 | L40: =F40 -> 8544.6373 | M40: =SUM(K40:L40) -> 18361.884 | N40: =H40 -> 5641 | O40: =I40 -> 3561.7504
...

Sheet 26.2
A1: 大连市热电集团所属热电厂生产月报表
A2: 2026 年 2 月
A3: 指 标 名 称 | B3: 计量单位 | C3: 代码 | D3: 本 月 实 际 | J3: 本 年 累 计
D4: 合 计 | E4: 其 中 | J4: 合 计 | K4: 其 中
E5: 北海热电厂 | F5: 香海热电厂 | G5: 主城区小计 | H5: 金州热电厂 | I5: 瓦房店热电厂 | K5: 北海热电厂 | L5: 香海热电厂 | M5: 主城区小计 | N5: 金州热电厂 | O5: 瓦房店热电厂
A6: 发电机组容量 | B6: 万千瓦 | C6: 001 | D6: =G6+H6+I6 -> 26.88 | E6: 10 | F6: 10 | G6: =SUM(E6:F6) -> 20 | H6: 3.6 | I6: =3.96-0.68 -> 3.28 | J6: =M6+N6+O6 -> 26.88 | K6: 10 | L6: 10 | M6: =SUM(K6:L6) -> 20 | N6: 3.6 | O6: 3.28
A7: 发电量 | B7: 千瓦时 | C7: 002 | D7: =G7+H7+I7 -> 0 | E7: =[2]产量!$C$15 -> 0 | F7: =[2]产量!$C$19 -> 0 | G7: =SUM(E7:F7) -> 0 | J7: =M7+N7+O7 -> 156424420 | K7: =E7+'26.1'!K7 -> 60753600 | L7: =F7+'26.1'!L7 -> 57676320 | M7: =SUM(K7:L7) -> 118429920 | N7: =H7+'26.1'!N7 -> 22641600 | O7: =I7+'26.1'!O7 -> 15352900
A8: 供电量 | B8: 千瓦时 | C8: 003 | D8: =G8+H8+I8 -> 0 | E8: =[2]产量!$E$15 -> 0 | F8: =[2]产量!$E$19 -> 0 | G8: =SUM(E8:F8) -> 0 | J8: =M8+N8+O8 -> 105076944 | K8: =E8+'26.1'!K8 -> 37145916 | L8: =F8+'26.1'!L8 -> 41137272 | M8: =SUM(K8:L8) -> 78283188 | N8: =H8+'26.1'!N8 -> 15642792 | O8: =I8+'26.1'!O8 -> 11150964
A9: 供热量 | B9: 吉焦 | C9: 004 | D9: =G9+H9+I9 -> 0 | E9: =[2]产量!$G$6 -> 0 | F9: =[2]产量!$G$7 -> 0 | G9: =SUM(E9:F9) -> 0 | J9: =M9+N9+O9 -> 2809586.1 | K9: =E9+'26.1'!K9 -> 980229.19 | L9: =F9+'26.1'!L9 -> 967138.54 | M9: =SUM(K9:L9) -> 1947367.7 | N9: =H9+'26.1'!N9 -> 570124 | O9: =I9+'26.1'!O9 -> 292094.32
A10: 其中：低真空、热泵供热量 | B10: 吉焦 | C10: 005 | D10: =G10+H10+I10 -> 0 | F10: =[2]产量!$G$29 -> 0 | G10: =SUM(E10:F10) -> 0 | J10: =M10+N10+O10 -> 377963 | K10: =E10+'26.1'!K10 -> 0 | L10: =F10+'26.1'!L10 -> 264848 | M10: =SUM(K10:L10) -> 264848 | N10: =H10+'26.1'!N10 -> 113115 | O10: =I10+'26.1'!O10 -> 0
A11: 高温水网供热量 | B11: 吉焦 | C11: 006 | D11: =G11+H11+I11 -> 0 | E11: =[2]产量!$G$28 -> 0 | F11: =[2]产量!$G$30 -> 0 | G11: =SUM(E11:F11) -> 0 | H11: =H9-H10 -> 0 | I11: =I9-I10 -> 0 | J11: =M11+N11+O11 -> 2097098.7 | K11: =E11+'26.1'!K11 -> 875606.4 | L11: =F11+'26.1'!L11 -> 472389 | M11: =SUM(K11:L11) -> 1347995.4 | N11: =H11+'26.1'!N11 -> 457009 | O11: =I11+'26.1'!O11 -> 292094.32
A12: 供汽量 | B12: 吨 | C12: 007 | D12: =G12+H12+I12 -> 0 | E12: =[2]产量!$G$15 -> 0 | F12: =[2]产量!$G$19 -> 0 | G12: =SUM(E12:F12) -> 0 | H12: 0 | J12: =M12+N12+O12 -> 113333 | K12: =E12+'26.1'!K12 -> 35445 | L12: =F12+'26.1'!L12 -> 77888 | M12: =SUM(K12:L12) -> 113333 | N12: =H12+'26.1'!N12 -> 0 | O12: =I12+'26.1'!O12 -> 0
A13: 期末供暖收费面积 | B13: 平方米 | C13: 008 | N13: =H13 -> 0 | O13: =I13 -> 0
A14: 生产耗原煤量 | B14: 吨 | C14: 009 | D14: =D15+D16 -> 0 | E14: =E15+E16 -> 0 | F14: =F15+F16 -> 0 | G14: =G15+G16 -> 0 | H14: =H15+H16 -> 0 | I14: =I15+I16 -> 0 | J14: =J15+J16 -> 201466.19 | K14: =K15+K16 -> 68272 | ... O14: =O15+O16 -> 20654.19
A15: 发电耗原煤量 | B15: 吨 | C15: 010 | D15: =G15+H15+I15 -> 0 | G15: =SUM(E15:F15) -> 0 | J15: =M15+N15+O15 -> 40206.772 | K15: =E15+'26.1'!K15 -> 14337.393 | L15: =F15+'26.1'!L15 -> 13051.19 | M15: =SUM(K15:L15) -> 27388.583 | N15: =H15+'26.1'!N15 -> 7865 | O15: =I15+'26.1'!O15 -> 4953.189
A16: 供热耗原煤量 | B16: 吨 | C16: 011 | D16: =G16+H16+I16 -> 0 | G16: =SUM(E16:F16) -> 0 | J16: =M16+N16+O16 -> 161259.42 | K16: =E16+'26.1'!K16 -> 53934.607 | L16: =F16+'26.1'!L16 -> 60187.81 | M16: =SUM(K16:L16) -> 114122.42 | N16: =H16+'26.1'!N16 -> 31436 | O16: =I16+'26.1'!O16 -> 15701.001
A17: 锅炉耗油量 | B17: 吨 | C17: 012 | D17: =D18+D19 -> 0 | E17: =E18+E19 -> 0 | F17: =F18+F19 -> 0 | G17: =G18+G19 -> 0 | H17: =H18+H19 -> 0 | I17: =I18+I19 -> 0 | J17: =J18+J19 -> 108.5 | K17: =K18+K19 -> 69.3 | ... O17: =O18+O19 -> 0.2
A18: 发电耗油量 | B18: 吨 | C18: 013 | D18: =G18+H18+I18 -> 0 | G18: =SUM(E18:F18) -> 0 | J18: =M18+N18+O18 -> 22.05624 | K18: =E18+'26.1'!K18 -> 14.553277 | L18: =F18+'26.1'!L18 -> 4.455 | M18: =SUM(K18:L18) -> 19.008277 | N18: =H18+'26.1'!N18 -> 3 | O18: =I18+'26.1'!O18 -> 0.047963043
A19: 供热耗油量 | B19: 吨 | C19: 014 | D19: =G19+H19+I19 -> 0 | G19: =SUM(E19:F19) -> 0 | J19: =M19+N19+O19 -> 86.44376 | K19: =E19+'26.1'!K19 -> 54.746723 | L19: =F19+'26.1'!L19 -> 20.545 | M19: =SUM(K19:L19) -> 75.291723 | N19: =H19+'26.1'!N19 -> 11 | O19: =I19+'26.1'!O19 -> 0.15203696
A20: 耗水量 | B20: 吨 | C20: 015 | D20: =G20+H20+I20 -> 0 | G20: =SUM(E20:F20) -> 0 | J20: =M20+N20+O20 -> 501831 | K20: =E20+'26.1'!K20 -> 177610 | L20: =F20+'26.1'!L20 -> 194774 | M20: =SUM(K20:L20) -> 372384 | N20: =H20+'26.1'!N20 -> 94794 | O20: =I20+'26.1'!O20 -> 34653
A21: 其中：耗再生水量(或井水) | B21: 吨 | C21: 016 | D21: =G21+H21+I21 -> 0 | G21: =SUM(E21:F21) -> 0 | J21: =M21+N21+O21 -> 132751 | K21: =E21+'26.1'!K21 -> 121213 | L21: =F21+'26.1'!L21 -> 0 | M21: =SUM(K21:L21) -> 121213 | N21: =H21+'26.1'!N21 -> 0 | O21: =I21+'26.1'!O21 -> 11538
A22: 耗酸量 | B22: 吨 | C22: 017 | D22: =G22+H22+I22 -> 0 | G22: =SUM(E22:F22) -> 0 | J22: =M22+N22+O22 -> 63.71 | K22: =E22+'26.1'!K22 -> 6.4 | L22: =F22+'26.1'!L22 -> 40 | M22: =SUM(K22:L22) -> 46.4 | N22: =H22+'26.1'!N22 -> 15 | O22: =I22+'26.1'!O22 -> 2.31
A23: 耗碱量 | B23: 吨 | C23: 018 | D23: =G23+H23+I23 -> 0 | G23: =SUM(E23:F23) -> 0 | J23: =M23+N23+O23 -> 54 | K23: =E23+'26.1'!K23 -> 9.7 | L23: =F23+'26.1'!L23 -> 32 | M23: =SUM(K23:L23) -> 41.7 | N23: =H23+'26.1'!N23 -> 10 | O23: =I23+'26.1'!O23 -> 2.3
A24: 耗石灰石量 | B24: 吨 | C24: 019 | D24: =G24+H24+I24 -> 0 | G24: =SUM(E24:F24) -> 0 | J24: =M24+N24+O24 -> 601.88 | K24: =E24+'26.1'!K24 -> 0 | L24: =F24+'26.1'!L24 -> 0 | M24: =SUM(K24:L24) -> 0 | N24: =H24+'26.1'!N24 -> 0 | O24: =I24+'26.1'!O24 -> 601.88
A25: 耗石灰石粉量 | B25: 吨 | C25: 020 | D25: =G25+H25+I25 -> 0 | G25: =SUM(E25:F25) -> 0 | J25: =M25+N25+O25 -> 3965.38 | K25: =E25+'26.1'!K25 -> 2045 | L25: =F25+'26.1'!L25 -> 854 | M25: =SUM(K25:L25) -> 2899 | N25: =H25+'26.1'!N25 -> 702 | O25: =I25+'26.1'!O25 -> 364.38
A26: 耗氨水量 | B26: 吨 | C26: 021 | D26: =G26+H26+I26 -> 0 | G26: =SUM(E26:F26) -> 0 | J26: =M26+N26+O26 -> 972.013 | K26: =E26+'26.1'!K26 -> 377.74 | L26: =F26+'26.1'!L26 -> 201 | M26: =SUM(K26:L26) -> 578.74 | N26: =H26+'26.1'!N26 -> 319 | O26: =I26+'26.1'!O26 -> 74.273
A27: 耗阻垢剂量(水质稳定剂) | B27: 吨 | C27: 022 | D27: =G27+H27+I27 -> 0 | G27: =SUM(E27:F27) -> 0 | J27: =M27+N27+O27 -> 3.125 | K27: =E27+'26.1'!K27 -> 1.075 | L27: =F27+'26.1'!L27 -> 1 | M27: =SUM(K27:L27) -> 2.075 | N27: =H27+'26.1'!N27 -> 1 | O27: =I27+'26.1'!O27 -> 0.05
A28: 耗杀菌剂量 | B28: 吨 | C28: 023 | D28: =G28+H28+I28 -> 0 | G28: =SUM(E28:F28) -> 0 | J28: =M28+N28+O28 -> 0 | K28: =E28+'26.1'!K28 -> 0 | L28: =F28+'26.1'!L28 -> 0 | M28: =SUM(K28:L28) -> 0 | N28: =H28+'26.1'!N28 -> 0 | O28: =I28+'26.1'!O28 -> 0
A29: 耗钢球量 | B29: 吨 | C29: 024 | D29: =G29+H29+I29 -> 0 | G29: =SUM(E29:F29) -> 0 | J29: =M29+N29+O29 -> 28 | K29: =E29+'26.1'!K29 -> 28 | L29: =F29+'26.1'!L29 -> 0 | M29: =SUM(K29:L29) -> 28 | N29: =H29+'26.1'!N29 -> 0 | O29: =I29+'26.1'!O29 -> 0
A30: 综合厂用电量 | B30: 千瓦时 | C30: 025 | D30: =G30+H30+I30 -> 0 | E30: =E7-E8 -> 0 | F30: =F7-F8 -> 0 | G30: =G7-G8 -> 0 | H30: =H7-H8 -> 0 | I30: =I7-I8 -> 0 | J30: =M30+N30+O30 -> 51347476 | K30: =E30+'26.1'!K30 -> 23607684 | L30: =F30+'26.1'!L30 -> 16539048 | M30: =M7-M8 -> 40146732 | N30: =H30+'26.1'!N30 -> 6998808 | O30: =I30+'26.1'!O30 -> 4201936
A31: 非生产厂用电量 | B31: 千瓦时 | C31: 026 | D31: =G31+H31+I31 -> 0 | G31: =SUM(E31:F31) -> 0 | J31: =M31+N31+O31 -> 7167192.5 | K31: =E31+'26.1'!K31 -> 6593264.5 | L31: =F31+'26.1'!L31 -> 573928 | M31: =SUM(K31:L31) -> 7167192.5 | N31: =H31+'26.1'!N31 -> 0 | O31: =I31+'26.1'!O31 -> 0
A32: 生产厂用电量 | B32: 千瓦时 | C32: 027 | D32: =D33+D34 -> 0 | E32: =E33+E34 -> 0 | F32: =F33+F34 -> 0 | G32: =G33+G34 -> 0 | H32: =H33+H34 -> 0 | I32: =I33+I34 -> 0 | J32: =J33+J34 -> 44180283 | K32: =K33+K34 -> 17014419 | ... O32: =O33+O34 -> 4201936
A33: 其中：发电厂用电量 | B33: 千瓦时 | C33: 028 | D33: =G33+H33+I33 -> 0 | G33: =SUM(E33:F33) -> 0 | J33: =M33+N33+O33 -> 8826323.6 | K33: =E33+'26.1'!K33 -> 3573096 | L33: =F33+'26.1'!L33 -> 2844984.4 | M33: =SUM(K33:L33) -> 6418080.4 | N33: =H33+'26.1'!N33 -> 1400555 | O33: =I33+'26.1'!O33 -> 1007688.2
A34: 供热厂用电量 | B34: 千瓦时 | C34: 029 | D34: =G34+H34+I34 -> 0 | G34: =SUM(E34:F34) -> 0 | J34: =M34+N34+O34 -> 35353959 | K34: =E34+'26.1'!K34 -> 13441323 | L34: =F34+'26.1'!L34 -> 13120136 | M34: =SUM(K34:L34) -> 26561458 | N34: =H34+'26.1'!N34 -> 5598253 | O34: =I34+'26.1'!O34 -> 3194247.8
A35: 综合厂用电率 | B35: % | C35: 030 | D35: =D30*100/D7 -> #DIV/0! | E35: =E30*100/E7 -> #DIV/0! | F35: =F30*100/F7 -> #DIV/0! | G35: =G30*100/G7 -> #DIV/0! | H35: =H30*100/H7 -> #DIV/0! | I35: =I30*100/I7 -> #DIV/0! | J35: =J30*100/J7 -> 32.825742 | K35: =K30*100/K7 -> 38.858082 | ... O35: =O30*100/O7 -> 27.369005
A36: 发电厂用电率 | B36: % | C36: 031 | D36: =D33*100/D7 -> #DIV/0! | E36: =E33*100/E7 -> #DIV/0! | F36: =F33*100/F7 -> #DIV/0! | G36: =G33*100/G7 -> #DIV/0! | H36: =H33*100/H7 -> #DIV/0! | I36: =I33*100/I7 -> #DIV/0! | J36: =J33*100/J7 -> 5.6425484 | K36: =K33*100/K7 -> 5.881291 | ... O36: =O33*100/O7 -> 6.5635039
A37: 供热厂用电率 | B37: 千瓦时/吉焦 | C37: 032 | D37: =D34/D9 -> #DIV/0! | E37: =E34/E9 -> #DIV/0! | F37: =F34/F9 -> #DIV/0! | G37: =G34/G9 -> #DIV/0! | H37: =H34/H9 -> #DIV/0! | I37: =I34/I9 -> #DIV/0! | J37: =J34/J9 -> 12.583334 | K37: =K34/K9 -> 13.712429 | ... O37: =O34/O9 -> 10.935672
A38: 耗标煤总量 | B38: 吨 | C38: 033 | D38: =D39+D42 -> 0 | E38: =E39+E42 -> 0 | F38: =F39+F42 -> 0 | G38: =G39+G42 -> 0 | H38: =H39+H42 -> 0 | I38: =I39+I42 -> 0 | J38: =J39+J42 -> 137897.36 | K38: =K39+K42 -> 46848.881 | ... O38: =O39+O42 -> 14852.348
A39: 发电标准煤耗量 | B39: 吨 | C39: 034 | D39: =D40+D41 -> 0 | E39: =E40+E41 -> 0 | F39: =F40+F41 -> 0 | G39: =G40+G41 -> 0 | H39: =H40+H41 -> 0 | I39: =I40+I41 -> 0 | J39: =J40+J41 -> 27596.4 | K39: =K40+K41 -> 9838.4525 | ... O39: =O40+O41 -> 3561.819
A40: 其中：煤折标准煤量 | B40: 吨 | C40: 035 | D40: =G40+H40+I40 -> 0 | G40: =SUM(E40:F40) -> 0 | J40: =M40+N40+O40 -> 27564.635 | K40: =E40+'26.1'!K40 -> 9817.2469 | L40: =F40+'26.1'!L40 -> 8544.6373 | M40: =SUM(K40:L40) -> 18361.884 | N40: =H40+'26.1'!N40 -> 5641 | O40: =I40+'26.1'!O40 -> 3561.7504
...

Sheet 26.3
A1: 大连市热电集团所属热电厂生产月报表
A2: 2026 年 3 月
A3: 指 标 名 称 | B3: 计量单位 | C3: 代码 | D3: 本 月 实 际 | J3: 本 年 累 计
D4: 合 计 | E4: 其 中 | J4: 合 计 | K4: 其 中
E5: 北海热电厂 | F5: 香海热电厂 | G5: 主城区小计 | H5: 金州热电厂 | I5: 瓦房店热电厂 | K5: 北海热电厂 | L5: 香海热电厂 | M5: 主城区小计 | N5: 金州热电厂 | O5: 瓦房店热电厂
A6: 发电机组容量 | B6: 万千瓦 | C6: 001 | D6: =G6+H6+I6 -> 26.88 | E6: 10 | F6: 10 | G6: =SUM(E6:F6) -> 20 | H6: 3.6 | I6: =3.96-0.68 -> 3.28 | J6: =M6+N6+O6 -> 26.88 | K6: 10 | L6: 10 | M6: =SUM(K6:L6) -> 20 | N6: 3.6 | O6: 3.28
A7: 发电量 | B7: 千瓦时 | C7: 002 | D7: =G7+H7+I7 -> 0 | E7: =[3]产量!$C$15 -> 0 | F7: =[3]产量!$C$19 -> 0 | G7: =SUM(E7:F7) -> 0 | J7: =M7+N7+O7 -> 156424420 | K7: =E7+'26.2'!K7 -> 60753600 | L7: =F7+'26.2'!L7 -> 57676320 | M7: =SUM(K7:L7) -> 118429920 | N7: =H7+'26.2'!N7 -> 22641600 | O7: =I7+'26.2'!O7 -> 15352900
A8: 供电量 | B8: 千瓦时 | C8: 003 | D8: =G8+H8+I8 -> 0 | E8: =[3]产量!$E$15 -> 0 | F8: =[3]产量!$E$19 -> 0 | G8: =SUM(E8:F8) -> 0 | J8: =M8+N8+O8 -> 105076944 | K8: =E8+'26.2'!K8 -> 37145916 | L8: =F8+'26.2'!L8 -> 41137272 | M8: =SUM(K8:L8) -> 78283188 | N8: =H8+'26.2'!N8 -> 15642792 | O8: =I8+'26.2'!O8 -> 11150964
A9: 供热量 | B9: 吉焦 | C9: 004 | D9: =G9+H9+I9 -> 0 | E9: =[3]产量!$G$6 -> 0 | F9: =[3]产量!$G$7 -> 0 | G9: =SUM(E9:F9) -> 0 | J9: =M9+N9+O9 -> 2809586.1 | K9: =E9+'26.2'!K9 -> 980229.19 | L9: =F9+'26.2'!L9 -> 967138.54 | M9: =SUM(K9:L9) -> 1947367.7 | N9: =H9+'26.2'!N9 -> 570124 | O9: =I9+'26.2'!O9 -> 292094.32
A10: 其中：低真空、热泵供热量 | B10: 吉焦 | C10: 005 | D10: =G10+H10+I10 -> 0 | F10: =[3]产量!$G$29 -> 0 | G10: =SUM(E10:F10) -> 0 | J10: =M10+N10+O10 -> 377963 | K10: =E10+'26.2'!K10 -> 0 | L10: =F10+'26.2'!L10 -> 264848 | M10: =SUM(K10:L10) -> 264848 | N10: =H10+'26.2'!N10 -> 113115 | O10: =I10+'26.2'!O10 -> 0
A11: 高温水网供热量 | B11: 吉焦 | C11: 006 | D11: =G11+H11+I11 -> 0 | E11: =[3]产量!$G$28 -> 0 | F11: =[3]产量!$G$30 -> 0 | G11: =SUM(E11:F11) -> 0 | H11: =H9-H10 -> 0 | I11: =I9-I10 -> 0 | J11: =M11+N11+O11 -> 2097098.7 | K11: =E11+'26.2'!K11 -> 875606.4 | L11: =F11+'26.2'!L11 -> 472389 | M11: =SUM(K11:L11) -> 1347995.4 | N11: =H11+'26.2'!N11 -> 457009 | O11: =I11+'26.2'!O11 -> 292094.32
A12: 供汽量 | B12: 吨 | C12: 007 | D12: =G12+H12+I12 -> 0 | E12: =[3]产量!$G$15 -> 0 | F12: =[3]产量!$G$19 -> 0 | G12: =SUM(E12:F12) -> 0 | H12: 0 | I12: 0 | J12: =M12+N12+O12 -> 113333 | K12: =E12+'26.2'!K12 -> 35445 | L12: =F12+'26.2'!L12 -> 77888 | M12: =SUM(K12:L12) -> 113333 | N12: =H12+'26.2'!N12 -> 0 | O12: =I12+'26.2'!O12 -> 0
A13: 期末供暖收费面积 | B13: 平方米 | C13: 008 | N13: =H13 -> 0 | O13: =I13 -> 0
A14: 生产耗原煤量 | B14: 吨 | C14: 009 | D14: =D15+D16 -> 0 | E14: =E15+E16 -> 0 | F14: =F15+F16 -> 0 | G14: =G15+G16 -> 0 | H14: =H15+H16 -> 0 | I14: =I15+I16 -> 0 | J14: =J15+J16 -> 201466.19 | K14: =K15+K16 -> 68272 | ... O14: =O15+O16 -> 20654.19
A15: 发电耗原煤量 | B15: 吨 | C15: 010 | D15: =G15+H15+I15 -> 0 | G15: =SUM(E15:F15) -> 0 | J15: =M15+N15+O15 -> 40206.772 | K15: =E15+'26.2'!K15 -> 14337.393 | L15: =F15+'26.2'!L15 -> 13051.19 | M15: =SUM(K15:L15) -> 27388.583 | N15: =H15+'26.2'!N15 -> 7865 | O15: =I15+'26.2'!O15 -> 4953.189
A16: 供热耗原煤量 | B16: 吨 | C16: 011 | D16: =G16+H16+I16 -> 0 | G16: =SUM(E16:F16) -> 0 | J16: =M16+N16+O16 -> 161259.42 | K16: =E16+'26.2'!K16 -> 53934.607 | L16: =F16+'26.2'!L16 -> 60187.81 | M16: =SUM(K16:L16) -> 114122.42 | N16: =H16+'26.2'!N16 -> 31436 | O16: =I16+'26.2'!O16 -> 15701.001
A17: 锅炉耗油量 | B17: 吨 | C17: 012 | D17: =D18+D19 -> 0 | E17: =E18+E19 -> 0 | F17: =F18+F19 -> 0 | G17: =G18+G19 -> 0 | H17: =H18+H19 -> 0 | I17: =I18+I19 -> 0 | J17: =J18+J19 -> 108.5 | K17: =K18+K19 -> 69.3 | ... O17: =O18+O19 -> 0.2
A18: 发电耗油量 | B18: 吨 | C18: 013 | D18: =G18+H18+I18 -> 0 | G18: =SUM(E18:F18) -> 0 | J18: =M18+N18+O18 -> 22.05624 | K18: =E18+'26.2'!K18 -> 14.553277 | L18: =F18+'26.2'!L18 -> 4.455 | M18: =SUM(K18:L18) -> 19.008277 | N18: =H18+'26.2'!N18 -> 3 | O18: =I18+'26.2'!O18 -> 0.047963043
A19: 供热耗油量 | B19: 吨 | C19: 014 | D19: =G19+H19+I19 -> 0 | G19: =SUM(E19:F19) -> 0 | J19: =M19+N19+O19 -> 86.44376 | K19: =E19+'26.2'!K19 -> 54.746723 | L19: =F19+'26.2'!L19 -> 20.545 | M19: =SUM(K19:L19) -> 75.291723 | N19: =H19+'26.2'!N19 -> 11 | O19: =I19+'26.2'!O19 -> 0.15203696
A20: 耗水量 | B20: 吨 | C20: 015 | D20: =G20+H20+I20 -> 0 | G20: =SUM(E20:F20) -> 0 | J20: =M20+N20+O20 -> 501831 | K20: =E20+'26.2'!K20 -> 177610 | L20: =F20+'26.2'!L20 -> 194774 | M20: =SUM(K20:L20) -> 372384 | N20: =H20+'26.2'!N20 -> 94794 | O20: =I20+'26.2'!O20 -> 34653
A21: 其中：耗再生水量(或井水) | B21: 吨 | C21: 016 | D21: =G21+H21+I21 -> 0 | G21: =SUM(E21:F21) -> 0 | J21: =M21+N21+O21 -> 132751 | K21: =E21+'26.2'!K21 -> 121213 | L21: =F21+'26.2'!L21 -> 0 | M21: =SUM(K21:L21) -> 121213 | N21: =H21+'26.2'!N21 -> 0 | O21: =I21+'26.2'!O21 -> 11538
A22: 耗酸量 | B22: 吨 | C22: 017 | D22: =G22+H22+I22 -> 0 | G22: =SUM(E22:F22) -> 0 | J22: =M22+N22+O22 -> 63.71 | K22: =E22+'26.2'!K22 -> 6.4 | L22: =F22+'26.2'!L22 -> 40 | M22: =SUM(K22:L22) -> 46.4 | N22: =H22+'26.2'!N22 -> 15 | O22: =I22+'26.2'!O22 -> 2.31
A23: 耗碱量 | B23: 吨 | C23: 018 | D23: =G23+H23+I23 -> 0 | G23: =SUM(E23:F23) -> 0 | J23: =M23+N23+O23 -> 54 | K23: =E23+'26.2'!K23 -> 9.7 | L23: =F23+'26.2'!L23 -> 32 | M23: =SUM(K23:L23) -> 41.7 | N23: =H23+'26.2'!N23 -> 10 | O23: =I23+'26.2'!O23 -> 2.3
A24: 耗石灰石量 | B24: 吨 | C24: 019 | D24: =G24+H24+I24 -> 0 | G24: =SUM(E24:F24) -> 0 | J24: =M24+N24+O24 -> 601.88 | K24: =E24+'26.2'!K24 -> 0 | L24: =F24+'26.2'!L24 -> 0 | M24: =SUM(K24:L24) -> 0 | N24: =H24+'26.2'!N24 -> 0 | O24: =I24+'26.2'!O24 -> 601.88
A25: 耗石灰石粉量 | B25: 吨 | C25: 020 | D25: =G25+H25+I25 -> 0 | G25: =SUM(E25:F25) -> 0 | J25: =M25+N25+O25 -> 3965.38 | K25: =E25+'26.2'!K25 -> 2045 | L25: =F25+'26.2'!L25 -> 854 | M25: =SUM(K25:L25) -> 2899 | N25: =H25+'26.2'!N25 -> 702 | O25: =I25+'26.2'!O25 -> 364.38
A26: 耗氨水量 | B26: 吨 | C26: 021 | D26: =G26+H26+I26 -> 0 | G26: =SUM(E26:F26) -> 0 | J26: =M26+N26+O26 -> 972.013 | K26: =E26+'26.2'!K26 -> 377.74 | L26: =F26+'26.2'!L26 -> 201 | M26: =SUM(K26:L26) -> 578.74 | N26: =H26+'26.2'!N26 -> 319 | O26: =I26+'26.2'!O26 -> 74.273
A27: 耗阻垢剂量(水质稳定剂) | B27: 吨 | C27: 022 | D27: =G27+H27+I27 -> 0 | G27: =SUM(E27:F27) -> 0 | J27: =M27+N27+O27 -> 3.125 | K27: =E27+'26.2'!K27 -> 1.075 | L27: =F27+'26.2'!L27 -> 1 | M27: =SUM(K27:L27) -> 2.075 | N27: =H27+'26.2'!N27 -> 1 | O27: =I27+'26.2'!O27 -> 0.05
A28: 耗杀菌剂量 | B28: 吨 | C28: 023 | D28: =G28+H28+I28 -> 0 | G28: =SUM(E28:F28) -> 0 | J28: =M28+N28+O28 -> 0 | K28: =E28+'26.2'!K28 -> 0 | L28: =F28+'26.2'!L28 -> 0 | M28: =SUM(K28:L28) -> 0 | N28: =H28+'26.2'!N28 -> 0 | O28: =I28+'26.2'!O28 -> 0
A29: 耗钢球量 | B29: 吨 | C29: 024 | D29: =G29+H29+I29 -> 0 | G29: =SUM(E29:F29) -> 0 | J29: =M29+N29+O29 -> 28 | K29: =E29+'26.2'!K29 -> 28 | L29: =F29+'26.2'!L29 -> 0 | M29: =SUM(K29:L29) -> 28 | N29: =H29+'26.2'!N29 -> 0 | O29: =I29+'26.2'!O29 -> 0
A30: 综合厂用电量 | B30: 千瓦时 | C30: 025 | D30: =G30+H30+I30 -> 0 | E30: =E7-E8 -> 0 | F30: =F7-F8 -> 0 | G30: =G7-G8 -> 0 | H30: =H7-H8 -> 0 | I30: =I7-I8 -> 0 | J30: =M30+N30+O30 -> 51347476 | K30: =E30+'26.2'!K30 -> 23607684 | L30: =F30+'26.2'!L30 -> 16539048 | M30: =M7-M8 -> 40146732 | N30: =H30+'26.2'!N30 -> 6998808 | O30: =I30+'26.2'!O30 -> 4201936
A31: 非生产厂用电量 | B31: 千瓦时 | C31: 026 | D31: =G31+H31+I31 -> 0 | G31: =SUM(E31:F31) -> 0 | H31: 0 | J31: =M31+N31+O31 -> 7167192.5 | K31: =E31+'26.2'!K31 -> 6593264.5 | L31: =F31+'26.2'!L31 -> 573928 | M31: =SUM(K31:L31) -> 7167192.5 | N31: =H31+'26.2'!N31 -> 0 | O31: =I31+'26.2'!O31 -> 0
A32: 生产厂用电量 | B32: 千瓦时 | C32: 027 | D32: =D33+D34 -> 0 | E32: =E33+E34 -> 0 | F32: =F33+F34 -> 0 | G32: =G33+G34 -> 0 | H32: =H33+H34 -> 0 | I32: =I33+I34 -> 0 | J32: =J33+J34 -> 44180283 | K32: =K33+K34 -> 17014419 | ... O32: =O33+O34 -> 4201936
A33: 其中：发电厂用电量 | B33: 千瓦时 | C33: 028 | D33: =G33+H33+I33 -> 0 | G33: =SUM(E33:F33) -> 0 | J33: =M33+N33+O33 -> 8826323.6 | K33: =E33+'26.2'!K33 -> 3573096 | L33: =F33+'26.2'!L33 -> 2844984.4 | M33: =SUM(K33:L33) -> 6418080.4 | N33: =H33+'26.2'!N33 -> 1400555 | O33: =I33+'26.2'!O33 -> 1007688.2
A34: 供热厂用电量 | B34: 千瓦时 | C34: 029 | D34: =G34+H34+I34 -> 0 | G34: =SUM(E34:F34) -> 0 | J34: =M34+N34+O34 -> 35353959 | K34: =E34+'26.2'!K34 -> 13441323 | L34: =F34+'26.2'!L34 -> 13120136 | M34: =SUM(K34:L34) -> 26561458 | N34: =H34+'26.2'!N34 -> 5598253 | O34: =I34+'26.2'!O34 -> 3194247.8
A35: 综合厂用电率 | B35: % | C35: 030 | D35: =D30*100/D7 -> #DIV/0! | E35: =E30*100/E7 -> #DIV/0! | F35: =F30*100/F7 -> #DIV/0! | G35: =G30*100/G7 -> #DIV/0! | H35: =H30*100/H7 -> #DIV/0! | I35: =I30*100/I7 -> #DIV/0! | J35: =J30*100/J7 -> 32.825742 | K35: =K30*100/K7 -> 38.858082 | ... O35: =O30*100/O7 -> 27.369005
A36: 发电厂用电率 | B36: % | C36: 031 | D36: =D33*100/D7 -> #DIV/0! | E36: =E33*100/E7 -> #DIV/0! | F36: =F33*100/F7 -> #DIV/0! | G36: =G33*100/G7 -> #DIV/0! | H36: =H33*100/H7 -> #DIV/0! | I36: =I33*100/I7 -> #DIV/0! | J36: =J33*100/J7 -> 5.6425484 | K36: =K33*100/K7 -> 5.881291 | ... O36: =O33*100/O7 -> 6.5635039
A37: 供热厂用电率 | B37: 千瓦时/吉焦 | C37: 032 | D37: =D34/D9 -> #DIV/0! | E37: =E34/E9 -> #DIV/0! | F37: =F34/F9 -> #DIV/0! | G37: =G34/G9 -> #DIV/0! | H37: =H34/H9 -> #DIV/0! | I37: =I34/I9 -> #DIV/0! | J37: =J34/J9 -> 12.583334 | K37: =K34/K9 -> 13.712429 | ... O37: =O34/O9 -> 10.935672
A38: 耗标煤总量 | B38: 吨 | C38: 033 | D38: =D39+D42 -> 0 | E38: =E39+E42 -> 0 | F38: =F39+F42 -> 0 | G38: =G39+G42 -> 0 | H38: =H39+H42 -> 0 | I38: =I39+I42 -> 0 | J38: =J39+J42 -> 137897.36 | K38: =K39+K42 -> 46848.881 | ... O38: =O39+O42 -> 14852.348
A39: 发电标准煤耗量 | B39: 吨 | C39: 034 | D39: =D40+D41 -> 0 | E39: =E40+E41 -> 0 | F39: =F40+F41 -> 0 | G39: =G40+G41 -> 0 | H39: =H40+H41 -> 0 | I39: =I40+I41 -> 0 | J39: =J40+J41 -> 27596.4 | K39: =K40+K41 -> 9838.4525 | ... O39: =O40+O41 -> 3561.819
A40: 其中：煤折标准煤量 | B40: 吨 | C40: 035 | D40: =G40+H40+I40 -> 0 | G40: =SUM(E40:F40) -> 0 | J40: =M40+N40+O40 -> 27564.635 | K40: =E40+'26.2'!K40 -> 9817.2469 | L40: =F40+'26.2'!L40 -> 8544.6373 | M40: =SUM(K40:L40) -> 18361.884 | N40: =H40+'26.2'!N40 -> 5641 | O40: =I40+'26.2'!O40 -> 3561.7504
...

Sheet 26.4
A1: 大连市热电集团所属热电厂生产月报表
A2: 2026 年 4 月
A3: 指 标 名 称 | B3: 计量单位 | C3: 代码 | D3: 本 月 实 际 | J3: 本 年 累 计
D4: 合 计 | E4: 其 中 | J4: 合 计 | K4: 其 中
E5: 北海热电厂 | F5: 香海热电厂 | G5: 主城区小计 | H5: 金州热电厂 | I5: 瓦房店热电厂 | K5: 北海热电厂 | L5: 香海热电厂 | M5: 主城区小计 | N5: 金州热电厂 | O5: 瓦房店热电厂
A6: 发电机组容量 | B6: 万千瓦 | C6: 001 | D6: =G6+H6+I6 -> 26.88 | E6: 10 | F6: 10 | G6: =SUM(E6:F6) -> 20 | H6: 3.6 | I6: =3.96-0.68 -> 3.28 | J6: =M6+N6+O6 -> 26.88 | K6: 10 | L6: 10 | M6: =SUM(K6:L6) -> 20 | N6: 3.6 | O6: 3.28
A7: 发电量 | B7: 千瓦时 | C7: 002 | D7: =G7+H7+I7 -> 0 | E7: =[4]产量!$C$15 -> 0 | F7: =[4]产量!$C$19 -> 0 | G7: =SUM(E7:F7) -> 0 | J7: =M7+N7+O7 -> 156424420 | K7: =E7+'26.3'!K7 -> 60753600 | L7: =F7+'26.3'!L7 -> 57676320 | M7: =SUM(K7:L7) -> 118429920 | N7: =H7+'26.3'!N7 -> 22641600 | O7: =I7+'26.3'!O7 -> 15352900
A8: 供电量 | B8: 千瓦时 | C8: 003 | D8: =G8+H8+I8 -> 0 | E8: =[4]产量!$E$15 -> 0 | F8: =[4]产量!$E$19 -> 0 | G8: =SUM(E8:F8) -> 0 | J8: =M8+N8+O8 -> 105076944 | K8: =E8+'26.3'!K8 -> 37145916 | L8: =F8+'26.3'!L8 -> 41137272 | M8: =SUM(K8:L8) -> 78283188 | N8: =H8+'26.3'!N8 -> 15642792 | O8: =I8+'26.3'!O8 -> 11150964
A9: 供热量 | B9: 吉焦 | C9: 004 | D9: =G9+H9+I9 -> 0 | E9: =[4]产量!$G$6 -> 0 | F9: =[4]产量!$G$7 -> 0 | G9: =SUM(E9:F9) -> 0 | J9: =M9+N9+O9 -> 2809586.1 | K9: =E9+'26.3'!K9 -> 980229.19 | L9: =F9+'26.3'!L9 -> 967138.54 | M9: =SUM(K9:L9) -> 1947367.7 | N9: =H9+'26.3'!N9 -> 570124 | O9: =I9+'26.3'!O9 -> 292094.32
A10: 其中：低真空、热泵供热量 | B10: 吉焦 | C10: 005 | D10: =G10+H10+I10 -> 0 | F10: =[4]产量!$G$29 -> 0 | G10: =SUM(E10:F10) -> 0 | J10: =M10+N10+O10 -> 377963 | K10: =E10+'26.3'!K10 -> 0 | L10: =F10+'26.3'!L10 -> 264848 | M10: =SUM(K10:L10) -> 264848 | N10: =H10+'26.3'!N10 -> 113115 | O10: =I10+'26.3'!O10 -> 0
A11: 高温水网供热量 | B11: 吉焦 | C11: 006 | D11: =G11+H11+I11 -> 0 | E11: =[4]产量!$G$28 -> 0 | F11: =[4]产量!$G$30 -> 0 | G11: =SUM(E11:F11) -> 0 | H11: =H9-H10 -> 0 | I11: =I9-I10 -> 0 | J11: =M11+N11+O11 -> 2097098.7 | K11: =E11+'26.3'!K11 -> 875606.4 | L11: =F11+'26.3'!L11 -> 472389 | M11: =SUM(K11:L11) -> 1347995.4 | N11: =H11+'26.3'!N11 -> 457009 | O11: =I11+'26.3'!O11 -> 292094.32
A12: 供汽量 | B12: 吨 | C12: 007 | D12: =G12+H12+I12 -> 0 | E12: =[4]产量!$G$15 -> 0 | F12: =[4]产量!$G$19 -> 0 | G12: =SUM(E12:F12) -> 0 | H12: 0 | I12: 0 | J12: =M12+N12+O12 -> 113333 | K12: =E12+'26.3'!K12 -> 35445 | L12: =F12+'26.3'!L12 -> 77888 | M12: =SUM(K12:L12) -> 113333 | N12: =H12+'26.3'!N12 -> 0 | O12: =I12+'26.3'!O12 -> 0
A13: 期末供暖收费面积 | B13: 平方米 | C13: 008 | N13: =H13 -> 0 | O13: =I13 -> 0
A14: 生产耗原煤量 | B14: 吨 | C14: 009 | D14: =D15+D16 -> 0 | E14: =E15+E16 -> 0 | F14: =F15+F16 -> 0 | G14: =G15+G16 -> 0 | H14: =H15+H16 -> 0 | I14: =I15+I16 -> 0 | J14: =J15+J16 -> 201466.19 | K14: =K15+K16 -> 68272 | ... O14: =O15+O16 -> 20654.19
A15: 发电耗原煤量 | B15: 吨 | C15: 010 | D15: =G15+H15+I15 -> 0 | G15: =SUM(E15:F15) -> 0 | J15: =M15+N15+O15 -> 40206.772 | K15: =E15+'26.3'!K15 -> 14337.393 | L15: =F15+'26.3'!L15 -> 13051.19 | M15: =SUM(K15:L15) -> 27388.583 | N15: =H15+'26.3'!N15 -> 7865 | O15: =I15+'26.3'!O15 -> 4953.189
A16: 供热耗原煤量 | B16: 吨 | C16: 011 | D16: =G16+H16+I16 -> 0 | G16: =SUM(E16:F16) -> 0 | J16: =M16+N16+O16 -> 161259.42 | K16: =E16+'26.3'!K16 -> 53934.607 | L16: =F16+'26.3'!L16 -> 60187.81 | M16: =SUM(K16:L16) -> 114122.42 | N16: =H16+'26.3'!N16 -> 31436 | O16: =I16+'26.3'!O16 -> 15701.001
A17: 锅炉耗油量 | B17: 吨 | C17: 012 | D17: =D18+D19 -> 0 | E17: =E18+E19 -> 0 | F17: =F18+F19 -> 0 | G17: =G18+G19 -> 0 | H17: =H18+H19 -> 0 | I17: =I18+I19 -> 0 | J17: =J18+J19 -> 108.5 | K17: =K18+K19 -> 69.3 | ... O17: =O18+O19 -> 0.2
A18: 发电耗油量 | B18: 吨 | C18: 013 | D18: =G18+H18+I18 -> 0 | G18: =SUM(E18:F18) -> 0 | J18: =M18+N18+O18 -> 22.05624 | K18: =E18+'26.3'!K18 -> 14.553277 | L18: =F18+'26.3'!L18 -> 4.455 | M18: =SUM(K18:L18) -> 19.008277 | N18: =H18+'26.3'!N18 -> 3 | O18: =I18+'26.3'!O18 -> 0.047963043
A19: 供热耗油量 | B19: 吨 | C19: 014 | D19: =G19+H19+I19 -> 0 | G19: =SUM(E19:F19) -> 0 | J19: =M19+N19+O19 -> 86.44376 | K19: =E19+'26.3'!K19 -> 54.746723 | L19: =F19+'26.3'!L19 -> 20.545 | M19: =SUM(K19:L19) -> 75.291723 | N19: =H19+'26.3'!N19 -> 11 | O19: =I19+'26.3'!O19 -> 0.15203696
A20: 耗水量 | B20: 吨 | C20: 015 | D20: =G20+H20+I20 -> 0 | G20: =SUM(E20:F20) -> 0 | J20: =M20+N20+O20 -> 501831 | K20: =E20+'26.3'!K20 -> 177610 | L20: =F20+'26.3'!L20 -> 194774 | M20: =SUM(K20:L20) -> 372384 | N20: =H20+'26.3'!N20 -> 94794 | O20: =I20+'26.3'!O20 -> 34653
A21: 其中：耗再生水量(或井水) | B21: 吨 | C21: 016 | D21: =G21+H21+I21 -> 0 | G21: =SUM(E21:F21) -> 0 | J21: =M21+N21+O21 -> 132751 | K21: =E21+'26.3'!K21 -> 121213 | L21: =F21+'26.3'!L21 -> 0 | M21: =SUM(K21:L21) -> 121213 | N21: =H21+'26.3'!N21 -> 0 | O21: =I21+'26.3'!O21 -> 11538
A22: 耗酸量 | B22: 吨 | C22: 017 | D22: =G22+H22+I22 -> 0 | G22: =SUM(E22:F22) -> 0 | J22: =M22+N22+O22 -> 63.71 | K22: =E22+'26.3'!K22 -> 6.4 | L22: =F22+'26.3'!L22 -> 40 | M22: =SUM(K22:L22) -> 46.4 | N22: =H22+'26.3'!N22 -> 15 | O22: =I22+'26.3'!O22 -> 2.31
A23: 耗碱量 | B23: 吨 | C23: 018 | D23: =G23+H23+I23 -> 0 | G23: =SUM(E23:F23) -> 0 | J23: =M23+N23+O23 -> 54 | K23: =E23+'26.3'!K23 -> 9.7 | L23: =F23+'26.3'!L23 -> 32 | M23: =SUM(K23:L23) -> 41.7 | N23: =H23+'26.3'!N23 -> 10 | O23: =I23+'26.3'!O23 -> 2.3
A24: 耗石灰石量 | B24: 吨 | C24: 019 | D24: =G24+H24+I24 -> 0 | G24: =SUM(E24:F24) -> 0 | J24: =M24+N24+O24 -> 601.88 | K24: =E24+'26.3'!K24 -> 0 | L24: =F24+'26.3'!L24 -> 0 | M24: =SUM(K24:L24) -> 0 | N24: =H24+'26.3'!N24 -> 0 | O24: =I24+'26.3'!O24 -> 601.88
A25: 耗石灰石粉量 | B25: 吨 | C25: 020 | D25: =G25+H25+I25 -> 0 | G25: =SUM(E25:F25) -> 0 | J25: =M25+N25+O25 -> 3965.38 | K25: =E25+'26.3'!K25 -> 2045 | L25: =F25+'26.3'!L25 -> 854 | M25: =SUM(K25:L25) -> 2899 | N25: =H25+'26.3'!N25 -> 702 | O25: =I25+'26.3'!O25 -> 364.38
A26: 耗氨水量 | B26: 吨 | C26: 021 | D26: =G26+H26+I26 -> 0 | G26: =SUM(E26:F26) -> 0 | J26: =M26+N26+O26 -> 972.013 | K26: =E26+'26.3'!K26 -> 377.74 | L26: =F26+'26.3'!L26 -> 201 | M26: =SUM(K26:L26) -> 578.74 | N26: =H26+'26.3'!N26 -> 319 | O26: =I26+'26.3'!O26 -> 74.273
A27: 耗阻垢剂量(水质稳定剂) | B27: 吨 | C27: 022 | D27: =G27+H27+I27 -> 0 | G27: =SUM(E27:F27) -> 0 | J27: =M27+N27+O27 -> 3.125 | K27: =E27+'26.3'!K27 -> 1.075 | L27: =F27+'26.3'!L27 -> 1 | M27: =SUM(K27:L27) -> 2.075 | N27: =H27+'26.3'!N27 -> 1 | O27: =I27+'26.3'!O27 -> 0.05
A28: 耗杀菌剂量 | B28: 吨 | C28: 023 | D28: =G28+H28+I28 -> 0 | G28: =SUM(E28:F28) -> 0 | J28: =M28+N28+O28 -> 0 | K28: =E28+'26.3'!K28 -> 0 | L28: =F28+'26.3'!L28 -> 0 | M28: =SUM(K28:L28) -> 0 | N28: =H28+'26.3'!N28 -> 0 | O28: =I28+'26.3'!O28 -> 0
A29: 耗钢球量 | B29: 吨 | C29: 024 | D29: =G29+H29+I29 -> 0 | G29: =SUM(E29:F29) -> 0 | J29: =M29+N29+O29 -> 28 | K29: =E29+'26.3'!K29 -> 28 | L29: =F29+'26.3'!L29 -> 0 | M29: =SUM(K29:L29) -> 28 | N29: =H29+'26.3'!N29 -> 0 | O29: =I29+'26.3'!O29 -> 0
A30: 综合厂用电量 | B30: 千瓦时 | C30: 025 | D30: =G30+H30+I30 -> 0 | E30: =E7-E8 -> 0 | F30: =F7-F8 -> 0 | G30: =G7-G8 -> 0 | H30: =H7-H8 -> 0 | I30: =I7-I8 -> 0 | J30: =M30+N30+O30 -> 51347476 | K30: =E30+'26.3'!K30 -> 23607684 | L30: =F30+'26.3'!L30 -> 16539048 | M30: =M7-M8 -> 40146732 | N30: =H30+'26.3'!N30 -> 6998808 | O30: =I30+'26.3'!O30 -> 4201936
A31: 非生产厂用电量 | B31: 千瓦时 | C31: 026 | D31: =G31+H31+I31 -> 0 | G31: =SUM(E31:F31) -> 0 | J31: =M31+N31+O31 -> 7167192.5 | K31: =E31+'26.3'!K31 -> 6593264.5 | L31: =F31+'26.3'!L31 -> 573928 | M31: =SUM(K31:L31) -> 7167192.5 | N31: =H31+'26.3'!N31 -> 0 | O31: =I31+'26.3'!O31 -> 0
A32: 生产厂用电量 | B32: 千瓦时 | C32: 027 | D32: =D33+D34 -> 0 | E32: =E33+E34 -> 0 | F32: =F33+F34 -> 0 | G32: =G33+G34 -> 0 | H32: =H33+H34 -> 0 | I32: =I33+I34 -> 0 | J32: =J33+J34 -> 44180283 | K32: =K33+K34 -> 17014419 | ... O32: =O33+O34 -> 4201936
A33: 其中：发电厂用电量 | B33: 千瓦时 | C33: 028 | D33: =G33+H33+I33 -> 0 | G33: =SUM(E33:F33) -> 0 | J33: =M33+N33+O33 -> 8826323.6 | K33: =E33+'26.3'!K33 -> 3573096 | L33: =F33+'26.3'!L33 -> 2844984.4 | M33: =SUM(K33:L33) -> 6418080.4 | N33: =H33+'26.3'!N33 -> 1400555 | O33: =I33+'26.3'!O33 -> 1007688.2
A34: 供热厂用电量 | B34: 千瓦时 | C34: 029 | D34: =G34+H34+I34 -> 0 | G34: =SUM(E34:F34) -> 0 | J34: =M34+N34+O34 -> 35353959 | K34: =E34+'26.3'!K34 -> 13441323 | L34: =F34+'26.3'!L34 -> 13120136 | M34: =SUM(K34:L34) -> 26561458 | N34: =H34+'26.3'!N34 -> 5598253 | O34: =I34+'26.3'!O34 -> 3194247.8
A35: 综合厂用电率 | B35: % | C35: 030 | D35: =D30*100/D7 -> #DIV/0! | E35: =E30*100/E7 -> #DIV/0! | F35: =F30*100/F7 -> #DIV/0! | G35: =G30*100/G7 -> #DIV/0! | H35: =H30*100/H7 -> #DIV/0! | I35: =I30*100/I7 -> #DIV/0! | J35: =J30*100/J7 -> 32.825742 | K35: =K30*100/K7 -> 38.858082 | ... O35: =O30*100/O7 -> 27.369005
A36: 发电厂用电率 | B36: % | C36: 031 | D36: =D33*100/D7 -> #DIV/0! | E36: =E33*100/E7 -> #DIV/0! | F36: =F33*100/F7 -> #DIV/0! | G36: =G33*100/G7 -> #DIV/0! | H36: =H33*100/H7 -> #DIV/0! | I36: =I33*100/I7 -> #DIV/0! | J36: =J33*100/J7 -> 5.6425484 | K36: =K33*100/K7 -> 5.881291 | ... O36: =O33*100/O7 -> 6.5635039
A37: 供热厂用电率 | B37: 千瓦时/吉焦 | C37: 032 | D37: =D34/D9 -> #DIV/0! | E37: =E34/E9 -> #DIV/0! | F37: =F34/F9 -> #DIV/0! | G37: =G34/G9 -> #DIV/0! | H37: =H34/H9 -> #DIV/0! | I37: =I34/I9 -> #DIV/0! | J37: =J34/J9 -> 12.583334 | K37: =K34/K9 -> 13.712429 | ... O37: =O34/O9 -> 10.935672
A38: 耗标煤总量 | B38: 吨 | C38: 033 | D38: =D39+D42 -> 0 | E38: =E39+E42 -> 0 | F38: =F39+F42 -> 0 | G38: =G39+G42 -> 0 | H38: =H39+H42 -> 0 | I38: =I39+I42 -> 0 | J38: =J39+J42 -> 137897.36 | K38: =K39+K42 -> 46848.881 | ... O38: =O39+O42 -> 14852.348
A39: 发电标准煤耗量 | B39: 吨 | C39: 034 | D39: =D40+D41 -> 0 | E39: =E40+E41 -> 0 | F39: =F40+F41 -> 0 | G39: =G40+G41 -> 0 | H39: =H40+H41 -> 0 | I39: =I40+I41 -> 0 | J39: =J40+J41 -> 27596.4 | K39: =K40+K41 -> 9838.4525 | ... O39: =O40+O41 -> 3561.819
A40: 其中：煤折标准煤量 | B40: 吨 | C40: 035 | D40: =G40+H40+I40 -> 0 | G40: =SUM(E40:F40) -> 0 | J40: =M40+N40+O40 -> 27564.635 | K40: =E40+'26.3'!K40 -> 9817.2469 | L40: =F40+'26.3'!L40 -> 8544.6373 | M40: =SUM(K40:L40) -> 18361.884 | N40: =H40+'26.3'!N40 -> 5641 | O40: =I40+'26.3'!O40 -> 3561.7504
...

Sheet 26.5
A1: 大连市热电集团所属热电厂生产月报表
A2: 2026 年 5 月
A3: 指 标 名 称 | B3: 计量单位 | C3: 代码 | D3: 本 月 实 际 | J3: 本 年 累 计
D4: 合 计 | E4: 其 中 | J4: 合 计 | K4: 其 中
E5: 北海热电厂 | F5: 香海热电厂 | G5: 主城区小计 | H5: 金州热电厂 | I5: 瓦房店热电厂 | K5: 北海热电厂 | L5: 香海热电厂 | M5: 主城区小计 | N5: 金州热电厂 | O5: 瓦房店热电厂
A6: 发电机组容量 | B6: 万千瓦 | C6: 001 | D6: =G6+H6+I6 -> 26.88 | E6: 10 | F6: 10 | G6: =SUM(E6:F6) -> 20 | H6: 3.6 | I6: =3.96-0.68 -> 3.28 | J6: =M6+N6+O6 -> 26.88 | K6: 10 | L6: 10 | M6: =SUM(K6:L6) -> 20 | N6: 3.6 | O6: 3.28
A7: 发电量 | B7: 千瓦时 | C7: 002 | D7: =G7+H7+I7 -> 0 | E7: =[5]产量!$C$15 -> 0 | F7: =[5]产量!$C$19 -> 0 | G7: =SUM(E7:F7) -> 0 | J7: =M7+N7+O7 -> 156424420 | K7: =E7+'26.4'!K7 -> 60753600 | L7: =F7+'26.4'!L7 -> 57676320 | M7: =SUM(K7:L7) -> 118429920 | N7: =H7+'26.4'!N7 -> 22641600 | O7: =I7+'26.4'!O7 -> 15352900
A8: 供电量 | B8: 千瓦时 | C8: 003 | D8: =G8+H8+I8 -> 0 | E8: =[5]产量!$E$15 -> 0 | F8: =[5]产量!$E$19 -> 0 | G8: =SUM(E8:F8) -> 0 | J8: =M8+N8+O8 -> 105076944 | K8: =E8+'26.4'!K8 -> 37145916 | L8: =F8+'26.4'!L8 -> 41137272 | M8: =SUM(K8:L8) -> 78283188 | N8: =H8+'26.4'!N8 -> 15642792 | O8: =I8+'26.4'!O8 -> 11150964
A9: 供热量 | B9: 吉焦 | C9: 004 | D9: =G9+H9+I9 -> 0 | E9: =[5]产量!$G$6 -> 0 | F9: =[5]产量!$G$7 -> 0 | G9: =SUM(E9:F9) -> 0 | J9: =M9+N9+O9 -> 2809586.1 | K9: =E9+'26.4'!K9 -> 980229.19 | L9: =F9+'26.4'!L9 -> 967138.54 | M9: =SUM(K9:L9) -> 1947367.7 | N9: =H9+'26.4'!N9 -> 570124 | O9: =I9+'26.4'!O9 -> 292094.32
A10: 其中：低真空、热泵供热量 | B10: 吉焦 | C10: 005 | D10: =G10+H10+I10 -> 0 | F10: =[5]产量!$G$29 -> 0 | G10: =SUM(E10:F10) -> 0 | J10: =M10+N10+O10 -> 377963 | K10: =E10+'26.4'!K10 -> 0 | L10: =F10+'26.4'!L10 -> 264848 | M10: =SUM(K10:L10) -> 264848 | N10: =H10+'26.4'!N10 -> 113115 | O10: =I10+'26.4'!O10 -> 0
A11: 高温水网供热量 | B11: 吉焦 | C11: 006 | D11: =G11+H11+I11 -> 0 | E11: =[5]产量!$G$28 -> 0 | F11: =[5]产量!$G$30 -> 0 | G11: =SUM(E11:F11) -> 0 | H11: =H9-H10 -> 0 | I11: =I9-I10 -> 0 | J11: =M11+N11+O11 -> 2097098.7 | K11: =E11+'26.4'!K11 -> 875606.4 | L11: =F11+'26.4'!L11 -> 472389 | M11: =SUM(K11:L11) -> 1347995.4 | N11: =H11+'26.4'!N11 -> 457009 | O11: =I11+'26.4'!O11 -> 292094.32
A12: 供汽量 | B12: 吨 | C12: 007 | D12: =G12+H12+I12 -> 0 | E12: =[5]产量!$G$15 -> 0 | F12: =[5]产量!$G$19 -> 0 | G12: =SUM(E12:F12) -> 0 | H12: 0 | I12: 0 | J12: =M12+N12+O12 -> 113333 | K12: =E12+'26.4'!K12 -> 35445 | L12: =F12+'26.4'!L12 -> 77888 | M12: =SUM(K12:L12) -> 113333 | N12: =H12+'26.4'!N12 -> 0 | O12: =I12+'26.4'!O12 -> 0
A13: 期末供暖收费面积 | B13: 平方米 | C13: 008 | N13: =H13 -> 0 | O13: =I13 -> 0
A14: 生产耗原煤量 | B14: 吨 | C14: 009 | D14: =D15+D16 -> 0 | E14: =E15+E16 -> 0 | F14: =F15+F16 -> 0 | G14: =G15+G16 -> 0 | H14: =H15+H16 -> 0 | I14: =I15+I16 -> 0 | J14: =J15+J16 -> 201466.19 | K14: =K15+K16 -> 68272 | ... O14: =O15+O16 -> 20654.19
A15: 发电耗原煤量 | B15: 吨 | C15: 010 | D15: =G15+H15+I15 -> 0 | G15: =SUM(E15:F15) -> 0 | J15: =M15+N15+O15 -> 40206.772 | K15: =E15+'26.4'!K15 -> 14337.393 | L15: =F15+'26.4'!L15 -> 13051.19 | M15: =SUM(K15:L15) -> 27388.583 | N15: =H15+'26.4'!N15 -> 7865 | O15: =I15+'26.4'!O15 -> 4953.189
A16: 供热耗原煤量 | B16: 吨 | C16: 011 | D16: =G16+H16+I16 -> 0 | G16: =SUM(E16:F16) -> 0 | J16: =M16+N16+O16 -> 161259.42 | K16: =E16+'26.4'!K16 -> 53934.607 | L16: =F16+'26.4'!L16 -> 60187.81 | M16: =SUM(K16:L16) -> 114122.42 | N16: =H16+'26.4'!N16 -> 31436 | O16: =I16+'26.4'!O16 -> 15701.001
A17: 锅炉耗油量 | B17: 吨 | C17: 012 | D17: =D18+D19 -> 0 | E17: =E18+E19 -> 0 | F17: =F18+F19 -> 0 | G17: =G18+G19 -> 0 | H17: =H18+H19 -> 0 | I17: =I18+I19 -> 0 | J17: =J18+J19 -> 108.5 | K17: =K18+K19 -> 69.3 | ... O17: =O18+O19 -> 0.2
A18: 发电耗油量 | B18: 吨 | C18: 013 | D18: =G18+H18+I18 -> 0 | G18: =SUM(E18:F18) -> 0 | J18: =M18+N18+O18 -> 22.05624 | K18: =E18+'26.4'!K18 -> 14.553277 | L18: =F18+'26.4'!L18 -> 4.455 | M18: =SUM(K18:L18) -> 19.008277 | N18: =H18+'26.4'!N18 -> 3 | O18: =I18+'26.4'!O18 -> 0.047963043
A19: 供热耗油量 | B19: 吨 | C19: 014 | D19: =G19+H19+I19 -> 0 | G19: =SUM(E19:F19) -> 0 | J19: =M19+N19+O19 -> 86.44376 | K19: =E19+'26.4'!K19 -> 54.746723 | L19: =F19+'26.4'!L19 -> 20.545 | M19: =SUM(K19:L19) -> 75.291723 | N19: =H19+'26.4'!N19 -> 11 | O19: =I19+'26.4'!O19 -> 0.15203696
A20: 耗水量 | B20: 吨 | C20: 015 | D20: =G20+H20+I20 -> 0 | G20: =SUM(E20:F20) -> 0 | J20: =M20+N20+O20 -> 501831 | K20: =E20+'26.4'!K20 -> 177610 | L20: =F20+'26.4'!L20 -> 194774 | M20: =SUM(K20:L20) -> 372384 | N20: =H20+'26.4'!N20 -> 94794 | O20: =I20+'26.4'!O20 -> 34653
A21: 其中：耗再生水量(或井水) | B21: 吨 | C21: 016 | D21: =G21+H21+I21 -> 0 | G21: =SUM(E21:F21) -> 0 | J21: =M21+N21+O21 -> 132751 | K21: =E21+'26.4'!K21 -> 121213 | L21: =F21+'26.4'!L21 -> 0 | M21: =SUM(K21:L21) -> 121213 | N21: =H21+'26.4'!N21 -> 0 | O21: =I21+'26.4'!O21 -> 11538
A22: 耗酸量 | B22: 吨 | C22: 017 | D22: =G22+H22+I22 -> 0 | G22: =SUM(E22:F22) -> 0 | J22: =M22+N22+O22 -> 63.71 | K22: =E22+'26.4'!K22 -> 6.4 | L22: =F22+'26.4'!L22 -> 40 | M22: =SUM(K22:L22) -> 46.4 | N22: =H22+'26.4'!N22 -> 15 | O22: =I22+'26.4'!O22 -> 2.31
A23: 耗碱量 | B23: 吨 | C23: 018 | D23: =G23+H23+I23 -> 0 | G23: =SUM(E23:F23) -> 0 | J23: =M23+N23+O23 -> 54 | K23: =E23+'26.4'!K23 -> 9.7 | L23: =F23+'26.4'!L23 -> 32 | M23: =SUM(K23:L23) -> 41.7 | N23: =H23+'26.4'!N23 -> 10 | O23: =I23+'26.4'!O23 -> 2.3
A24: 耗石灰石量 | B24: 吨 | C24: 019 | D24: =G24+H24+I24 -> 0 | G24: =SUM(E24:F24) -> 0 | J24: =M24+N24+O24 -> 601.88 | K24: =E24+'26.4'!K24 -> 0 | L24: =F24+'26.4'!L24 -> 0 | M24: =SUM(K24:L24) -> 0 | N24: =H24+'26.4'!N24 -> 0 | O24: =I24+'26.4'!O24 -> 601.88
A25: 耗石灰石粉量 | B25: 吨 | C25: 020 | D25: =G25+H25+I25 -> 0 | G25: =SUM(E25:F25) -> 0 | J25: =M25+N25+O25 -> 3965.38 | K25: =E25+'26.4'!K25 -> 2045 | L25: =F25+'26.4'!L25 -> 854 | M25: =SUM(K25:L25) -> 2899 | N25: =H25+'26.4'!N25 -> 702 | O25: =I25+'26.4'!O25 -> 364.38
A26: 耗氨水量 | B26: 吨 | C26: 021 | D26: =G26+H26+I26 -> 0 | G26: =SUM(E26:F26) -> 0 | J26: =M26+N26+O26 -> 972.013 | K26: =E26+'26.4'!K26 -> 377.74 | L26: =F26+'26.4'!L26 -> 201 | M26: =SUM(K26:L26) -> 578.74 | N26: =H26+'26.4'!N26 -> 319 | O26: =I26+'26.4'!O26 -> 74.273
A27: 耗阻垢剂量(水质稳定剂) | B27: 吨 | C27: 022 | D27: =G27+H27+I27 -> 0 | G27: =SUM(E27:F27) -> 0 | J27: =M27+N27+O27 -> 3.125 | K27: =E27+'26.4'!K27 -> 1.075 | L27: =F27+'26.4'!L27 -> 1 | M27: =SUM(K27:L27) -> 2.075 | N27: =H27+'26.4'!N27 -> 1 | O27: =I27+'26.4'!O27 -> 0.05
A28: 耗杀菌剂量 | B28: 吨 | C28: 023 | D28: =G28+H28+I28 -> 0 | G28: =SUM(E28:F28) -> 0 | J28: =M28+N28+O28 -> 0 | K28: =E28+'26.4'!K28 -> 0 | L28: =F28+'26.4'!L28 -> 0 | M28: =SUM(K28:L28) -> 0 | N28: =H28+'26.4'!N28 -> 0 | O28: =I28+'26.4'!O28 -> 0
A29: 耗钢球量 | B29: 吨 | C29: 024 | D29: =G29+H29+I29 -> 0 | G29: =SUM(E29:F29) -> 0 | J29: =M29+N29+O29 -> 28 | K29: =E29+'26.4'!K29 -> 28 | L29: =F29+'26.4'!L29 -> 0 | M29: =SUM(K29:L29) -> 28 | N29: =H29+'26.4'!N29 -> 0 | O29: =I29+'26.4'!O29 -> 0
A30: 综合厂用电量 | B30: 千瓦时 | C30: 025 | D30: =G30+H30+I30 -> 0 | E30: =E7-E8 -> 0 | F30: =F7-F8 -> 0 | G30: =G7-G8 -> 0 | H30: =H7-H8 -> 0 | I30: =I7-I8 -> 0 | J30: =M30+N30+O30 -> 51347476 | K30: =E30+'26.4'!K30 -> 23607684 | L30: =F30+'26.4'!L30 -> 16539048 | M30: =M7-M8 -> 40146732 | N30: =H30+'26.4'!N30 -> 6998808 | O30: =I30+'26.4'!O30 -> 4201936
A31: 非生产厂用电量 | B31: 千瓦时 | C31: 026 | D31: =G31+H31+I31 -> 0 | G31: =SUM(E31:F31) -> 0 | J31: =M31+N31+O31 -> 7167192.5 | K31: =E31+'26.4'!K31 -> 6593264.5 | L31: =F31+'26.4'!L31 -> 573928 | M31: =SUM(K31:L31) -> 7167192.5 | N31: =H31+'26.4'!N31 -> 0 | O31: =I31+'26.4'!O31 -> 0
A32: 生产厂用电量 | B32: 千瓦时 | C32: 027 | D32: =D33+D34 -> 0 | E32: =E33+E34 -> 0 | F32: =F33+F34 -> 0 | G32: =G33+G34 -> 0 | H32: =H33+H34 -> 0 | I32: =I33+I34 -> 0 | J32: =J33+J34 -> 44180283 | K32: =K33+K34 -> 17014419 | ... O32: =O33+O34 -> 4201936
A33: 其中：发电厂用电量 | B33: 千瓦时 | C33: 028 | D33: =G33+H33+I33 -> 0 | G33: =SUM(E33:F33) -> 0 | J33: =M33+N33+O33 -> 8826323.6 | K33: =E33+'26.4'!K33 -> 3573096 | L33: =F33+'26.4'!L33 -> 2844984.4 | M33: =SUM(K33:L33) -> 6418080.4 | N33: =H33+'26.4'!N33 -> 1400555 | O33: =I33+'26.4'!O33 -> 1007688.2
A34: 供热厂用电量 | B34: 千瓦时 | C34: 029 | D34: =G34+H34+I34 -> 0 | G34: =SUM(E34:F34) -> 0 | J34: =M34+N34+O34 -> 35353959 | K34: =E34+'26.4'!K34 -> 13441323 | L34: =F34+'26.4'!L34 -> 13120136 | M34: =SUM(K34:L34) -> 26561458 | N34: =H34+'26.4'!N34 -> 5598253 | O34: =I34+'26.4'!O34 -> 3194247.8
A35: 综合厂用电率 | B35: % | C35: 030 | D35: =D30*100/D7 -> #DIV/0! | E35: =E30*100/E7 -> #DIV/0! | F35: =F30*100/F7 -> #DIV/0! | G35: =G30*100/G7 -> #DIV/0! | H35: =H30*100/H7 -> #DIV/0! | I35: =I30*100/I7 -> #DIV/0! | J35: =J30*100/J7 -> 32.825742 | K35: =K30*100/K7 -> 38.858082 | ... O35: =O30*100/O7 -> 27.369005
A36: 发电厂用电率 | B36: % | C36: 031 | D36: =D33*100/D7 -> #DIV/0! | E36: =E33*100/E7 -> #DIV/0! | F36: =F33*100/F7 -> #DIV/0! | G36: =G33*100/G7 -> #DIV/0! | H36: =H33*100/H7 -> #DIV/0! | I36: =I33*100/I7 -> #DIV/0! | J36: =J33*100/J7 -> 5.6425484 | K36: =K33*100/K7 -> 5.881291 | ... O36: =O33*100/O7 -> 6.5635039
A37: 供热厂用电率 | B37: 千瓦时/吉焦 | C37: 032 | D37: =D34/D9 -> #DIV/0! | E37: =E34/E9 -> #DIV/0! | F37: =F34/F9 -> #DIV/0! | G37: =G34/G9 -> #DIV/0! | H37: =H34/H9 -> #DIV/0! | I37: =I34/I9 -> #DIV/0! | J37: =J34/J9 -> 12.583334 | K37: =K34/K9 -> 13.712429 | ... O37: =O34/O9 -> 10.935672
A38: 耗标煤总量 | B38: 吨 | C38: 033 | D38: =D39+D42 -> 0 | E38: =E39+E42 -> 0 | F38: =F39+F42 -> 0 | G38: =G39+G42 -> 0 | H38: =H39+H42 -> 0 | I38: =I39+I42 -> 0 | J38: =J39+J42 -> 137897.36 | K38: =K39+K42 -> 46848.881 | ... O38: =O39+O42 -> 14852.348
A39: 发电标准煤耗量 | B39: 吨 | C39: 034 | D39: =D40+D41 -> 0 | E39: =E40+E41 -> 0 | F39: =F40+F41 -> 0 | G39: =G40+G41 -> 0 | H39: =H40+H41 -> 0 | I39: =I40+I41 -> 0 | J39: =J40+J41 -> 27596.4 | K39: =K40+K41 -> 9838.4525 | ... O39: =O40+O41 -> 3561.819
A40: 其中：煤折标准煤量 | B40: 吨 | C40: 035 | D40: =G40+H40+I40 -> 0 | G40: =SUM(E40:F40) -> 0 | J40: =M40+N40+O40 -> 27564.635 | K40: =E40+'26.4'!K40 -> 9817.2469 | L40: =F40+'26.4'!L40 -> 8544.6373 | M40: =SUM(K40:L40) -> 18361.884 | N40: =H40+'26.4'!N40 -> 5641 | O40: =I40+'26.4'!O40 -> 3561.7504
...

Sheet 26.6
A1: 大连市热电集团所属热电厂生产月报表
A2: 2026 年 6 月
A3: 指 标 名 称 | B3: 计量单位 | C3: 代码 | D3: 本 月 实 际 | J3: 本 年 累 计
D4: 合 计 | E4: 其 中 | J4: 合 计 | K4: 其 中
E5: 北海热电厂 | F5: 香海热电厂 | G5: 主城区小计 | H5: 金州热电厂 | I5: 瓦房店热电厂 | K5: 北海热电厂 | L5: 香海热电厂 | M5: 主城区小计 | N5: 金州热电厂 | O5: 瓦房店热电厂
A6: 发电机组容量 | B6: 万千瓦 | C6: 001 | D6: =G6+H6+I6 -> 26.88 | E6: 10 | F6: 10 | G6: =SUM(E6:F6) -> 20 | H6: 3.6 | I6: =3.96-0.68 -> 3.28 | J6: =M6+N6+O6 -> 26.88 | K6: 10 | L6: 10 | M6: =SUM(K6:L6) -> 20 | N6: 3.6 | O6: 3.28
A7: 发电量 | B7: 千瓦时 | C7: 002 | D7: =G7+H7+I7 -> 0 | E7: =[6]产量!$C$15 -> 0 | F7: =[6]产量!$C$19 -> 0 | G7: =SUM(E7:F7) -> 0 | J7: =M7+N7+O7 -> 156424420 | K7: =E7+'26.5'!K7 -> 60753600 | L7: =F7+'26.5'!L7 -> 57676320 | M7: =SUM(K7:L7) -> 118429920 | N7: =H7+'26.5'!N7 -> 22641600 | O7: =I7+'26.5'!O7 -> 15352900
A8: 供电量 | B8: 千瓦时 | C8: 003 | D8: =G8+H8+I8 -> 0 | E8: =[6]产量!$E$15 -> 0 | F8: =[6]产量!$E$19 -> 0 | G8: =SUM(E8:F8) -> 0 | J8: =M8+N8+O8 -> 105076944 | K8: =E8+'26.5'!K8 -> 37145916 | L8: =F8+'26.5'!L8 -> 41137272 | M8: =SUM(K8:L8) -> 78283188 | N8: =H8+'26.5'!N8 -> 15642792 | O8: =I8+'26.5'!O8 -> 11150964
A9: 供热量 | B9: 吉焦 | C9: 004 | D9: =G9+H9+I9 -> 0 | E9: =[6]产量!$G$6 -> 0 | F9: =[6]产量!$G$7 -> 0 | G9: =SUM(E9:F9) -> 0 | J9: =M9+N9+O9 -> 2809586.1 | K9: =E9+'26.5'!K9 -> 980229.19 | L9: =F9+'26.5'!L9 -> 967138.54 | M9: =SUM(K9:L9) -> 1947367.7 | N9: =H9+'26.5'!N9 -> 570124 | O9: =I9+'26.5'!O9 -> 292094.32
A10: 其中：低真空、热泵供热量 | B10: 吉焦 | C10: 005 | D10: =G10+H10+I10 -> 0 | F10: =[6]产量!$G$29 -> 0 | G10: =SUM(E10:F10) -> 0 | J10: =M10+N10+O10 -> 377963 | K10: =E10+'26.5'!K10 -> 0 | L10: =F10+'26.5'!L10 -> 264848 | M10: =SUM(K10:L10) -> 264848 | N10: =H10+'26.5'!N10 -> 113115 | O10: =I10+'26.5'!O10 -> 0
A11: 高温水网供热量 | B11: 吉焦 | C11: 006 | D11: =G11+H11+I11 -> 0 | E11: =[6]产量!$G$28 -> 0 | F11: =[6]产量!$G$30 -> 0 | G11: =SUM(E11:F11) -> 0 | H11: =H9-H10 -> 0 | I11: =I9-I10 -> 0 | J11: =M11+N11+O11 -> 2097098.7 | K11: =E11+'26.5'!K11 -> 875606.4 | L11: =F11+'26.5'!L11 -> 472389 | M11: =SUM(K11:L11) -> 1347995.4 | N11: =H11+'26.5'!N11 -> 457009 | O11: =I11+'26.5'!O11 -> 292094.32
A12: 供汽量 | B12: 吨 | C12: 007 | D12: =G12+H12+I12 -> 0 | E12: =[6]产量!$G$15 -> 0 | F12: =[6]产量!$G$19 -> 0 | G12: =SUM(E12:F12) -> 0 | H12: 0 | I12: 0 | J12: =M12+N12+O12 -> 113333 | K12: =E12+'26.5'!K12 -> 35445 | L12: =F12+'26.5'!L12 -> 77888 | M12: =SUM(K12:L12) -> 113333 | N12: =H12+'26.5'!N12 -> 0 | O12: =I12+'26.5'!O12 -> 0
A13: 期末供暖收费面积 | B13: 平方米 | C13: 008 | N13: =H13 -> 0 | O13: =I13 -> 0
A14: 生产耗原煤量 | B14: 吨 | C14: 009 | D14: =D15+D16 -> 0 | E14: =E15+E16 -> 0 | F14: =F15+F16 -> 0 | G14: =G15+G16 -> 0 | H14: =H15+H16 -> 0 | I14: =I15+I16 -> 0 | J14: =J15+J16 -> 201466.19 | K14: =K15+K16 -> 68272 | ... O14: =O15+O16 -> 20654.19
A15: 发电耗原煤量 | B15: 吨 | C15: 010 | D15: =G15+H15+I15 -> 0 | G15: =SUM(E15:F15) -> 0 | J15: =M15+N15+O15 -> 40206.772 | K15: =E15+'26.5'!K15 -> 14337.393 | L15: =F15+'26.5'!L15 -> 13051.19 | M15: =SUM(K15:L15) -> 27388.583 | N15: =H15+'26.5'!N15 -> 7865 | O15: =I15+'26.5'!O15 -> 4953.189
A16: 供热耗原煤量 | B16: 吨 | C16: 011 | D16: =G16+H16+I16 -> 0 | G16: =SUM(E16:F16) -> 0 | J16: =M16+N16+O16 -> 161259.42 | K16: =E16+'26.5'!K16 -> 53934.607 | L16: =F16+'26.5'!L16 -> 60187.81 | M16: =SUM(K16:L16) -> 114122.42 | N16: =H16+'26.5'!N16 -> 31436 | O16: =I16+'26.5'!O16 -> 15701.001
A17: 锅炉耗油量 | B17: 吨 | C17: 012 | D17: =D18+D19 -> 0 | E17: =E18+E19 -> 0 | F17: =F18+F19 -> 0 | G17: =G18+G19 -> 0 | H17: =H18+H19 -> 0 | I17: =I18+I19 -> 0 | J17: =J18+J19 -> 108.5 | K17: =K18+K19 -> 69.3 | ... O17: =O18+O19 -> 0.2
A18: 发电耗油量 | B18: 吨 | C18: 013 | D18: =G18+H18+I18 -> 0 | G18: =SUM(E18:F18) -> 0 | J18: =M18+N18+O18 -> 22.05624 | K18: =E18+'26.5'!K18 -> 14.553277 | L18: =F18+'26.5'!L18 -> 4.455 | M18: =SUM(K18:L18) -> 19.008277 | N18: =H18+'26.5'!N18 -> 3 | O18: =I18+'26.5'!O18 -> 0.047963043
A19: 供热耗油量 | B19: 吨 | C19: 014 | D19: =G19+H19+I19 -> 0 | G19: =SUM(E19:F19) -> 0 | J19: =M19+N19+O19 -> 86.44376 | K19: =E19+'26.5'!K19 -> 54.746723 | L19: =F19+'26.5'!L19 -> 20.545 | M19: =SUM(K19:L19) -> 75.291723 | N19: =H19+'26.5'!N19 -> 11 | O19: =I19+'26.5'!O19 -> 0.15203696
A20: 耗水量 | B20: 吨 | C20: 015 | D20: =G20+H20+I20 -> 0 | G20: =SUM(E20:F20) -> 0 | J20: =M20+N20+O20 -> 501831 | K20: =E20+'26.5'!K20 -> 177610 | L20: =F20+'26.5'!L20 -> 194774 | M20: =SUM(K20:L20) -> 372384 | N20: =H20+'26.5'!N20 -> 94794 | O20: =I20+'26.5'!O20 -> 34653
A21: 其中：耗再生水量(或井水) | B21: 吨 | C21: 016 | D21: =G21+H21+I21 -> 0 | G21: =SUM(E21:F21) -> 0 | J21: =M21+N21+O21 -> 132751 | K21: =E21+'26.5'!K21 -> 121213 | L21: =F21+'26.5'!L21 -> 0 | M21: =SUM(K21:L21) -> 121213 | N21: =H21+'26.5'!N21 -> 0 | O21: =I21+'26.5'!O21 -> 11538
A22: 耗酸量 | B22: 吨 | C22: 017 | D22: =G22+H22+I22 -> 0 | G22: =SUM(E22:F22) -> 0 | J22: =M22+N22+O22 -> 63.71 | K22: =E22+'26.5'!K22 -> 6.4 | L22: =F22+'26.5'!L22 -> 40 | M22: =SUM(K22:L22) -> 46.4 | N22: =H22+'26.5'!N22 -> 15 | O22: =I22+'26.5'!O22 -> 2.31
A23: 耗碱量 | B23: 吨 | C23: 018 | D23: =G23+H23+I23 -> 0 | G23: =SUM(E23:F23) -> 0 | J23: =M23+N23+O23 -> 54 | K23: =E23+'26.5'!K23 -> 9.7 | L23: =F23+'26.5'!L23 -> 32 | M23: =SUM(K23:L23) -> 41.7 | N23: =H23+'26.5'!N23 -> 10 | O23: =I23+'26.5'!O23 -> 2.3
A24: 耗石灰石量 | B24: 吨 | C24: 019 | D24: =G24+H24+I24 -> 0 | G24: =SUM(E24:F24) -> 0 | J24: =M24+N24+O24 -> 601.88 | K24: =E24+'26.5'!K24 -> 0 | L24: =F24+'26.5'!L24 -> 0 | M24: =SUM(K24:L24) -> 0 | N24: =H24+'26.5'!N24 -> 0 | O24: =I24+'26.5'!O24 -> 601.88
A25: 耗石灰石粉量 | B25: 吨 | C25: 020 | D25: =G25+H25+I25 -> 0 | G25: =SUM(E25:F25) -> 0 | J25: =M25+N25+O25 -> 3965.38 | K25: =E25+'26.5'!K25 -> 2045 | L25: =F25+'26.5'!L25 -> 854 | M25: =SUM(K25:L25) -> 2899 | N25: =H25+'26.5'!N25 -> 702 | O25: =I25+'26.5'!O25 -> 364.38
A26: 耗氨水量 | B26: 吨 | C26: 021 | D26: =G26+H26+I26 -> 0 | G26: =SUM(E26:F26) -> 0 | J26: =M26+N26+O26 -> 972.013 | K26: =E26+'26.5'!K26 -> 377.74 | L26: =F26+'26.5'!L26 -> 201 | M26: =SUM(K26:L26) -> 578.74 | N26: =H26+'26.5'!N26 -> 319 | O26: =I26+'26.5'!O26 -> 74.273
A27: 耗阻垢剂量(水质稳定剂) | B27: 吨 | C27: 022 | D27: =G27+H27+I27 -> 0 | G27: =SUM(E27:F27) -> 0 | J27: =M27+N27+O27 -> 3.125 | K27: =E27+'26.5'!K27 -> 1.075 | L27: =F27+'26.5'!L27 -> 1 | M27: =SUM(K27:L27) -> 2.075 | N27: =H27+'26.5'!N27 -> 1 | O27: =I27+'26.5'!O27 -> 0.05
A28: 耗杀菌剂量 | B28: 吨 | C28: 023 | D28: =G28+H28+I28 -> 0 | G28: =SUM(E28:F28) -> 0 | J28: =M28+N28+O28 -> 0 | K28: =E28+'26.5'!K28 -> 0 | L28: =F28+'26.5'!L28 -> 0 | M28: =SUM(K28:L28) -> 0 | N28: =H28+'26.5'!N28 -> 0 | O28: =I28+'26.5'!O28 -> 0
A29: 耗钢球量 | B29: 吨 | C29: 024 | D29: =G29+H29+I29 -> 0 | G29: =SUM(E29:F29) -> 0 | J29: =M29+N29+O29 -> 28 | K29: =E29+'26.5'!K29 -> 28 | L29: =F29+'26.5'!L29 -> 0 | M29: =SUM(K29:L29) -> 28 | N29: =H29+'26.5'!N29 -> 0 | O29: =I29+'26.5'!O29 -> 0
A30: 综合厂用电量 | B30: 千瓦时 | C30: 025 | D30: =G30+H30+I30 -> 0 | E30: =E7-E8 -> 0 | F30: =F7-F8 -> 0 | G30: =G7-G8 -> 0 | H30: =H7-H8 -> 0 | I30: =I7-I8 -> 0 | J30: =M30+N30+O30 -> 51347476 | K30: =E30+'26.5'!K30 -> 23607684 | L30: =F30+'26.5'!L30 -> 16539048 | M30: =M7-M8 -> 40146732 | N30: =H30+'26.5'!N30 -> 6998808 | O30: =I30+'26.5'!O30 -> 4201936
A31: 非生产厂用电量 | B31: 千瓦时 | C31: 026 | D31: =G31+H31+I31 -> 0 | G31: =SUM(E31:F31) -> 0 | J31: =M31+N31+O31 -> 7167192.5 | K31: =E31+'26.5'!K31 -> 6593264.5 | L31: =F31+'26.5'!L31 -> 573928 | M31: =SUM(K31:L31) -> 7167192.5 | N31: =H31+'26.5'!N31 -> 0 | O31: =I31+'26.5'!O31 -> 0
A32: 生产厂用电量 | B32: 千瓦时 | C32: 027 | D32: =D33+D34 -> 0 | E32: =E33+E34 -> 0 | F32: =F33+F34 -> 0 | G32: =G33+G34 -> 0 | H32: =H33+H34 -> 0 | I32: =I33+I34 -> 0 | J32: =J33+J34 -> 44180283 | K32: =K33+K34 -> 17014419 | ... O32: =O33+O34 -> 4201936
A33: 其中：发电厂用电量 | B33: 千瓦时 | C33: 028 | D33: =G33+H33+I33 -> 0 | G33: =SUM(E33:F33) -> 0 | J33: =M33+N33+O33 -> 8826323.6 | K33: =E33+'26.5'!K33 -> 3573096 | L33: =F33+'26.5'!L33 -> 2844984.4 | M33: =SUM(K33:L33) -> 6418080.4 | N33: =H33+'26.5'!N33 -> 1400555 | O33: =I33+'26.5'!O33 -> 1007688.2
A34: 供热厂用电量 | B34: 千瓦时 | C34: 029 | D34: =G34+H34+I34 -> 0 | G34: =SUM(E34:F34) -> 0 | J34: =M34+N34+O34 -> 35353959 | K34: =E34+'26.5'!K34 -> 13441323 | L34: =F34+'26.5'!L34 -> 13120136 | M34: =SUM(K34:L34) -> 26561458 | N34: =H34+'26.5'!N34 -> 5598253 | O34: =I34+'26.5'!O34 -> 3194247.8
A35: 综合厂用电率 | B35: % | C35: 030 | D35: =D30*100/D7 -> #DIV/0! | E35: =E30*100/E7 -> #DIV/0! | F35: =F30*100/F7 -> #DIV/0! | G35: =G30*100/G7 -> #DIV/0! | H35: =H30*100/H7 -> #DIV/0! | I35: =I30*100/I7 -> #DIV/0! | J35: =J30*100/J7 -> 32.825742 | K35: =K30*100/K7 -> 38.858082 | ... O35: =O30*100/O7 -> 27.369005
A36: 发电厂用电率 | B36: % | C36: 031 | D36: =D33*100/D7 -> #DIV/0! | E36: =E33*100/E7 -> #DIV/0! | F36: =F33*100/F7 -> #DIV/0! | G36: =G33*100/G7 -> #DIV/0! | H36: =H33*100/H7 -> #DIV/0! | I36: =I33*100/I7 -> #DIV/0! | J36: =J33*100/J7 -> 5.6425484 | K36: =K33*100/K7 -> 5.881291 | ... O36: =O33*100/O7 -> 6.5635039
A37: 供热厂用电率 | B37: 千瓦时/吉焦 | C37: 032 | D37: =D34/D9 -> #DIV/0! | E37: =E34/E9 -> #DIV/0! | F37: =F34/F9 -> #DIV/0! | G37: =G34/G9 -> #DIV/0! | H37: =H34/H9 -> #DIV/0! | I37: =I34/I9 -> #DIV/0! | J37: =J34/J9 -> 12.583334 | K37: =K34/K9 -> 13.712429 | ... O37: =O34/O9 -> 10.935672
A38: 耗标煤总量 | B38: 吨 | C38: 033 | D38: =D39+D42 -> 0 | E38: =E39+E42 -> 0 | F38: =F39+F42 -> 0 | G38: =G39+G42 -> 0 | H38: =H39+H42 -> 0 | I38: =I39+I42 -> 0 | J38: =J39+J42 -> 137897.36 | K38: =K39+K42 -> 46848.881 | ... O38: =O39+O42 -> 14852.348
A39: 发电标准煤耗量 | B39: 吨 | C39: 034 | D39: =D40+D41 -> 0 | E39: =E40+E41 -> 0 | F39: =F40+F41 -> 0 | G39: =G40+G41 -> 0 | H39: =H40+H41 -> 0 | I39: =I40+I41 -> 0 | J39: =J40+J41 -> 27596.4 | K39: =K40+K41 -> 9838.4525 | ... O39: =O40+O41 -> 3561.819
A40: 其中：煤折标准煤量 | B40: 吨 | C40: 035 | D40: =G40+H40+I40 -> 0 | G40: =SUM(E40:F40) -> 0 | J40: =M40+N40+O40 -> 27564.635 | K40: =E40+'26.5'!K40 -> 9817.2469 | L40: =F40+'26.5'!L40 -> 8544.6373 | M40: =SUM(K40:L40) -> 18361.884 | N40: =H40+'26.5'!N40 -> 5641 | O40: =I40+'26.5'!O40 -> 3561.7504
...

Sheet 26.7
A1: 大连市热电集团所属热电厂生产月报表
A2: 2026 年 7 月
A3: 指 标 名 称 | B3: 计量单位 | C3: 代码 | D3: 本 月 实 际 | J3: 本 年 累 计
D4: 合 计 | E4: 其 中 | J4: 合 计 | K4: 其 中
E5: 北海热电厂 | F5: 香海热电厂 | G5: 主城区小计 | H5: 金州热电厂 | I5: 瓦房店热电厂 | K5: 北海热电厂 | L5: 香海热电厂 | M5: 主城区小计 | N5: 金州热电厂 | O5: 瓦房店热电厂
