Workbook

Sheet 26.1
A1: 代码 | B1: 项目 | C1: 计量单位 | D1: 本 月 实 际 | I1: 本 年 累 计
D2: 北海水炉 | E2: 金普 | F2: 临海 | G2: 庄河 | H2: 合计 | I2: 北海水炉 | J2: 金普 | K2: 临海 | L2: 庄河 | M2: 合计
A3: 001 | B3: 装机总容量 | C3: 兆瓦 | D3: 348 | E3: 162 | G3: 14 | H3: =E3+F3+G3 -> 176 | I3: =D3 -> 348 | J3: =E3 -> 162 | K3: =F3 -> 0 | L3: =G3 -> 14 | M3: =J3+K3+L3 -> 176
A4: 002 | B4: 期末供热面积 | C4: 平方米 | D4: - | H4: =E4+F4+G4 -> 0 | J4: =E4 -> 0 | K4: =F4 -> 0 | L4: =G4 -> 0 | M4: =J4+K4+L4 -> 0
B5: 其中：高温水面积 | C5: 平方米 | D5: - | E5: 55000 | F5: 0 | G5: 0 | H5: =E5+F5+G5 -> 55000 | J5: =E5 -> 55000 | K5: =F5 -> 0 | L5: =G5 -> 0 | M5: =J5+K5+L5 -> 55000
A6: 003 | B6: 实际平均供热面积 | C6: 平方米 | D6: - | E6: =E4 -> 0 | F6: =F4 -> 0 | G6: =G4 -> 0 | H6: =E6+F6+G6 -> 0 | J6: =E6 -> 0 | K6: =F6 -> 0 | L6: =G6 -> 0 | M6: =J6+K6+L6 -> 0
A7: 004 | B7: 供汽量 | C7: 吨 | D7: - | E7: 0 | F7: 0 | G7: 0 | H7: =E7+F7+G7 -> 0 | J7: =E7 -> 0 | K7: =F7 -> 0 | L7: =G7 -> 0 | M7: =J7+K7+L7 -> 0
A8: 005 | B8: 供热量 | C8: 吉焦 | H8: =E8+F8+G8 -> 0 | I8: =D8 -> 0 | J8: =E8 -> 0 | K8: =F8 -> 0 | L8: =G8 -> 0 | M8: =J8+K8+L8 -> 0
A9: 006 | B9: 高温水销售量 | C9: 吉焦 | E9: =[1]售热量!$D$25 -> 0 | H9: =E9+F9+G9 -> 0 | J9: =E9 -> 0 | K9: =F9 -> 0 | L9: =G9 -> 0 | M9: =J9+K9+L9 -> 0
A10: 007 | B10: 生产耗原煤量 | C10: 吨 | H10: =E10+F10+G10 -> 0 | I10: =D10 -> 0 | J10: =E10 -> 0 | K10: =F10 -> 0 | L10: =G10 -> 0 | M10: =J10+K10+L10 -> 0
A11: 008 | B11: 耗油量 | C11: 吨 | H11: =E11+F11+G11 -> 0 | I11: =D11 -> 0 | J11: =E11 -> 0 | K11: =F11 -> 0 | L11: =G11 -> 0 | M11: =J11+K11+L11 -> 0
A12: 009 | B12: 耗标煤总量 | C12: 吨 | D12: =D13+D14 -> 0 | E12: =E13+E14 -> 0 | F12: =F13+F14 -> 0 | G12: =G13+G14 -> 0 | H12: =E12+F12+G12 -> 0 | I12: =I13+I14 -> 0 | J12: =E12 -> 0 | K12: =F12 -> 0 | L12: =G12 -> 0 | M12: =J12+K12+L12 -> 0
B13: 其中：煤折标准煤量 | C13: 吨 | I13: =D13 -> 0 | J13: =E13 -> 0 | L13: =G13 -> 0
B14: 油折标准煤量 | C14: 吨 | I14: =D14 -> 0
A15: 010 | B15: 耗水量 | C15: 吨 | I15: =D15 -> 0 | J15: =E15 -> 0 | K15: =F15 -> 0 | L15: =G15 -> 0 | M15: =J15+K15+L15 -> 0
B16: 其中：耗井水(再生水)量 | C16: 吨 | I16: =D16 -> 0 | J16: =E16 -> 0 | K16: =F16 -> 0 | L16: =G16 -> 0 | M16: =J16+K16+L16 -> 0
A17: 011 | B17: 耗电量 | C17: 千瓦时 | D17: =D18+D19 -> 0 | I17: =D17 -> 0 | J17: =E17 -> 0 | L17: =G17 -> 0 | M17: =J17+K17+L17 -> 0
B18: 其中：耗厂用电量 | C18: 千瓦时 | I18: =D18 -> 0
B19: 耗外购电量 | C19: 千瓦时 | E19: =E17 -> 0 | F19: =F17 -> 0 | G19: =G17 -> 0 | I19: =D19 -> 0 | L19: =G19 -> 0
B20: 脱硫脱硝耗水量 | C20: 吨 | I20: =D20 -> 0
B21: 脱硫脱硝耗电量 | C21: 千瓦时 | I21: =D21 -> 0
A22: 012 | B22: 耗氧化镁(石灰石粉)量 | C22: 吨 | I22: =D22 -> 0 | J22: =E22 -> 0 | K22: =F22 -> 0 | L22: =G22 -> 0 | M22: =J22+K22+L22 -> 0
A23: 013 | B23: 耗脱硝剂(氨水)量 | C23: 吨 | I23: =D23 -> 0 | J23: =E23 -> 0 | K23: =F23 -> 0 | L23: =G23 -> 0 | M23: =J23+K23+L23 -> 0
A24: 014 | B24: 供热用电率 | C24: 千瓦时/吉焦 | D24: =D17/D8 -> #DIV/0! | E24: =E17/E8 -> #DIV/0! | F24: =F17/F8 -> #DIV/0! | G24: =G17/G8 -> #DIV/0! | H24: =H17/H8 -> #DIV/0! | I24: =I17/I8 -> #DIV/0! | J24: =J17/J8 -> #DIV/0! | K24: =K17/K8 -> #DIV/0! | ... M24: =M17/M8 -> #DIV/0!
A25: 015 | B25: 供热煤耗率 | C25: 千克/吉焦 | D25: =D12*1000/D8 -> #DIV/0! | E25: =E12*1000/E8 -> #DIV/0! | F25: =F12*1000/F8 -> #DIV/0! | G25: =G12*1000/G8 -> #DIV/0! | H25: =H12*1000/H8 -> #DIV/0! | I25: =I12*1000/I8 -> #DIV/0! | J25: =J12*1000/J8 -> #DIV/0! | K25: =K12*1000/K8 -> #DIV/0! | ... M25: =M12*1000/M8 -> #DIV/0!
A26: 016 | B26: 入厂煤量 | C26: 吨 | I26: =D26 -> 0 | J26: =E26 -> 0 | K26: =F26 -> 0 | L26: =G26 -> 0 | M26: =J26+K26+L26 -> 0
A27: 017 | B27: 期末库存煤量 | C27: 吨 | E27: =J27 -> 12569.7 | F27: =K27 -> 0 | G27: =L27 -> 1108.5 | J27: ='[2]25.12'!$J$27+E26-E10 -> 12569.7 | K27: ='[2]25.12'!$K$27+F26-F10 -> 0 | L27: ='[2]25.12'!$L$27+G26-G10 -> 1108.5 | M27: =J27+K27+L27 -> 13678.2
A28: 018 | B28: 入炉煤低位发热量 | C28: 千焦/千克 | D28: =D13*29308/D10 -> #DIV/0! | E28: =E12*29308/E10 -> #DIV/0! | F28: =F12*29308/F10 -> #DIV/0! | G28: =G12*29308/G10 -> #DIV/0! | H28: =H12*29308/H10 -> #DIV/0! | I28: =I13*29308/I10 -> #DIV/0! | J28: =J12*29308/J10 -> #DIV/0! | K28: =K12*29308/K10 -> #DIV/0! | L28: =L12*29308/L10 -> #DIV/0! | M28: =M12*29308/M10 -> #DIV/0!
A29: 019 | B29: 入厂煤低位发热量 | C29: 千焦/千克 | J29: 16894
A30: 020 | B30: 锅炉热效率 | C30: % | D30: =D8/(D12*29.308) -> #DIV/0! | E30: =E8/(E12*29.308) -> #DIV/0! | F30: =F8/(F12*29.308) -> #DIV/0! | G30: =(G8-G36)/(G12*29.308) -> #DIV/0! | H30: =H8/(H12*29.308) -> #DIV/0! | I30: =I8/(I12*29.308) -> #DIV/0! | J30: =J8/(J12*29.308) -> #DIV/0! | K30: =K8/(K12*29.308) -> #DIV/0! | L30: =L8/(L12*29.308) -> #DIV/0! | M30: =M8/(M12*29.308) -> #DIV/0!
A31: 021 | B31: 锅炉设备利用率 | C31: % | D31: =D8/3.6/D3/(DAY(DATE(2026,2,0))*24) -> 0 | E31: =E8/3.6/E3/(DAY(DATE(2026,2,0))*24) -> 0 | F31: =F8/3.6/F3/(DAY(DATE(2026,2,0))*24) -> #DIV/0! | G31: =(G8-G36)/3.6/G3/(DAY(DATE(2026,2,0))*24) -> 0 | H31: =H8/3.6/H3/(DAY(DATE(2026,2,0))*24) -> 0 | I31: =I8/3.6/I3/(DATEDIF(DATE(2026,1,1),DATE(2026,2,1),"D")*24) -> 0 | J31: =J8/3.6/J3/(DATEDIF(DATE(2026,1,1),DATE(2026,2,1),"D")*24) -> 0 | K31: =K8/3.6/K3/(DATEDIF(DATE(2026,1,1),DATE(2026,2,1),"D")*24) -> #DIV/0! | L31: =(L8-L36)/3.6/L3/(DATEDIF(DATE(2026,1,1),DATE(2026,2,1),"D")*24) -> 0 | M31: =M8/3.6/M3/(DATEDIF(DATE(2026,1,1),DATE(2026,2,1),"D")*24) -> 0
A32: 022 | B32: 供暖热耗率 | C32: 吉焦/平方米 | E32: =E8/E6 -> #DIV/0! | F32: =F8/F6 -> #DIV/0! | G32: =G8/G6 -> #DIV/0! | H32: =H8/H6 -> #DIV/0! | J32: =J8/J6 -> #DIV/0! | K32: =K8/K6 -> #DIV/0! | L32: =L8/L6 -> #DIV/0! | M32: =M8/M6 -> #DIV/0!
A33: 023 | B33: 单位面积耗标准煤量 | C33: 千克/平方米 | E33: =E12*1000/E6 -> #DIV/0! | F33: =F12*1000/F6 -> #DIV/0! | G33: =G12*1000/G6 -> #DIV/0! | H33: =H12*1000/H6 -> #DIV/0! | J33: =J12*1000/J6 -> #DIV/0! | K33: =K12*1000/K6 -> #DIV/0! | L33: =L12*1000/L6 -> #DIV/0! | M33: =M12*1000/M6 -> #DIV/0!
A34: 024 | B34: 单位面积耗电量 | C34: 千瓦时/平方米 | E34: =E17/E6 -> #DIV/0! | F34: =F17/F6 -> #DIV/0! | G34: =G17/G6 -> #DIV/0! | H34: =H17/H6 -> #DIV/0! | J34: =J17/J6 -> #DIV/0! | K34: =K17/K6 -> #DIV/0! | L34: =L17/L6 -> #DIV/0! | M34: =M17/M6 -> #DIV/0!
A35: 025 | B35: 单位面积耗水量 | C35: 千克/平方米 | E35: =E15*1000/E6 -> #DIV/0! | F35: =F15*1000/F6 -> #DIV/0! | G35: =G15*1000/G6 -> #DIV/0! | H35: =H15*1000/H6 -> #DIV/0! | J35: =J15*1000/J6 -> #DIV/0! | K35: =K15*1000/K6 -> #DIV/0! | L35: =L15*1000/L6 -> #DIV/0! | M35: =M15*1000/M6 -> #DIV/0!
B36: 外购热量 | C36: 吉焦 | L36: =G36 -> 0
A37: 电锅炉房(机车)
A38: 代码 | B38: 项 目 | C38: 计量单位 | D38: 本月实际 | E38: 本年累计
A39: 001 | B39: 装机总容量 | C39: 兆瓦 | D39: 0.55 | E39: 0.55
A40: 002 | B40: 期末供暖面积 | C40: 平方米 | D40: 7625.06 | E40: =D40 -> 7625.06
...

Sheet 26.2
A1: 代码 | B1: 项目 | C1: 计量单位 | D1: 本 月 实 际 | I1: 本 年 累 计
D2: 北海水炉 | E2: 金普 | F2: 临海 | G2: 庄河 | H2: 合计 | I2: 北海水炉 | J2: 金普 | K2: 临海 | L2: 庄河 | M2: 合计
A3: 001 | B3: 装机总容量 | C3: 兆瓦 | D3: 348 | E3: 162 | G3: 263 | H3: =E3+F3+G3 -> 425 | I3: =D3 -> 348 | J3: =E3 -> 162 | K3: =F3 -> 0 | L3: =G3 -> 263 | M3: =J3+K3+L3 -> 425
A4: 002 | B4: 期末供热面积 | C4: 平方米 | D4: - | H4: =E4+F4+G4 -> 0 | I4: =D4 -> - | J4: =E4 -> 0 | K4: =F4 -> 0 | L4: =G4 -> 0 | M4: =J4+K4+L4 -> 0
B5: 其中：高温水面积 | C5: 平方米 | D5: - | E5: 55000 | F5: 0 | G5: 0 | H5: =E5+F5+G5 -> 55000 | I5: =D5 -> - | J5: =E5 -> 55000 | K5: =F5 -> 0 | L5: =G5 -> 0 | M5: =J5+K5+L5 -> 55000
A6: 003 | B6: 实际平均供热面积 | C6: 平方米 | D6: - | E6: =E4 -> 0 | F6: =F4 -> 0 | G6: =G4 -> 0 | H6: =E6+F6+G6 -> 0 | I6: =D6 -> - | J6: =E6 -> 0 | K6: =F6 -> 0 | L6: =G6 -> 0 | M6: =J6+K6+L6 -> 0
A7: 004 | B7: 供汽量 | C7: 吨 | D7: 0 | E7: 0 | F7: 0 | G7: 0 | H7: =E7+F7+G7 -> 0 | I7: =D7+'26.1'!I7 -> 0 | J7: =E7+'26.1'!J7 -> 0 | K7: =F7+'26.1'!K7 -> 0 | L7: =G7+'26.1'!L7 -> 0 | M7: =J7+K7+L7 -> 0
A8: 005 | B8: 供热量 | C8: 吉焦 | H8: =E8+F8+G8 -> 0 | I8: =D8+'26.1'!I8 -> 0 | J8: =E8+'26.1'!J8 -> 0 | K8: =F8+'26.1'!K8 -> 0 | L8: =G8+'26.1'!L8 -> 0 | M8: =J8+K8+L8 -> 0
A9: 006 | B9: 高温水销售量 | C9: 吉焦 | E9: =[1]售热量!$E$25 -> 0 | H9: =E9+F9+G9 -> 0 | I9: =D9+'26.1'!I9 -> 0 | J9: =E9+'26.1'!J9 -> 0 | K9: =F9+'26.1'!K9 -> 0 | L9: =G9+'26.1'!L9 -> 0 | M9: =J9+K9+L9 -> 0
A10: 007 | B10: 生产耗原煤量 | C10: 吨 | H10: =E10+F10+G10 -> 0 | I10: =D10+'26.1'!I10 -> 0 | J10: =E10+'26.1'!J10 -> 0 | K10: =F10+'26.1'!K10 -> 0 | L10: =G10+'26.1'!L10 -> 0 | M10: =J10+K10+L10 -> 0
A11: 008 | B11: 耗油量 | C11: 吨 | H11: =E11+F11+G11 -> 0 | I11: =D11+'26.1'!I11 -> 0 | J11: =E11+'26.1'!J11 -> 0 | K11: =F11+'26.1'!K11 -> 0 | L11: =G11+'26.1'!L11 -> 0 | M11: =J11+K11+L11 -> 0
A12: 009 | B12: 耗标煤总量 | C12: 吨 | D12: =D13+D14 -> 0 | E12: =E13+E14 -> 0 | F12: =F13+F14 -> 0 | G12: =G13+G14 -> 0 | H12: =E12+F12+G12 -> 0 | I12: =D12+'26.1'!I12 -> 0 | J12: =E12+'26.1'!J12 -> 0 | K12: =F12+'26.1'!K12 -> 0 | L12: =G12+'26.1'!L12 -> 0 | M12: =J12+K12+L12 -> 0
B13: 其中：煤折标准煤量 | C13: 吨 | I13: =D13+'26.1'!I13 -> 0 | J13: =E13+'26.1'!J13 -> 0 | K13: =F13+'26.1'!K13 -> 0 | L13: =G13+'26.1'!L13 -> 0
B14: 油折标准煤量 | C14: 吨 | I14: =D14+'26.1'!I14 -> 0 | J14: =E14+'26.1'!J14 -> 0 | K14: =F14+'26.1'!K14 -> 0 | L14: =G14+'26.1'!L14 -> 0
A15: 010 | B15: 耗水量 | C15: 吨 | I15: =D15+'26.1'!I15 -> 0 | J15: =E15+'26.1'!J15 -> 0 | K15: =F15+'26.1'!K15 -> 0 | L15: =G15+'26.1'!L15 -> 0 | M15: =J15+K15+L15 -> 0
B16: 其中：耗井水(再生水)量 | C16: 吨 | I16: =D16+'26.1'!I16 -> 0 | J16: =E16+'26.1'!J16 -> 0 | K16: =F16+'26.1'!K16 -> 0 | L16: =G16+'26.1'!L16 -> 0 | M16: =J16+K16+L16 -> 0
A17: 011 | B17: 耗电量 | C17: 千瓦时 | D17: =D18+D19 -> 0 | I17: =D17+'26.1'!I17 -> 0 | J17: =E17+'26.1'!J17 -> 0 | L17: =G17+'26.1'!L17 -> 0 | M17: =J17+K17+L17 -> 0
B18: 其中：耗厂用电量 | C18: 千瓦时 | I18: =D18+'26.1'!I18 -> 0 | J18: =E18+'26.1'!J18 -> 0 | K18: =F18+'26.1'!K18 -> 0 | L18: =G18+'26.1'!L18 -> 0
B19: 耗外购电量 | C19: 千瓦时 | E19: =E17 -> 0 | F19: =F17 -> 0 | G19: =G17 -> 0 | I19: =D19+'26.1'!I19 -> 0 | J19: =E19+'26.1'!J19 -> 0 | K19: =F19+'26.1'!K19 -> 0 | L19: =G19+'26.1'!L19 -> 0
B20: 脱硫脱硝耗水量 | C20: 吨 | I20: =D20+'26.1'!I20 -> 0 | J20: =E20+'26.1'!J20 -> 0 | K20: =F20+'26.1'!K20 -> 0 | L20: =G20+'26.1'!L20 -> 0
B21: 脱硫脱硝耗电量 | C21: 千瓦时 | I21: =D21+'26.1'!I21 -> 0 | J21: =E21+'26.1'!J21 -> 0 | K21: =F21+'26.1'!K21 -> 0 | L21: =G21+'26.1'!L21 -> 0
A22: 012 | B22: 耗氧化镁(石灰石粉)量 | C22: 吨 | I22: =D22+'26.1'!I22 -> 0 | J22: =E22+'26.1'!J22 -> 0 | K22: =F22+'26.1'!K22 -> 0 | L22: =G22+'26.1'!L22 -> 0 | M22: =J22+K22+L22 -> 0
A23: 013 | B23: 耗脱硝剂(氨水)量 | C23: 吨 | I23: =D23+'26.1'!I23 -> 0 | J23: =E23+'26.1'!J23 -> 0 | K23: =F23+'26.1'!K23 -> 0 | L23: =G23+'26.1'!L23 -> 0 | M23: =J23+K23+L23 -> 0
A24: 014 | B24: 供热用电率 | C24: 千瓦时/吉焦 | D24: =D17/D8 -> #DIV/0! | E24: =E17/E8 -> #DIV/0! | F24: =F17/F8 -> #DIV/0! | G24: =G17/G8 -> #DIV/0! | H24: =H17/H8 -> #DIV/0! | I24: =I17/I8 -> #DIV/0! | J24: =J17/J8 -> #DIV/0! | K24: =K17/K8 -> #DIV/0! | ... M24: =M17/M8 -> #DIV/0!
A25: 015 | B25: 供热煤耗率 | C25: 千克/吉焦 | D25: =D12*1000/D8 -> #DIV/0! | E25: =E12*1000/E8 -> #DIV/0! | F25: =F12*1000/F8 -> #DIV/0! | G25: =G12*1000/G8 -> #DIV/0! | H25: =H12*1000/H8 -> #DIV/0! | I25: =I12*1000/I8 -> #DIV/0! | J25: =J12*1000/J8 -> #DIV/0! | K25: =K12*1000/K8 -> #DIV/0! | ... M25: =M12*1000/M8 -> #DIV/0!
A26: 016 | B26: 入厂煤量 | C26: 吨 | I26: =D26+'26.1'!I26 -> 0 | J26: =E26+'26.1'!J26 -> 0 | K26: =F26+'26.1'!K26 -> 0 | L26: =G26+'26.1'!L26 -> 0 | M26: =J26+K26+L26 -> 0
A27: 017 | B27: 期末库存煤量 | C27: 吨 | E27: =J27 -> 12569.7 | F27: =K27 -> 0 | G27: =L27 -> 1108.5 | I27: =D27 -> 0 | J27: ='26.1'!J27+E26-E10 -> 12569.7 | K27: ='26.1'!K27+F26-F10 -> 0 | L27: ='26.1'!L27+G26-G10 -> 1108.5 | M27: =J27+K27+L27 -> 13678.2
A28: 018 | B28: 入炉煤低位发热量 | C28: 千焦/千克 | D28: =D13*29308/D10 -> #DIV/0! | E28: =E12*29308/E10 -> #DIV/0! | F28: =F12*29308/F10 -> #DIV/0! | G28: =G12*29308/G10 -> #DIV/0! | H28: =H12*29308/H10 -> #DIV/0! | I28: =I13*29308/I10 -> #DIV/0! | J28: =J12*29308/J10 -> #DIV/0! | K28: =K12*29308/K10 -> #DIV/0! | L28: =L12*29308/L10 -> #DIV/0! | M28: =M12*29308/M10 -> #DIV/0!
A29: 019 | B29: 入厂煤低位发热量 | C29: 千焦/千克
A30: 020 | B30: 锅炉热效率 | C30: % | D30: =D8/(D12*29.308) -> #DIV/0! | E30: =E8/(E12*29.308) -> #DIV/0! | F30: =F8/(F12*29.308) -> #DIV/0! | G30: =(G8-G36)/(G12*29.308) -> #DIV/0! | H30: =H8/(H12*29.308) -> #DIV/0! | I30: =I8/(I12*29.308) -> #DIV/0! | J30: =J8/(J12*29.308) -> #DIV/0! | K30: =K8/(K12*29.308) -> #DIV/0! | L30: =L8/(L12*29.308) -> #DIV/0! | M30: =M8/(M12*29.308) -> #DIV/0!
A31: 021 | B31: 锅炉设备利用率 | C31: % | D31: =D8/3.6/D3/(DAY(DATE(2026,3,0))*24) -> 0 | E31: =E8/3.6/E3/(DAY(DATE(2026,3,0))*24) -> 0 | F31: =F8/3.6/F3/(DAY(DATE(2026,3,0))*24) -> #DIV/0! | G31: =(G8-G36)/3.6/G3/(DAY(DATE(2026,3,0))*24) -> 0 | H31: =H8/3.6/H3/(DAY(DATE(2026,3,0))*24) -> 0 | I31: =I8/3.6/I3/(DATEDIF(DATE(2026,1,1),DATE(2026,3,1),"D")*24) -> 0 | J31: =J8/3.6/J3/(DATEDIF(DATE(2026,1,1),DATE(2026,3,1),"D")*24) -> 0 | K31: =K8/3.6/K3/(DATEDIF(DATE(2026,1,1),DATE(2026,3,1),"D")*24) -> #DIV/0! | L31: =(L8-L36)/3.6/L3/(DATEDIF(DATE(2026,1,1),DATE(2026,3,1),"D")*24) -> 0 | M31: =M8/3.6/M3/(DATEDIF(DATE(2026,1,1),DATE(2026,3,1),"D")*24) -> 0
A32: 022 | B32: 供暖热耗率 | C32: 吉焦/平方米 | E32: =E8/E6 -> #DIV/0! | F32: =F8/F6 -> #DIV/0! | G32: =G8/G6 -> #DIV/0! | H32: =H8/H6 -> #DIV/0! | J32: =J8/J6 -> #DIV/0! | K32: =K8/K6 -> #DIV/0! | L32: =L8/L6 -> #DIV/0! | M32: =M8/M6 -> #DIV/0!
A33: 023 | B33: 单位面积耗标准煤量 | C33: 千克/平方米 | E33: =E12*1000/E6 -> #DIV/0! | F33: =F12*1000/F6 -> #DIV/0! | G33: =G12*1000/G6 -> #DIV/0! | H33: =H12*1000/H6 -> #DIV/0! | J33: =J12*1000/J6 -> #DIV/0! | K33: =K12*1000/K6 -> #DIV/0! | L33: =L12*1000/L6 -> #DIV/0! | M33: =M12*1000/M6 -> #DIV/0!
A34: 024 | B34: 单位面积耗电量 | C34: 千瓦时/平方米 | E34: =E17/E6 -> #DIV/0! | F34: =F17/F6 -> #DIV/0! | G34: =G17/G6 -> #DIV/0! | H34: =H17/H6 -> #DIV/0! | J34: =J17/J6 -> #DIV/0! | K34: =K17/K6 -> #DIV/0! | L34: =L17/L6 -> #DIV/0! | M34: =M17/M6 -> #DIV/0!
A35: 025 | B35: 单位面积耗水量 | C35: 千克/平方米 | E35: =E15*1000/E6 -> #DIV/0! | F35: =F15*1000/F6 -> #DIV/0! | G35: =G15*1000/G6 -> #DIV/0! | H35: =H15*1000/H6 -> #DIV/0! | J35: =J15*1000/J6 -> #DIV/0! | K35: =K15*1000/K6 -> #DIV/0! | L35: =L15*1000/L6 -> #DIV/0! | M35: =M15*1000/M6 -> #DIV/0!
B36: 外购热量 | C36: 吉焦 | L36: =G36+'26.1'!G36 -> 0
A37: 电锅炉房(机车)
A38: 代码 | B38: 项 目 | C38: 计量单位 | D38: 本月实际 | E38: 本年累计
A39: 001 | B39: 装机总容量 | C39: 兆瓦 | D39: 0.55 | E39: 0.55
A40: 002 | B40: 期末供暖面积 | C40: 平方米 | E40: =D40 -> 0
...

Sheet 26.3
A1: 代码 | B1: 项目 | C1: 计量单位 | D1: 本 月 实 际 | I1: 本 年 累 计
D2: 北海水炉 | E2: 金普 | F2: 临海 | G2: 庄河 | H2: 合计 | I2: 北海水炉 | J2: 金普 | K2: 临海 | L2: 庄河 | M2: 合计
A3: 001 | B3: 装机总容量 | C3: 兆瓦 | D3: 348 | E3: 162 | G3: 263 | H3: =E3+F3+G3 -> 425 | I3: =D3 -> 348 | J3: =E3 -> 162 | K3: =F3 -> 0 | L3: =G3 -> 263 | M3: =J3+K3+L3 -> 425
A4: 002 | B4: 期末供热面积 | C4: 平方米 | D4: - | H4: =E4+F4+G4 -> 0 | I4: =D4 -> - | J4: =E4 -> 0 | K4: =F4 -> 0 | L4: =G4 -> 0 | M4: =J4+K4+L4 -> 0
B5: 其中：高温水面积 | C5: 平方米 | D5: - | E5: 55000 | F5: 0 | G5: 0 | H5: =E5+F5+G5 -> 55000 | I5: =D5 -> - | J5: =E5 -> 55000 | K5: =F5 -> 0 | L5: =G5 -> 0 | M5: =J5+K5+L5 -> 55000
A6: 003 | B6: 实际平均供热面积 | C6: 平方米 | D6: - | E6: =E4 -> 0 | F6: =F4 -> 0 | G6: =G4 -> 0 | H6: =E6+F6+G6 -> 0 | I6: =D6 -> - | J6: =E6 -> 0 | K6: =F6 -> 0 | L6: =G6 -> 0 | M6: =J6+K6+L6 -> 0
A7: 004 | B7: 供汽量 | C7: 吨 | D7: 0 | E7: 0 | F7: 0 | H7: =E7+F7+G7 -> 0 | I7: =D7+'26.2'!I7 -> 0 | J7: =E7+'26.2'!J7 -> 0 | K7: =F7+'26.2'!K7 -> 0 | L7: =G7+'26.2'!L7 -> 0 | M7: =J7+K7+L7 -> 0
A8: 005 | B8: 供热量 | C8: 吉焦 | H8: =E8+F8+G8 -> 0 | I8: =D8+'26.2'!I8 -> 0 | J8: =E8+'26.2'!J8 -> 0 | K8: =F8+'26.2'!K8 -> 0 | L8: =G8+'26.2'!L8 -> 0 | M8: =J8+K8+L8 -> 0
A9: 006 | B9: 高温水销售量 | C9: 吉焦 | E9: =[1]售热量!$G$25 -> 0 | H9: =E9+F9+G9 -> 0 | I9: =D9+'26.2'!I9 -> 0 | J9: =E9+'26.2'!J9 -> 0 | K9: =F9+'26.2'!K9 -> 0 | L9: =G9+'26.2'!L9 -> 0 | M9: =J9+K9+L9 -> 0
A10: 007 | B10: 生产耗原煤量 | C10: 吨 | H10: =E10+F10+G10 -> 0 | I10: =D10+'26.2'!I10 -> 0 | J10: =E10+'26.2'!J10 -> 0 | K10: =F10+'26.2'!K10 -> 0 | L10: =G10+'26.2'!L10 -> 0 | M10: =J10+K10+L10 -> 0
A11: 008 | B11: 耗油量 | C11: 吨 | H11: =E11+F11+G11 -> 0 | I11: =D11+'26.2'!I11 -> 0 | J11: =E11+'26.2'!J11 -> 0 | K11: =F11+'26.2'!K11 -> 0 | L11: =G11+'26.2'!L11 -> 0 | M11: =J11+K11+L11 -> 0
A12: 009 | B12: 耗标煤总量 | C12: 吨 | D12: =D13+D14 -> 0 | E12: =E13+E14 -> 0 | F12: =F13+F14 -> 0 | G12: =G13+G14 -> 0 | H12: =E12+F12+G12 -> 0 | I12: =D12+'26.2'!I12 -> 0 | J12: =E12+'26.2'!J12 -> 0 | K12: =F12+'26.2'!K12 -> 0 | L12: =G12+'26.2'!L12 -> 0 | M12: =J12+K12+L12 -> 0
B13: 其中：煤折标准煤量 | C13: 吨 | I13: =D13+'26.2'!I13 -> 0 | J13: =E13+'26.2'!J13 -> 0 | K13: =F13+'26.2'!K13 -> 0 | L13: =G13+'26.2'!L13 -> 0
B14: 油折标准煤量 | C14: 吨 | I14: =D14+'26.2'!I14 -> 0 | J14: =E14+'26.2'!J14 -> 0 | K14: =F14+'26.2'!K14 -> 0 | L14: =G14+'26.2'!L14 -> 0
A15: 010 | B15: 耗水量 | C15: 吨 | I15: =D15+'26.2'!I15 -> 0 | J15: =E15+'26.2'!J15 -> 0 | K15: =F15+'26.2'!K15 -> 0 | L15: =G15+'26.2'!L15 -> 0 | M15: =J15+K15+L15 -> 0
B16: 其中：耗井水(再生水)量 | C16: 吨 | I16: =D16+'26.2'!I16 -> 0 | J16: =E16+'26.2'!J16 -> 0 | K16: =F16+'26.2'!K16 -> 0 | L16: =G16+'26.2'!L16 -> 0 | M16: =J16+K16+L16 -> 0
A17: 011 | B17: 耗电量 | C17: 千瓦时 | I17: =D17+'26.2'!I17 -> 0 | J17: =E17+'26.2'!J17 -> 0 | L17: =G17+'26.2'!L17 -> 0 | M17: =J17+K17+L17 -> 0
B18: 其中：耗厂用电量 | C18: 千瓦时 | I18: =D18+'26.2'!I18 -> 0 | J18: =E18+'26.2'!J18 -> 0 | K18: =F18+'26.2'!K18 -> 0 | L18: =G18+'26.2'!L18 -> 0
B19: 耗外购电量 | C19: 千瓦时 | I19: =D19+'26.2'!I19 -> 0 | K19: =F19+'26.2'!K19 -> 0 | L19: =G19+'26.2'!L19 -> 0
B20: 脱硫脱硝耗水量 | C20: 吨 | I20: =D20+'26.2'!I20 -> 0 | J20: =E20+'26.2'!J20 -> 0 | K20: =F20+'26.2'!K20 -> 0 | L20: =G20+'26.2'!L20 -> 0
B21: 脱硫脱硝耗电量 | C21: 千瓦时 | I21: =D21+'26.2'!I21 -> 0 | J21: =E21+'26.2'!J21 -> 0 | K21: =F21+'26.2'!K21 -> 0 | L21: =G21+'26.2'!L21 -> 0
A22: 012 | B22: 耗氧化镁(石灰石粉)量 | C22: 吨 | I22: =D22+'26.2'!I22 -> 0 | J22: =E22+'26.2'!J22 -> 0 | K22: =F22+'26.2'!K22 -> 0 | L22: =G22+'26.2'!L22 -> 0 | M22: =J22+K22+L22 -> 0
A23: 013 | B23: 耗脱硝剂(氨水)量 | C23: 吨 | I23: =D23+'26.2'!I23 -> 0 | J23: =E23+'26.2'!J23 -> 0 | K23: =F23+'26.2'!K23 -> 0 | L23: =G23+'26.2'!L23 -> 0 | M23: =J23+K23+L23 -> 0
A24: 014 | B24: 供热用电率 | C24: 千瓦时/吉焦 | D24: =D17/D8 -> #DIV/0! | E24: =E17/E8 -> #DIV/0! | F24: =F17/F8 -> #DIV/0! | G24: =G17/G8 -> #DIV/0! | H24: =H17/H8 -> #DIV/0! | I24: =I17/I8 -> #DIV/0! | J24: =J17/J8 -> #DIV/0! | K24: =K17/K8 -> #DIV/0! | ... M24: =M17/M8 -> #DIV/0!
A25: 015 | B25: 供热煤耗率 | C25: 千克/吉焦 | D25: =D12*1000/D8 -> #DIV/0! | E25: =E12*1000/E8 -> #DIV/0! | F25: =F12*1000/F8 -> #DIV/0! | G25: =G12*1000/G8 -> #DIV/0! | H25: =H12*1000/H8 -> #DIV/0! | I25: =I12*1000/I8 -> #DIV/0! | J25: =J12*1000/J8 -> #DIV/0! | K25: =K12*1000/K8 -> #DIV/0! | ... M25: =M12*1000/M8 -> #DIV/0!
A26: 016 | B26: 入厂煤量 | C26: 吨 | I26: =D26+'26.2'!I26 -> 0 | J26: =E26+'26.2'!J26 -> 0 | K26: =F26+'26.2'!K26 -> 0 | L26: =G26+'26.2'!L26 -> 0 | M26: =J26+K26+L26 -> 0
A27: 017 | B27: 期末库存煤量 | C27: 吨 | E27: =J27 -> 12569.7 | F27: =K27 -> 0 | G27: =L27 -> 1108.5 | I27: =D27 -> 0 | J27: ='26.2'!J27+E26-E10 -> 12569.7 | K27: ='26.2'!K27+F26-F10 -> 0 | L27: ='26.2'!L27+G26-G10 -> 1108.5 | M27: =J27+K27+L27 -> 13678.2
A28: 018 | B28: 入炉煤低位发热量 | C28: 千焦/千克 | D28: =D13*29308/D10 -> #DIV/0! | E28: =E12*29308/E10 -> #DIV/0! | F28: =F12*29308/F10 -> #DIV/0! | G28: =G12*29308/G10 -> #DIV/0! | H28: =H12*29308/H10 -> #DIV/0! | I28: =I13*29308/I10 -> #DIV/0! | J28: =J12*29308/J10 -> #DIV/0! | K28: =K12*29308/K10 -> #DIV/0! | L28: =L12*29308/L10 -> #DIV/0! | M28: =M12*29308/M10 -> #DIV/0!
A29: 019 | B29: 入厂煤低位发热量 | C29: 千焦/千克
A30: 020 | B30: 锅炉热效率 | C30: % | D30: =D8/(D12*29.308) -> #DIV/0! | E30: =E8/(E12*29.308) -> #DIV/0! | F30: =F8/(F12*29.308) -> #DIV/0! | G30: =(G8-G36)/(G12*29.308) -> #DIV/0! | H30: =H8/(H12*29.308) -> #DIV/0! | I30: =I8/(I12*29.308) -> #DIV/0! | J30: =J8/(J12*29.308) -> #DIV/0! | K30: =K8/(K12*29.308) -> #DIV/0! | L30: =L8/(L12*29.308) -> #DIV/0! | M30: =M8/(M12*29.308) -> #DIV/0!
A31: 021 | B31: 锅炉设备利用率 | C31: % | D31: =D8/3.6/D3/(DAY(DATE(2026,4,0))*24) -> 0 | E31: =E8/3.6/E3/(DAY(DATE(2026,4,0))*24) -> 0 | F31: =F8/3.6/F3/(DAY(DATE(2026,4,0))*24) -> #DIV/0! | G31: =(G8-G36)/3.6/G3/(DAY(DATE(2026,4,0))*24) -> 0 | H31: =H8/3.6/H3/(DAY(DATE(2026,4,0))*24) -> 0 | I31: =I8/3.6/I3/(DATEDIF(DATE(2026,1,1),DATE(2026,4,1),"D")*24) -> 0 | J31: =J8/3.6/J3/(DATEDIF(DATE(2026,1,1),DATE(2026,4,1),"D")*24) -> 0 | K31: =K8/3.6/K3/(DATEDIF(DATE(2026,1,1),DATE(2026,4,1),"D")*24) -> #DIV/0! | L31: =(L8-L36)/3.6/L3/(DATEDIF(DATE(2026,1,1),DATE(2026,4,1),"D")*24) -> 0 | M31: =M8/3.6/M3/(DATEDIF(DATE(2026,1,1),DATE(2026,4,1),"D")*24) -> 0
A32: 022 | B32: 供暖热耗率 | C32: 吉焦/平方米 | E32: =E8/E6 -> #DIV/0! | F32: =F8/F6 -> #DIV/0! | G32: =G8/G6 -> #DIV/0! | H32: =H8/H6 -> #DIV/0! | J32: =J8/J6 -> #DIV/0! | K32: =K8/K6 -> #DIV/0! | L32: =L8/L6 -> #DIV/0! | M32: =M8/M6 -> #DIV/0!
A33: 023 | B33: 单位面积耗标准煤量 | C33: 千克/平方米 | E33: =E12*1000/E6 -> #DIV/0! | F33: =F12*1000/F6 -> #DIV/0! | G33: =G12*1000/G6 -> #DIV/0! | H33: =H12*1000/H6 -> #DIV/0! | J33: =J12*1000/J6 -> #DIV/0! | K33: =K12*1000/K6 -> #DIV/0! | L33: =L12*1000/L6 -> #DIV/0! | M33: =M12*1000/M6 -> #DIV/0!
A34: 024 | B34: 单位面积耗电量 | C34: 千瓦时/平方米 | E34: =E17/E6 -> #DIV/0! | F34: =F17/F6 -> #DIV/0! | G34: =G17/G6 -> #DIV/0! | H34: =H17/H6 -> #DIV/0! | J34: =J17/J6 -> #DIV/0! | K34: =K17/K6 -> #DIV/0! | L34: =L17/L6 -> #DIV/0! | M34: =M17/M6 -> #DIV/0!
A35: 025 | B35: 单位面积耗水量 | C35: 千克/平方米 | E35: =E15*1000/E6 -> #DIV/0! | F35: =F15*1000/F6 -> #DIV/0! | G35: =G15*1000/G6 -> #DIV/0! | H35: =H15*1000/H6 -> #DIV/0! | J35: =J15*1000/J6 -> #DIV/0! | K35: =K15*1000/K6 -> #DIV/0! | L35: =L15*1000/L6 -> #DIV/0! | M35: =M15*1000/M6 -> #DIV/0!
B36: 外购热量 | C36: 吉焦 | L36: =G36+'26.2'!L36 -> 0
A37: 电锅炉房(机车)
A38: 代码 | B38: 项 目 | C38: 计量单位 | D38: 本月实际 | E38: 本年累计
A39: 001 | B39: 装机总容量 | C39: 兆瓦 | D39: 0.55 | E39: 0.55
A40: 002 | B40: 期末供暖面积 | C40: 平方米 | E40: =D40 -> 0
...

Sheet 26.4
A1: 代码 | B1: 项目 | C1: 计量单位 | D1: 本 月 实 际 | I1: 本 年 累 计
D2: 北海水炉 | E2: 金普 | F2: 临海 | G2: 庄河 | H2: 合计 | I2: 北海水炉 | J2: 金普 | K2: 临海 | L2: 庄河 | M2: 合计
A3: 001 | B3: 装机总容量 | C3: 兆瓦 | D3: 348 | E3: 162 | G3: 263 | H3: =E3+F3+G3 -> 425 | I3: =D3 -> 348 | J3: =E3 -> 162 | K3: =F3 -> 0 | L3: =G3 -> 263 | M3: =J3+K3+L3 -> 425
A4: 002 | B4: 期末供热面积 | C4: 平方米 | D4: - | I4: =D4 -> - | J4: =E4 -> 0 | K4: =F4 -> 0 | L4: =G4 -> 0 | M4: =J4+K4+L4 -> 0
B5: 其中：高温水面积 | C5: 平方米 | D5: - | E5: 55000 | F5: 0 | G5: 0 | H5: =E5+F5+G5 -> 55000 | I5: =D5 -> - | J5: =E5 -> 55000 | K5: =F5 -> 0 | L5: =G5 -> 0 | M5: =J5+K5+L5 -> 55000
A6: 003 | B6: 实际平均供热面积 | C6: 平方米 | D6: - | E6: =E4 -> 0 | F6: =F4 -> 0 | G6: =G4 -> 0 | H6: =E6+F6+G6 -> 0 | I6: =D6 -> - | J6: =E6 -> 0 | K6: =F6 -> 0 | L6: =G6 -> 0 | M6: =J6+K6+L6 -> 0
A7: 004 | B7: 供汽量 | C7: 吨 | D7: 0 | E7: 0 | F7: 0 | H7: =E7+F7+G7 -> 0 | I7: =D7+'26.3'!I7 -> 0 | J7: =E7+'26.3'!J7 -> 0 | K7: =F7+'26.3'!K7 -> 0 | L7: =G7+'26.3'!L7 -> 0 | M7: =J7+K7+L7 -> 0
A8: 005 | B8: 供热量 | C8: 吉焦 | I8: =D8+'26.3'!I8 -> 0 | J8: =E8+'26.3'!J8 -> 0 | K8: =F8+'26.3'!K8 -> 0 | L8: =G8+'26.3'!L8 -> 0 | M8: =J8+K8+L8 -> 0
A9: 006 | B9: 高温水销售量 | C9: 吉焦 | D9: 0 | E9: =[1]售热量!$I$25 -> 0 | H9: =E9+F9+G9 -> 0 | I9: =D9+'26.3'!I9 -> 0 | J9: =E9+'26.3'!J9 -> 0 | K9: =F9+'26.3'!K9 -> 0 | L9: =G9+'26.3'!L9 -> 0 | M9: =J9+K9+L9 -> 0
A10: 007 | B10: 生产耗原煤量 | C10: 吨 | H10: =E10+F10+G10 -> 0 | I10: =D10+'26.3'!I10 -> 0 | J10: =E10+'26.3'!J10 -> 0 | K10: =F10+'26.3'!K10 -> 0 | L10: =G10+'26.3'!L10 -> 0 | M10: =J10+K10+L10 -> 0
A11: 008 | B11: 耗油量 | C11: 吨 | H11: =E11+F11+G11 -> 0 | I11: =D11+'26.3'!I11 -> 0 | J11: =E11+'26.3'!J11 -> 0 | K11: =F11+'26.3'!K11 -> 0 | L11: =G11+'26.3'!L11 -> 0 | M11: =J11+K11+L11 -> 0
A12: 009 | B12: 耗标煤总量 | C12: 吨 | D12: =D13+D14 -> 0 | E12: =E13+E14 -> 0 | F12: =F13+F14 -> 0 | G12: =G13+G14 -> 0 | H12: =E12+F12+G12 -> 0 | I12: =D12+'26.3'!I12 -> 0 | J12: =E12+'26.3'!J12 -> 0 | K12: =F12+'26.3'!K12 -> 0 | L12: =G12+'26.3'!L12 -> 0 | M12: =J12+K12+L12 -> 0
B13: 其中：煤折标准煤量 | C13: 吨 | I13: =D13+'26.3'!I13 -> 0 | J13: =E13+'26.3'!J13 -> 0 | K13: =F13+'26.3'!K13 -> 0 | L13: =G13+'26.3'!L13 -> 0
B14: 油折标准煤量 | C14: 吨 | I14: =D14+'26.3'!I14 -> 0 | J14: =E14+'26.3'!J14 -> 0 | K14: =F14+'26.3'!K14 -> 0 | L14: =G14+'26.3'!L14 -> 0
A15: 010 | B15: 耗水量 | C15: 吨 | I15: =D15+'26.3'!I15 -> 0 | J15: =E15+'26.3'!J15 -> 0 | K15: =F15+'26.3'!K15 -> 0 | L15: =G15+'26.3'!L15 -> 0 | M15: =J15+K15+L15 -> 0
B16: 其中：耗井水(再生水)量 | C16: 吨 | I16: =D16+'26.3'!I16 -> 0 | J16: =E16+'26.3'!J16 -> 0 | K16: =F16+'26.3'!K16 -> 0 | L16: =G16+'26.3'!L16 -> 0 | M16: =J16+K16+L16 -> 0
A17: 011 | B17: 耗电量 | C17: 千瓦时 | I17: =D17+'26.3'!I17 -> 0 | J17: =E17+'26.3'!J17 -> 0 | L17: =G17+'26.3'!L17 -> 0 | M17: =J17+K17+L17 -> 0
B18: 其中：耗厂用电量 | C18: 千瓦时 | I18: =D18+'26.3'!I18 -> 0 | J18: =E18+'26.3'!J18 -> 0 | K18: =F18+'26.3'!K18 -> 0 | L18: =G18+'26.3'!L18 -> 0
B19: 耗外购电量 | C19: 千瓦时 | I19: =D19+'26.3'!I19 -> 0 | K19: =F19+'26.3'!K19 -> 0 | L19: =G19+'26.3'!L19 -> 0
B20: 脱硫脱硝耗水量 | C20: 吨 | I20: =D20+'26.3'!I20 -> 0 | J20: =E20+'26.3'!J20 -> 0 | K20: =F20+'26.3'!K20 -> 0 | L20: =G20+'26.3'!L20 -> 0
B21: 脱硫脱硝耗电量 | C21: 千瓦时 | I21: =D21+'26.3'!I21 -> 0 | J21: =E21+'26.3'!J21 -> 0 | K21: =F21+'26.3'!K21 -> 0 | L21: =G21+'26.3'!L21 -> 0
A22: 012 | B22: 耗氧化镁(石灰石粉)量 | C22: 吨 | I22: =D22+'26.3'!I22 -> 0 | J22: =E22+'26.3'!J22 -> 0 | K22: =F22+'26.3'!K22 -> 0 | L22: =G22+'26.3'!L22 -> 0 | M22: =J22+K22+L22 -> 0
A23: 013 | B23: 耗脱硝剂(氨水)量 | C23: 吨 | I23: =D23+'26.3'!I23 -> 0 | J23: =E23+'26.3'!J23 -> 0 | K23: =F23+'26.3'!K23 -> 0 | L23: =G23+'26.3'!L23 -> 0 | M23: =J23+K23+L23 -> 0
A24: 014 | B24: 供热用电率 | C24: 千瓦时/吉焦 | D24: =D17/D8 -> #DIV/0! | E24: =E17/E8 -> #DIV/0! | F24: =F17/F8 -> #DIV/0! | G24: =G17/G8 -> #DIV/0! | H24: =H17/H8 -> #DIV/0! | I24: =I17/I8 -> #DIV/0! | J24: =J17/J8 -> #DIV/0! | K24: =K17/K8 -> #DIV/0! | ... M24: =M17/M8 -> #DIV/0!
A25: 015 | B25: 供热煤耗率 | C25: 千克/吉焦 | D25: =D12*1000/D8 -> #DIV/0! | E25: =E12*1000/E8 -> #DIV/0! | F25: =F12*1000/F8 -> #DIV/0! | G25: =G12*1000/G8 -> #DIV/0! | H25: =H12*1000/H8 -> #DIV/0! | I25: =I12*1000/I8 -> #DIV/0! | J25: =J12*1000/J8 -> #DIV/0! | K25: =K12*1000/K8 -> #DIV/0! | ... M25: =M12*1000/M8 -> #DIV/0!
A26: 016 | B26: 入厂煤量 | C26: 吨 | I26: =D26+'26.3'!I26 -> 0 | J26: =E26+'26.3'!J26 -> 0 | K26: =F26+'26.3'!K26 -> 0 | L26: =G26+'26.3'!L26 -> 0 | M26: =J26+K26+L26 -> 0
A27: 017 | B27: 期末库存煤量 | C27: 吨 | E27: =J27 -> 12569.7 | G27: =L27 -> 1108.5 | I27: =D27 -> 0 | J27: ='26.3'!J27+E26-E10 -> 12569.7 | K27: ='26.3'!K27+F26-F10 -> 0 | L27: ='26.3'!L27+G26-G10 -> 1108.5 | M27: =J27+K27+L27 -> 13678.2
A28: 018 | B28: 入炉煤低位发热量 | C28: 千焦/千克 | D28: =D13*29308/D10 -> #DIV/0! | E28: =E12*29308/E10 -> #DIV/0! | F28: =F12*29308/F10 -> #DIV/0! | G28: =G12*29308/G10 -> #DIV/0! | H28: =H12*29308/H10 -> #DIV/0! | I28: =I13*29308/I10 -> #DIV/0! | J28: =J12*29308/J10 -> #DIV/0! | K28: =K12*29308/K10 -> #DIV/0! | L28: =L12*29308/L10 -> #DIV/0! | M28: =M12*29308/M10 -> #DIV/0!
A29: 019 | B29: 入厂煤低位发热量 | C29: 千焦/千克
A30: 020 | B30: 锅炉热效率 | C30: % | D30: =D8/(D12*29.308) -> #DIV/0! | E30: =E8/(E12*29.308) -> #DIV/0! | F30: =F8/(F12*29.308) -> #DIV/0! | G30: =(G8-G36)/(G12*29.308) -> #DIV/0! | H30: =H8/(H12*29.308) -> #DIV/0! | I30: =I8/(I12*29.308) -> #DIV/0! | J30: =J8/(J12*29.308) -> #DIV/0! | K30: =K8/(K12*29.308) -> #DIV/0! | L30: =L8/(L12*29.308) -> #DIV/0! | M30: =M8/(M12*29.308) -> #DIV/0!
A31: 021 | B31: 锅炉设备利用率 | C31: % | D31: =D8/3.6/D3/(5*24) -> 0 | E31: =E8/3.6/E3/(5*24) -> 0 | F31: =F8/3.6/F3/(5*24) -> #DIV/0! | G31: =(G8-G36)/3.6/G3/(DAY(DATE(2026,5,0))*24) -> 0 | H31: =H8/3.6/H3/(5*24) -> 0 | I31: =I8/3.6/I3/(DATEDIF(DATE(2026,1,1),DATE(2026,5,1),"D")*24) -> 0 | J31: =J8/3.6/J3/(DATEDIF(DATE(2026,1,1),DATE(2026,5,1),"D")*24) -> 0 | K31: =K8/3.6/K3/(DATEDIF(DATE(2026,1,1),DATE(2026,5,1),"D")*24) -> #DIV/0! | L31: =(L8-L36)/3.6/L3/(DATEDIF(DATE(2026,1,1),DATE(2026,5,1),"D")*24) -> 0 | M31: =M8/3.6/M3/(DATEDIF(DATE(2026,1,1),DATE(2026,5,1),"D")*24) -> 0
A32: 022 | B32: 供暖热耗率 | C32: 吉焦/平方米 | E32: =E8/E6 -> #DIV/0! | F32: =F8/F6 -> #DIV/0! | G32: =G8/G6 -> #DIV/0! | H32: =H8/H6 -> #DIV/0! | J32: =J8/J6 -> #DIV/0! | K32: =K8/K6 -> #DIV/0! | L32: =L8/L6 -> #DIV/0! | M32: =M8/M6 -> #DIV/0!
A33: 023 | B33: 单位面积耗标准煤量 | C33: 千克/平方米 | E33: =E12*1000/E6 -> #DIV/0! | F33: =F12*1000/F6 -> #DIV/0! | G33: =G12*1000/G6 -> #DIV/0! | H33: =H12*1000/H6 -> #DIV/0! | J33: =J12*1000/J6 -> #DIV/0! | K33: =K12*1000/K6 -> #DIV/0! | L33: =L12*1000/L6 -> #DIV/0! | M33: =M12*1000/M6 -> #DIV/0!
A34: 024 | B34: 单位面积耗电量 | C34: 千瓦时/平方米 | E34: =E17/E6 -> #DIV/0! | F34: =F17/F6 -> #DIV/0! | G34: =G17/G6 -> #DIV/0! | H34: =H17/H6 -> #DIV/0! | J34: =J17/J6 -> #DIV/0! | K34: =K17/K6 -> #DIV/0! | L34: =L17/L6 -> #DIV/0! | M34: =M17/M6 -> #DIV/0!
A35: 025 | B35: 单位面积耗水量 | C35: 千克/平方米 | E35: =E15*1000/E6 -> #DIV/0! | F35: =F15*1000/F6 -> #DIV/0! | G35: =G15*1000/G6 -> #DIV/0! | H35: =H15*1000/H6 -> #DIV/0! | J35: =J15*1000/J6 -> #DIV/0! | K35: =K15*1000/K6 -> #DIV/0! | L35: =L15*1000/L6 -> #DIV/0! | M35: =M15*1000/M6 -> #DIV/0!
B36: 外购热量 | C36: 吉焦 | L36: =G36+'26.3'!L36 -> 0
A37: 电锅炉房(机车)
A38: 代码 | B38: 项 目 | C38: 计量单位 | D38: 本月实际 | E38: 本年累计
A39: 001 | B39: 装机总容量 | C39: 兆瓦 | D39: 0.55 | E39: 0.55
A40: 002 | B40: 期末供暖面积 | C40: 平方米 | E40: =D40 -> 0
...

Sheet 26.5
A1: 代码 | B1: 项目 | C1: 计量单位 | D1: 本 月 实 际 | I1: 本 年 累 计
D2: 北海水炉 | E2: 金普 | F2: 临海 | G2: 庄河 | H2: 合计 | I2: 北海水炉 | J2: 金普 | K2: 临海 | L2: 庄河 | M2: 合计
A3: 001 | B3: 装机总容量 | C3: 兆瓦 | D3: 348 | E3: 162 | G3: 263 | H3: =E3+F3+G3 -> 425 | I3: =D3 -> 348 | J3: =E3 -> 162 | K3: =F3 -> 0 | L3: =G3 -> 263 | M3: =J3+K3+L3 -> 425
A4: 002 | B4: 期末供热面积 | C4: 平方米 | D4: - | I4: =D4 -> - | J4: =E4 -> 0 | K4: =F4 -> 0 | L4: =G4 -> 0 | M4: =J4+K4+L4 -> 0
B5: 其中：高温水面积 | C5: 平方米 | D5: - | E5: 55000 | F5: 0 | G5: 0 | H5: =E5+F5+G5 -> 55000 | I5: =D5 -> - | J5: =E5 -> 55000 | K5: =F5 -> 0 | L5: =G5 -> 0 | M5: =J5+K5+L5 -> 55000
A6: 003 | B6: 实际平均供热面积 | C6: 平方米 | D6: - | E6: =E4 -> 0 | F6: =F4 -> 0 | G6: =G4 -> 0 | H6: =E6+F6+G6 -> 0 | I6: =D6 -> - | J6: =E6 -> 0 | K6: =F6 -> 0 | L6: =G6 -> 0 | M6: =J6+K6+L6 -> 0
A7: 004 | B7: 供汽量 | C7: 吨 | D7: 0 | E7: 0 | F7: 0 | H7: =E7+F7+G7 -> 0 | I7: =D7+'26.4'!I7 -> 0 | J7: =E7+'26.4'!J7 -> 0 | K7: =F7+'26.4'!K7 -> 0 | L7: =G7+'26.4'!L7 -> 0 | M7: =J7+K7+L7 -> 0
A8: 005 | B8: 供热量 | C8: 吉焦 | I8: =D8+'26.4'!I8 -> 0 | J8: =E8+'26.4'!J8 -> 0 | K8: =F8+'26.4'!K8 -> 0 | L8: =G8+'26.4'!L8 -> 0 | M8: =J8+K8+L8 -> 0
A9: 006 | B9: 高温水销售量 | C9: 吉焦 | D9: 0 | E9: =[1]售热量!$K$25 -> 0 | H9: =E9+F9+G9 -> 0 | I9: =D9+'26.4'!I9 -> 0 | J9: =E9+'26.4'!J9 -> 0 | K9: =F9+'26.4'!K9 -> 0 | L9: =G9+'26.4'!L9 -> 0 | M9: =J9+K9+L9 -> 0
A10: 007 | B10: 生产耗原煤量 | C10: 吨 | H10: =E10+F10+G10 -> 0 | I10: =D10+'26.4'!I10 -> 0 | J10: =E10+'26.4'!J10 -> 0 | K10: =F10+'26.4'!K10 -> 0 | L10: =G10+'26.4'!L10 -> 0 | M10: =J10+K10+L10 -> 0
A11: 008 | B11: 耗油量 | C11: 吨 | E11: 0 | H11: =E11+F11+G11 -> 0 | I11: =D11+'26.4'!I11 -> 0 | J11: =E11+'26.4'!J11 -> 0 | K11: =F11+'26.4'!K11 -> 0 | L11: =G11+'26.4'!L11 -> 0 | M11: =J11+K11+L11 -> 0
A12: 009 | B12: 耗标煤总量 | C12: 吨 | D12: =D13+D14 -> 0 | E12: =E13+E14 -> 0 | F12: =F13+F14 -> 0 | G12: =G13+G14 -> 0 | H12: =E12+F12+G12 -> 0 | I12: =D12+'26.4'!I12 -> 0 | J12: =E12+'26.4'!J12 -> 0 | K12: =F12+'26.4'!K12 -> 0 | L12: =G12+'26.4'!L12 -> 0 | M12: =J12+K12+L12 -> 0
B13: 其中：煤折标准煤量 | C13: 吨 | I13: =D13+'26.4'!I13 -> 0 | J13: =E13+'26.4'!J13 -> 0 | K13: =F13+'26.4'!K13 -> 0 | L13: =G13+'26.4'!L13 -> 0
B14: 油折标准煤量 | C14: 吨 | I14: =D14+'26.4'!I14 -> 0 | J14: =E14+'26.4'!J14 -> 0 | K14: =F14+'26.4'!K14 -> 0 | L14: =G14+'26.4'!L14 -> 0
A15: 010 | B15: 耗水量 | C15: 吨 | I15: =D15+'26.4'!I15 -> 0 | J15: =E15+'26.4'!J15 -> 0 | K15: =F15+'26.4'!K15 -> 0 | L15: =G15+'26.4'!L15 -> 0 | M15: =J15+K15+L15 -> 0
B16: 其中：耗井水(再生水)量 | C16: 吨 | I16: =D16+'26.4'!I16 -> 0 | J16: =E16+'26.4'!J16 -> 0 | K16: =F16+'26.4'!K16 -> 0 | L16: =G16+'26.4'!L16 -> 0 | M16: =J16+K16+L16 -> 0
A17: 011 | B17: 耗电量 | C17: 千瓦时 | I17: =D17+'26.4'!I17 -> 0 | J17: =E17+'26.4'!J17 -> 0 | L17: =G17+'26.4'!L17 -> 0 | M17: =J17+K17+L17 -> 0
B18: 其中：耗厂用电量 | C18: 千瓦时 | I18: =D18+'26.4'!I18 -> 0 | J18: =E18+'26.4'!J18 -> 0 | K18: =F18+'26.4'!K18 -> 0 | L18: =G18+'26.4'!L18 -> 0
B19: 耗外购电量 | C19: 千瓦时 | I19: =D19+'26.4'!I19 -> 0 | K19: =F19+'26.4'!K19 -> 0 | L19: =G19+'26.4'!L19 -> 0
B20: 脱硫脱硝耗水量 | C20: 吨 | I20: =D20+'26.4'!I20 -> 0 | J20: =E20+'26.4'!J20 -> 0 | K20: =F20+'26.4'!K20 -> 0 | L20: =G20+'26.4'!L20 -> 0
B21: 脱硫脱硝耗电量 | C21: 千瓦时 | I21: =D21+'26.4'!I21 -> 0 | J21: =E21+'26.4'!J21 -> 0 | K21: =F21+'26.4'!K21 -> 0 | L21: =G21+'26.4'!L21 -> 0
A22: 012 | B22: 耗氧化镁(石灰石粉)量 | C22: 吨 | I22: =D22+'26.4'!I22 -> 0 | J22: =E22+'26.4'!J22 -> 0 | K22: =F22+'26.4'!K22 -> 0 | L22: =G22+'26.4'!L22 -> 0 | M22: =J22+K22+L22 -> 0
A23: 013 | B23: 耗脱硝剂(氨水)量 | C23: 吨 | I23: =D23+'26.4'!I23 -> 0 | J23: =E23+'26.4'!J23 -> 0 | K23: =F23+'26.4'!K23 -> 0 | L23: =G23+'26.4'!L23 -> 0 | M23: =J23+K23+L23 -> 0
A24: 014 | B24: 供热用电率 | C24: 千瓦时/吉焦 | D24: =D17/D8 -> #DIV/0! | E24: =E17/E8 -> #DIV/0! | F24: =F17/F8 -> #DIV/0! | G24: =G17/G8 -> #DIV/0! | H24: =H17/H8 -> #DIV/0! | I24: =I17/I8 -> #DIV/0! | J24: =J17/J8 -> #DIV/0! | K24: =K17/K8 -> #DIV/0! | ... M24: =M17/M8 -> #DIV/0!
A25: 015 | B25: 供热煤耗率 | C25: 千克/吉焦 | D25: =D12*1000/D8 -> #DIV/0! | E25: =E12*1000/E8 -> #DIV/0! | F25: =F12*1000/F8 -> #DIV/0! | G25: =G12*1000/G8 -> #DIV/0! | H25: =H12*1000/H8 -> #DIV/0! | I25: =I12*1000/I8 -> #DIV/0! | J25: =J12*1000/J8 -> #DIV/0! | K25: =K12*1000/K8 -> #DIV/0! | ... M25: =M12*1000/M8 -> #DIV/0!
A26: 016 | B26: 入厂煤量 | C26: 吨 | I26: =D26+'26.4'!I26 -> 0 | J26: =E26+'26.4'!J26 -> 0 | K26: =F26+'26.4'!K26 -> 0 | L26: =G26+'26.4'!L26 -> 0 | M26: =J26+K26+L26 -> 0
A27: 017 | B27: 期末库存煤量 | C27: 吨 | E27: =J27 -> 12569.7 | G27: =L27 -> 1108.5 | I27: =D27 -> 0 | J27: ='26.4'!J27+E26-E10 -> 12569.7 | K27: ='26.4'!K27+F26-F10 -> 0 | L27: ='26.4'!L27+G26-G10 -> 1108.5 | M27: =J27+K27+L27 -> 13678.2
A28: 018 | B28: 入炉煤低位发热量 | C28: 千焦/千克 | D28: =D13*29308/D10 -> #DIV/0! | E28: =E12*29308/E10 -> #DIV/0! | F28: =F12*29308/F10 -> #DIV/0! | G28: =G12*29308/G10 -> #DIV/0! | H28: =H12*29308/H10 -> #DIV/0! | I28: =I13*29308/I10 -> #DIV/0! | J28: =J12*29308/J10 -> #DIV/0! | K28: =K12*29308/K10 -> #DIV/0! | L28: =L12*29308/L10 -> #DIV/0! | M28: =M12*29308/M10 -> #DIV/0!
A29: 019 | B29: 入厂煤低位发热量 | C29: 千焦/千克
A30: 020 | B30: 锅炉热效率 | C30: % | D30: =D8/(D12*29.308) -> #DIV/0! | E30: =E8/(E12*29.308) -> #DIV/0! | F30: =F8/(F12*29.308) -> #DIV/0! | G30: =(G8-G36)/(G12*29.308) -> #DIV/0! | H30: =H8/(H12*29.308) -> #DIV/0! | I30: =I8/(I12*29.308) -> #DIV/0! | J30: =J8/(J12*29.308) -> #DIV/0! | K30: =K8/(K12*29.308) -> #DIV/0! | L30: =L8/(L12*29.308) -> #DIV/0! | M30: =M8/(M12*29.308) -> #DIV/0!
A31: 021 | B31: 锅炉设备利用率 | C31: % | D31: =D8/3.6/D3/(DAY(DATE(2026,6,0))*24) -> 0 | E31: =E8/3.6/E3/(DAY(DATE(2026,6,0))*24) -> 0 | F31: =F8/3.6/F3/(DAY(DATE(2026,6,0))*24) -> #DIV/0! | G31: =(G8-G36)/3.6/G3/(DAY(DATE(2026,6,0))*24) -> 0 | H31: =H8/3.6/H3/(DAY(DATE(2026,6,0))*24) -> 0 | I31: =I8/3.6/I3/(DATEDIF(DATE(2026,1,1),DATE(2026,6,1),"D")*24) -> 0 | J31: =J8/3.6/J3/(DATEDIF(DATE(2026,1,1),DATE(2026,6,1),"D")*24) -> 0 | K31: =K8/3.6/K3/(DATEDIF(DATE(2026,1,1),DATE(2026,6,1),"D")*24) -> #DIV/0! | L31: =(L8-L36)/3.6/L3/(DATEDIF(DATE(2026,1,1),DATE(2026,6,1),"D")*24) -> 0 | M31: =M8/3.6/M3/(DATEDIF(DATE(2026,1,1),DATE(2026,6,1),"D")*24) -> 0
A32: 022 | B32: 供暖热耗率 | C32: 吉焦/平方米 | E32: =E8/E6 -> #DIV/0! | F32: =F8/F6 -> #DIV/0! | G32: =G8/G6 -> #DIV/0! | H32: =H8/H6 -> #DIV/0! | J32: =J8/J6 -> #DIV/0! | K32: =K8/K6 -> #DIV/0! | L32: =L8/L6 -> #DIV/0! | M32: =M8/M6 -> #DIV/0!
A33: 023 | B33: 单位面积耗标准煤量 | C33: 千克/平方米 | E33: =E12*1000/E6 -> #DIV/0! | F33: =F12*1000/F6 -> #DIV/0! | G33: =G12*1000/G6 -> #DIV/0! | H33: =H12*1000/H6 -> #DIV/0! | J33: =J12*1000/J6 -> #DIV/0! | K33: =K12*1000/K6 -> #DIV/0! | L33: =L12*1000/L6 -> #DIV/0! | M33: =M12*1000/M6 -> #DIV/0!
A34: 024 | B34: 单位面积耗电量 | C34: 千瓦时/平方米 | E34: =E17/E6 -> #DIV/0! | F34: =F17/F6 -> #DIV/0! | G34: =G17/G6 -> #DIV/0! | H34: =H17/H6 -> #DIV/0! | J34: =J17/J6 -> #DIV/0! | K34: =K17/K6 -> #DIV/0! | L34: =L17/L6 -> #DIV/0! | M34: =M17/M6 -> #DIV/0!
A35: 025 | B35: 单位面积耗水量 | C35: 千克/平方米 | E35: =E15*1000/E6 -> #DIV/0! | F35: =F15*1000/F6 -> #DIV/0! | G35: =G15*1000/G6 -> #DIV/0! | H35: =H15*1000/H6 -> #DIV/0! | J35: =J15*1000/J6 -> #DIV/0! | K35: =K15*1000/K6 -> #DIV/0! | L35: =L15*1000/L6 -> #DIV/0! | M35: =M15*1000/M6 -> #DIV/0!
B36: 外购热量 | C36: 吉焦 | L36: =G36+'26.4'!L36 -> 0
A37: 电锅炉房(机车)
A38: 代码 | B38: 项 目 | C38: 计量单位 | D38: 本月实际 | E38: 本年累计
A39: 001 | B39: 装机总容量 | C39: 兆瓦 | D39: 0.55 | E39: 0.55
A40: 002 | B40: 期末供暖面积 | C40: 平方米 | E40: =D40 -> 0
...

Sheet 26.6
A1: 代码 | B1: 项目 | C1: 计量单位 | D1: 本 月 实 际 | I1: 本 年 累 计
D2: 北海水炉 | E2: 金普 | F2: 临海 | G2: 庄河 | H2: 合计 | I2: 北海水炉 | J2: 金普 | K2: 临海 | L2: 庄河 | M2: 合计
A3: 001 | B3: 装机总容量 | C3: 兆瓦 | D3: 348 | E3: 162 | G3: 263 | H3: =E3+F3+G3 -> 425 | I3: =D3 -> 348 | J3: =E3 -> 162 | K3: =F3 -> 0 | L3: =G3 -> 263 | M3: =J3+K3+L3 -> 425
A4: 002 | B4: 期末供热面积 | C4: 平方米 | D4: - | I4: =D4 -> - | J4: =E4 -> 0 | K4: =F4 -> 0 | L4: =G4 -> 0 | M4: =J4+K4+L4 -> 0
B5: 其中：高温水面积 | C5: 平方米 | D5: - | E5: 55000 | F5: 0 | G5: 0 | H5: =E5+F5+G5 -> 55000 | I5: =D5 -> - | J5: =E5 -> 55000 | K5: =F5 -> 0 | L5: =G5 -> 0 | M5: =J5+K5+L5 -> 55000
A6: 003 | B6: 实际平均供热面积 | C6: 平方米 | D6: - | E6: =E4 -> 0 | F6: =F4 -> 0 | G6: =G4 -> 0 | H6: =E6+F6+G6 -> 0 | I6: =D6 -> - | J6: =E6 -> 0 | K6: =F6 -> 0 | L6: =G6 -> 0 | M6: =J6+K6+L6 -> 0
A7: 004 | B7: 供汽量 | C7: 吨 | D7: 0 | E7: 0 | F7: 0 | H7: =E7+F7+G7 -> 0 | I7: =D7+'26.5'!I7 -> 0 | J7: =E7+'26.5'!J7 -> 0 | K7: =F7+'26.5'!K7 -> 0 | L7: =G7+'26.5'!L7 -> 0 | M7: =J7+K7+L7 -> 0
A8: 005 | B8: 供热量 | C8: 吉焦 | I8: =D8+'26.5'!I8 -> 0 | J8: =E8+'26.5'!J8 -> 0 | K8: =F8+'26.5'!K8 -> 0 | L8: =G8+'26.5'!L8 -> 0 | M8: =J8+K8+L8 -> 0
A9: 006 | B9: 高温水销售量 | C9: 吉焦 | D9: 0 | E9: =[1]售热量!$M$25 -> 0 | H9: =E9+F9+G9 -> 0 | I9: =D9+'26.5'!I9 -> 0 | J9: =E9+'26.5'!J9 -> 0 | K9: =F9+'26.5'!K9 -> 0 | L9: =G9+'26.5'!L9 -> 0 | M9: =J9+K9+L9 -> 0
A10: 007 | B10: 生产耗原煤量 | C10: 吨 | H10: =E10+F10+G10 -> 0 | I10: =D10+'26.5'!I10 -> 0 | J10: =E10+'26.5'!J10 -> 0 | K10: =F10+'26.5'!K10 -> 0 | L10: =G10+'26.5'!L10 -> 0 | M10: =J10+K10+L10 -> 0
A11: 008 | B11: 耗油量 | C11: 吨 | E11: 0 | H11: =E11+F11+G11 -> 0 | I11: =D11+'26.5'!I11 -> 0 | J11: =E11+'26.5'!J11 -> 0 | K11: =F11+'26.5'!K11 -> 0 | L11: =G11+'26.5'!L11 -> 0 | M11: =J11+K11+L11 -> 0
A12: 009 | B12: 耗标煤总量 | C12: 吨 | D12: =D13+D14 -> 0 | E12: =E13+E14 -> 0 | F12: =F13+F14 -> 0 | G12: =G13+G14 -> 0 | H12: =E12+F12+G12 -> 0 | I12: =D12+'26.5'!I12 -> 0 | J12: =E12+'26.5'!J12 -> 0 | K12: =F12+'26.5'!K12 -> 0 | L12: =G12+'26.5'!L12 -> 0 | M12: =J12+K12+L12 -> 0
B13: 其中：煤折标准煤量 | C13: 吨 | I13: =D13+'26.5'!I13 -> 0 | J13: =E13+'26.5'!J13 -> 0 | K13: =F13+'26.5'!K13 -> 0 | L13: =G13+'26.5'!L13 -> 0
B14: 油折标准煤量 | C14: 吨 | I14: =D14+'26.5'!I14 -> 0 | J14: =E14+'26.5'!J14 -> 0 | K14: =F14+'26.5'!K14 -> 0 | L14: =G14+'26.5'!L14 -> 0
A15: 010 | B15: 耗水量 | C15: 吨 | I15: =D15+'26.5'!I15 -> 0 | J15: =E15+'26.5'!J15 -> 0 | K15: =F15+'26.5'!K15 -> 0 | L15: =G15+'26.5'!L15 -> 0 | M15: =J15+K15+L15 -> 0
B16: 其中：耗井水(再生水)量 | C16: 吨 | I16: =D16+'26.5'!I16 -> 0 | J16: =E16+'26.5'!J16 -> 0 | K16: =F16+'26.5'!K16 -> 0 | L16: =G16+'26.5'!L16 -> 0 | M16: =J16+K16+L16 -> 0
A17: 011 | B17: 耗电量 | C17: 千瓦时 | I17: =D17+'26.5'!I17 -> 0 | J17: =E17+'26.5'!J17 -> 0 | L17: =G17+'26.5'!L17 -> 0 | M17: =J17+K17+L17 -> 0
B18: 其中：耗厂用电量 | C18: 千瓦时 | I18: =D18+'26.5'!I18 -> 0 | J18: =E18+'26.5'!J18 -> 0 | K18: =F18+'26.5'!K18 -> 0 | L18: =G18+'26.5'!L18 -> 0
B19: 耗外购电量 | C19: 千瓦时 | I19: =D19+'26.5'!I19 -> 0 | K19: =F19+'26.5'!K19 -> 0 | L19: =G19+'26.5'!L19 -> 0
B20: 脱硫脱硝耗水量 | C20: 吨 | I20: =D20+'26.5'!I20 -> 0 | J20: =E20+'26.5'!J20 -> 0 | K20: =F20+'26.5'!K20 -> 0 | L20: =G20+'26.5'!L20 -> 0
B21: 脱硫脱硝耗电量 | C21: 千瓦时 | I21: =D21+'26.5'!I21 -> 0 | J21: =E21+'26.5'!J21 -> 0 | K21: =F21+'26.5'!K21 -> 0 | L21: =G21+'26.5'!L21 -> 0
A22: 012 | B22: 耗氧化镁(石灰石粉)量 | C22: 吨 | I22: =D22+'26.5'!I22 -> 0 | J22: =E22+'26.5'!J22 -> 0 | K22: =F22+'26.5'!K22 -> 0 | L22: =G22+'26.5'!L22 -> 0 | M22: =J22+K22+L22 -> 0
A23: 013 | B23: 耗脱硝剂(氨水)量 | C23: 吨 | I23: =D23+'26.5'!I23 -> 0 | J23: =E23+'26.5'!J23 -> 0 | K23: =F23+'26.5'!K23 -> 0 | L23: =G23+'26.5'!L23 -> 0 | M23: =J23+K23+L23 -> 0
A24: 014 | B24: 供热用电率 | C24: 千瓦时/吉焦 | D24: =D17/D8 -> #DIV/0! | E24: =E17/E8 -> #DIV/0! | F24: =F17/F8 -> #DIV/0! | G24: =G17/G8 -> #DIV/0! | H24: =H17/H8 -> #DIV/0! | I24: =I17/I8 -> #DIV/0! | J24: =J17/J8 -> #DIV/0! | K24: =K17/K8 -> #DIV/0! | ... M24: =M17/M8 -> #DIV/0!
A25: 015 | B25: 供热煤耗率 | C25: 千克/吉焦 | D25: =D12*1000/D8 -> #DIV/0! | E25: =E12*1000/E8 -> #DIV/0! | F25: =F12*1000/F8 -> #DIV/0! | G25: =G12*1000/G8 -> #DIV/0! | H25: =H12*1000/H8 -> #DIV/0! | I25: =I12*1000/I8 -> #DIV/0! | J25: =J12*1000/J8 -> #DIV/0! | K25: =K12*1000/K8 -> #DIV/0! | ... M25: =M12*1000/M8 -> #DIV/0!
A26: 016 | B26: 入厂煤量 | C26: 吨 | I26: =D26+'26.5'!I26 -> 0 | J26: =E26+'26.5'!J26 -> 0 | K26: =F26+'26.5'!K26 -> 0 | L26: =G26+'26.5'!L26 -> 0 | M26: =J26+K26+L26 -> 0
A27: 017 | B27: 期末库存煤量 | C27: 吨 | E27: =J27 -> 12569.7 | G27: =L27 -> 1108.5 | J27: ='26.5'!J27+E26-E10 -> 12569.7 | K27: ='26.5'!K27+F26-F10 -> 0 | L27: ='26.5'!L27+G26-G10 -> 1108.5 | M27: =J27+K27+L27 -> 13678.2
A28: 018 | B28: 入炉煤低位发热量 | C28: 千焦/千克 | D28: =D13*29308/D10 -> #DIV/0! | E28: =E12*29308/E10 -> #DIV/0! | F28: =F12*29308/F10 -> #DIV/0! | G28: =G12*29308/G10 -> #DIV/0! | H28: =H12*29308/H10 -> #DIV/0! | I28: =I13*29308/I10 -> #DIV/0! | J28: =J12*29308/J10 -> #DIV/0! | K28: =K12*29308/K10 -> #DIV/0! | L28: =L12*29308/L10 -> #DIV/0! | M28: =M12*29308/M10 -> #DIV/0!
A29: 019 | B29: 入厂煤低位发热量 | C29: 千焦/千克
A30: 020 | B30: 锅炉热效率 | C30: % | D30: =D8/(D12*29.308) -> #DIV/0! | E30: =E8/(E12*29.308) -> #DIV/0! | F30: =F8/(F12*29.308) -> #DIV/0! | G30: =(G8-G36)/(G12*29.308) -> #DIV/0! | H30: =H8/(H12*29.308) -> #DIV/0! | I30: =I8/(I12*29.308) -> #DIV/0! | J30: =J8/(J12*29.308) -> #DIV/0! | K30: =K8/(K12*29.308) -> #DIV/0! | L30: =L8/(L12*29.308) -> #DIV/0! | M30: =M8/(M12*29.308) -> #DIV/0!
A31: 021 | B31: 锅炉设备利用率 | C31: % | D31: =D8/3.6/D3/(DAY(DATE(2026,7,0))*24) -> 0 | E31: =E8/3.6/E3/(DAY(DATE(2026,7,0))*24) -> 0 | F31: =F8/3.6/F3/(DAY(DATE(2026,7,0))*24) -> #DIV/0! | G31: =(G8-G36)/3.6/G3/(DAY(DATE(2026,7,0))*24) -> 0 | H31: =H8/3.6/H3/(DAY(DATE(2026,7,0))*24) -> 0 | I31: =I8/3.6/I3/(DATEDIF(DATE(2026,1,1),DATE(2026,7,1),"D")*24) -> 0 | J31: =J8/3.6/J3/(DATEDIF(DATE(2026,1,1),DATE(2026,7,1),"D")*24) -> 0 | K31: =K8/3.6/K3/(DATEDIF(DATE(2026,1,1),DATE(2026,7,1),"D")*24) -> #DIV/0! | L31: =(L8-L36)/3.6/L3/(DATEDIF(DATE(2026,1,1),DATE(2026,7,1),"D")*24) -> 0 | M31: =M8/3.6/M3/(DATEDIF(DATE(2026,1,1),DATE(2026,7,1),"D")*24) -> 0
A32: 022 | B32: 供暖热耗率 | C32: 吉焦/平方米 | E32: =E8/E6 -> #DIV/0! | F32: =F8/F6 -> #DIV/0! | G32: =G8/G6 -> #DIV/0! | H32: =H8/H6 -> #DIV/0! | J32: =J8/J6 -> #DIV/0! | K32: =K8/K6 -> #DIV/0! | L32: =L8/L6 -> #DIV/0! | M32: =M8/M6 -> #DIV/0!
A33: 023 | B33: 单位面积耗标准煤量 | C33: 千克/平方米 | E33: =E12*1000/E6 -> #DIV/0! | F33: =F12*1000/F6 -> #DIV/0! | G33: =G12*1000/G6 -> #DIV/0! | H33: =H12*1000/H6 -> #DIV/0! | J33: =J12*1000/J6 -> #DIV/0! | K33: =K12*1000/K6 -> #DIV/0! | L33: =L12*1000/L6 -> #DIV/0! | M33: =M12*1000/M6 -> #DIV/0!
A34: 024 | B34: 单位面积耗电量 | C34: 千瓦时/平方米 | E34: =E17/E6 -> #DIV/0! | F34: =F17/F6 -> #DIV/0! | G34: =G17/G6 -> #DIV/0! | H34: =H17/H6 -> #DIV/0! | J34: =J17/J6 -> #DIV/0! | K34: =K17/K6 -> #DIV/0! | L34: =L17/L6 -> #DIV/0! | M34: =M17/M6 -> #DIV/0!
A35: 025 | B35: 单位面积耗水量 | C35: 千克/平方米 | E35: =E15*1000/E6 -> #DIV/0! | F35: =F15*1000/F6 -> #DIV/0! | G35: =G15*1000/G6 -> #DIV/0! | H35: =H15*1000/H6 -> #DIV/0! | J35: =J15*1000/J6 -> #DIV/0! | K35: =K15*1000/K6 -> #DIV/0! | L35: =L15*1000/L6 -> #DIV/0! | M35: =M15*1000/M6 -> #DIV/0!
B36: 外购热量 | C36: 吉焦 | L36: =G36+'26.5'!L36 -> 0
A37: 电锅炉房(机车)
A38: 代码 | B38: 项 目 | C38: 计量单位 | D38: 本月实际 | E38: 本年累计
A39: 001 | B39: 装机总容量 | C39: 兆瓦 | D39: 0.55 | E39: 0.55
A40: 002 | B40: 期末供暖面积 | C40: 平方米 | D40: 7592.12 | E40: =D40 -> 7592.12
...

Sheet 26.7
A1: 代码 | B1: 项目 | C1: 计量单位 | D1: 本 月 实 际 | I1: 本 年 累 计
D2: 北海水炉 | E2: 金普 | F2: 临海 | G2: 庄河 | H2: 合计 | I2: 北海水炉 | J2: 金普 | K2: 临海 | L2: 庄河 | M2: 合计
A3: 001 | B3: 装机总容量 | C3: 兆瓦 | D3: 348 | E3: 162 | G3: 263 | H3: =E3+F3+G3 -> 425 | I3: =D3 -> 348 | J3: =E3 -> 162 | K3: =F3 -> 0 | L3: =G3 -> 263 | M3: =J3+K3+L3 -> 425
A4: 002 | B4: 期末供热面积 | C4: 平方米 | D4: - | I4: =D4 -> - | J4: =E4 -> 0 | K4: =F4 -> 0 | L4: =G4 -> 0 | M4: =J4+K4+L4 -> 0
B5: 其中：高温水面积 | C5: 平方米 | D5: - | E5: 55000 | F5: 0 | G5: 0 | H5: =E5+F5+G5 -> 55000 | I5: =D5 -> - | J5: =E5 -> 55000 | K5: =F5 -> 0 | L5: =G5 -> 0 | M5: =J5+K5+L5 -> 55000
A6: 003 | B6: 实际平均供热面积 | C6: 平方米 | D6: - | E6: =E4 -> 0 | F6: =F4 -> 0 | G6: =G4 -> 0 | H6: =E6+F6+G6 -> 0 | I6: =D6 -> - | J6: =E6 -> 0 | K6: =F6 -> 0 | L6: =G6 -> 0 | M6: =J6+K6+L6 -> 0
A7: 004 | B7: 供汽量 | C7: 吨 | D7: 0 | E7: 0 | F7: 0 | H7: =E7+F7+G7 -> 0 | I7: =D7+'26.6'!I7 -> 0 | J7: =E7+'26.6'!J7 -> 0 | K7: =F7+'26.6'!K7 -> 0 | L7: =G7+'26.6'!L7 -> 0 | M7: =J7+K7+L7 -> 0
A8: 005 | B8: 供热量 | C8: 吉焦 | I8: =D8+'26.6'!I8 -> 0 | J8: =E8+'26.6'!J8 -> 0 | K8: =F8+'26.6'!K8 -> 0 | L8: =G8+'26.6'!L8 -> 0 | M8: =J8+K8+L8 -> 0
A9: 006 | B9: 高温水销售量 | C9: 吉焦 | D9: 0 | E9: =[1]售热量!$O$25 -> 0 | H9: =E9+F9+G9 -> 0 | I9: =D9+'26.6'!I9 -> 0 | J9: =E9+'26.6'!J9 -> 0 | K9: =F9+'26.6'!K9 -> 0 | L9: =G9+'26.6'!L9 -> 0 | M9: =J9+K9+L9 -> 0
A10: 007 | B10: 生产耗原煤量 | C10: 吨 | H10: =E10+F10+G10 -> 0 | I10: =D10+'26.6'!I10 -> 0 | J10: =E10+'26.6'!J10 -> 0 | K10: =F10+'26.6'!K10 -> 0 | L10: =G10+'26.6'!L10 -> 0 | M10: =J10+K10+L10 -> 0
A11: 008 | B11: 耗油量 | C11: 吨 | E11: 0 | H11: =E11+F11+G11 -> 0 | I11: =D11+'26.6'!I11 -> 0 | J11: =E11+'26.6'!J11 -> 0 | K11: =F11+'26.6'!K11 -> 0 | L11: =G11+'26.6'!L11 -> 0 | M11: =J11+K11+L11 -> 0
A12: 009 | B12: 耗标煤总量 | C12: 吨 | D12: =D13+D14 -> 0 | E12: =E13+E14 -> 0 | F12: =F13+F14 -> 0 | G12: =G13+G14 -> 0 | H12: =E12+F12+G12 -> 0 | I12: =D12+'26.6'!I12 -> 0 | J12: =E12+'26.6'!J12 -> 0 | K12: =F12+'26.6'!K12 -> 0 | L12: =G12+'26.6'!L12 -> 0 | M12: =J12+K12+L12 -> 0
B13: 其中：煤折标准煤量 | C13: 吨 | I13: =D13+'26.6'!I13 -> 0 | J13: =E13+'26.6'!J13 -> 0 | K13: =F13+'26.6'!K13 -> 0 | L13: =G13+'26.6'!L13 -> 0
B14: 油折标准煤量 | C14: 吨 | I14: =D14+'26.6'!I14 -> 0 | J14: =E14+'26.6'!J14 -> 0 | K14: =F14+'26.6'!K14 -> 0 | L14: =G14+'26.6'!L14 -> 0
A15: 010 | B15: 耗水量 | C15: 吨 | I15: =D15+'26.6'!I15 -> 0 | J15: =E15+'26.6'!J15 -> 0 | K15: =F15+'26.6'!K15 -> 0 | L15: =G15+'26.6'!L15 -> 0 | M15: =J15+K15+L15 -> 0
B16: 其中：耗井水(再生水)量 | C16: 吨 | I16: =D16+'26.6'!I16 -> 0 | J16: =E16+'26.6'!J16 -> 0 | K16: =F16+'26.6'!K16 -> 0 | L16: =G16+'26.6'!L16 -> 0 | M16: =J16+K16+L16 -> 0
A17: 011 | B17: 耗电量 | C17: 千瓦时 | I17: =D17+'26.6'!I17 -> 0 | J17: =E17+'26.6'!J17 -> 0 | L17: =G17+'26.6'!L17 -> 0 | M17: =J17+K17+L17 -> 0
B18: 其中：耗厂用电量 | C18: 千瓦时 | I18: =D18+'26.6'!I18 -> 0 | J18: =E18+'26.6'!J18 -> 0 | K18: =F18+'26.6'!K18 -> 0 | L18: =G18+'26.6'!L18 -> 0
B19: 耗外购电量 | C19: 千瓦时 | I19: =D19+'26.6'!I19 -> 0 | K19: =F19+'26.6'!K19 -> 0 | L19: =G19+'26.6'!L19 -> 0
B20: 脱硫脱硝耗水量 | C20: 吨 | I20: =D20+'26.6'!I20 -> 0 | J20: =E20+'26.6'!J20 -> 0 | K20: =F20+'26.6'!K20 -> 0 | L20: =G20+'26.6'!L20 -> 0
B21: 脱硫脱硝耗电量 | C21: 千瓦时 | I21: =D21+'26.6'!I21 -> 0 | J21: =E21+'26.6'!J21 -> 0 | K21: =F21+'26.6'!K21 -> 0 | L21: =G21+'26.6'!L21 -> 0
A22: 012 | B22: 耗氧化镁(石灰石粉)量 | C22: 吨 | I22: =D22+'26.6'!I22 -> 0 | J22: =E22+'26.6'!J22 -> 0 | K22: =F22+'26.6'!K22 -> 0 | L22: =G22+'26.6'!L22 -> 0 | M22: =J22+K22+L22 -> 0
A23: 013 | B23: 耗脱硝剂(氨水)量 | C23: 吨 | I23: =D23+'26.6'!I23 -> 0 | J23: =E23+'26.6'!J23 -> 0 | K23: =F23+'26.6'!K23 -> 0 | L23: =G23+'26.6'!L23 -> 0 | M23: =J23+K23+L23 -> 0
A24: 014 | B24: 供热用电率 | C24: 千瓦时/吉焦 | D24: =D17/D8 -> #DIV/0! | E24: =E17/E8 -> #DIV/0! | F24: =F17/F8 -> #DIV/0! | G24: =G17/G8 -> #DIV/0! | H24: =H17/H8 -> #DIV/0! | I24: =I17/I8 -> #DIV/0! | J24: =J17/J8 -> #DIV/0! | K24: =K17/K8 -> #DIV/0! | ... M24: =M17/M8 -> #DIV/0!
A25: 015 | B25: 供热煤耗率 | C25: 千克/吉焦 | D25: =D12*1000/D8 -> #DIV/0! | E25: =E12*1000/E8 -> #DIV/0! | F25: =F12*1000/F8 -> #DIV/0! | G25: =G12*1000/G8 -> #DIV/0! | H25: =H12*1000/H8 -> #DIV/0! | I25: =I12*1000/I8 -> #DIV/0! | J25: =J12*1000/J8 -> #DIV/0! | K25: =K12*1000/K8 -> #DIV/0! | ... M25: =M12*1000/M8 -> #DIV/0!
A26: 016 | B26: 入厂煤量 | C26: 吨 | I26: =D26+'26.6'!I26 -> 0 | J26: =E26+'26.6'!J26 -> 0 | K26: =F26+'26.6'!K26 -> 0 | L26: =G26+'26.6'!L26 -> 0 | M26: =J26+K26+L26 -> 0
A27: 017 | B27: 期末库存煤量 | C27: 吨 | E27: =J27 -> 12569.7 | G27: =L27 -> 1108.5 | J27: ='26.6'!J27+E26-E10 -> 12569.7 | K27: ='26.6'!K27+F26-F10 -> 0 | L27: ='26.6'!L27+G26-G10 -> 1108.5 | M27: =J27+K27+L27 -> 13678.2
A28: 018 | B28: 入炉煤低位发热量 | C28: 千焦/千克 | D28: =D13*29308/D10 -> #DIV/0! | E28: =E12*29308/E10 -> #DIV/0! | F28: =F12*29308/F10 -> #DIV/0! | G28: =G12*29308/G10 -> #DIV/0! | H28: =H12*29308/H10 -> #DIV/0! | I28: =I13*29308/I10 -> #DIV/0! | J28: =J12*29308/J10 -> #DIV/0! | K28: =K12*29308/K10 -> #DIV/0! | L28: =L12*29308/L10 -> #DIV/0! | M28: =M12*29308/M10 -> #DIV/0!
A29: 019 | B29: 入厂煤低位发热量 | C29: 千焦/千克
A30: 020 | B30: 锅炉热效率 | C30: % | D30: =D8/(D12*29.308) -> #DIV/0! | E30: =E8/(E12*29.308) -> #DIV/0! | F30: =F8/(F12*29.308) -> #DIV/0! | G30: =(G8-G36)/(G12*29.308) -> #DIV/0! | H30: =H8/(H12*29.308) -> #DIV/0! | I30: =I8/(I12*29.308) -> #DIV/0! | J30: =J8/(J12*29.308) -> #DIV/0! | K30: =K8/(K12*29.308) -> #DIV/0! | L30: =L8/(L12*29.308) -> #DIV/0! | M30: =M8/(M12*29.308) -> #DIV/0!
A31: 021 | B31: 锅炉设备利用率 | C31: % | D31: =D8/3.6/D3/(DAY(DATE(2026,8,0))*24) -> 0 | E31: =E8/3.6/E3/(DAY(DATE(2026,8,0))*24) -> 0 | F31: =F8/3.6/F3/(DAY(DATE(2026,8,0))*24) -> #DIV/0! | G31: =(G8-G36)/3.6/G3/(DAY(DATE(2026,8,0))*24) -> 0 | H31: =H8/3.6/H3/(DAY(DATE(2026,8,0))*24) -> 0 | I31: =I8/3.6/I3/(DATEDIF(DATE(2026,1,1),DATE(2026,8,1),"D")*24) -> 0 | J31: =J8/3.6/J3/(DATEDIF(DATE(2026,1,1),DATE(2026,8,1),"D")*24) -> 0 | K31: =K8/3.6/K3/(DATEDIF(DATE(2026,1,1),DATE(2026,8,1),"D")*24) -> #DIV/0! | L31: =(L8-L36)/3.6/L3/(DATEDIF(DATE(2026,1,1),DATE(2026,8,1),"D")*24) -> 0 | M31: =M8/3.6/M3/(DATEDIF(DATE(2026,1,1),DATE(2026,8,1),"D")*24) -> 0
A32: 022 | B32: 供暖热耗率 | C32: 吉焦/平方米 | E32: =E8/E6 -> #DIV/0! | F32: =F8/F6 -> #DIV/0! | G32: =G8/G6 -> #DIV/0! | H32: =H8/H6 -> #DIV/0! | J32: =J8/J6 -> #DIV/0! | K32: =K8/K6 -> #DIV/0! | L32: =L8/L6 -> #DIV/0! | M32: =M8/M6 -> #DIV/0!
A33: 023 | B33: 单位面积耗标准煤量 | C33: 千克/平方米 | E33: =E12*1000/E6 -> #DIV/0! | F33: =F12*1000/F6 -> #DIV/0! | G33: =G12*1000/G6 -> #DIV/0! | H33: =H12*1000/H6 -> #DIV/0! | J33: =J12*1000/J6 -> #DIV/0! | K33: =K12*1000/K6 -> #DIV/0! | L33: =L12*1000/L6 -> #DIV/0! | M33: =M12*1000/M6 -> #DIV/0!
A34: 024 | B34: 单位面积耗电量 | C34: 千瓦时/平方米 | E34: =E17/E6 -> #DIV/0! | F34: =F17/F6 -> #DIV/0! | G34: =G17/G6 -> #DIV/0! | H34: =H17/H6 -> #DIV/0! | J34: =J17/J6 -> #DIV/0! | K34: =K17/K6 -> #DIV/0! | L34: =L17/L6 -> #DIV/0! | M34: =M17/M6 -> #DIV/0!
A35: 025 | B35: 单位面积耗水量 | C35: 千克/平方米 | E35: =E15*1000/E6 -> #DIV/0! | F35: =F15*1000/F6 -> #DIV/0! | G35: =G15*1000/G6 -> #DIV/0! | H35: =H15*1000/H6 -> #DIV/0! | J35: =J15*1000/J6 -> #DIV/0! | K35: =K15*1000/K6 -> #DIV/0! | L35: =L15*1000/L6 -> #DIV/0! | M35: =M15*1000/M6 -> #DIV/0!
B36: 外购热量 | C36: 吉焦 | L36: =G36+'26.6'!L36 -> 0
A37: 电锅炉房(机车)
A38: 代码 | B38: 项 目 | C38: 计量单位 | D38: 本月实际 | E38: 本年累计
A39: 001 | B39: 装机总容量 | C39: 兆瓦 | D39: 0.55 | E39: 0.55
A40: 002 | B40: 期末供暖面积 | C40: 平方米 | E40: =D40 -> 0
...

Sheet 26.8
A1: 代码 | B1: 项目 | C1: 计量单位 | D1: 本 月 实 际 | I1: 本 年 累 计
D2: 北海水炉 | E2: 金普 | F2: 临海 | G2: 庄河 | H2: 合计 | I2: 北海水炉 | J2: 金普 | K2: 临海 | L2: 庄河 | M2: 合计
A3: 001 | B3: 装机总容量 | C3: 兆瓦 | D3: 348 | E3: 162 | G3: 263 | H3: =E3+F3+G3 -> 425 | I3: =D3 -> 348 | J3: =E3 -> 162 | K3: =F3 -> 0 | L3: =G3 -> 263 | M3: =J3+K3+L3 -> 425
A4: 002 | B4: 期末供热面积 | C4: 平方米 | D4: - | I4: =D4 -> - | J4: =E4 -> 0 | K4: =F4 -> 0 | L4: =G4 -> 0 | M4: =J4+K4+L4 -> 0
B5: 其中：高温水面积 | C5: 平方米 | D5: - | E5: 55000 | F5: 0 | G5: 0 | H5: =E5+F5+G5 -> 55000 | I5: =D5 -> - | J5: =E5 -> 55000 | K5: =F5 -> 0 | L5: =G5 -> 0 | M5: =J5+K5+L5 -> 55000
A6: 003 | B6: 实际平均供热面积 | C6: 平方米 | D6: - | E6: =E4 -> 0 | F6: =F4 -> 0 | G6: =G4 -> 0 | H6: =E6+F6+G6 -> 0 | I6: =D6 -> - | J6: =E6 -> 0 | K6: =F6 -> 0 | L6: =G6 -> 0 | M6: =J6+K6+L6 -> 0
A7: 004 | B7: 供汽量 | C7: 吨 | D7: 0 | E7: 0 | F7: 0 | H7: =E7+F7+G7 -> 0 | I7: =D7+'26.7'!I7 -> 0 | J7: =E7+'26.7'!J7 -> 0 | K7: =F7+'26.7'!K7 -> 0 | L7: =G7+'26.7'!L7 -> 0 | M7: =J7+K7+L7 -> 0
A8: 005 | B8: 供热量 | C8: 吉焦 | I8: =D8+'26.7'!I8 -> 0 | J8: =E8+'26.7'!J8 -> 0 | K8: =F8+'26.7'!K8 -> 0 | L8: =G8+'26.7'!L8 -> 0 | M8: =J8+K8+L8 -> 0
A9: 006 | B9: 高温水销售量 | C9: 吉焦 | D9: 0 | E9: =[1]售热量!$Q$25 -> 0 | H9: =E9+F9+G9 -> 0 | I9: =D9+'26.7'!I9 -> 0 | J9: =E9+'26.7'!J9 -> 0 | K9: =F9+'26.7'!K9 -> 0 | L9: =G9+'26.7'!L9 -> 0 | M9: =J9+K9+L9 -> 0
A10: 007 | B10: 生产耗原煤量 | C10: 吨 | H10: =E10+F10+G10 -> 0 | I10: =D10+'26.7'!I10 -> 0 | J10: =E10+'26.7'!J10 -> 0 | K10: =F10+'26.7'!K10 -> 0 | L10: =G10+'26.7'!L10 -> 0 | M10: =J10+K10+L10 -> 0
A11: 008 | B11: 耗油量 | C11: 吨 | E11: 0 | H11: =E11+F11+G11 -> 0 | I11: =D11+'26.7'!I11 -> 0 | J11: =E11+'26.7'!J11 -> 0 | K11: =F11+'26.7'!K11 -> 0 | L11: =G11+'26.7'!L11 -> 0 | M11: =J11+K11+L11 -> 0
A12: 009 | B12: 耗标煤总量 | C12: 吨 | D12: =D13+D14 -> 0 | E12: =E13+E14 -> 0 | F12: =F13+F14 -> 0 | G12: =G13+G14 -> 0 | H12: =E12+F12+G12 -> 0 | I12: =D12+'26.7'!I12 -> 0 | J12: =E12+'26.7'!J12 -> 0 | K12: =F12+'26.7'!K12 -> 0 | L12: =G12+'26.7'!L12 -> 0 | M12: =J12+K12+L12 -> 0
B13: 其中：煤折标准煤量 | C13: 吨 | I13: =D13+'26.7'!I13 -> 0 | J13: =E13+'26.7'!J13 -> 0 | K13: =F13+'26.7'!K13 -> 0 | L13: =G13+'26.7'!L13 -> 0
B14: 油折标准煤量 | C14: 吨 | I14: =D14+'26.7'!I14 -> 0 | J14: =E14+'26.7'!J14 -> 0 | K14: =F14+'26.7'!K14 -> 0 | L14: =G14+'26.7'!L14 -> 0
A15: 010 | B15: 耗水量 | C15: 吨 | I15: =D15+'26.7'!I15 -> 0 | J15: =E15+'26.7'!J15 -> 0 | K15: =F15+'26.7'!K15 -> 0 | L15: =G15+'26.7'!L15 -> 0 | M15: =J15+K15+L15 -> 0
B16: 其中：耗井水(再生水)量 | C16: 吨 | I16: =D16+'26.7'!I16 -> 0 | J16: =E16+'26.7'!J16 -> 0 | K16: =F16+'26.7'!K16 -> 0 | L16: =G16+'26.7'!L16 -> 0 | M16: =J16+K16+L16 -> 0
A17: 011 | B17: 耗电量 | C17: 千瓦时 | I17: =D17+'26.7'!I17 -> 0 | J17: =E17+'26.7'!J17 -> 0 | L17: =G17+'26.7'!L17 -> 0 | M17: =J17+K17+L17 -> 0
B18: 其中：耗厂用电量 | C18: 千瓦时 | I18: =D18+'26.7'!I18 -> 0 | J18: =E18+'26.7'!J18 -> 0 | K18: =F18+'26.7'!K18 -> 0 | L18: =G18+'26.7'!L18 -> 0
B19: 耗外购电量 | C19: 千瓦时 | I19: =D19+'26.7'!I19 -> 0 | K19: =F19+'26.7'!K19 -> 0 | L19: =G19+'26.7'!L19 -> 0
B20: 脱硫脱硝耗水量 | C20: 吨 | I20: =D20+'26.7'!I20 -> 0 | J20: =E20+'26.7'!J20 -> 0 | K20: =F20+'26.7'!K20 -> 0 | L20: =G20+'26.7'!L20 -> 0
B21: 脱硫脱硝耗电量 | C21: 千瓦时 | I21: =D21+'26.7'!I21 -> 0 | J21: =E21+'26.7'!J21 -> 0 | K21: =F21+'26.7'!K21 -> 0 | L21: =G21+'26.7'!L21 -> 0
A22: 012 | B22: 耗氧化镁(石灰石粉)量 | C22: 吨 | I22: =D22+'26.7'!I22 -> 0 | J22: =E22+'26.7'!J22 -> 0 | K22: =F22+'26.7'!K22 -> 0 | L22: =G22+'26.7'!L22 -> 0 | M22: =J22+K22+L22 -> 0
A23: 013 | B23: 耗脱硝剂(氨水)量 | C23: 吨 | I23: =D23+'26.7'!I23 -> 0 | J23: =E23+'26.7'!J23 -> 0 | K23: =F23+'26.7'!K23 -> 0 | L23: =G23+'26.7'!L23 -> 0 | M23: =J23+K23+L23 -> 0
A24: 014 | B24: 供热用电率 | C24: 千瓦时/吉焦 | D24: =D17/D8 -> #DIV/0! | E24: =E17/E8 -> #DIV/0! | F24: =F17/F8 -> #DIV/0! | G24: =G17/G8 -> #DIV/0! | H24: =H17/H8 -> #DIV/0! | I24: =I17/I8 -> #DIV/0! | J24: =J17/J8 -> #DIV/0! | K24: =K17/K8 -> #DIV/0! | ... M24: =M17/M8 -> #DIV/0!
A25: 015 | B25: 供热煤耗率 | C25: 千克/吉焦 | D25: =D12*1000/D8 -> #DIV/0! | E25: =E12*1000/E8 -> #DIV/0! | F25: =F12*1000/F8 -> #DIV/0! | G25: =G12*1000/G8 -> #DIV/0! | H25: =H12*1000/H8 -> #DIV/0! | I25: =I12*1000/I8 -> #DIV/0! | J25: =J12*1000/J8 -> #DIV/0! | K25: =K12*1000/K8 -> #DIV/0! | ... M25: =M12*1000/M8 -> #DIV/0!
A26: 016 | B26: 入厂煤量 | C26: 吨 | I26: =D26+'26.7'!I26 -> 0 | J26: =E26+'26.7'!J26 -> 0 | K26: =F26+'26.7'!K26 -> 0 | L26: =G26+'26.7'!L26 -> 0 | M26: =J26+K26+L26 -> 0
A27: 017 | B27: 期末库存煤量 | C27: 吨 | E27: =J27 -> 12569.7 | G27: =L27 -> 1108.5 | J27: ='26.7'!J27+E26-E10 -> 12569.7 | K27: ='26.7'!K27+F26-F10 -> 0 | L27: ='26.7'!L27+G26-G10 -> 1108.5 | M27: =J27+K27+L27 -> 13678.2
A28: 018 | B28: 入炉煤低位发热量 | C28: 千焦/千克 | D28: =D13*29308/D10 -> #DIV/0! | E28: =E12*29308/E10 -> #DIV/0! | F28: =F12*29308/F10 -> #DIV/0! | G28: =G12*29308/G10 -> #DIV/0! | H28: =H12*29308/H10 -> #DIV/0! | I28: =I13*29308/I10 -> #DIV/0! | J28: =J12*29308/J10 -> #DIV/0! | K28: =K12*29308/K10 -> #DIV/0! | L28: =L12*29308/L10 -> #DIV/0! | M28: =M12*29308/M10 -> #DIV/0!
A29: 019 | B29: 入厂煤低位发热量 | C29: 千焦/千克
A30: 020 | B30: 锅炉热效率 | C30: % | D30: =D8/(D12*29.308) -> #DIV/0! | E30: =E8/(E12*29.308) -> #DIV/0! | F30: =F8/(F12*29.308) -> #DIV/0! | G30: =(G8-G36)/(G12*29.308) -> #DIV/0! | H30: =H8/(H12*29.308) -> #DIV/0! | I30: =I8/(I12*29.308) -> #DIV/0! | J30: =J8/(J12*29.308) -> #DIV/0! | K30: =K8/(K12*29.308) -> #DIV/0! | L30: =L8/(L12*29.308) -> #DIV/0! | M30: =M8/(M12*29.308) -> #DIV/0!
A31: 021 | B31: 锅炉设备利用率 | C31: % | D31: =D8/3.6/D3/(DAY(DATE(2026,9,0))*24) -> 0 | E31: =E8/3.6/E3/(DAY(DATE(2026,9,0))*24) -> 0 | F31: =F8/3.6/F3/(DAY(DATE(2026,9,0))*24) -> #DIV/0! | G31: =(G8-G36)/3.6/G3/(DAY(DATE(2026,9,0))*24) -> 0 | H31: =H8/3.6/H3/(DAY(DATE(2026,9,0))*24) -> 0 | I31: =I8/3.6/I3/(DATEDIF(DATE(2026,1,1),DATE(2026,9,1),"D")*24) -> 0 | J31: =J8/3.6/J3/(DATEDIF(DATE(2026,1,1),DATE(2026,9,1),"D")*24) -> 0 | K31: =K8/3.6/K3/(DATEDIF(DATE(2026,1,1),DATE(2026,9,1),"D")*24) -> #DIV/0! | L31: =(L8-L36)/3.6/L3/(DATEDIF(DATE(2026,1,1),DATE(2026,9,1),"D")*24) -> 0 | M31: =M8/3.6/M3/(DATEDIF(DATE(2026,1,1),DATE(2026,9,1),"D")*24) -> 0
A32: 022 | B32: 供暖热耗率 | C32: 吉焦/平方米 | E32: =E8/E6 -> #DIV/0! | F32: =F8/F6 -> #DIV/0! | G32: =G8/G6 -> #DIV/0! | H32: =H8/H6 -> #DIV/0! | J32: =J8/J6 -> #DIV/0! | K32: =K8/K6 -> #DIV/0! | L32: =L8/L6 -> #DIV/0! | M32: =M8/M6 -> #DIV/0!
A33: 023 | B33: 单位面积耗标准煤量 | C33: 千克/平方米 | E33: =E12*1000/E6 -> #DIV/0! | F33: =F12*1000/F6 -> #DIV/0! | G33: =G12*1000/G6 -> #DIV/0! | H33: =H12*1000/H6 -> #DIV/0! | J33: =J12*1000/J6 -> #DIV/0! | K33: =K12*1000/K6 -> #DIV/0! | L33: =L12*1000/L6 -> #DIV/0! | M33: =M12*1000/M6 -> #DIV/0!
A34: 024 | B34: 单位面积耗电量 | C34: 千瓦时/平方米 | E34: =E17/E6 -> #DIV/0! | F34: =F17/F6 -> #DIV/0! | G34: =G17/G6 -> #DIV/0! | H34: =H17/H6 -> #DIV/0! | J34: =J17/J6 -> #DIV/0! | K34: =K17/K6 -> #DIV/0! | L34: =L17/L6 -> #DIV/0! | M34: =M17/M6 -> #DIV/0!
A35: 025 | B35: 单位面积耗水量 | C35: 千克/平方米 | E35: =E15*1000/E6 -> #DIV/0! | F35: =F15*1000/F6 -> #DIV/0! | G35: =G15*1000/G6 -> #DIV/0! | H35: =H15*1000/H6 -> #DIV/0! | J35: =J15*1000/J6 -> #DIV/0! | K35: =K15*1000/K6 -> #DIV/0! | L35: =L15*1000/L6 -> #DIV/0! | M35: =M15*1000/M6 -> #DIV/0!
B36: 外购热量 | C36: 吉焦 | L36: =G36+'26.7'!L36 -> 0
A37: 电锅炉房(机车)
A38: 代码 | B38: 项 目 | C38: 计量单位 | D38: 本月实际 | E38: 本年累计
A39: 001 | B39: 装机总容量 | C39: 兆瓦 | D39: 0.55 | E39: 0.55
A40: 002 | B40: 期末供暖面积 | C40: 平方米 | E40: =D40 -> 0
...

Sheet 26.9
A1: 代码 | B1: 项目 | C1: 计量单位 | D1: 本 月 实 际 | I1: 本 年 累 计
D2: 北海水炉 | E2: 金普 | F2: 临海 | G2: 庄河 | H2: 合计 | I2: 北海水炉 | J2: 金普 | K2: 临海 | L2: 庄河 | M2: 合计
A3: 001 | B3: 装机总容量 | C3: 兆瓦 | D3: 348 | E3: 162 | G3: 263 | H3: =E3+F3+G3 -> 425 | I3: =D3 -> 348 | J3: =E3 -> 162 | K3: =F3 -> 0 | L3: =G3 -> 263 | M3: =J3+K3+L3 -> 425
A4: 002 | B4: 期末供热面积 | C4: 平方米 | D4: - | I4: =D4 -> - | J4: =E4 -> 0 | K4: =F4 -> 0 | L4: =G4 -> 0 | M4: =J4+K4+L4 -> 0
B5: 其中：高温水面积 | C5: 平方米 | D5: - | E5: 55000 | F5: 0 | G5: 0 | H5: =E5+F5+G5 -> 55000 | I5: =D5 -> - | J5: =E5 -> 55000 | K5: =F5 -> 0 | L5: =G5 -> 0 | M5: =J5+K5+L5 -> 55000
A6: 003 | B6: 实际平均供热面积 | C6: 平方米 | D6: - | E6: =E4 -> 0 | F6: =F4 -> 0 | G6: =G4 -> 0 | H6: =E6+F6+G6 -> 0 | I6: =D6 -> - | J6: =E6 -> 0 | K6: =F6 -> 0 | L6: =G6 -> 0 | M6: =J6+K6+L6 -> 0
A7: 004 | B7: 供汽量 | C7: 吨 | D7: 0 | E7: 0 | F7: 0 | H7: =E7+F7+G7 -> 0 | I7: =D7+'26.8'!I7 -> 0 | J7: =E7+'26.8'!J7 -> 0 | K7: =F7+'26.8'!K7 -> 0 | L7: =G7+'26.8'!L7 -> 0 | M7: =J7+K7+L7 -> 0
A8: 005 | B8: 供热量 | C8: 吉焦 | I8: =D8+'26.8'!I8 -> 0 | J8: =E8+'26.8'!J8 -> 0 | K8: =F8+'26.8'!K8 -> 0 | L8: =G8+'26.8'!L8 -> 0 | M8: =J8+K8+L8 -> 0
A9: 006 | B9: 高温水销售量 | C9: 吉焦 | D9: 0 | E9: =[1]售热量!$S$25 -> 0 | H9: =E9+F9+G9 -> 0 | I9: =D9+'26.8'!I9 -> 0 | J9: =E9+'26.8'!J9 -> 0 | K9: =F9+'26.8'!K9 -> 0 | L9: =G9+'26.8'!L9 -> 0 | M9: =J9+K9+L9 -> 0
A10: 007 | B10: 生产耗原煤量 | C10: 吨 | H10: =E10+F10+G10 -> 0 | I10: =D10+'26.8'!I10 -> 0 | J10: =E10+'26.8'!J10 -> 0 | K10: =F10+'26.8'!K10 -> 0 | L10: =G10+'26.8'!L10 -> 0 | M10: =J10+K10+L10 -> 0
A11: 008 | B11: 耗油量 | C11: 吨 | E11: 0 | H11: =E11+F11+G11 -> 0 | I11: =D11+'26.8'!I11 -> 0 | J11: =E11+'26.8'!J11 -> 0 | K11: =F11+'26.8'!K11 -> 0 | L11: =G11+'26.8'!L11 -> 0 | M11: =J11+K11+L11 -> 0
A12: 009 | B12: 耗标煤总量 | C12: 吨 | D12: =D13+D14 -> 0 | E12: =E13+E14 -> 0 | F12: =F13+F14 -> 0 | G12: =G13+G14 -> 0 | H12: =E12+F12+G12 -> 0 | I12: =D12+'26.8'!I12 -> 0 | J12: =E12+'26.8'!J12 -> 0 | K12: =F12+'26.8'!K12 -> 0 | L12: =G12+'26.8'!L12 -> 0 | M12: =J12+K12+L12 -> 0
