Workbook

Sheet 2026底表
A1: 生产指标 | B1: 统计时间 | C1: 46296 | D1: 46297 | E1: 46298 | F1: 46299 | G1: 46300 | H1: 46301 | I1: 46302 | J1: 46303 | K1: 46304 | L1: 46305 | M1: 46306 | N1: 46307 | O1: 46308 | P1: 46309 | Q1: 46310 | R1: 46311 | S1: 46312 | T1: 46313 | U1: 46314 | V1: 46315 | W1: 46316 | X1: 46317 | Y1: 46318 | Z1: 46319 | AA1: 46320 | AB1: 46321 | AC1: 46322 | AD1: 46323 | AE1: 46324 | AF1: 46325 | AG1: 46326 | AW1: 生产指标 | AX1: 统计时间 | AY1: 46321
A2: 天气 | B2: 2025 当日最低温度 | AW2: 天气 | AX2: 2025 当日最低温度
B3: 2025 当日最高温度 | AX3: 2025 当日最高温度
B4: 2025 气象 | AX4: 2025 气象
B5: 2026 当日最低温度 | AX5: 2026 当日最低温度
B6: 2026 当日最高温度 | AX6: 2026 当日最高温度
B7: 2026 气象 | AX7: 2026 气象
A8: 汇总 | AW8: 汇总
A9: 运行方式 炉/机 | AW9: 运行方式 炉/机
B11: 计划 | AX11: 计划
A12: 发电量 （万千万时) | AW12: 发电量 （万千万时)
B14: 计划值 | AX14: 计划值
B15: 与计划差值 | AX15: 与计划差值
B16: 同比差值 | AX16: 同比差值
A17: 上网供电量 （万千万时) | AW17: 上网供电量 （万千万时)
B19: 计划值 | AX19: 计划值
B20: 与计划差值 | AX20: 与计划差值
B21: 同比差值 | AX21: 同比差值
A22: 综合厂 用电量 （万千万时) | AW22: 综合厂 用电量 （万千万时)
B24: 计划值 | AX24: 计划值
B25: 与计划差值 | AX25: 与计划差值
B26: 同比差值 | AX26: 同比差值
A27: 综合 厂用电率 （%） | AW27: 综合 厂用电率 （%）
B29: 计划值 | AX29: 计划值
B30: 与计划差值 | AX30: 与计划差值
B31: 同比差值 | AX31: 同比差值
A32: 外供汽量 (吨） | AW32: 外供汽量 (吨）
B34: 计划值 | AX34: 计划值
B35: 与计划差值 | AX35: 与计划差值
B36: 同比差值 | AX36: 同比差值
A37: 供首站汽量 （吨） | AW37: 供首站汽量 （吨）
B41: 同比差值 | AX41: 同比差值
A42: 天然气炉 供汽量 （吨） | AW42: 天然气炉 供汽量 （吨）
B44: 同比差值 | AX44: 同比差值
A45: 外供热总量 （吉焦） | AW45: 外供热总量 （吉焦）
B47: 计划值 | AX47: 计划值
B48: 与计划差值 | AX48: 与计划差值
B49: 同比差值 | AX49: 同比差值
A50: 电厂耗原煤量 （吨） | AW50: 电厂耗原煤量 （吨）
B52: 计划值 | AX52: 计划值
...

Sheet 2026.10
A1: 生产指标 | B1: 统计时间 | C1: 46296 | D1: 46297 | E1: 46298 | F1: 46299 | G1: 46300 | H1: 46301 | I1: 46302 | J1: 46303 | K1: 46304 | L1: 46305 | M1: 46306 | N1: 46307 | O1: 46308 | P1: 46309 | Q1: 46310 | R1: 46311 | S1: 46312 | T1: 46313 | U1: 46314 | V1: 46315 | W1: 46316 | X1: 46317 | Y1: 46318 | Z1: 46319 | AA1: 46320 | AB1: 46321 | AC1: 46322 | AD1: 46323 | AE1: 46324 | AF1: 46325 | AG1: 46326 | AI1: 46322 | AJ1: AC | AU1: =U129 -> 0
A2: 天气 | B2: 2025 当日最低温度 | C2: 19 | D2: 20 | E2: 20 | F2: 19 | G2: 17 | H2: 14 | I2: 14 | J2: 3 | K2: 11 | L2: 12 | M2: 14 | N2: 14 | O2: 16 | P2: 15 | Q2: 14 | R2: 12 | S2: 10 | T2: 5 | U2: 4 | V2: 4 | W2: 6 | X2: 6 | Y2: 5 | Z2: 6 | AA2: 9 | AB2: 6 | AC2: 6 | AD2: 9 | AE2: 14 | AF2: 9 | AG2: 9
B3: 2025 当日最高温度 | C3: 30 | D3: 25 | E3: 27 | F3: 27 | G3: 25 | H3: 23 | I3: 24 | J3: 20 | K3: 14 | L3: 16 | M3: 19 | N3: 21 | O3: 21 | P3: 23 | Q3: 20 | R3: 15 | S3: 19 | T3: 11 | U3: 10 | V3: 10 | W3: 10 | X3: 12 | Y3: 15 | Z3: 12 | AA3: 16 | AB3: 14 | AC3: 10 | AD3: 16 | AE3: 18 | AF3: 15 | AG3: 15
B4: 2025 气象 | C4: 晴 西北风4级 | D4: 晴 西北风3级 | E4: 晴 南风3级 | F4: 晴 西南风3级 | G4: 多云 西南风3级 | H4: 阴~多云 西北风3级 | I4: 晴 北风5级 | J4: 晴 北风3级 | K4: 阴 西南风2级 | L4: 晴 北风4级 | M4: 阴-晴 西南风3级 | N4: 晴 西南风2级 | O4: 阴-多云 东南风3级 | P4: 小雨-多云 南风3级 | Q4: 多云-小雨 南风3级 | R4: 多云 北风5级 | S4: 阴 北风6级 | T4: 晴转多云 东北风4级 | U4: 晴 北风4级 | V4: 晴 北风4级 | W4: 晴 北风5级 | X4: 晴 北风4级 | Y4: 晴 北风5级 | Z4: 阴 北风3级 | AA4: 阴转小雨 西风3级 | AB4: 多云转晴 西北风4级 | AC4: 晴 北风3级 | AD4: 多云转阴 南风4级 | AE4: 多云转小雨 西南风5级 | AF4: 阵雨转小雨 东北风4级 | AG4: 多云 西北风4级
B5: 2026 当日最低温度 | C5: 14 | D5: 14 | E5: 17 | F5: 14 | G5: 14 | H5: 14 | I5: 15 | J5: 15 | K5: 18 | L5: 18 | M5: 15 | N5: 14 | O5: 14 | P5: 13 | Q5: 14 | R5: 16 | S5: 15 | T5: 13 | U5: 13 | V5: 10 | W5: 9 | X5: 9 | Y5: 12 | Z5: 10 | AA5: 10 | AB5: 10 | AC5: 8 | AD5: 8
B6: 2026 当日最高温度 | C6: 20 | D6: 22 | E6: 21 | F6: 19 | G6: 19 | H6: 19 | I6: 23 | J6: 25 | K6: 24 | L6: 24 | M6: 23 | N6: 23 | O6: 20 | P6: 22 | Q6: 24 | R6: 21 | S6: 23 | T6: 21 | U6: 20 | V6: 19 | W6: 12 | X6: 16 | Y6: 17 | Z6: 18 | AA6: 18 | AB6: 15 | AC6: 13 | AD6: 17
B7: 2026 气象 | C7: 晴 西北风3级 | D7: 晴 南风1级 | E7: 多云转雷阵雨 南风2级 | F7: 阴转多云 西北风3级 | G7: 晴 北风4级 | H7: 晴 西北风3级 | I7: 晴 西风3级 | J7: 晴 西南风4级 | K7: 晴 南风5级 | L7: 阴 南风1级 | M7: 多云 南风1级 | N7: 雾 南风3级 | O7: 晴 西风1级 | P7: 多云转小雨 南风2级 | Q7: 雾霾转阴 西北风1级 | R7: 多云 东南风3级 | S7: 阴小雨转大雨 南风5级 | T7: 阴转多云 东北风2级 | U7: 阴 东风1级 | V7: 小雨转晴 西北风5级 | W7: 晴 北风5级 | X7: 多云 南风3级 | Y7: 阴转晴 南风3级 | Z7: 阴转晴 东北风3级 | AA7: 晴 北风3级 | AB7: 多云转晴 北风4级 | AC7: 晴 北风6级 | AD7: 多云 南风2级
A8: 汇总
A9: 运行方式 炉/机 | P9: 46310 | Q9: 轻度雾霾转阴 | R9: 24℃ | S9: 14℃ | T9: 西北风1级 | AU9: =AO155 -> 0
P10: 46311 | Q10: 多云 | R10: 21℃ | S10: 16℃ | T10: 东南风3级 | AU10: =U147 -> 0.952076
B11: 计划 | P11: 46312 | Q11: 阴偶有小雨转大雨 | R11: 23℃ | S11: 15℃ | T11: 南风5级 | AU11: =AO147 -> 0
A12: 发电量 （万千万时) | C12: =C173 -> 0 | D12: =D173 -> 0 | E12: =E173 -> 0 | F12: =F173 -> 0 | G12: =G173 -> 0 | H12: =H173 -> 0 | I12: =I173 -> 0 | J12: =J173 -> 0 | ... O12: =O173 -> 0 | P12: 46313 | Q12: 阴转多云 | R12: 21℃ | S12: 13℃ | T12: 东北风2级 | U12: =U173 -> 0 | V12: =V173 -> 0 | W12: =W173 -> 0 | X12: =X173 -> 0 | Y12: =Y173 -> 0 | Z12: =Z173 -> 0 | AA12: =AA173 -> 0 | AB12: =AB173 -> 0 | ... AG12: =AG173 -> 0 | AH12: =SUM(C12:AG12) -> 46313 | AU12: =U186 -> 1.74
C13: =C174 -> 0 | D13: =D174 -> 0 | E13: =E174 -> 0 | F13: =F174 -> 0 | G13: =G174 -> 0 | H13: =H174 -> 0 | I13: =I174 -> 0 | J13: =J174 -> 0 | ... O13: =O174 -> 0 | P13: 46314 | Q13: 阴 | R13: 20℃ | S13: 13℃ | T13: 东风1级 | U13: =U174 -> 0 | V13: =V174 -> 0 | W13: =W174 -> 0 | X13: =X174 -> 0 | Y13: =Y174 -> 0 | Z13: =Z174 -> 0 | AA13: =AA174 -> 0 | AB13: =AB174 -> 0 | ... AG13: =AG174 -> 0 | AH13: =SUM(C13:AG13) -> 46314 | AU13: =AO188 -> 0
B14: 计划值 | C14: =C175 -> 0 | D14: =D175 -> 0 | E14: =E175 -> 0 | F14: =F175 -> 0 | G14: =G175 -> 0 | H14: =H175 -> 0 | I14: =I175 -> 0 | J14: =J175 -> 0 | ... AG14: =AG175 -> 0 | AH14: =SUM(C14:AG14) -> 0 | AU14: =U181 -> 0
B15: 与计划差值 | C15: =C176 -> 0 | D15: =D176 -> 0 | E15: =E176 -> 0 | F15: =F176 -> 0 | G15: =G176 -> 0 | H15: =H176 -> 0 | I15: =I176 -> 0 | J15: =J176 -> 0 | ... AG15: =AG176 -> 0 | AH15: =SUM(C15:AG15) -> 0 | AU15: =AO181 -> 0
B16: 同比差值 | C16: =C177 -> 0 | D16: =D177 -> 0 | E16: =E177 -> 0 | F16: =F177 -> 0 | G16: =G177 -> 0 | H16: =H177 -> 0 | I16: =I177 -> 0 | J16: =J177 -> 0 | ... AG16: =AG177 -> 0 | AH16: =SUM(C16:AG16) -> 0 | AU16: =U189 -> #DIV/0!
A17: 上网供电量 （万千万时) | C17: =C178 -> 0 | D17: =D178 -> 0 | E17: =E178 -> 0 | F17: =F178 -> 0 | G17: =G178 -> 0 | H17: =H178 -> 0 | I17: =I178 -> 0 | J17: =J178 -> 0 | ... AG17: =AG178 -> 0 | AH17: =SUM(C17:AG17) -> 0 | AU17: =AO191 -> 0
C18: =C179 -> 0 | D18: =D179 -> 0 | E18: =E179 -> 0 | F18: =F179 -> 0 | G18: =G179 -> 0 | H18: =H179 -> 0 | I18: =I179 -> 0 | J18: =J179 -> 0 | ... AG18: =AG179 -> 0 | AH18: =SUM(C18:AG18) -> 0 | AU18: =U192 -> #DIV/0!
B19: 计划值 | C19: =C180 -> 0 | D19: =D180 -> 0 | E19: =E180 -> 0 | F19: =F180 -> 0 | G19: =G180 -> 0 | H19: =H180 -> 0 | I19: =I180 -> 0 | J19: =J180 -> 0 | ... AG19: =AG180 -> 0 | AH19: =SUM(C19:AG19) -> 0 | AU19: =AO194 -> 1069
B20: 与计划差值 | C20: =C181 -> 0 | D20: =D181 -> 0 | E20: =E181 -> 0 | F20: =F181 -> 0 | G20: =G181 -> 0 | H20: =H181 -> 0 | I20: =I181 -> 0 | J20: =J181 -> 0 | ... AG20: =AG181 -> 0 | AH20: =SUM(C20:AG20) -> 0 | AU20: =AU2/((AU4-AU21)*U137/1000) -> #DIV/0!
B21: 同比差值 | C21: =C182 -> 0 | D21: =D182 -> 0 | E21: =E182 -> 0 | F21: =F182 -> 0 | G21: =G182 -> 0 | H21: =H182 -> 0 | I21: =I182 -> 0 | J21: =J182 -> 0 | ... AG21: =AG182 -> 0 | AH21: =SUM(C21:AG21) -> 0 | AU21: =U300 -> 0
A22: 综合厂 用电量 （万千万时) | C22: =C183 -> 0.48 | D22: =D183 -> 0.54 | E22: =E183 -> 0.54 | F22: =F183 -> 0.6 | G22: =G183 -> 0.54 | H22: =H183 -> 0.6 | I22: =I183 -> 0.54 | J22: =J183 -> 0.72 | ... AG22: =AG183 -> 6.19975 | AH22: =SUM(C22:AG22) -> 84.709338
C23: =C184 -> 0.54 | D23: =D184 -> 0.54 | E23: =E184 -> 0.54 | F23: =F184 -> 0.54 | G23: =G184 -> 0.54 | H23: =H184 -> 0.54 | I23: =I184 -> 0.48 | J23: =J184 -> 0.72 | ... AG23: =AG184 -> 0 | AH23: =SUM(C23:AG23) -> 54.96
B24: 计划值 | C24: =C185 -> 0 | D24: =D185 -> 0 | E24: =E185 -> 0 | F24: =F185 -> 0 | G24: =G185 -> 0 | H24: =H185 -> 0 | I24: =I185 -> 0 | J24: =J185 -> 0 | ... AG24: =AG185 -> 0 | AH24: =SUM(C24:AG24) -> 0
B25: 与计划差值 | C25: =C186 -> 0.54 | D25: =D186 -> 0.54 | E25: =E186 -> 0.54 | F25: =F186 -> 0.54 | G25: =G186 -> 0.54 | H25: =H186 -> 0.54 | I25: =I186 -> 0.48 | J25: =J186 -> 0.72 | ... AG25: =AG186 -> 0 | AH25: =SUM(C25:AG25) -> 54.96
B26: 同比差值 | C26: =C187 -> 0.06 | D26: =D187 -> 0 | E26: =E187 -> 0 | F26: =F187 -> -0.06 | G26: =G187 -> 0 | H26: =H187 -> -0.06 | I26: =I187 -> -0.06 | J26: =J187 -> 0 | ... AG26: =AG187 -> -6.19975 | AH26: =SUM(C26:AG26) -> -29.749338
A27: 综合 厂用电率 （%） | C27: =C188 -> #DIV/0! | D27: =D188 -> #DIV/0! | E27: =E188 -> #DIV/0! | F27: =F188 -> #DIV/0! | G27: =G188 -> #DIV/0! | H27: =H188 -> #DIV/0! | I27: =I188 -> #DIV/0! | J27: =J188 -> #DIV/0! | ... AF27: =AF188 -> #DIV/0! | AH27: =AH22/AH12 -> 0.0018290618
C28: =C189 -> #DIV/0! | D28: =D189 -> #DIV/0! | E28: =E189 -> #DIV/0! | F28: =F189 -> #DIV/0! | G28: =G189 -> #DIV/0! | H28: =H189 -> #DIV/0! | I28: =I189 -> #DIV/0! | J28: =J189 -> #DIV/0! | ... AG28: =AG189 -> #DIV/0! | AH28: =AH23/AH13 -> 0.0011866822
B29: 计划值 | C29: =C190 -> 0 | D29: =D190 -> 0 | E29: =E190 -> 0 | F29: =F190 -> 0 | G29: =G190 -> 0 | H29: =H190 -> 0 | I29: =I190 -> 0 | J29: =J190 -> 0 | ... AH29: =AH190 -> 0
B30: 与计划差值 | C30: =C191 -> #DIV/0! | D30: =D191 -> #DIV/0! | E30: =E191 -> #DIV/0! | F30: =F191 -> #DIV/0! | G30: =G191 -> #DIV/0! | H30: =H191 -> #DIV/0! | I30: =I191 -> #DIV/0! | J30: =J191 -> #DIV/0! | ... AG30: =AG191 -> #DIV/0! | AH30: =SUM(C30:AG30) -> #DIV/0!
B31: 同比差值 | C31: =C192 -> #DIV/0! | D31: =D192 -> #DIV/0! | E31: =E192 -> #DIV/0! | F31: =F192 -> #DIV/0! | G31: =G192 -> #DIV/0! | H31: =H192 -> #DIV/0! | I31: =I192 -> #DIV/0! | J31: =J192 -> #DIV/0! | ... AG31: =AG192 -> #DIV/0! | AH31: =SUM(C31:AG31) -> #DIV/0!
A32: 外供汽量 (吨） | C32: =C193+C432 -> 0 | D32: =D193+D432 -> 0 | E32: =E193+E432 -> 0 | F32: =F193+F432 -> 0 | G32: =G193+G432 -> 0 | H32: =H193+H432 -> 0 | I32: =I193+I432 -> 0 | J32: =J193+J432 -> 0 | ... AG32: =AG193+AG432 -> 0 | AH32: =SUM(C32:AG32) -> 0
C33: =C194 -> 0 | D33: =D194 -> 0 | E33: =E194 -> 0 | F33: =F194 -> 0 | G33: =G194 -> 0 | H33: =H194 -> 0 | I33: =I194 -> 0 | J33: =J194 -> 0 | ... AG33: =AG194 -> 0 | AH33: =SUM(C33:AG33) -> 0
B34: 计划值 | C34: =C195 -> 0 | D34: =D195 -> 0 | E34: =E195 -> 0 | F34: =F195 -> 0 | G34: =G195 -> 0 | H34: =H195 -> 0 | I34: =I195 -> 0 | J34: =J195 -> 0 | ... AG34: =AG195 -> 0 | AH34: =SUM(C34:AG34) -> 0
B35: 与计划差值 | C35: =C33-C34 -> 0 | D35: =D33-D34 -> 0 | E35: =E33-E34 -> 0 | F35: =F33-F34 -> 0 | G35: =G33-G34 -> 0 | H35: =H33-H34 -> 0 | I35: =I33-I34 -> 0 | J35: =J33-J34 -> 0 | ... AG35: =AG33-AG34 -> 0 | AH35: =SUM(C35:AG35) -> 0
B36: 同比差值 | C36: =C33-C32 -> 0 | D36: =D33-D32 -> 0 | E36: =E33-E32 -> 0 | F36: =F33-F32 -> 0 | G36: =G33-G32 -> 0 | H36: =H33-H32 -> 0 | I36: =I33-I32 -> 0 | J36: =J33-J32 -> 0 | ... AG36: =AG33-AG32 -> 0 | AH36: =SUM(C36:AG36) -> 0
A37: 供首站汽量 （吨） | C37: =C459+C475 -> 0 | D37: =D459+D475 -> 0 | E37: =E459+E475 -> 0 | F37: =F459+F475 -> 0 | G37: =G459+G475 -> 0 | H37: =H459+H475 -> 0 | I37: =I459+I475 -> 0 | J37: =J459+J475 -> 0 | ... AG37: =AG459+AG475 -> 0 | AH37: =SUM(C37:AG37) -> 0
C40: =C460+C476 -> 0 | D40: =D460+D476 -> 0 | E40: =E460+E476 -> 0 | F40: =F460+F476 -> 0 | G40: =G460+G476 -> 0 | H40: =H460+H476 -> 0 | I40: =I460+I476 -> 0 | J40: =J460+J476 -> 0 | ... AG40: =AG460+AG476 -> 0 | AH40: =SUM(C40:AG40) -> 0
B41: 同比差值 | C41: =C40-C37 -> 0 | D41: =D40-D37 -> 0 | E41: =E40-E37 -> 0 | F41: =F40-F37 -> 0 | G41: =G40-G37 -> 0 | H41: =H40-H37 -> 0 | I41: =I40-I37 -> 0 | J41: =J40-J37 -> 0 | ... AG41: =AG40-AG37 -> 0 | AH41: =SUM(C41:AG41) -> 0
A42: 天然气炉 供汽量 （吨） | C42: =C432 -> 0 | D42: =D432 -> 0 | E42: =E432 -> 0 | F42: =F432 -> 0 | G42: =G432 -> 0 | H42: =H432 -> 0 | I42: =I432 -> 0 | J42: =J432 -> 0 | ... AG42: =AG432 -> 0 | AH42: =SUM(C42:AG42) -> 0
...

Sheet 2026.11
A1: 生产指标 | B1: 统计时间 | C1: 46327 | D1: 46328 | E1: 46329 | F1: 46330 | G1: 46331 | H1: 46332 | I1: 46333 | J1: 46334 | K1: 46335 | L1: 46336 | M1: 46337 | N1: 46338 | O1: 46339 | P1: 46340 | Q1: 46341 | R1: 46342 | S1: 46343 | T1: 46344 | U1: 46345 | V1: 46346 | W1: 46347 | X1: 46348 | Y1: 46349 | Z1: 46350 | AA1: 46351 | AB1: 46352 | AC1: 46353 | AD1: 46354 | AE1: 46355 | AF1: 46356 | AG1: 46357 | AJ1: E | AU1: =U129 -> 0
A2: 天气 | B2: 2025 当日最低温度 | C2: 4 | D2: 3 | E2: 3 | F2: 12 | G2: 12 | H2: 9 | I2: 9 | J2: 11 | K2: 5 | L2: -4 | M2: -5 | N2: 0 | O2: 7 | P2: -1 | Q2: 7 | R2: 2 | S2: 2 | T2: 2 | U2: 2 | V2: 4 | W2: 9 | X2: 8 | Y2: 7 | Z2: 0 | AA2: 1 | AB2: 0 | AC2: 0 | AD2: 4 | AE2: 5 | AF2: -1
B3: 2025 当日最高温度 | C3: 16 | D3: 8 | E3: 13 | F3: 16 | G3: 16 | H3: 16 | I3: 16 | J3: 16 | K3: 13 | L3: 15 | M3: 13 | N3: 18 | O3: 13 | P3: 12 | Q3: 17 | R3: 13 | S3: 4 | T3: 6 | U3: 13 | V3: 11 | W3: 15 | X3: 14 | Y3: 14 | Z3: 12 | AA3: 7 | AB3: 11 | AC3: 6 | AD3: 12 | AE3: 13 | AF3: 13
B4: 2025 气象 | C4: 晴 西北风5级 | D4: 晴 北风5级 | E4: 晴 南风4级 | F4: 晴 南风3级 | G4: 多云转晴 西风3级 | H4: 多云转晴 西风3级 | I4: 多云转阴 西风3级 | J4: 多云转晴 西风4级 | K4: 雾 西北风5级 | L4: 晴 西风3级 | M4: 晴 南风2级 | N4: 雾转晴 西风4级 | O4: 晴 北风4级 | P4: 晴 东南风2级 | Q4: 晴转多云 西南风3级 | R4: 晴 西北风5级 | S4: 阴 西北风5级 | T4: 晴 西北风5级 | U4: 晴 西南风2级 | V4: 晴 北风4级 | W4: 晴 西南风4级 | X4: 霾 西南风4级 | Y4: 多云 北风5级 | Z4: 阴转雨夹雪 北风5级 | AA4: 晴 北风5级 | AB4: 多云转阴 西南风5级 | AC4: 晴 北风5级 | AD4: 晴 南风5级 | AE4: 晴 南风5级 | AF4: 多云转晴 西北风5级
B5: 2026 当日最低温度
B6: 2026 当日最高温度
B7: 2026 气象
A8: 汇总
A9: 运行方式 炉/机 | Q9: 轻度雾霾转阴 | R9: 24℃ | S9: 14℃ | T9: 西北风1级 | AU9: =AO155 -> 0
Q10: 多云 | R10: 21℃ | S10: 16℃ | T10: 东南风3级 | AU10: =U147 -> 0.952076
B11: 计划 | Q11: 阴偶有小雨转大雨 | R11: 23℃ | S11: 15℃ | T11: 南风5级 | AU11: =AO147 -> 0
A12: 发电量 （万千万时) | C12: =C173 -> 2.016 | D12: =D173 -> 20.448 | E12: =E173 -> 49.728 | F12: =F173 -> 47.28 | G12: =G173 -> 46.992 | H12: =H173 -> 53.76 | I12: =I173 -> 48.384 | J12: =J173 -> 77.376 | ... O12: =O173 -> 111.792 | Q12: 阴转多云 | R12: 21℃ | S12: 13℃ | T12: 东北风2级 | U12: =U173 -> 116.448 | V12: =V173 -> 117.744 | W12: =W173 -> 129.648 | X12: =X173 -> 128.832 | Y12: =Y173 -> 127.344 | Z12: =Z173 -> 140.064 | AA12: =AA173 -> 180.24 | AB12: =AB173 -> 169.872 | ... AG12: =AG173 -> 0 | AH12: =SUM(C12:AG12) -> 2633.664 | AU12: =U186 -> 1.74
C13: =C174 -> 0 | D13: =D174 -> 0 | E13: =E174 -> 0 | F13: =F174 -> 0 | G13: =G174 -> 0 | H13: =H174 -> 0 | I13: =I174 -> 0 | J13: =J174 -> 0 | ... O13: =O174 -> 0 | Q13: 阴 | R13: 20℃ | S13: 13℃ | T13: 东风1级 | U13: =U174 -> 0 | V13: =V174 -> 0 | W13: =W174 -> 0 | X13: =X174 -> 0 | Y13: =Y174 -> 0 | Z13: =Z174 -> 0 | AA13: =AA174 -> 0 | AB13: =AB174 -> 0 | ... AG13: =AG174 -> 0 | AH13: =SUM(C13:AG13) -> 0 | AU13: =AO188 -> 0
B14: 计划值 | C14: =C175 -> 0 | D14: =D175 -> 0 | E14: =E175 -> 0 | F14: =F175 -> 0 | G14: =G175 -> 0 | H14: =H175 -> 0 | I14: =I175 -> 0 | J14: =J175 -> 0 | ... AG14: =AG175 -> 0 | AH14: =SUM(C14:AG14) -> 0 | AU14: =U181 -> 0
B15: 与计划差值 | C15: =C176 -> 0 | D15: =D176 -> 0 | E15: =E176 -> 0 | F15: =F176 -> 0 | G15: =G176 -> 0 | H15: =H176 -> 0 | I15: =I176 -> 0 | J15: =J176 -> 0 | ... AG15: =AG176 -> 0 | AH15: =SUM(C15:AG15) -> 0 | AU15: =AO181 -> 0
B16: 同比差值 | C16: =C177 -> -2.016 | D16: =D177 -> -20.448 | E16: =E177 -> -49.728 | F16: =F177 -> -47.28 | G16: =G177 -> -46.992 | H16: =H177 -> -53.76 | I16: =I177 -> -48.384 | J16: =J177 -> -77.376 | ... AG16: =AG177 -> 0 | AH16: =SUM(C16:AG16) -> -3339.792 | AU16: =U189 -> #DIV/0!
A17: 上网供电量 （万千万时) | C17: =C178 -> 1.6371 | D17: =D178 -> 13.9574 | E17: =E178 -> 32.7096 | F17: =F178 -> 28.512 | G17: =G178 -> 18.216 | H17: =H178 -> 23.6016 | I17: =I178 -> 17.8525 | J17: =J178 -> 44.2728 | ... AG17: =AG178 -> 0 | AH17: =SUM(C17:AG17) -> 2257.9374 | AU17: =AO191 -> 0
C18: =C179 -> 0 | D18: =D179 -> 0 | E18: =E179 -> 0 | F18: =F179 -> 0 | G18: =G179 -> 0 | H18: =H179 -> 0 | I18: =I179 -> 0 | J18: =J179 -> 0 | ... AG18: =AG179 -> 0 | AH18: =SUM(C18:AG18) -> 0 | AU18: =U192 -> #DIV/0!
B19: 计划值 | C19: =C180 -> 0 | D19: =D180 -> 0 | E19: =E180 -> 0 | F19: =F180 -> 0 | G19: =G180 -> 0 | H19: =H180 -> 0 | I19: =I180 -> 0 | J19: =J180 -> 0 | ... AG19: =AG180 -> 0 | AH19: =SUM(C19:AG19) -> 0 | AU19: =AO194 -> 0
B20: 与计划差值 | C20: =C181 -> 0 | D20: =D181 -> 0 | E20: =E181 -> 0 | F20: =F181 -> 0 | G20: =G181 -> 0 | H20: =H181 -> 0 | I20: =I181 -> 0 | J20: =J181 -> 0 | ... AG20: =AG181 -> 0 | AH20: =SUM(C20:AG20) -> 0 | AU20: =AU2/((AU4-AU21)*U137/1000) -> #DIV/0!
B21: 同比差值 | C21: =C182 -> -1.6371 | D21: =D182 -> -13.9574 | E21: =E182 -> -32.7096 | F21: =F182 -> -28.512 | G21: =G182 -> -18.216 | H21: =H182 -> -23.6016 | I21: =I182 -> -17.8525 | J21: =J182 -> -44.2728 | ... AG21: =AG182 -> 0 | AH21: =SUM(C21:AG21) -> -2257.9374 | AU21: =U300 -> 0
A22: 综合厂 用电量 （万千万时) | C22: =C183 -> 0 | D22: =D183 -> 0 | E22: =E183 -> 0 | F22: =F183 -> 0 | G22: =G183 -> 0 | H22: =H183 -> 0 | I22: =I183 -> 0 | J22: =J183 -> 0 | ... AG22: =AG183 -> 0 | AH22: =SUM(C22:AG22) -> 0
C23: =C184 -> 0 | D23: =D184 -> 0 | E23: =E184 -> 0 | F23: =F184 -> 0 | G23: =G184 -> 0 | H23: =H184 -> 0 | I23: =I184 -> 0 | J23: =J184 -> 0 | ... AG23: =AG184 -> 0 | AH23: =SUM(C23:AG23) -> 43.86
B24: 计划值 | C24: =C185 -> 0 | D24: =D185 -> 0 | E24: =E185 -> 0 | F24: =F185 -> 0 | G24: =G185 -> 0 | H24: =H185 -> 0 | I24: =I185 -> 0 | J24: =J185 -> 0 | ... AG24: =AG185 -> 0 | AH24: =SUM(C24:AG24) -> 0
B25: 与计划差值 | C25: =C186 -> 0 | D25: =D186 -> 0 | E25: =E186 -> 0 | F25: =F186 -> 0 | G25: =G186 -> 0 | H25: =H186 -> 0 | I25: =I186 -> 0 | J25: =J186 -> 0 | ... AG25: =AG186 -> 0 | AH25: =SUM(C25:AG25) -> 43.86
B26: 同比差值 | C26: =C187 -> 0 | D26: =D187 -> 0 | E26: =E187 -> 0 | F26: =F187 -> 0 | G26: =G187 -> 0 | H26: =H187 -> 0 | I26: =I187 -> 0 | J26: =J187 -> 0 | ... AG26: =AG187 -> 0 | AH26: =SUM(C26:AG26) -> 43.86
A27: 综合 厂用电率 （%） | C27: =C188 -> 0 | D27: =D188 -> 0 | E27: =E188 -> 0 | F27: =F188 -> 0 | G27: =G188 -> 0 | H27: =H188 -> 0 | I27: =I188 -> 0 | J27: =J188 -> 0 | ... AF27: =AF188 -> 0 | AH27: =AH22/AH12 -> 0
C28: =C189 -> #DIV/0! | D28: =D189 -> #DIV/0! | E28: =E189 -> #DIV/0! | F28: =F189 -> #DIV/0! | G28: =G189 -> #DIV/0! | H28: =H189 -> #DIV/0! | I28: =I189 -> #DIV/0! | J28: =J189 -> #DIV/0! | ... AG28: =AG189 -> #DIV/0! | AH28: =AH23/AH13 -> #DIV/0!
B29: 计划值 | C29: =C190 -> 0 | D29: =D190 -> 0 | E29: =E190 -> 0 | F29: =F190 -> 0 | G29: =G190 -> 0 | H29: =H190 -> 0 | I29: =I190 -> 0 | J29: =J190 -> 0 | ... AH29: =AH190 -> 0
B30: 与计划差值 | C30: =C191 -> #DIV/0! | D30: =D191 -> #DIV/0! | E30: =E191 -> #DIV/0! | F30: =F191 -> #DIV/0! | G30: =G191 -> #DIV/0! | H30: =H191 -> #DIV/0! | I30: =I191 -> #DIV/0! | J30: =J191 -> #DIV/0! | ... AG30: =AG191 -> #DIV/0! | AH30: =SUM(C30:AG30) -> #DIV/0!
B31: 同比差值 | C31: =C192 -> #DIV/0! | D31: =D192 -> #DIV/0! | E31: =E192 -> #DIV/0! | F31: =F192 -> #DIV/0! | G31: =G192 -> #DIV/0! | H31: =H192 -> #DIV/0! | I31: =I192 -> #DIV/0! | J31: =J192 -> #DIV/0! | ... AG31: =AG192 -> #DIV/0! | AH31: =SUM(C31:AG31) -> #DIV/0!
A32: 外供汽量 (吨） | C32: =C193+C432 -> 0 | D32: =D193+D432 -> 0 | E32: =E193+E432 -> 0 | F32: =F193+F432 -> 0 | G32: =G193+G432 -> 0 | H32: =H193+H432 -> 0 | I32: =I193+I432 -> 0 | J32: =J193+J432 -> 0 | ... AG32: =AG193+AG432 -> 0 | AH32: =SUM(C32:AG32) -> 10162.8
C33: =C194 -> 0 | D33: =D194 -> 0 | E33: =E194 -> 0 | F33: =F194 -> 0 | G33: =G194 -> 0 | H33: =H194 -> 0 | I33: =I194 -> 0 | J33: =J194 -> 0 | ... AG33: =AG194 -> 0 | AH33: =SUM(C33:AG33) -> 0
B34: 计划值 | C34: =C195 -> 0 | D34: =D195 -> 0 | E34: =E195 -> 0 | F34: =F195 -> 0 | G34: =G195 -> 0 | H34: =H195 -> 0 | I34: =I195 -> 0 | J34: =J195 -> 0 | ... AG34: =AG195 -> 0 | AH34: =SUM(C34:AG34) -> 0
B35: 与计划差值 | C35: =C33-C34 -> 0 | D35: =D33-D34 -> 0 | E35: =E33-E34 -> 0 | F35: =F33-F34 -> 0 | G35: =G33-G34 -> 0 | H35: =H33-H34 -> 0 | I35: =I33-I34 -> 0 | J35: =J33-J34 -> 0 | ... AG35: =AG33-AG34 -> 0 | AH35: =SUM(C35:AG35) -> 0
B36: 同比差值 | C36: =C33-C32 -> 0 | D36: =D33-D32 -> 0 | E36: =E33-E32 -> 0 | F36: =F33-F32 -> 0 | G36: =G33-G32 -> 0 | H36: =H33-H32 -> 0 | I36: =I33-I32 -> 0 | J36: =J33-J32 -> 0 | ... AG36: =AG33-AG32 -> 0 | AH36: =SUM(C36:AG36) -> -10162.8
A37: 供首站汽量 （吨） | C37: =C459+C475 -> 826 | D37: =D459+D475 -> 3008 | E37: =E459+E475 -> 3068 | F37: =F459+F475 -> 2806 | G37: =G459+G475 -> 3000 | H37: =H459+H475 -> 4897 | I37: =I459+I475 -> 2914 | J37: =J459+J475 -> 1149 | ... AG37: =AG459+AG475 -> 0 | AH37: =SUM(C37:AG37) -> 137945
C40: =C460+C476 -> 0 | D40: =D460+D476 -> 0 | E40: =E460+E476 -> 0 | F40: =F460+F476 -> 0 | G40: =G460+G476 -> 0 | H40: =H460+H476 -> 0 | I40: =I460+I476 -> 0 | J40: =J460+J476 -> 0 | ... AG40: =AG460+AG476 -> 0 | AH40: =SUM(C40:AG40) -> 0
B41: 同比差值 | C41: =C40-C37 -> -826 | D41: =D40-D37 -> -3008 | E41: =E40-E37 -> -3068 | F41: =F40-F37 -> -2806 | G41: =G40-G37 -> -3000 | H41: =H40-H37 -> -4897 | I41: =I40-I37 -> -2914 | J41: =J40-J37 -> -1149 | ... AG41: =AG40-AG37 -> 0 | AH41: =SUM(C41:AG41) -> -137945
A42: 天然气炉 供汽量 （吨） | C42: =C432 -> 0 | D42: =D432 -> 0 | E42: =E432 -> 0 | F42: =F432 -> 0 | G42: =G432 -> 0 | H42: =H432 -> 0 | I42: =I432 -> 0 | J42: =J432 -> 0 | ... AG42: =AG432 -> 0 | AH42: =SUM(C42:AG42) -> 0
...

Sheet Sheet2
A1: 生产指标 | B1: 统计时间 | C1: 45962 | D1: 45963 | E1: 45964 | F1: 45965 | G1: 45966 | H1: 45967 | I1: 45968 | J1: 45969 | K1: 45970 | L1: 45971 | M1: 45972 | N1: 45973 | O1: 45974 | P1: 45975 | Q1: 45976 | R1: 45977 | S1: 45978 | T1: 45979 | U1: 45980 | V1: 45981 | W1: 45982 | X1: 45983 | Y1: 45984 | Z1: 45985 | AA1: 45986 | AB1: 45987 | AC1: 45988 | AD1: 45989 | AE1: 45990 | AF1: 45991 | AI1: 45991 | AU1: =U129 -> 0
A2: 天气 | B2: 2024 当日最低温度 | C2: 15 | D2: 15 | E2: 7 | F2: 4 | G2: 4 | H2: 4 | I2: 12 | J2: 12 | K2: 12 | L2: 12 | M2: 12 | N2: 9 | O2: 10 | P2: 12 | Q2: 13 | R2: 5 | S2: 2 | T2: 0 | U2: 4 | V2: 8 | W2: 3 | X2: 1 | Y2: 1 | Z2: 7 | AA2: 6 | AB2: 0 | AC2: -1 | AD2: 1 | AE2: 2 | AF2: 5
B3: 2024 当日最高温度 | C3: 19 | D3: 19 | E3: 20 | F3: 9 | G3: 12 | H3: 10 | I3: 16 | J3: 14 | K3: 16 | L3: 17 | M3: 17 | N3: 13 | O3: 15 | P3: 16 | Q3: 15 | R3: 15 | S3: 7 | T3: 5 | U3: 11 | V3: 13 | W3: 12 | X3: 7 | Y3: 7 | Z3: 11 | AA3: 12 | AB3: 5 | AC3: 2 | AD3: 3 | AE3: 8 | AF3: 10
B4: 2024 气象 | C4: 小雨转晴 西南风2级 | D4: 多云 南风3级 | E4: 多云转晴西北风5-6级 | F4: 多云转晴西北风3级 | G4: 晴 北风5级 | H4: 多云 北风4级 | I4: 晴 微风 | J4: 多云 西南风2级 | K4: 多云 西南风4级 | L4: 阴 西南风4级 | M4: 晴 西风2级 | N4: 多云 西南风3级 | O4: 多云 西南风3级 | P4: 小雨 西南风3级 | Q4: 雾 东北风4级 | R4: 小雨 西南风3级 | S4: 晴 东北风4级 | T4: 晴 东北风5级 | U4: 多云 西南风3级 | V4: 多云 西风2级 | W4: 晴 西北风3级 | X4: 晴 北风4级 | Y4: 晴 东北风3级 | Z4: 多云 南风3级 | AA4: 中雨 西北风5级 | AB4: 小雪转阴 西北风6级 | AC4: 多云 西北风6级 | AD4: 多云 西北风7级 | AE4: 多云 西北风6级 | AF4: 晴转多云 西北风4级
B5: 2025 当日最低温度 | C5: 4 | D5: 3 | E5: 3 | F5: 12 | G5: 12 | H5: 9 | I5: 9 | J5: 11 | K5: 5 | L5: -4 | M5: -5 | N5: 0 | O5: 7 | P5: -1 | Q5: 7 | R5: 2 | S5: 2 | T5: 2 | U5: 2 | V5: 4 | W5: 9 | X5: 8 | Y5: 7 | Z5: 0 | AA5: 1 | AB5: 0 | AC5: 0 | AD5: 4 | AE5: 5 | AF5: -1
B6: 2025 当日最高温度 | C6: 16 | D6: 8 | E6: 13 | F6: 16 | G6: 16 | H6: 16 | I6: 16 | J6: 16 | K6: 13 | L6: 15 | M6: 13 | N6: 18 | O6: 13 | P6: 12 | Q6: 17 | R6: 13 | S6: 4 | T6: 6 | U6: 13 | V6: 11 | W6: 15 | X6: 14 | Y6: 14 | Z6: 12 | AA6: 7 | AB6: 11 | AC6: 6 | AD6: 12 | AE6: 13 | AF6: 13
B7: 2025 气象 | C7: 晴 西北风5级 | D7: 晴 北风5级 | E7: 晴 南风4级 | F7: 晴 南风3级 | G7: 多云转晴 西风3级 | H7: 多云转晴 西风3级 | I7: 多云转阴 西风3级 | J7: 多云转晴 西风4级 | K7: 雾 西北风5级 | L7: 晴 西风3级 | M7: 晴 南风2级 | N7: 雾转晴 西风4级 | O7: 晴 北风4级 | P7: 晴 东南风2级 | Q7: 晴转多云 西南风3级 | R7: 晴 西北风5级 | S7: 阴 西北风5级 | T7: 晴 西北风5级 | U7: 晴 西南风2级 | V7: 晴 北风4级 | W7: 晴 西南风4级 | X7: 霾 西南风4级 | Y7: 多云 北风5级 | Z7: 阴转雨夹雪 北风5级 | AA7: 晴 北风5级 | AB7: 多云转阴 西南风5级 | AC7: 晴 北风5级 | AD7: 晴 南风5级 | AE7: 晴 南风5级 | AF7: 多云转晴 西北风5级
A8: 汇总
A9: 运行方式 炉/机 | AU9: =AO155 -> 0
AU10: =U147 -> 87.013182
B11: 计划 | AU11: =AO147 -> 0
A12: 发电量 （万千万时) | C12: =C173 -> 12.672 | D12: =D173 -> 62.496 | E12: =E173 -> 76.896 | F12: =F173 -> 122.112 | G12: =G173 -> 118.128 | H12: =H173 -> 115.152 | I12: =I173 -> 117.216 | J12: =J173 -> 114.576 | ... AG12: =AG173 -> 0 | AH12: =SUM(C12:AG12) -> 3431.241 | AU12: =U186 -> 3.7502425
C13: =C174 -> 2.016 | D13: =D174 -> 20.448 | E13: =E174 -> 49.728 | F13: =F174 -> 47.28 | G13: =G174 -> 46.992 | H13: =H174 -> 53.76 | I13: =I174 -> 48.384 | J13: =J174 -> 77.376 | ... AG13: =AG174 -> 0 | AH13: =SUM(C13:AG13) -> 3339.792 | AU13: =AO188 -> 18072.864
B14: 计划值 | C14: =C175 -> 47.170418 | D14: =D175 -> 60.449039 | E14: =E175 -> 81.4255 | F14: =F175 -> 126.42248 | G14: =G175 -> 119.16309 | H14: =H175 -> 123.12162 | I14: =I175 -> 103.34149 | J14: =J175 -> 63.605843 | ... AG14: =AG175 -> 0 | AH14: =SUM(C14:AG14) -> 4378.0487 | AU14: =U181 -> -18.334663
B15: 与计划差值 | C15: =C176 -> -45.154418 | D15: =D176 -> -40.001038 | E15: =E176 -> -31.6975 | F15: =F176 -> -79.142484 | G15: =G176 -> -72.171087 | H15: =H176 -> -69.36162 | I15: =I176 -> -54.957487 | J15: =J176 -> 13.770157 | ... AG15: =AG176 -> 0 | AH15: =SUM(C15:AG15) -> -1038.2567 | AU15: =AO181 -> 121.776
B16: 同比差值 | C16: =C177 -> -10.656 | D16: =D177 -> -42.048 | E16: =E177 -> -27.168 | F16: =F177 -> -74.832 | G16: =G177 -> -71.136 | H16: =H177 -> -61.392 | I16: =I177 -> -68.832 | J16: =J177 -> -37.2 | ... AG16: =AG177 -> 0 | AH16: =SUM(C16:AG16) -> -91.449 | AU16: =U189 -> 0.33755153
A17: 上网供电量 （万千万时) | C17: =C178 -> 10.1376 | D17: =D178 -> 37.7784 | E17: =E178 -> 47.4408 | F17: =F178 -> 82.368 | G17: =G178 -> 79.128 | H17: =H178 -> 80.784 | I17: =I178 -> 82.8414 | J17: =J178 -> 80.6256 | ... AG17: =AG178 -> 0 | AH17: =SUM(C17:AG17) -> 2317.3974 | AU17: =AO191 -> 32771
C18: =C179 -> 1.6371 | D18: =D179 -> 13.9574 | E18: =E179 -> 32.7096 | F18: =F179 -> 28.512 | G18: =G179 -> 18.216 | H18: =H179 -> 23.6016 | I18: =I179 -> 17.8525 | J18: =J179 -> 44.2728 | ... AG18: =AG179 -> 0 | AH18: =SUM(C18:AG18) -> 2257.9374 | AU18: =U192 -> 0.017112726
B19: 计划值 | C19: =C180 -> 34.370254 | D19: =D180 -> 44.045587 | E19: =E180 -> 59.329876 | F19: =F180 -> 92.116479 | G19: =G180 -> 86.826992 | H19: =H180 -> 89.711337 | I19: =I180 -> 75.298741 | J19: =J180 -> 46.345761 | ... AG19: =AG180 -> 0 | AH19: =SUM(C19:AG19) -> 3190.0214 | AU19: =AO194 -> 2463
B20: 与计划差值 | C20: =C181 -> -32.733154 | D20: =D181 -> -30.088187 | E20: =E181 -> -26.620276 | F20: =F181 -> -63.604479 | G20: =G181 -> -68.610992 | H20: =H181 -> -66.109737 | I20: =I181 -> -57.446241 | J20: =J181 -> -2.0729611 | ... AG20: =AG181 -> 0 | AH20: =SUM(C20:AG20) -> -932.08401 | AU20: =AU2/((AU4-AU21)*U137/1000) -> #DIV/0!
B21: 同比差值 | C21: =C182 -> -8.5005 | D21: =D182 -> -23.821 | E21: =E182 -> -14.7312 | F21: =F182 -> -53.856 | G21: =G182 -> -60.912 | H21: =H182 -> -57.1824 | I21: =I182 -> -64.9889 | J21: =J182 -> -36.3528 | ... AG21: =AG182 -> 0 | AH21: =SUM(C21:AG21) -> -59.46 | AU21: =U300 -> 569.66954
A22: 综合厂 用电量 （万千万时) | C22: =C183 -> 20.8993 | D22: =D183 -> 24.7176 | E22: =E183 -> 29.4552 | F22: =F183 -> 39.744 | G22: =G183 -> 39 | H22: =H183 -> 34.368 | I22: =I183 -> 34.3746 | J22: =J183 -> 33.9504 | ... AG22: =AG183 -> 0 | AH22: =SUM(C22:AG22) -> 1132.2085
C23: =C184 -> 19.8122 | D23: =D184 -> 19.26 | E23: =E184 -> 24.091752 | F23: =F184 -> 27.217848 | G23: =G184 -> 31.751544 | H23: =H184 -> 37.31016 | I23: =I184 -> 31.43438 | J23: =J184 -> 33.1032 | ... AG23: =AG184 -> 0 | AH23: =SUM(C23:AG23) -> 1140.6107
B24: 计划值 | C24: =C185 -> 12.800165 | D24: =D185 -> 16.403451 | E24: =E185 -> 22.095624 | F24: =F185 -> 34.306005 | G24: =G185 -> 32.336095 | H24: =H185 -> 33.410283 | I24: =I185 -> 28.042746 | J24: =J185 -> 17.260081 | ... AG24: =AG185 -> 0 | AH24: =SUM(C24:AG24) -> 1188.0273
B25: 与计划差值 | C25: =C186 -> 7.0120352 | D25: =D186 -> 2.8565489 | E25: =E186 -> 1.9961283 | F25: =F186 -> -7.0881573 | G25: =G186 -> -0.58455142 | H25: =H186 -> 3.8998773 | I25: =I186 -> 3.3916342 | J25: =J186 -> 15.843119 | ... AG25: =AG186 -> 0 | AH25: =SUM(C25:AG25) -> -47.416612
B26: 同比差值 | C26: =C187 -> -1.0871 | D26: =D187 -> -5.4576 | E26: =E187 -> -5.363448 | F26: =F187 -> -12.526152 | G26: =G187 -> -7.248456 | H26: =H187 -> 2.94216 | I26: =I187 -> -2.94022 | J26: =J187 -> -0.8472 | ... AG26: =AG187 -> 0 | AH26: =SUM(C26:AG26) -> 8.402184
A27: 综合 厂用电率 （%） | C27: =C188 -> 1.6492503 | D27: =D188 -> 0.39550691 | E27: =E188 -> 0.38305243 | F27: =F188 -> 0.3254717 | G27: =G188 -> 0.33015035 | H27: =H188 -> 0.29845769 | I27: =I188 -> 0.2932586 | J27: =J188 -> 0.29631336 | ... AF27: =AF188 -> 0.3157969 | AH27: =AH22/AH12 -> 0.32997056
C28: =C189 -> 9.8274802 | D28: =D189 -> 0.94190141 | E28: =E189 -> 0.48447056 | F28: =F189 -> 0.5756736 | G28: =G189 -> 0.67567978 | H28: =H189 -> 0.69401339 | I28: =I189 -> 0.64968543 | J28: =J189 -> 0.42782258 | ... AG28: =AG189 -> #DIV/0! | AH28: =AH23/AH13 -> 0.34152147
B29: 计划值 | C29: =C190 -> 0.27136 | D29: =D190 -> 1.27136 | E29: =E190 -> 2.27136 | F29: =F190 -> 0.27136 | G29: =G190 -> 0.27136 | H29: =H190 -> 0.27136 | I29: =I190 -> 0.27136 | J29: =J190 -> 0.27136 | ... AH29: =AH190 -> 0.27136
B30: 与计划差值 | C30: =C191 -> 9.5561202 | D30: =D191 -> -0.32945859 | E30: =E191 -> -1.7868894 | F30: =F191 -> 0.3043136 | G30: =G191 -> 0.40431978 | H30: =H191 -> 0.42265339 | I30: =I191 -> 0.37832543 | J30: =J191 -> 0.15646258 | ... AG30: =AG191 -> #DIV/0! | AH30: =SUM(C30:AG30) -> #DIV/0!
B31: 同比差值 | C31: =C192 -> 8.1782298 | D31: =D192 -> 0.5463945 | E31: =E192 -> 0.10141813 | F31: =F192 -> 0.25020191 | G31: =G192 -> 0.34552943 | H31: =H192 -> 0.3955557 | I31: =I192 -> 0.35642683 | J31: =J192 -> 0.13150922 | ... AG31: =AG192 -> #DIV/0! | AH31: =SUM(C31:AG31) -> #DIV/0!
A32: 外供汽量 (吨） | C32: =C193+C432 -> 0 | D32: =D193+D432 -> 0 | E32: =E193+E432 -> 0 | F32: =F193+F432 -> 0 | G32: =G193+G432 -> 0 | H32: =H193+H432 -> 0 | I32: =I193+I432 -> 0 | J32: =J193+J432 -> 0 | ... AG32: =AG193+AG432 -> 0 | AH32: =SUM(C32:AG32) -> 9741
C33: =C194 -> 0 | D33: =D194 -> 0 | E33: =E194 -> 0 | F33: =F194 -> 0 | G33: =G194 -> 0 | H33: =H194 -> 0 | I33: =I194 -> 0 | J33: =J194 -> 0 | ... AG33: =AG194 -> 0 | AH33: =SUM(C33:AG33) -> 10162.8
B34: 计划值 | C34: =C195 -> 0 | D34: =D195 -> 0 | E34: =E195 -> 0 | F34: =F195 -> 0 | G34: =G195 -> 0 | H34: =H195 -> 0 | I34: =I195 -> 0 | J34: =J195 -> 0 | ... AG34: =AG195 -> 0 | AH34: =SUM(C34:AG34) -> 9741
B35: 与计划差值 | C35: =C33-C34 -> 0 | D35: =D33-D34 -> 0 | E35: =E33-E34 -> 0 | F35: =F33-F34 -> 0 | G35: =G33-G34 -> 0 | H35: =H33-H34 -> 0 | I35: =I33-I34 -> 0 | J35: =J33-J34 -> 0 | ... AG35: =AG33-AG34 -> 0 | AH35: =SUM(C35:AG35) -> 421.8
B36: 同比差值 | C36: =C33-C32 -> 0 | D36: =D33-D32 -> 0 | E36: =E33-E32 -> 0 | F36: =F33-F32 -> 0 | G36: =G33-G32 -> 0 | H36: =H33-H32 -> 0 | I36: =I33-I32 -> 0 | J36: =J33-J32 -> 0 | ... AG36: =AG33-AG32 -> 0 | AH36: =SUM(C36:AG36) -> 421.8
A37: 供首站汽量 （吨） | C37: =C459+C475 -> 950 | D37: =D459+D475 -> 1712 | E37: =E459+E475 -> 2227 | F37: =F459+F475 -> 4469 | G37: =G459+G475 -> 4824 | H37: =H459+H475 -> 4437 | I37: =I459+I475 -> 5382 | J37: =J459+J475 -> 5314 | ... AG37: =AG459+AG475 -> 0 | AH37: =SUM(C37:AG37) -> 138239
C40: =C460+C476 -> 826 | D40: =D460+D476 -> 3008 | E40: =E460+E476 -> 3068 | F40: =F460+F476 -> 2806 | G40: =G460+G476 -> 3000 | H40: =H460+H476 -> 4897 | I40: =I460+I476 -> 2914 | J40: =J460+J476 -> 1149 | ... AG40: =AG460+AG476 -> 0 | AH40: =SUM(C40:AG40) -> 137945
B41: 同比差值 | C41: =C40-C37 -> -124 | D41: =D40-D37 -> 1296 | E41: =E40-E37 -> 841 | F41: =F40-F37 -> -1663 | G41: =G40-G37 -> -1824 | H41: =H40-H37 -> 460 | I41: =I40-I37 -> -2468 | J41: =J40-J37 -> -4165 | ... AG41: =AG40-AG37 -> 0 | AH41: =SUM(C41:AG41) -> -294
A42: 天然气炉 供汽量 （吨） | C42: =C432 -> 0 | D42: =D432 -> 0 | E42: =E432 -> 0 | F42: =F432 -> 0 | G42: =G432 -> 0 | H42: =H432 -> 0 | I42: =I432 -> 0 | J42: =J432 -> 0 | ... AG42: =AG432 -> 0 | AH42: =SUM(C42:AG42) -> 0
...
