Workbook

Sheet 全口径
A1: 指标 类别 | B1: 项 目 | C1: 计量单位 | D1: 本年计划 | E1: 本月计划 | F1: 上年同期 | G1: 本月实际 | H1: 本年累计 | I1: 年计划 完成率 | J1: 与月计划比较 | L1: 与上年同期比较
J2: 差异 | K2: ±% | L2: 差异 | M2: ±%
A3: 产品 销量 | B3: 售电量 | C3: 万千瓦时 | D3: =北海!D4+香海!D4+金州!D4+北方!D4 -> 0 | E3: =北海!E4+香海!E4+金州!E4+北方!E4 -> 12130 | F3: =[3]全口径!$G$3 -> 10723.867 | G3: =北海!G4+香海!G4+金州!G4+北方!G4 -> 10507.694 | H3: =北海!H4+香海!H4+金州!H4+北方!H4 -> 10507.694 | I3: =IFERROR(H3/D3,"-") -> - | J3: =IFERROR(G3-E3,"-") -> -1622.3056 | K3: =IFERROR(J3/E3,"-") -> -0.13374325 | L3: =IFERROR(G3-F3,"-") -> -216.1725 | M3: =IFERROR(L3/F3,"-") -> -0.020158074
B4: 售汽量 | C4: 吨 | D4: =主城区!D9 -> 0 | E4: =主城区!E9 -> 51000 | F4: =[3]全口径!$G$4 -> 48270 | G4: =[5]售热量!$D$27 -> 55460 | H4: =[5]售热量!$D$27 -> 55460 | I4: =IFERROR(H4/D4,"-") -> - | J4: =IFERROR(G4-E4,"-") -> 4460 | K4: =IFERROR(J4/E4,"-") -> 0.08745098 | L4: =IFERROR(G4-F4,"-") -> 7190 | M4: =IFERROR(L4/F4,"-") -> 0.1489538
B5: 高温水销售量 | C5: 吉焦 | D5: =主城区!D10+金州!D7+北方!D6+金普!D8 -> 0 | E5: =主城区!E10+金州!E7+北方!E6+金普!E8 -> 448469.7 | F5: =[3]全口径!$G$5 -> 431877 | G5: =[5]售热量!$D$28 -> 493498.5 | H5: =[5]售热量!$D$28 -> 493498.5 | I5: =IFERROR(H5/D5,"-") -> - | J5: =IFERROR(G5-E5,"-") -> 45028.8 | K5: =IFERROR(J5/E5,"-") -> 0.10040545 | L5: =IFERROR(G5-F5,"-") -> 61621.5 | M5: =IFERROR(L5/F5,"-") -> 0.14268299
B6: 期末供暖收费面积 | C6: 平方米 | D6: =主城区!D11+金州!D8+北方!D7+金普!D4-金普!D5+庄河!D4+研究院!D4 -> 0 | E6: =主城区!E11+金州!E8+北方!E7+金普!E4-金普!E5+庄河!E4+研究院!E4 -> 36675854 | F6: =主城区!F11+金州!F8+北方!F7+金普!F4-金普!F5+庄河!F4+研究院!F4 -> 35851865 | G6: =H6 -> 36379778 | H6: =主城区!H11+金州!H8+北方!H7+金普!H4-金普!H5+庄河!H4+研究院!H4 -> 36379778 | I6: =IFERROR(H6/D6,"-") -> - | J6: =IFERROR(G6-E6,"-") -> -296076.46 | K6: =IFERROR(J6/E6,"-") -> -0.0080727898 | L6: =IFERROR(G6-F6,"-") -> 527912.37 | M6: =IFERROR(L6/F6,"-") -> 0.014724823
A7: 产品 产量 | B7: 发电量 | C7: 万千瓦时 | D7: =北海!D3+香海!D3+金州!D3+北方!D3 -> 0 | E7: =北海!E3+香海!E3+金州!E3+北方!E3 -> 16952 | F7: =[3]全口径!$G$7 -> 15044.43 | G7: =北海!G3+香海!G3+金州!G3+北方!G3 -> 15642.442 | H7: =北海!H3+香海!H3+金州!H3+北方!H3 -> 15642.442 | I7: =IFERROR(H7/D7,"-") -> - | J7: =IFERROR(G7-E7,"-") -> -1309.558 | K7: =IFERROR(J7/E7,"-") -> -0.077250944 | L7: =IFERROR(G7-F7,"-") -> 598.012 | M7: =IFERROR(L7/F7,"-") -> 0.039749728
B8: 供热量 | C8: 吉焦 | D8: =主城区!D6+金州!D5+北方!D5+金普!D7+庄河!D6+研究院!D6 -> 0 | E8: =主城区!E6+金州!E5+北方!E5+金普!E7+庄河!E6+研究院!E6 -> 3506609.2 | F8: =[3]全口径!$G$8 -> 3363790.3 | G8: =北海!G6+北海水炉!G4+香海!G6+金州!G5+北方!G5+金普!G7+庄河!G6+研究院!G6+主城区电锅炉!G6+天然气炉!D5+天然气炉!E5 -> 3972697.2 | H8: =北海!H6+北海水炉!H4+香海!H6+金州!H5+北方!H5+金普!H7+庄河!H6+研究院!H6+主城区电锅炉!H6+天然气炉!F5+天然气炉!G5 -> 3972697.2 | I8: =IFERROR(H8/D8,"-") -> - | J8: =IFERROR(G8-E8,"-") -> 466088.04 | K8: =IFERROR(J8/E8,"-") -> 0.13291702 | L8: =IFERROR(G8-F8,"-") -> 608906.89 | M8: =IFERROR(L8/F8,"-") -> 0.18101808
B9: 其中：低真空供热量 | C9: 吉焦 | D9: =香海!D7+金州!D6 -> 0 | E9: =香海!E7+金州!E6 -> 325082 | F9: =[3]全口径!$G$9 -> 320756 | G9: =香海!G7+金州!G6 -> 377963 | H9: =香海!H7+金州!H6 -> 377963 | I9: =IFERROR(H9/D9,"-") -> - | J9: =IFERROR(G9-E9,"-") -> 52881 | K9: =IFERROR(J9/E9,"-") -> 0.16266973 | L9: =IFERROR(G9-F9,"-") -> 57207 | M9: =IFERROR(L9/F9,"-") -> 0.17835052
B10: 高温水网供热量 | C10: 吉焦 | D10: =北海!D7+北海水炉!D4+香海!D8+金州!D5-金州!D6+北方!D5 -> 0 | E10: =北海!E7+北海水炉!E4+香海!E8+金州!E5-金州!E6+北方!E5 -> 2555674 | F10: =[3]全口径!$G$10 -> 2375894.5 | G10: =北海!G7+北海水炉!G4+香海!G8+金州!G5-金州!G6+北方!G5 -> 2837808.7 | H10: =北海!H7+北海水炉!H4+香海!H8+金州!H5-金州!H6+北方!H5 -> 2837808.7 | I10: =IFERROR(H10/D10,"-") -> - | J10: =IFERROR(G10-E10,"-") -> 282134.72 | K10: =IFERROR(J10/E10,"-") -> 0.11039543 | L10: =IFERROR(G10-F10,"-") -> 461914.26 | M10: =IFERROR(L10/F10,"-") -> 0.19441699
B11: 供汽量 | C11: 吨 | D11: =主城区!D5 -> 0 | E11: =主城区!E5 -> 94011 | F11: =[3]全口径!$G$11 -> 93850 | G11: =北海!G5+香海!G5+天然气炉!D4+天然气炉!E4 -> 113333 | H11: =北海!H5+香海!H5+天然气炉!F4+天然气炉!G4 -> 113333 | I11: =IFERROR(H11/D11,"-") -> - | J11: =IFERROR(G11-E11,"-") -> 19322 | K11: =IFERROR(J11/E11,"-") -> 0.20552914 | L11: =IFERROR(G11-F11,"-") -> 19483 | M11: =IFERROR(L11/F11,"-") -> 0.20759723
A12: 主要物料消耗量 | B12: 生产耗原煤量 | C12: 吨 | D12: =北海!D12+北海水炉!D5+香海!D13+金州!D13+北方!D12+金普!D9+庄河!D8 -> 0 | E12: =北海!E12+北海水炉!E5+香海!E13+金州!E13+北方!E12+金普!E9+庄河!E8 -> 230508.17 | F12: =[3]全口径!$G$12 -> 232266.77 | G12: =北海!G12+北海水炉!G5+香海!G13+金州!G13+北方!G12+金普!G9+庄河!G8 -> 257483.19 | H12: =北海!H12+北海水炉!H5+香海!H13+金州!H13+北方!H12+金普!H9+庄河!H8 -> 257483.19 | I12: =IFERROR(H12/D12,"-") -> - | J12: =IFERROR(G12-E12,"-") -> 26975.018 | K12: =IFERROR(J12/E12,"-") -> 0.11702413 | L12: =IFERROR(G12-F12,"-") -> 25216.42 | M12: =IFERROR(L12/F12,"-") -> 0.10856663
B13: 锅炉耗柴油量 | C13: 吨 | D13: =主城区!D13+金州!D23+北方!D23 -> 0 | E13: =北海!E24+北海水炉!E6+香海!E23+金州!E23+北方!E23 -> 89 | F13: =[3]全口径!$G$13 -> 98.3 | G13: =北海!G24+北海水炉!G6+香海!G23+金州!G23+北方!G23 -> 117.5 | H13: =北海!H24+北海水炉!H6+香海!H23+金州!H23+北方!H23 -> 117.5 | I13: =IFERROR(H13/D13,"-") -> - | J13: =IFERROR(G13-E13,"-") -> 28.5 | K13: =IFERROR(J13/E13,"-") -> 0.32022472 | L13: =IFERROR(G13-F13,"-") -> 19.2 | M13: =IFERROR(L13/F13,"-") -> 0.19532045
B14: 耗水量 | C14: 吨 | D14: =主城区!D14+金州!D21+北方!D20+金普!D11+庄河!D10+研究院!D7 -> 0 | E14: =北海!E22+北海水炉!E9+香海!E22+供热公司!E12+金州!E21+北方!E20+金普!E11+庄河!E10+研究院!E7+主城区电锅炉!E7 -> 691983.21 | F14: =[3]全口径!$G$14 -> 810644.3 | G14: =北海!G22+北海水炉!G9+香海!G22+供热公司!G12+金州!G21+北方!G20+金普!G11+庄河!G10+研究院!G7+主城区电锅炉!G7+天然气炉!D8 -> 690103.01 | H14: =北海!H22+北海水炉!H9+香海!H22+供热公司!H12+金州!H21+北方!H20+金普!H11+庄河!H10+研究院!H7+主城区电锅炉!H7+天然气炉!F8 -> 690103.01 | I14: =IFERROR(H14/D14,"-") -> - | J14: =IFERROR(G14-E14,"-") -> -1880.1995 | K14: =IFERROR(J14/E14,"-") -> -0.0027171173 | L14: =IFERROR(G14-F14,"-") -> -120541.29 | M14: =IFERROR(L14/F14,"-") -> -0.14869813
B15: 其中：热网耗水量 | C15: 吨 | D15: =主城区!D23+金州!D22+北方!D22+金普!D11+庄河!D10+研究院!D7 -> 0 | E15: =主城区!E23+金州!E22+北方!E22+金普!E11+庄河!E10+研究院!E7 -> 325689.21 | F15: =主城区!F23+金州!F22+北方!F22+金普!F11+庄河!F10+研究院!F7 -> 419023.4 | G15: =主城区!G23+金州!G22+北方!G22+金普!G11+庄河!G10+研究院!G7 -> 336995.01 | H15: =主城区!H23+金州!H22+北方!H22+金普!H11+庄河!H10+研究院!H7 -> 336995.01 | I15: =IFERROR(H15/D15,"-") -> - | J15: =IFERROR(G15-E15,"-") -> 11305.8 | K15: =IFERROR(J15/E15,"-") -> 0.034713463 | L15: =IFERROR(G15-F15,"-") -> -82028.39 | M15: =IFERROR(L15/F15,"-") -> -0.19576088
B16: 耗井水量 | C16: 吨 | D16: =北方!D21 -> 0 | E16: =北方!E21 -> 0 | F16: =[3]全口径!$G$15 -> 21789.9 | G16: =北方!G21 -> 11538 | H16: =北方!H21 -> 11538 | I16: =IFERROR(H16/D16,"-") -> - | J16: =IFERROR(G16-E16,"-") -> 11538 | K16: =IFERROR(J16/E16,"-") -> - | L16: =IFERROR(G16-F16,"-") -> -10251.9 | M16: =IFERROR(L16/F16,"-") -> -0.47048862
B17: 耗再生水量 | C17: 吨 | D17: =北海!D23+北海水炉!D10 -> 0 | E17: =北海!E23+北海水炉!E10 -> 116709 | F17: =[3]全口径!$G$16 -> 116709 | G17: =北海!G23+北海水炉!G10 -> 121513 | H17: =北海!H23+北海水炉!H10 -> 121513 | I17: =IFERROR(H17/D17,"-") -> - | J17: =IFERROR(G17-E17,"-") -> 4804 | K17: =IFERROR(J17/E17,"-") -> 0.041162207 | L17: =IFERROR(G17-F17,"-") -> 4804 | M17: =IFERROR(L17/F17,"-") -> 0.041162207
B18: 耗酸量 | C18: 吨 | D18: =主城区!D15+金州!D15+北方!D14 -> 0 | E18: =北海!E14+香海!E15+金州!E15+北方!E14 -> 99 | F18: =[3]全口径!$G$17 -> 83.22 | G18: =北海!G14+香海!G15+金州!G15+北方!G14 -> 63.71 | H18: =北海!H14+香海!H15+金州!H15+北方!H14 -> 63.71 | I18: =IFERROR(H18/D18,"-") -> - | J18: =IFERROR(G18-E18,"-") -> -35.29 | K18: =IFERROR(J18/E18,"-") -> -0.35646465 | L18: =IFERROR(G18-F18,"-") -> -19.51 | M18: =IFERROR(L18/F18,"-") -> -0.23443884
B19: 耗碱量 | C19: 吨 | D19: =主城区!D16+金州!D14+北方!D13 -> 0 | E19: =北海!E13+香海!E14+金州!E14+北方!E13 -> 86 | F19: =[3]全口径!$G$18 -> 73.12 | G19: =北海!G13+香海!G14+金州!G14+北方!G13 -> 54 | H19: =北海!H13+香海!H14+金州!H14+北方!H13 -> 54 | I19: =IFERROR(H19/D19,"-") -> - | J19: =IFERROR(G19-E19,"-") -> -32 | K19: =IFERROR(J19/E19,"-") -> -0.37209302 | L19: =IFERROR(G19-F19,"-") -> -19.12 | M19: =IFERROR(L19/F19,"-") -> -0.26148796
B20: 耗石灰石量 | C20: 吨 | D20: =北方!D24 -> 0 | E20: =北方!E24 -> 830 | F20: =[3]全口径!$G$19 -> 837.04 | G20: =北方!G24 -> 601.88 | H20: =北方!H24 -> 601.88 | I20: =IFERROR(H20/D20,"-") -> - | J20: =IFERROR(G20-E20,"-") -> -228.12 | K20: =IFERROR(J20/E20,"-") -> -0.27484337 | L20: =IFERROR(G20-F20,"-") -> -235.16 | M20: =IFERROR(L20/F20,"-") -> -0.28094237
B21: 耗石灰石粉量 | C21: 吨 | D21: =主城区!D17+金州!D24+北方!D25 -> 0 | E21: =北海!E25+北海水炉!E16+香海!E24+金州!E24+北方!E25 -> 4858 | F21: =[3]全口径!$G$20 -> 3668.42 | G21: =北海!G25+北海水炉!G16+香海!G24+金州!G24+北方!G25 -> 4699.67 | H21: =北海!H25+北海水炉!H16+香海!H24+金州!H24+北方!H25 -> 4699.67 | I21: =IFERROR(H21/D21,"-") -> - | J21: =IFERROR(G21-E21,"-") -> -158.33 | K21: =IFERROR(J21/E21,"-") -> -0.032591601 | L21: =IFERROR(G21-F21,"-") -> 1031.25 | M21: =IFERROR(L21/F21,"-") -> 0.28111558
B22: 耗氨水量 | C22: 吨 | D22: =主城区!D18+金州!D16+北方!D15 -> 0 | E22: =北海!E15+北海水炉!E17+香海!E16+金州!E16+北方!E15 -> 1454 | F22: =[3]全口径!$G$21 -> 1446.976 | G22: =北海!G15+北海水炉!G17+香海!G16+金州!G16+北方!G15 -> 1225.813 | H22: =北海!H15+北海水炉!H17+香海!H16+金州!H16+北方!H15 -> 1225.813 | I22: =IFERROR(H22/D22,"-") -> - | J22: =IFERROR(G22-E22,"-") -> -228.187 | K22: =IFERROR(J22/E22,"-") -> -0.15693741 | L22: =IFERROR(G22-F22,"-") -> -221.163 | M22: =IFERROR(L22/F22,"-") -> -0.15284497
B23: 耗阻垢剂量 | C23: 吨 | D23: =主城区!D19+金州!D17+北方!D16 -> 0 | E23: =主城区!E19+金州!E17+北方!E16 -> 4.2 | F23: =[3]全口径!$G$22 -> 4.369 | G23: =北海!G16+香海!G17+金州!G17+北方!G16+中水!G14 -> 3.175 | H23: =北海!H16+香海!H17+金州!H17+北方!H16+中水!H14 -> 3.175 | I23: =IFERROR(H23/D23,"-") -> - | J23: =IFERROR(G23-E23,"-") -> -1.025 | K23: =IFERROR(J23/E23,"-") -> -0.24404762 | L23: =IFERROR(G23-F23,"-") -> -1.194 | M23: =IFERROR(L23/F23,"-") -> -0.27328908
B24: 耗杀菌剂量 | C24: 吨 | D24: =主城区!D20+金州!D18+北方!D17 -> 0 | E24: =主城区!E20+金州!E18+北方!E17 -> 0 | F24: =[3]全口径!$G$23 -> 0 | G24: =北海!G17+香海!G18+金州!G18+北方!G17+中水!G16 -> 0 | H24: =北海!H17+香海!H18+金州!H18+北方!H17+中水!H16 -> 0 | I24: =IFERROR(H24/D24,"-") -> - | J24: =IFERROR(G24-E24,"-") -> 0 | K24: =IFERROR(J24/E24,"-") -> - | L24: =IFERROR(G24-F24,"-") -> 0 | M24: =IFERROR(L24/F24,"-") -> -
B25: 耗钢球量 | C25: 吨 | D25: =北海!D18 -> 0 | E25: =北海!E18 -> 40 | F25: =[3]全口径!$G$24 -> 25 | G25: =北海!G18 -> 28 | H25: =北海!H18 -> 28 | I25: =IFERROR(H25/D25,"-") -> - | J25: =IFERROR(G25-E25,"-") -> -12 | K25: =IFERROR(J25/E25,"-") -> -0.3 | L25: =IFERROR(G25-F25,"-") -> 3 | M25: =IFERROR(L25/F25,"-") -> 0.12
B26: 耗氧化镁量 | C26: 吨 | D26: =金普!D13+庄河!D12 -> 0 | E26: =金普!E13+庄河!E12 -> 67.86375 | F26: =[3]全口径!$G$25 -> 218.3 | G26: =金普!G13+庄河!G12 -> 51.9 | H26: =金普!H13+庄河!H12 -> 51.9 | I26: =IFERROR(H26/D26,"-") -> - | J26: =IFERROR(G26-E26,"-") -> -15.96375 | K26: =IFERROR(J26/E26,"-") -> -0.23523236 | L26: =IFERROR(G26-F26,"-") -> -166.4 | M26: =IFERROR(L26/F26,"-") -> -0.76225378
B27: 脱硫脱硝耗水量 | C27: 吨 | D27: =主城区!D21+金州!D19+北方!D18 -> 0 | E27: =主城区!E21+金州!E19+北方!E18 -> 67419 | F27: =[3]全口径!$G$26 -> 96729 | G27: =北海!G19+北海水炉!G14+香海!G19+金州!G19+北方!G18 -> 83369 | H27: =北海!H19+北海水炉!H14+香海!H19+金州!H19+北方!H18 -> 83369 | I27: =IFERROR(H27/D27,"-") -> - | J27: =IFERROR(G27-E27,"-") -> 15950 | K27: =IFERROR(J27/E27,"-") -> 0.23658019 | L27: =IFERROR(G27-F27,"-") -> -13360 | M27: =IFERROR(L27/F27,"-") -> -0.13811783
B28: 脱硫脱硝耗电量 | C28: 千瓦时 | D28: =主城区!D22+金州!D20+北方!D19 -> 0 | E28: =主城区!E22+金州!E20+北方!E19 -> 3040000 | F28: =[3]全口径!$G$27 -> 3449610 | G28: =北海!G20+北海水炉!G15+香海!G20+金州!G20+北方!G19 -> 4301759.4 | H28: =北海!H20+北海水炉!H15+香海!H20+金州!H20+北方!H19 -> 4301759.4 | I28: =IFERROR(H28/D28,"-") -> - | J28: =IFERROR(G28-E28,"-") -> 1261759.4 | K28: =IFERROR(J28/E28,"-") -> 0.41505243 | L28: =IFERROR(G28-F28,"-") -> 852149.4 | M28: =IFERROR(L28/F28,"-") -> 0.24702775
B29: 主城区一次网电厂补水量 | C29: 吨 | D29: =主城区!D24 -> 0 | E29: =主城区!E24 -> 82300 | F29: =[3]全口径!$G$28 -> 90983 | G29: =北海!G21+香海!G21 -> 99619 | H29: =北海!H21+香海!H21 -> 99619 | I29: =IFERROR(H29/D29,"-") -> - | J29: =IFERROR(G29-E29,"-") -> 17319 | K29: =IFERROR(J29/E29,"-") -> 0.21043742 | L29: =IFERROR(G29-F29,"-") -> 8636 | M29: =IFERROR(L29/F29,"-") -> 0.094918831
B30: 供暖耗热量 | C30: 吉焦 | D30: =主城区!D25+金州!D5-金州!D7+北方!D5-北方!D6+金普!D7-金普!D8+庄河!D6+研究院!D6 -> 0 | E30: =主城区!E25+金州!E5-金州!E7+北方!E5-北方!E6+金普!E7-金普!E8+庄河!E6+研究院!E6 -> 2563891.8 | F30: =主城区!F25+金州!F5-金州!F7+北方!F5-北方!F6+金普!F7-金普!F8+庄河!F6+研究院!F6 -> 2456071.6 | G30: =主城区!G25+金州!G5-金州!G7+北方!G5-北方!G6+金普!G7-金普!G8+庄河!G6+研究院!G6 -> 2969533.3 | H30: =主城区!H25+金州!H5-金州!H7+北方!H5-北方!H6+金普!H7-金普!H8+庄河!H6+研究院!H6 -> 2969533.3 | I30: =IFERROR(H30/D30,"-") -> - | J30: =IFERROR(G30-E30,"-") -> 405641.5 | K30: =IFERROR(J30/E30,"-") -> 0.15821319 | L30: =IFERROR(G30-F30,"-") -> 513461.65 | M30: =IFERROR(L30/F30,"-") -> 0.20905809
B31: 外购电量 | C31: 万千瓦时 | D31: =北海!D26+北海水炉!D13+香海!D25+供热公司!D13+金州!D25+北方!D26+金普!D12+庄河!D11+研究院!D8+主城区电锅炉!D8 -> 0 | E31: =北海!E26+北海水炉!E13+香海!E25+供热公司!E13+金州!E25+北方!E26+金普!E12+庄河!E11+研究院!E8+主城区电锅炉!E8 -> 1550.5398 | F31: =[3]全口径!$G$29 -> 1650.9018 | G31: =北海!G26+北海水炉!G13+香海!G25+供热公司!G13+金州!G25+北方!G26+金普!G12+庄河!G11+研究院!G8+主城区电锅炉!G8 -> 1504.9236 | H31: =北海!H26+北海水炉!H13+香海!H25+供热公司!H13+金州!H25+北方!H26+金普!H12+庄河!H11+研究院!H8+主城区电锅炉!H8 -> 1504.9236 | I31: =IFERROR(H31/D31,"-") -> - | J31: =IFERROR(G31-E31,"-") -> -45.616165 | K31: =IFERROR(J31/E31,"-") -> -0.029419538 | L31: =IFERROR(G31-F31,"-") -> -145.97815 | M31: =IFERROR(L31/F31,"-") -> -0.088423281
B32: 其中：热网耗电量 | C32: 万千瓦时 | D32: =主城区!D31+金州!D26+北方!D27+金普!D12+庄河!D11+研究院!D8 -> 0 | E32: =主城区!E31+金州!E26+北方!E27+金普!E12+庄河!E11+研究院!E8 -> 1550.5398 | F32: =主城区!F31+金州!F26+北方!F27+金普!F12+庄河!F11+研究院!F8 -> 1650.9018 | G32: =主城区!G31+金州!G26+北方!G27+金普!G12+庄河!G11+研究院!G8 -> 1504.9236 | H32: =主城区!H31+金州!H26+北方!H27+金普!H12+庄河!H11+研究院!H8 -> 1504.9236 | I32: =IFERROR(H32/D32,"-") -> - | J32: =IFERROR(G32-E32,"-") -> -45.616165 | K32: =IFERROR(J32/E32,"-") -> -0.029419538 | L32: =IFERROR(G32-F32,"-") -> -145.97815 | M32: =IFERROR(L32/F32,"-") -> -0.088423281
B33: 综合厂用电量 | C33: 万千瓦时 | D33: =D7-D3 -> 0 | E33: =E7-E3 -> 4822 | F33: =[3]全口径!$G$30 -> 4320.5631 | G33: =北海!G27+香海!G26+金州!G27+北方!G28 -> 5134.7476 | H33: =北海!H27+香海!H26+金州!H27+北方!H28 -> 5134.7476 | I33: =IFERROR(H33/D33,"-") -> - | J33: =IFERROR(G33-E33,"-") -> 312.7476 | K33: =IFERROR(J33/E33,"-") -> 0.064858482 | L33: =IFERROR(G33-F33,"-") -> 814.1845 | M33: =IFERROR(L33/F33,"-") -> 0.18844407
B34: 非生产厂用电量 | C34: 万千瓦时 | D34: =D33-D35-D36 -> 0 | E34: =E33-E35-E36 -> 554.16595 | F34: =F33-F35-F36 -> 539.31038 | G34: =G33-G35-G36 -> 716.71932 | H34: =H33-H35-H36 -> 716.71932 | I34: =IFERROR(H34/D34,"-") -> - | J34: =IFERROR(G34-E34,"-") -> 162.55338 | K34: =IFERROR(J34/E34,"-") -> 0.29332978 | L34: =IFERROR(G34-F34,"-") -> 177.40895 | M34: =IFERROR(L34/F34,"-") -> 0.32895519
B35: 发电厂用电量 | C35: 万千瓦时 | D35: =北海!D29+香海!D28+金州!D28+北方!D29 -> 0 | E35: =北海!E29+香海!E28+金州!E28+北方!E29 -> 803.3236 | F35: =[3]全口径!$G$31 -> 713.11058 | G35: =北海!G29+香海!G28+金州!G28+北方!G29 -> 882.63236 | H35: =北海!H29+香海!H28+金州!H28+北方!H29 -> 882.63236 | I35: =IFERROR(H35/D35,"-") -> - | J35: =IFERROR(G35-E35,"-") -> 79.308755 | K35: =IFERROR(J35/E35,"-") -> 0.098725787 | L35: =IFERROR(G35-F35,"-") -> 169.52178 | M35: =IFERROR(L35/F35,"-") -> 0.23772159
B36: 供热厂用电量 | C36: 万千瓦时 | D36: =北海!D30+香海!D29+金州!D29+北方!D30 -> 0 | E36: =北海!E30+香海!E29+金州!E29+北方!E30 -> 3464.5105 | F36: =[3]全口径!$G$32 -> 3068.1421 | G36: =北海!G30+香海!G29+金州!G29+北方!G30 -> 3535.3959 | H36: =北海!H30+香海!H29+金州!H29+北方!H30 -> 3535.3959 | I36: =IFERROR(H36/D36,"-") -> - | J36: =IFERROR(G36-E36,"-") -> 70.885468 | K36: =IFERROR(J36/E36,"-") -> 0.020460457 | L36: =IFERROR(G36-F36,"-") -> 467.25377 | M36: =IFERROR(L36/F36,"-") -> 0.15229209
B37: 耗标煤总量 | C37: 吨 | D37: =D38+D39 -> 0 | E37: =E38+E39 -> 157994.54 | F37: =[3]全口径!$G$33 -> 157462.54 | G37: =G38+G39 -> 173491.26 | H37: =H38+H39 -> 173491.26 | I37: =IFERROR(H37/D37,"-") -> - | J37: =IFERROR(G37-E37,"-") -> 15496.717 | K37: =IFERROR(J37/E37,"-") -> 0.09808388 | L37: =IFERROR(G37-F37,"-") -> 16028.717 | M37: =IFERROR(L37/F37,"-") -> 0.10179384
B38: 发电标准煤耗量 | C38: 吨 | D38: =主城区!D33+金州!D9+北方!D8 -> 0 | E38: =北海!E8+香海!E9+金州!E9+北方!E8 -> 25605.142 | F38: =[3]全口径!$G$34 -> 23416.13 | G38: =北海!G8+香海!G9+金州!G9+北方!G8 -> 27596.4 | H38: =北海!H8+香海!H9+金州!H9+北方!H8 -> 27596.4 | I38: =IFERROR(H38/D38,"-") -> - | J38: =IFERROR(G38-E38,"-") -> 1991.2581 | K38: =IFERROR(J38/E38,"-") -> 0.0777679 | L38: =IFERROR(G38-F38,"-") -> 4180.2704 | M38: =IFERROR(L38/F38,"-") -> 0.17852098
B39: 供热标准煤耗量 | C39: 吨 | D39: =主城区!D34+金州!D10+北方!D9+金普!D10+庄河!D9 -> 0 | E39: =北海!E9+北海水炉!E7+香海!E10+金州!E10+北方!E9+金普!E10+庄河!E9 -> 132389.4 | F39: =[3]全口径!$G$35 -> 134046.41 | G39: =北海!G9+北海水炉!G7+香海!G10+金州!G10+北方!G9+金普!G10+庄河!G9 -> 145894.86 | H39: =北海!H9+北海水炉!H7+香海!H10+金州!H10+北方!H9+金普!H10+庄河!H9 -> 145894.86 | I39: =IFERROR(H39/D39,"-") -> - | J39: =IFERROR(G39-E39,"-") -> 13505.459 | K39: =IFERROR(J39/E39,"-") -> 0.10201315 | L39: =IFERROR(G39-F39,"-") -> 11848.446 | M39: =IFERROR(L39/F39,"-") -> 0.088390629
B40: 其中：煤折标煤量 | C40: 吨 | D40: =主城区!D35+金州!D12+北方!D11+金普!D10+庄河!D9 -> 0 | E40: =主城区!E35+金州!E12+北方!E11+金普!E10+庄河!E9 -> 157864.86 | F40: =主城区!F35+金州!F12+北方!F11+金普!F10+庄河!F9 -> 157319.38 | G40: =主城区!G35+金州!G12+北方!G11+金普!G10+庄河!G9 -> 173320.45 | H40: =主城区!H35+金州!H12+北方!H11+金普!H10+庄河!H9 -> 173320.45 | I40: =IFERROR(H40/D40,"-") -> - | J40: =IFERROR(G40-E40,"-") -> 15455.593 | K40: =IFERROR(J40/E40,"-") -> 0.097903948 | L40: =IFERROR(G40-F40,"-") -> 16001.071 | M40: =IFERROR(L40/F40,"-") -> 0.10171074
...

Sheet 主城区
A1: 指标类别 | B1: 项 目 | C1: 计量单位 | D1: 本年计划 | E1: 本月计划 | F1: 上年同期 | G1: 本月实际 | H1: 本年累计 | I1: 年计划 完成率 | J1: 与月计划比较 | L1: 与上年同期比较
J2: 差异 | K2: ±% | L2: 差异 | M2: ±%
A3: 产销指标 | B3: 发电量 | C3: 万千瓦时 | D3: =北海!D3+香海!D3 -> 0 | E3: =北海!E3+香海!E3 -> 13431 | F3: =[3]主城区!G3 -> 11627.856 | G3: =北海!G3+香海!G3 -> 11842.992 | H3: =北海!H3+香海!H3 -> 11842.992 | I3: =IFERROR(H3/D3,"-") -> - | J3: =IFERROR(G3-E3,"-") -> -1588.008 | K3: =IFERROR(J3/E3,"-") -> -0.11823453 | L3: =IFERROR(G3-F3,"-") -> 215.136 | M3: =IFERROR(L3/F3,"-") -> 0.018501777
B4: 售电量 | C4: 万千瓦时 | D4: =北海!D4+香海!D4 -> 0 | E4: =北海!E4+香海!E4 -> 9618 | F4: =[3]主城区!G4 -> 8297.9709 | G4: =北海!G4+香海!G4 -> 7828.3188 | H4: =北海!H4+香海!H4 -> 7828.3188 | I4: =IFERROR(H4/D4,"-") -> - | J4: =IFERROR(G4-E4,"-") -> -1789.6812 | K4: =IFERROR(J4/E4,"-") -> -0.18607623 | L4: =IFERROR(G4-F4,"-") -> -469.6521 | M4: =IFERROR(L4/F4,"-") -> -0.056598427
B5: 供汽量 | C5: 吨 | D5: =北海!D5+香海!D5 -> 0 | E5: =北海!E5+香海!E5 -> 94011 | F5: =[3]主城区!G5 -> 93850 | G5: =北海!G5+香海!G5+天然气炉!D4+天然气炉!E4 -> 113333 | H5: =北海!H5+香海!H5+天然气炉!F4+天然气炉!G4 -> 113333 | I5: =IFERROR(H5/D5,"-") -> - | J5: =IFERROR(G5-E5,"-") -> 19322 | K5: =IFERROR(J5/E5,"-") -> 0.20552914 | L5: =IFERROR(G5-F5,"-") -> 19483 | M5: =IFERROR(L5/F5,"-") -> 0.20759723
B6: 供热量 | C6: 吉焦 | D6: =集团本部!D6+股份本部!D6 -> 0 | E6: =北海!E6+北海水炉!E4+香海!E6+主城区电锅炉!E6 -> 2384644.7 | F6: =[3]主城区!G6 -> 2232740.5 | G6: =北海!G6+北海水炉!G4+香海!G6+主城区电锅炉!G6+天然气炉!D5+天然气炉!E5 -> 2688518.7 | H6: =北海!H6+北海水炉!H4+香海!H6+主城区电锅炉!H6+天然气炉!F5+天然气炉!G5 -> 2688518.7 | I6: =IFERROR(H6/D6,"-") -> - | J6: =IFERROR(G6-E6,"-") -> 303874.03 | K6: =IFERROR(J6/E6,"-") -> 0.12742948 | L6: =IFERROR(G6-F6,"-") -> 455778.25 | M6: =IFERROR(L6/F6,"-") -> 0.204134
B7: 低真空供热量 | C7: 吉焦 | D7: =香海!D7 -> 0 | E7: =香海!E7 -> 222082 | F7: =[3]主城区!G7 -> 217507 | G7: =香海!G7 -> 264848 | H7: =香海!H7 -> 264848 | I7: =IFERROR(H7/D7,"-") -> - | J7: =IFERROR(G7-E7,"-") -> 42766 | K7: =IFERROR(J7/E7,"-") -> 0.19256851 | L7: =IFERROR(G7-F7,"-") -> 47341 | M7: =IFERROR(L7/F7,"-") -> 0.21765277
B8: 高温水网供热量 | C8: 吉焦 | D8: =北海!D7+北海水炉!D4+香海!D8 -> 0 | E8: =北海!E7+北海水炉!E4+香海!E8 -> 1884674 | F8: =[3]主城区!G8 -> 1737820 | G8: =北海!G7+北海水炉!G4+香海!G8 -> 2088705.4 | H8: =北海!H7+北海水炉!H4+香海!H8 -> 2088705.4 | I8: =IFERROR(H8/D8,"-") -> - | J8: =IFERROR(G8-E8,"-") -> 204031.4 | K8: =IFERROR(J8/E8,"-") -> 0.10825819 | L8: =IFERROR(G8-F8,"-") -> 350885.4 | M8: =IFERROR(L8/F8,"-") -> 0.20191125
B9: 售汽量 | C9: 吨 | D9: =集团本部!D9 -> 0 | E9: =集团本部!E9 -> 51000 | F9: =[3]主城区!G9 -> 48270 | G9: =[5]售热量!$D$18 -> 55460 | H9: =[5]售热量!$D$18 -> 55460 | I9: =IFERROR(H9/D9,"-") -> - | J9: =IFERROR(G9-E9,"-") -> 4460 | K9: =IFERROR(J9/E9,"-") -> 0.08745098 | L9: =IFERROR(G9-F9,"-") -> 7190 | M9: =IFERROR(L9/F9,"-") -> 0.1489538
B10: 高温水销售量 | C10: 吉焦 | D10: =集团本部!D10+股份本部!D10 -> 0 | E10: =集团本部!E10+股份本部!E10 -> 430000 | F10: =[3]主城区!G10 -> 414571 | G10: =[5]售热量!$D$19 -> 463052 | H10: =[5]售热量!$D$19 -> 463052 | I10: =IFERROR(H10/D10,"-") -> - | J10: =IFERROR(G10-E10,"-") -> 33052 | K10: =IFERROR(J10/E10,"-") -> 0.076865116 | L10: =IFERROR(G10-F10,"-") -> 48481 | M10: =IFERROR(L10/F10,"-") -> 0.11694257
B11: 期末供暖收费面积 | C11: 平方米 | D11: =集团本部!D11+股份本部!D11 -> 0 | E11: =供热公司!E3+主城区电锅炉!E4 -> 22907592 | F11: =[3]主城区!G11 -> 22164541 | G11: =H11 -> 22948925 | H11: =供热公司!H3+主城区电锅炉!H4 -> 22948925 | I11: =IFERROR(H11/D11,"-") -> - | J11: =IFERROR(G11-E11,"-") -> 41332.99 | K11: =IFERROR(J11/E11,"-") -> 0.0018043359 | L11: =IFERROR(G11-F11,"-") -> 784383.59 | M11: =IFERROR(L11/F11,"-") -> 0.035389119
A12: 消耗指标 | B12: 生产耗原煤量 | C12: 吨 | D12: =北海!D12+北海水炉!D5+香海!D13 -> 0 | E12: =北海!E12+北海水炉!E5+香海!E13 -> 165107.22 | F12: =[3]主城区!G12 -> 154156 | G12: =北海!G12+北海水炉!G5+香海!G13 -> 184355 | H12: =北海!H12+北海水炉!H5+香海!H13 -> 184355 | I12: =IFERROR(H12/D12,"-") -> - | J12: =IFERROR(G12-E12,"-") -> 19247.778 | K12: =IFERROR(J12/E12,"-") -> 0.11657744 | L12: =IFERROR(G12-F12,"-") -> 30199 | M12: =IFERROR(L12/F12,"-") -> 0.19589896
B13: 锅炉耗柴油量 | C13: 吨 | D13: =北海!D24+北海水炉!D6+香海!D23 -> 0 | E13: =北海!E24+北海水炉!E6+香海!E23 -> 67 | F13: =[3]主城区!G13 -> 73.5 | G13: =北海!G24+北海水炉!G6+香海!G23 -> 103.3 | H13: =北海!H24+北海水炉!H6+香海!H23 -> 103.3 | I13: =IFERROR(H13/D13,"-") -> - | J13: =IFERROR(G13-E13,"-") -> 36.3 | K13: =IFERROR(J13/E13,"-") -> 0.54179104 | L13: =IFERROR(G13-F13,"-") -> 29.8 | M13: =IFERROR(L13/F13,"-") -> 0.40544218
B14: 耗水量 | C14: 吨 | D14: =北海!D22+北海水炉!D9+香海!D22+供热公司!D12+主城区电锅炉!D7 -> 0 | E14: =北海!E22+北海水炉!E9+香海!E22+供热公司!E12+主城区电锅炉!E7 -> 493632.81 | F14: =[3]主城区!G14 -> 548648 | G14: =北海!G22+北海水炉!G9+香海!G22+主城区电锅炉!G7+天然气炉!D8+供热公司!G12 -> 488400 | H14: =北海!H22+北海水炉!H9+香海!H22+主城区电锅炉!H7+天然气炉!F8+供热公司!H12 -> 488400 | I14: =IFERROR(H14/D14,"-") -> - | J14: =IFERROR(G14-E14,"-") -> -5232.8095 | K14: =IFERROR(J14/E14,"-") -> -0.010600611 | L14: =IFERROR(G14-F14,"-") -> -60248 | M14: =IFERROR(L14/F14,"-") -> -0.10981176
B15: 耗酸量 | C15: 吨 | D15: =北海!D14+香海!D15 -> 0 | E15: =北海!E14+香海!E15 -> 67 | F15: =[3]主城区!G15 -> 60 | G15: =北海!G14+香海!G15 -> 46.4 | H15: =北海!H14+香海!H15 -> 46.4 | I15: =IFERROR(H15/D15,"-") -> - | J15: =IFERROR(G15-E15,"-") -> -20.6 | K15: =IFERROR(J15/E15,"-") -> -0.30746269 | L15: =IFERROR(G15-F15,"-") -> -13.6 | M15: =IFERROR(L15/F15,"-") -> -0.22666667
B16: 耗碱量 | C16: 吨 | D16: =北海!D13+香海!D14 -> 0 | E16: =北海!E13+香海!E14 -> 55 | F16: =[3]主城区!G16 -> 55 | G16: =北海!G13+香海!G14 -> 41.7 | H16: =北海!H13+香海!H14 -> 41.7 | I16: =IFERROR(H16/D16,"-") -> - | J16: =IFERROR(G16-E16,"-") -> -13.3 | K16: =IFERROR(J16/E16,"-") -> -0.24181818 | L16: =IFERROR(G16-F16,"-") -> -13.3 | M16: =IFERROR(L16/F16,"-") -> -0.24181818
B17: 耗石灰石粉量 | C17: 吨 | D17: =北海!D25+北海水炉!D16+香海!D24 -> 0 | E17: =北海!E25+北海水炉!E16+香海!E24 -> 4014 | F17: =[3]主城区!G17 -> 2731 | G17: =北海!G25+北海水炉!G16+香海!G24 -> 3633.29 | H17: =北海!H25+北海水炉!H16+香海!H24 -> 3633.29 | I17: =IFERROR(H17/D17,"-") -> - | J17: =IFERROR(G17-E17,"-") -> -380.71 | K17: =IFERROR(J17/E17,"-") -> -0.094845541 | L17: =IFERROR(G17-F17,"-") -> 902.29 | M17: =IFERROR(L17/F17,"-") -> 0.33038814
B18: 耗氨水量 | C18: 吨 | D18: =北海!D15+北海水炉!D17+香海!D16 -> 0 | E18: =北海!E15+北海水炉!E17+香海!E16 -> 725 | F18: =[3]主城区!G18 -> 633.63 | G18: =北海!G15+北海水炉!G17+香海!G16 -> 832.54 | H18: =北海!H15+北海水炉!H17+香海!H16 -> 832.54 | I18: =IFERROR(H18/D18,"-") -> - | J18: =IFERROR(G18-E18,"-") -> 107.54 | K18: =IFERROR(J18/E18,"-") -> 0.14833103 | L18: =IFERROR(G18-F18,"-") -> 198.91 | M18: =IFERROR(L18/F18,"-") -> 0.31392137
B19: 耗阻垢剂量 | C19: 吨 | D19: =集团本部!D19+股份本部!D19 -> 0 | E19: =集团本部!E19+股份本部!E19 -> 2.1 | F19: =[3]主城区!G19 -> 2.25 | G19: =北海!G16+香海!G17+中水!G14 -> 2.125 | H19: =北海!H16+香海!H17+中水!H14 -> 2.125 | I19: =IFERROR(H19/D19,"-") -> - | J19: =IFERROR(G19-E19,"-") -> 0.025 | K19: =IFERROR(J19/E19,"-") -> 0.011904762 | L19: =IFERROR(G19-F19,"-") -> -0.125 | M19: =IFERROR(L19/F19,"-") -> -0.055555556
B20: 耗杀菌剂量 | C20: 吨 | D20: =集团本部!D20+股份本部!D20 -> 0 | E20: =集团本部!E20+股份本部!E20 -> 0 | F20: =[3]主城区!G20 -> 0 | G20: =北海!G17+香海!G18+中水!G16 -> 0 | H20: =北海!H17+香海!H18+中水!H16 -> 0 | I20: =IFERROR(H20/D20,"-") -> - | J20: =IFERROR(G20-E20,"-") -> 0 | K20: =IFERROR(J20/E20,"-") -> - | L20: =IFERROR(G20-F20,"-") -> 0 | M20: =IFERROR(L20/F20,"-") -> -
B21: 脱硫脱硝耗水量 | C21: 吨 | D21: =北海!D19+香海!D19 -> 0 | E21: =北海!E19+香海!E19 -> 42019 | F21: =[3]主城区!G21 -> 69222 | G21: =北海!G19+北海水炉!G14+香海!G19 -> 52151 | H21: =北海!H19+北海水炉!H14+香海!H19 -> 52151 | I21: =IFERROR(H21/D21,"-") -> - | J21: =IFERROR(G21-E21,"-") -> 10132 | K21: =IFERROR(J21/E21,"-") -> 0.24112901 | L21: =IFERROR(G21-F21,"-") -> -17071 | M21: =IFERROR(L21/F21,"-") -> -0.24661235
B22: 脱硫脱硝耗电量 | C22: 千瓦时 | D22: =北海!D20+香海!D20 -> 0 | E22: =北海!E20+香海!E20 -> 1950000 | F22: =[3]主城区!G22 -> 2316899 | G22: =北海!G20+北海水炉!G15+香海!G20 -> 2927190.4 | H22: =北海!H20+北海水炉!H15+香海!H20 -> 2927190.4 | I22: =IFERROR(H22/D22,"-") -> - | J22: =IFERROR(G22-E22,"-") -> 977190.4 | K22: =IFERROR(J22/E22,"-") -> 0.50112328 | L22: =IFERROR(G22-F22,"-") -> 610291.4 | M22: =IFERROR(L22/F22,"-") -> 0.26340872
B23: 热网耗水量 | C23: 吨 | D23: =供热公司!D12+主城区电锅炉!D7 -> 0 | E23: =供热公司!E12+主城区电锅炉!E7 -> 192338.81 | F23: =供热公司!F12+主城区电锅炉!F7 -> 229365 | G23: =供热公司!G12+主城区电锅炉!G7 -> 201193 | H23: =供热公司!H12+主城区电锅炉!H7 -> 201193 | I23: =IFERROR(H23/D23,"-") -> - | J23: =IFERROR(G23-E23,"-") -> 8854.1905 | K23: =IFERROR(J23/E23,"-") -> 0.046034342 | L23: =IFERROR(G23-F23,"-") -> -28172 | M23: =IFERROR(L23/F23,"-") -> -0.12282606
B24: 其中：一次网电厂补水量 | C24: 吨 | D24: =北海!D21+香海!D21 -> 0 | E24: =北海!E21+香海!E21 -> 82300 | F24: =[3]主城区!G23 -> 90983 | G24: =北海!G21+香海!G21 -> 99619 | H24: =北海!H21+香海!H21 -> 99619 | I24: =IFERROR(H24/D24,"-") -> - | J24: =IFERROR(G24-E24,"-") -> 17319 | K24: =IFERROR(J24/E24,"-") -> 0.21043742 | L24: =IFERROR(G24-F24,"-") -> 8636 | M24: =IFERROR(L24/F24,"-") -> 0.094918831
B25: 供暖耗热量 | C25: 吉焦 | D25: =供热公司!D7+主城区电锅炉!D6 -> 0 | E25: =供热公司!E7+主城区电锅炉!E6 -> 1460397 | F25: =供热公司!F7+主城区电锅炉!F6 -> 1342327.8 | G25: =供热公司!G7+主城区电锅炉!G6 -> 1715801.3 | H25: =供热公司!H7+主城区电锅炉!H6 -> 1715801.3 | I25: =IFERROR(H25/D25,"-") -> - | J25: =IFERROR(G25-E25,"-") -> 255404.29 | K25: =IFERROR(J25/E25,"-") -> 0.17488689 | L25: =IFERROR(G25-F25,"-") -> 373473.52 | M25: =IFERROR(L25/F25,"-") -> 0.27822826
B26: 综合厂用电量 | C26: 万千瓦时 | D26: =D3-D4 -> 0 | E26: =E3-E4 -> 3813 | F26: =[3]主城区!G24 -> 3329.8851 | G26: =北海!G27+香海!G26 -> 4014.6732 | H26: =北海!H27+香海!H26 -> 4014.6732 | I26: =IFERROR(H26/D26,"-") -> - | J26: =IFERROR(G26-E26,"-") -> 201.6732 | K26: =IFERROR(J26/E26,"-") -> 0.052890952 | L26: =IFERROR(G26-F26,"-") -> 684.7881 | M26: =IFERROR(L26/F26,"-") -> 0.20564917
B27: 非生产厂用电量 | C27: 万千瓦时 | D27: =D26-D28-D29 -> 0 | E27: =E26-E28-E29 -> 534.16595 | F27: =F26-F28-F29 -> 539.31038 | G27: =G26-G28-G29 -> 716.71932 | H27: =北海!H28+香海!H27 -> 716.71932 | I27: =IFERROR(H27/D27,"-") -> - | J27: =IFERROR(G27-E27,"-") -> 182.55338 | K27: =IFERROR(J27/E27,"-") -> 0.34175405 | L27: =IFERROR(G27-F27,"-") -> 177.40895 | M27: =IFERROR(L27/F27,"-") -> 0.32895519
B28: 发电厂用电量 | C28: 万千瓦时 | D28: =北海!D29+香海!D28 -> 0 | E28: =北海!E29+香海!E28 -> 606.9236 | F28: =[3]主城区!G25 -> 516.74749 | G28: =北海!G29+香海!G28 -> 641.80804 | H28: =北海!H29+香海!H28 -> 641.80804 | I28: =IFERROR(H28/D28,"-") -> - | J28: =IFERROR(G28-E28,"-") -> 34.884436 | K28: =IFERROR(J28/E28,"-") -> 0.057477474 | L28: =IFERROR(G28-F28,"-") -> 125.06055 | M28: =IFERROR(L28/F28,"-") -> 0.24201482
B29: 供热厂用电量 | C29: 万千瓦时 | D29: =北海!D30+香海!D29 -> 0 | E29: =北海!E30+香海!E29 -> 2671.9105 | F29: =[3]主城区!G26 -> 2273.8272 | G29: =北海!G30+香海!G29 -> 2656.1458 | H29: =北海!H30+香海!H29 -> 2656.1458 | I29: =IFERROR(H29/D29,"-") -> - | J29: =IFERROR(G29-E29,"-") -> -15.764613 | K29: =IFERROR(J29/E29,"-") -> -0.0059001277 | L29: =IFERROR(G29-F29,"-") -> 382.3186 | M29: =IFERROR(L29/F29,"-") -> 0.16813881
B30: 外购电量 | C30: 万千瓦时 | D30: =集团本部!D28+股份本部!D21 -> 0 | E30: =集团本部!E28+股份本部!E21 -> 761.832 | F30: =集团本部!F28+股份本部!F21 -> 716.82671 | G30: =集团本部!G28+股份本部!G21 -> 691.11908 | H30: =集团本部!H28+股份本部!H21 -> 691.11908 | I30: =IFERROR(H30/D30,"-") -> - | J30: =IFERROR(G30-E30,"-") -> -70.712921 | K30: =IFERROR(J30/E30,"-") -> -0.092819572 | L30: =IFERROR(G30-F30,"-") -> -25.707631 | M30: =IFERROR(L30/F30,"-") -> -0.035863105
B31: 其中：热网耗电量 | C31: 万千瓦时 | D31: =供热公司!D13+主城区电锅炉!D8 -> 0 | E31: =供热公司!E13+主城区电锅炉!E8 -> 761.832 | F31: =供热公司!F13+主城区电锅炉!F8 -> 716.82671 | G31: =供热公司!G13+主城区电锅炉!G8 -> 691.11908 | H31: =供热公司!H13+主城区电锅炉!H8 -> 691.11908 | I31: =IFERROR(H31/D31,"-") -> - | J31: =IFERROR(G31-E31,"-") -> -70.712921 | K31: =IFERROR(J31/E31,"-") -> -0.092819572 | L31: =IFERROR(G31-F31,"-") -> -25.707631 | M31: =IFERROR(L31/F31,"-") -> -0.035863105
B32: 耗标煤总量 | C32: 吨 | D32: =D33+D34 -> 0 | E32: =E33+E34 -> 112166 | F32: =[3]主城区!G28 -> 103579.84 | G32: =G33+G34 -> 122460.93 | H32: =H33+H34 -> 122460.93 | I32: =IFERROR(H32/D32,"-") -> - | J32: =IFERROR(G32-E32,"-") -> 10294.931 | K32: =IFERROR(J32/E32,"-") -> 0.091782994 | L32: =IFERROR(G32-F32,"-") -> 18881.094 | M32: =IFERROR(L32/F32,"-") -> 0.18228542
B33: 发电标准煤耗量 | C33: 吨 | D33: =北海!D8+香海!D9 -> 0 | E33: =北海!E8+香海!E9 -> 18296 | F33: =[3]主城区!G29 -> 16136.6 | G33: =北海!G8+香海!G9 -> 18389.581 | H33: =北海!H8+香海!H9 -> 18389.581 | I33: =IFERROR(H33/D33,"-") -> - | J33: =IFERROR(G33-E33,"-") -> 93.581157 | K33: =IFERROR(J33/E33,"-") -> 0.0051148424 | L33: =IFERROR(G33-F33,"-") -> 2252.9812 | M33: =IFERROR(L33/F33,"-") -> 0.13961932
B34: 供热标准煤耗量 | C34: 吨 | D34: =北海!D9+北海水炉!D7+香海!D10 -> 0 | E34: =北海!E9+北海水炉!E7+香海!E10 -> 93870 | F34: =[3]主城区!G30 -> 87443.237 | G34: =北海!G9+北海水炉!G7+香海!G10 -> 104071.35 | H34: =北海!H9+北海水炉!H7+香海!H10 -> 104071.35 | I34: =IFERROR(H34/D34,"-") -> - | J34: =IFERROR(G34-E34,"-") -> 10201.35 | K34: =IFERROR(J34/E34,"-") -> 0.1086753 | L34: =IFERROR(G34-F34,"-") -> 16628.113 | M34: =IFERROR(L34/F34,"-") -> 0.19015894
B35: 其中：煤折标煤量 | C35: 吨 | D35: =集团本部!D32+股份本部!D25 -> 0 | E35: =集团本部!E32+股份本部!E25 -> 112068.37 | F35: =[3]主城区!G31 -> 103472.81 | G35: =集团本部!G32+股份本部!G25 -> 122310.41 | H35: =集团本部!H32+股份本部!H25 -> 122310.41 | I35: =IFERROR(H35/D35,"-") -> - | J35: =IFERROR(G35-E35,"-") -> 10242.036 | K35: =IFERROR(J35/E35,"-") -> 0.09139096 | L35: =IFERROR(G35-F35,"-") -> 18837.598 | M35: =IFERROR(L35/F35,"-") -> 0.1820536
A36: 单耗与效率 | B36: 综合厂用电率 | C36: % | D36: =(D3-D4)/D3 -> #DIV/0! | E36: =(E3-E4)/E3 -> 0.28389547 | F36: =[3]主城区!G32 -> 0.28637137 | G36: =G26/G3 -> 0.33899146 | H36: =H26/H3 -> 0.33899146 | I36: - | J36: =IFERROR(G36-E36,"-") -> 0.055095999 | K36: - | L36: =IFERROR(G36-F36,"-") -> 0.05262009 | M36: -
B37: 发电煤耗率 | C37: 克/千瓦时 | D37: =D33*100/D3 -> #DIV/0! | E37: =E33*100/E3 -> 136.22217 | F37: =[3]主城区!G33 -> 138.77537 | G37: =G33*100/G3 -> 155.27817 | H37: =H33*100/H3 -> 155.27817 | I37: =IFERROR(H37/D37,"-") -> - | J37: =IFERROR(G37-E37,"-") -> 19.055997 | K37: =IFERROR(J37/E37,"-") -> 0.1398891 | L37: =IFERROR(G37-F37,"-") -> 16.502801 | M37: =IFERROR(L37/F37,"-") -> 0.11891736
B38: 供电煤耗率 | C38: 克/千瓦时 | D38: =D33*100/(D3-D28) -> #DIV/0! | E38: =E33*100/(E3-E28) -> 142.66914 | F38: =[3]主城区!G34 -> 145.22943 | G38: =G33*100/(G3-G28) -> 164.17533 | H38: =H33*100/(H3-H28) -> 164.17533 | I38: =IFERROR(H38/D38,"-") -> - | J38: =IFERROR(G38-E38,"-") -> 21.50619 | K38: =IFERROR(J38/E38,"-") -> 0.1507417 | L38: =IFERROR(G38-F38,"-") -> 18.9459 | M38: =IFERROR(L38/F38,"-") -> 0.13045496
B39: 供热煤耗率 | C39: 千克/吉焦 | D39: =D34*1000/(D6-主城区电锅炉!D6) -> #DIV/0! | E39: =E34*1000/E6 -> 39.364355 | F39: =[3]主城区!G35 -> 39.171049 | G39: =G34*1000/(G6-主城区电锅炉!G6-天然气炉!D5-天然气炉!E5) -> 38.715901 | H39: =H34*1000/(H6-主城区电锅炉!H6-天然气炉!F5-天然气炉!G5) -> 38.715901 | I39: =IFERROR(H39/D39,"-") -> - | J39: =IFERROR(G39-E39,"-") -> -0.64845419 | K39: =IFERROR(J39/E39,"-") -> -0.016473132 | L39: =IFERROR(G39-F39,"-") -> -0.45514896 | M39: =IFERROR(L39/F39,"-") -> -0.011619524
B40: 入炉煤低位发热量 | C40: 千焦/千克 | D40: =D32*29308/D12 -> #DIV/0! | E40: =E32*29308/E12 -> 19910.462 | F40: =[3]主城区!G36 -> 19676.896 | G40: =('[6]26.1'!$G$40+'[6]26.1'!$G$43+北海水炉!G7)*29308/G12 -> 19446.491 | H40: =('[6]26.1'!$M$40+'[6]26.1'!$M$43+北海水炉!H7)*29308/H12 -> 19446.491 | I40: =IFERROR(H40/D40,"-") -> - | J40: =IFERROR(G40-E40,"-") -> -463.97129 | K40: =IFERROR(J40/E40,"-") -> -0.023302889 | L40: =IFERROR(G40-F40,"-") -> -230.4047 | M40: =IFERROR(L40/F40,"-") -> -0.011709403
...

Sheet 集团本部
A1: 指标类别 | B1: 项 目 | C1: 计量单位 | D1: 本年计划 | E1: 本月计划 | F1: 上年同期 | G1: 本月实际 | H1: 本年累计 | I1: 年计划 完成率 | J1: 与月计划比较 | L1: 与上年同期比较
J2: 差异 | K2: ±% | L2: 差异 | M2: ±%
A3: 产销指标 | B3: 发电量 | C3: 万千瓦时 | D3: =香海!D3 -> 0 | E3: =香海!E3 -> 5849 | F3: =[3]集团本部!G3 -> 5823.936 | G3: =香海!G3 -> 5767.632 | H3: =香海!H3 -> 5767.632 | I3: =IFERROR(H3/D3,"-") -> - | J3: =IFERROR(G3-E3,"-") -> -81.368 | K3: =IFERROR(J3/E3,"-") -> -0.013911438 | L3: =IFERROR(G3-F3,"-") -> -56.304 | M3: =IFERROR(L3/F3,"-") -> -0.0096676887
B4: 售电量 | C4: 万千瓦时 | D4: =香海!D4 -> 0 | E4: =香海!E4 -> 4387 | F4: =[3]集团本部!G4 -> 4365.4248 | G4: =香海!G4 -> 4113.7272 | H4: =香海!H4 -> 4113.7272 | I4: =IFERROR(H4/D4,"-") -> - | J4: =IFERROR(G4-E4,"-") -> -273.2728 | K4: =IFERROR(J4/E4,"-") -> -0.062291498 | L4: =IFERROR(G4-F4,"-") -> -251.6976 | M4: =IFERROR(L4/F4,"-") -> -0.057657069
B5: 供热量 | C5: 吉焦 | D5: =SUM(D6:D8) -> 0 | E5: =SUM(E6:E8) -> 967175.89 | F5: =[3]集团本部!G5 -> 996043.06 | G5: =SUM(G6:G8) -> 1168934.9 | H5: =SUM(H6:H8) -> 1168934.9 | I5: =IFERROR(H5/D5,"-") -> - | J5: =IFERROR(G5-E5,"-") -> 201759.05 | K5: =IFERROR(J5/E5,"-") -> 0.20860637 | L5: =IFERROR(G5-F5,"-") -> 172891.89 | M5: =IFERROR(L5/F5,"-") -> 0.17357873
B6: 其中：香海热电厂生产 | C6: 吉焦 | D6: =香海!D6 -> 0 | E6: =香海!E6 -> 835500.11 | F6: =[3]集团本部!G6 -> 840392.89 | G6: =香海!G6 -> 967138.54 | H6: =香海!H6 -> 967138.54 | I6: =IFERROR(H6/D6,"-") -> - | J6: =IFERROR(G6-E6,"-") -> 131638.43 | K6: =IFERROR(J6/E6,"-") -> 0.15755645 | L6: =IFERROR(G6-F6,"-") -> 126745.66 | M6: =IFERROR(L6/F6,"-") -> 0.15081714
B7: 自股份公司购入量(蒸汽) | C7: 吉焦 | E7: =股份本部!E8*2.952 -> -18252.216 | F7: =[3]集团本部!G7 -> 4971.168 | G7: =股份本部!G8*2.952 -> 3542.4 | H7: =股份本部!H8*2.952 -> 3542.4 | I7: =IFERROR(H7/D7,"-") -> - | J7: =IFERROR(G7-E7,"-") -> 21794.616 | K7: =IFERROR(J7/E7,"-") -> -1.1940805 | L7: =IFERROR(G7-F7,"-") -> -1428.768 | M7: =IFERROR(L7/F7,"-") -> -0.28741093
B8: 自股份公司购入量(高温水) | C8: 吉焦 | E8: =股份本部!E9 -> 149928 | F8: =[3]集团本部!G8 -> 150679 | G8: =股份本部!G9 -> 198254 | H8: =股份本部!H9 -> 198254 | I8: =IFERROR(H8/D8,"-") -> - | J8: =IFERROR(G8-E8,"-") -> 48326 | K8: =IFERROR(J8/E8,"-") -> 0.32232805 | L8: =IFERROR(G8-F8,"-") -> 47575 | M8: =IFERROR(L8/F8,"-") -> 0.31573743
B9: 售汽量 | C9: 吨 | E9: ='[2]2.主城区汇总表'!$M$15 -> 51000 | F9: =[3]集团本部!G9 -> 48270 | G9: =[5]售热量!$D$11 -> 55460 | H9: =[5]售热量!$D$11 -> 55460 | I9: =IFERROR(H9/D9,"-") -> - | J9: =IFERROR(G9-E9,"-") -> 4460 | K9: =IFERROR(J9/E9,"-") -> 0.08745098 | L9: =IFERROR(G9-F9,"-") -> 7190 | M9: =IFERROR(L9/F9,"-") -> 0.1489538
B10: 高温水销售量 | C10: 吉焦 | E10: ='[2]2.主城区汇总表'!$M$25-股份本部!E10 -> 329500 | F10: =[3]集团本部!G10 -> 317566 | G10: =[5]售热量!$D$13 -> 358546 | H10: =[5]售热量!$D$13 -> 358546 | I10: =IFERROR(H10/D10,"-") -> - | J10: =IFERROR(G10-E10,"-") -> 29046 | K10: =IFERROR(J10/E10,"-") -> 0.088151745 | L10: =IFERROR(G10-F10,"-") -> 40980 | M10: =IFERROR(L10/F10,"-") -> 0.12904404
B11: 期末供暖收费面积 | C11: 平方米 | D11: =供热公司!D3-股份本部!D11+主城区电锅炉!D4 -> 0 | E11: =供热公司!E3-股份本部!E11+主城区电锅炉!E4 -> 5964581.6 | F11: =[3]集团本部!G11 -> 6061989.4 | G11: =H11 -> 6633927.5 | H11: =供热公司!H3+主城区电锅炉!H4-股份本部!H11 -> 6633927.5 | I11: =IFERROR(H11/D11,"-") -> - | J11: =IFERROR(G11-E11,"-") -> 669345.93 | K11: =IFERROR(J11/E11,"-") -> 0.1122201 | L11: =IFERROR(G11-F11,"-") -> 571938.05 | M11: =IFERROR(L11/F11,"-") -> 0.094348243
A12: 消耗指标 | B12: 生产耗原煤量 | C12: 吨 | D12: =香海!D13 -> 0 | E12: =香海!E13 -> 59828 | F12: =[3]集团本部!G12 -> 61990 | G12: =香海!G13 -> 73239 | H12: =香海!H13 -> 73239 | I12: =IFERROR(H12/D12,"-") -> - | J12: =IFERROR(G12-E12,"-") -> 13411 | K12: =IFERROR(J12/E12,"-") -> 0.22415926 | L12: =IFERROR(G12-F12,"-") -> 11249 | M12: =IFERROR(L12/F12,"-") -> 0.18146475
B13: 锅炉耗柴油量 | C13: 吨 | D13: =香海!D23 -> 0 | E13: =香海!E23 -> 8 | F13: =[3]集团本部!G13 -> 15 | G13: =香海!G23 -> 25 | H13: =香海!H23 -> 25 | I13: =IFERROR(H13/D13,"-") -> - | J13: =IFERROR(G13-E13,"-") -> 17 | K13: =IFERROR(J13/E13,"-") -> 2.125 | L13: =IFERROR(G13-F13,"-") -> 10 | M13: =IFERROR(L13/F13,"-") -> 0.66666667
B14: 耗水量 | C14: 吨 | D14: =香海!D22+供热公司!D12-北海!D21+主城区电锅炉!D7 -> 0 | E14: =香海!E22+供热公司!E12-北海!E21+主城区电锅炉!E7 -> 300038.81 | F14: =[3]集团本部!G14 -> 327634 | G14: =香海!G22+供热公司!G12-北海!G21+主城区电锅炉!G7 -> 296348 | H14: =香海!H22+供热公司!H12-北海!H21+主城区电锅炉!H7 -> 296348 | I14: =IFERROR(H14/D14,"-") -> - | J14: =IFERROR(G14-E14,"-") -> -3690.8095 | K14: =IFERROR(J14/E14,"-") -> -0.012301107 | L14: =IFERROR(G14-F14,"-") -> -31286 | M14: =IFERROR(L14/F14,"-") -> -0.0954907
B15: 耗酸量 | C15: 吨 | D15: =香海!D15 -> 0 | E15: =香海!E15 -> 46 | F15: =[3]集团本部!G15 -> 46 | G15: =香海!G15 -> 40 | H15: =香海!H15 -> 40 | I15: =IFERROR(H15/D15,"-") -> - | J15: =IFERROR(G15-E15,"-") -> -6 | K15: =IFERROR(J15/E15,"-") -> -0.13043478 | L15: =IFERROR(G15-F15,"-") -> -6 | M15: =IFERROR(L15/F15,"-") -> -0.13043478
B16: 耗碱量 | C16: 吨 | D16: =香海!D14 -> 0 | E16: =香海!E14 -> 37 | F16: =[3]集团本部!G16 -> 37 | G16: =香海!G14 -> 32 | H16: =香海!H14 -> 32 | I16: =IFERROR(H16/D16,"-") -> - | J16: =IFERROR(G16-E16,"-") -> -5 | K16: =IFERROR(J16/E16,"-") -> -0.13513514 | L16: =IFERROR(G16-F16,"-") -> -5 | M16: =IFERROR(L16/F16,"-") -> -0.13513514
B17: 耗石灰石粉量 | C17: 吨 | D17: =香海!D24 -> 0 | E17: =香海!E24 -> 925 | F17: =[3]集团本部!G17 -> 840 | G17: =香海!G24 -> 854 | H17: =香海!H24 -> 854 | I17: =IFERROR(H17/D17,"-") -> - | J17: =IFERROR(G17-E17,"-") -> -71 | K17: =IFERROR(J17/E17,"-") -> -0.076756757 | L17: =IFERROR(G17-F17,"-") -> 14 | M17: =IFERROR(L17/F17,"-") -> 0.016666667
B18: 耗氨水量 | C18: 吨 | D18: =香海!D16 -> 0 | E18: =香海!E16 -> 130 | F18: =[3]集团本部!G18 -> 113 | G18: =香海!G16 -> 201 | H18: =香海!H16 -> 201 | I18: =IFERROR(H18/D18,"-") -> - | J18: =IFERROR(G18-E18,"-") -> 71 | K18: =IFERROR(J18/E18,"-") -> 0.54615385 | L18: =IFERROR(G18-F18,"-") -> 88 | M18: =IFERROR(L18/F18,"-") -> 0.77876106
B19: 耗阻垢剂量 | C19: 吨 | D19: =香海!D17 -> 0 | E19: =香海!E17 -> 0.9 | F19: =[3]集团本部!G19 -> 1 | G19: =香海!G17 -> 1 | H19: =香海!H17 -> 1 | I19: =IFERROR(H19/D19,"-") -> - | J19: =IFERROR(G19-E19,"-") -> 0.1 | K19: =IFERROR(J19/E19,"-") -> 0.11111111 | L19: =IFERROR(G19-F19,"-") -> 0 | M19: =IFERROR(L19/F19,"-") -> 0
B20: 耗杀菌剂量 | C20: 吨 | D20: =香海!D18 -> 0 | E20: =香海!E18 -> 0 | F20: =[3]集团本部!G20 -> 0 | G20: =香海!G18 -> 0 | H20: =香海!H18 -> 0 | I20: =IFERROR(H20/D20,"-") -> - | J20: =IFERROR(G20-E20,"-") -> 0 | K20: =IFERROR(J20/E20,"-") -> - | L20: =IFERROR(G20-F20,"-") -> 0 | M20: =IFERROR(L20/F20,"-") -> -
B21: 脱硫脱硝耗水量 | C21: 吨 | D21: =香海!D19 -> 0 | E21: =香海!E19 -> 25000 | F21: =[3]集团本部!G21 -> 25240 | G21: =香海!G19 -> 32849 | H21: =香海!H19 -> 32849 | I21: =IFERROR(H21/D21,"-") -> - | J21: =IFERROR(G21-E21,"-") -> 7849 | K21: =IFERROR(J21/E21,"-") -> 0.31396 | L21: =IFERROR(G21-F21,"-") -> 7609 | M21: =IFERROR(L21/F21,"-") -> 0.30146593
B22: 脱硫脱硝耗电量 | C22: 千瓦时 | D22: =香海!D20 -> 0 | E22: =香海!E20 -> 1080000 | F22: =[3]集团本部!G22 -> 1075554 | G22: =香海!G20 -> 1283190 | H22: =香海!H20 -> 1283190 | I22: =IFERROR(H22/D22,"-") -> - | J22: =IFERROR(G22-E22,"-") -> 203190 | K22: =IFERROR(J22/E22,"-") -> 0.18813889 | L22: =IFERROR(G22-F22,"-") -> 207636 | M22: =IFERROR(L22/F22,"-") -> 0.19305028
B23: 一次网电厂补水量 | C23: 吨 | D23: =香海!D21 -> 0 | E23: =香海!E21 -> 25000 | F23: =[3]集团本部!G23 -> 26263 | G23: =香海!G21 -> 25920 | H23: =香海!H21 -> 25920 | I23: =IFERROR(H23/D23,"-") -> - | J23: =IFERROR(G23-E23,"-") -> 920 | K23: =IFERROR(J23/E23,"-") -> 0.0368 | L23: =IFERROR(G23-F23,"-") -> -343 | M23: =IFERROR(L23/F23,"-") -> -0.013060199
B24: 综合厂用电量 | C24: 万千瓦时 | D24: =D3-D4 -> 0 | E24: =香海!E26 -> 1462 | F24: =[3]集团本部!G24 -> 1458.5112 | G24: =香海!G26 -> 1653.9048 | H24: =香海!H26 -> 1653.9048 | I24: =IFERROR(H24/D24,"-") -> - | J24: =IFERROR(G24-E24,"-") -> 191.9048 | K24: =IFERROR(J24/E24,"-") -> 0.13126183 | L24: =IFERROR(G24-F24,"-") -> 195.3936 | M24: =IFERROR(L24/F24,"-") -> 0.13396784
B25: 非生产厂用电量 | C25: 万千瓦时 | D25: =D24-D26-D27 -> 0 | E25: =E24-E26-E27 -> 85 | F25: =F24-F26-F27 -> 85.107 | G25: =G24-G26-G27 -> 57.3928 | H25: =香海!H27 -> 57.3928 | I25: =IFERROR(H25/D25,"-") -> - | J25: =IFERROR(G25-E25,"-") -> -27.6072 | K25: =IFERROR(J25/E25,"-") -> -0.32479059 | L25: =IFERROR(G25-F25,"-") -> -27.7142 | M25: =IFERROR(L25/F25,"-") -> -0.32563949
B26: 发电厂用电量 | C26: 万千瓦时 | D26: =香海!D28 -> 0 | E26: =香海!E28 -> 246 | F26: =[3]集团本部!G25 -> 255.8652 | G26: =香海!G28 -> 284.49844 | H26: =香海!H28 -> 284.49844 | I26: =IFERROR(H26/D26,"-") -> - | J26: =IFERROR(G26-E26,"-") -> 38.498438 | K26: =IFERROR(J26/E26,"-") -> 0.15649772 | L26: =IFERROR(G26-F26,"-") -> 28.633238 | M26: =IFERROR(L26/F26,"-") -> 0.11190751
B27: 供热厂用电量 | C27: 万千瓦时 | D27: =香海!D29 -> 0 | E27: =香海!E29 -> 1131 | F27: =[3]集团本部!G26 -> 1117.539 | G27: =香海!G29 -> 1312.0136 | H27: =香海!H29 -> 1312.0136 | I27: =IFERROR(H27/D27,"-") -> - | J27: =IFERROR(G27-E27,"-") -> 181.01356 | K27: =IFERROR(J27/E27,"-") -> 0.16004736 | L27: =IFERROR(G27-F27,"-") -> 194.47456 | M27: =IFERROR(L27/F27,"-") -> 0.17402038
B28: 外购电量 | C28: 万千瓦时 | D28: =香海!D25+供热公司!D13+主城区电锅炉!D8 -> 0 | E28: =香海!E25+供热公司!E13+主城区电锅炉!E8 -> 761.832 | F28: =香海!F25+供热公司!F13+主城区电锅炉!F8 -> 716.82671 | G28: =香海!G25+供热公司!G13+主城区电锅炉!G8 -> 691.11908 | H28: =香海!H25+供热公司!H13+主城区电锅炉!H8 -> 691.11908 | I28: =IFERROR(H28/D28,"-") -> - | J28: =IFERROR(G28-E28,"-") -> -70.712921 | K28: =IFERROR(J28/E28,"-") -> -0.092819572 | L28: =IFERROR(G28-F28,"-") -> -25.707631 | M28: =IFERROR(L28/F28,"-") -> -0.035863105
B29: 耗标煤总量 | C29: 吨 | D29: =D30+D31 -> 0 | E29: =E30+E31 -> 41037 | F29: =[3]集团本部!G28 -> 40896.557 | G29: =G30+G31 -> 47986.132 | H29: =H30+H31 -> 47986.132 | I29: =IFERROR(H29/D29,"-") -> - | J29: =IFERROR(G29-E29,"-") -> 6949.1317 | K29: =IFERROR(J29/E29,"-") -> 0.1693382 | L29: =IFERROR(G29-F29,"-") -> 7089.5748 | M29: =IFERROR(L29/F29,"-") -> 0.17335383
B30: 发电标准煤耗量 | C30: 吨 | D30: =香海!D9 -> 0 | E30: =香海!E9 -> 7329 | F30: =[3]集团本部!G29 -> 7619 | G30: =香海!G9 -> 8551.1287 | H30: =香海!H9 -> 8551.1287 | I30: =IFERROR(H30/D30,"-") -> - | J30: =IFERROR(G30-E30,"-") -> 1222.1287 | K30: =IFERROR(J30/E30,"-") -> 0.16675245 | L30: =IFERROR(G30-F30,"-") -> 932.12868 | M30: =IFERROR(L30/F30,"-") -> 0.12234265
B31: 供热标准煤耗量 | C31: 吨 | D31: =香海!D10 -> 0 | E31: =香海!E10 -> 33708 | F31: =[3]集团本部!G30 -> 33277.557 | G31: =香海!G10 -> 39435.003 | H31: =香海!H10 -> 39435.003 | I31: =IFERROR(H31/D31,"-") -> - | J31: =IFERROR(G31-E31,"-") -> 5727.0031 | K31: =IFERROR(J31/E31,"-") -> 0.16990041 | L31: =IFERROR(G31-F31,"-") -> 6157.4461 | M31: =IFERROR(L31/F31,"-") -> 0.185033
B32: 其中：煤折标煤量 | C32: 吨 | D32: =香海!D12 -> 0 | E32: =香海!E12 -> 41025.343 | F32: =[3]集团本部!G31 -> 40874.772 | G32: =香海!G12 -> 47949.704 | H32: =香海!H12 -> 47949.704 | I32: =IFERROR(H32/D32,"-") -> - | J32: =IFERROR(G32-E32,"-") -> 6924.361 | K32: =IFERROR(J32/E32,"-") -> 0.16878253 | L32: =IFERROR(G32-F32,"-") -> 7074.9319 | M32: =IFERROR(L32/F32,"-") -> 0.17308798
A33: 单耗与效率 | B33: 综合厂用电率 | C33: % | D33: =(D3-D4)/D3 -> #DIV/0! | E33: =(E3-E4)/E3 -> 0.24995726 | F33: =[3]集团本部!G32 -> 0.25043393 | G33: =(G3-G4)/G3 -> 0.2867563 | H33: =(H3-H4)/H3 -> 0.2867563 | I33: - | J33: =IFERROR(G33-E33,"-") -> 0.03679904 | K33: - | L33: =IFERROR(G33-F33,"-") -> 0.036322365 | M33: -
B34: 发电煤耗率 | C34: 克/千瓦时 | D34: =D30*100/D3 -> #DIV/0! | E34: =E30*100/E3 -> 125.30347 | F34: =[3]集团本部!G33 -> 130.82218 | G34: =G30*100/G3 -> 148.26065 | H34: =H30*100/H3 -> 148.26065 | I34: =IFERROR(H34/D34,"-") -> - | J34: =IFERROR(G34-E34,"-") -> 22.957179 | K34: =IFERROR(J34/E34,"-") -> 0.18321264 | L34: =IFERROR(G34-F34,"-") -> 17.43847 | M34: =IFERROR(L34/F34,"-") -> 0.13329904
B35: 供电煤耗率 | C35: 克/千瓦时 | D35: =D30*100/(D3-D26) -> #DIV/0! | E35: =E30*100/(E3-E26) -> 130.80493 | F35: =[3]集团本部!G34 -> 136.83375 | G35: =G30*100/(G3-G26) -> 155.95332 | H35: =H30*100/(H3-H26) -> 155.95332 | I35: =IFERROR(H35/D35,"-") -> - | J35: =IFERROR(G35-E35,"-") -> 25.148391 | K35: =IFERROR(J35/E35,"-") -> 0.19225875 | L35: =IFERROR(G35-F35,"-") -> 19.119569 | M35: =IFERROR(L35/F35,"-") -> 0.13972846
B36: 供热煤耗率 | C36: 千克/吉焦 | D36: =D31*1000/香海!D6 -> #DIV/0! | E36: =E31*1000/香海!E6 -> 40.344698 | F36: =[3]集团本部!G35 -> 39.597619 | G36: =G31*1000/香海!G6 -> 40.774927 | H36: =H31*1000/香海!H6 -> 40.774927 | I36: =IFERROR(H36/D36,"-") -> - | J36: =IFERROR(G36-E36,"-") -> 0.43022814 | K36: =IFERROR(J36/E36,"-") -> 0.010663808 | L36: =IFERROR(G36-F36,"-") -> 1.1773081 | M36: =IFERROR(L36/F36,"-") -> 0.02973179
B37: 入炉煤低位发热量 | C37: 千焦/千克 | D37: =D29*29308/D12 -> #DIV/0! | E37: =E29*29308/E12 -> 20102.835 | F37: =[3]集团本部!G36 -> 19325.017 | G37: =香海!G40 -> 19188 | H37: =香海!H40 -> 19188 | I37: =IFERROR(H37/D37,"-") -> - | J37: =IFERROR(G37-E37,"-") -> -914.83473 | K37: =IFERROR(J37/E37,"-") -> -0.045507747 | L37: =IFERROR(G37-F37,"-") -> -137.01738 | M37: =IFERROR(L37/F37,"-") -> -0.0070901557
A38: 设备利用率 | B38: 发电设备利用率 | C38: % | D38: =D3/10/8760 -> 0 | E38: =E3/10/(DAY(DATE(2026,2,0))*24) -> 0.78615591 | F38: =[3]集团本部!G37 -> 0.7827871 | G38: =G3/10/(DAY(DATE(2026,2,0))*24) -> 0.77521935 | H38: =H3/10/(DATEDIF(DATE(2026,1,1),DATE(2026,2,1),"D")*24) -> 0.77521935 | I38: - | J38: =IFERROR(G38-E38,"-") -> -0.010936559 | K38: - | L38: =IFERROR(G38-F38,"-") -> -0.0075677419 | M38: -
B39: 供热设备利用率 | C39: % | D39: =香海!D6*1000/528/(8760*3600) -> 0 | E39: =香海!E6*1000/528/((DAY(DATE(2026,2,0))*24)*3600) -> 0.59079546 | F39: =[3]集团本部!G38 -> 0.59425523 | G39: =香海!G6*1000/528/((DAY(DATE(2026,2,0))*24)*3600) -> 0.6838791 | H39: =香海!H6*1000/528/((DATEDIF(DATE(2026,1,1),DATE(2026,2,1),"D")*24)*3600) -> 0.6838791 | I39: - | J39: =IFERROR(G39-E39,"-") -> 0.093083637 | K39: - | L39: =IFERROR(G39-F39,"-") -> 0.089623876 | M39: -

Sheet 股份本部
A1: 指标类别 | B1: 项 目 | C1: 计量单位 | D1: 本年计划 | E1: 本月计划 | F1: 上年同期 | G1: 本月实际 | H1: 本年累计 | I1: 年计划 完成率 | J1: 与月计划比较 | L1: 与上年同期比较
J2: 差异 | K2: ±% | L2: 差异 | M2: ±%
A3: 产销指标 | B3: 发电量 | C3: 万千瓦时 | D3: =北海!D3 -> 0 | E3: =北海!E3 -> 7582 | F3: =[3]股份本部!G3 -> 5803.92 | G3: =北海!G3 -> 6075.36 | H3: =北海!H3 -> 6075.36 | I3: =IFERROR(H3/D3,"-") -> - | J3: =IFERROR(G3-E3,"-") -> -1506.64 | K3: =IFERROR(J3/E3,"-") -> -0.19871274 | L3: =IFERROR(G3-F3,"-") -> 271.44 | M3: =IFERROR(L3/F3,"-") -> 0.046768391
B4: 售电量 | C4: 万千瓦时 | D4: =北海!D4 -> 0 | E4: =北海!E4 -> 5231 | F4: =[3]股份本部!G4 -> 3932.5461 | G4: =北海!G4 -> 3714.5916 | H4: =北海!H4 -> 3714.5916 | I4: =IFERROR(H4/D4,"-") -> - | J4: =IFERROR(G4-E4,"-") -> -1516.4084 | K4: =IFERROR(J4/E4,"-") -> -0.28988882 | L4: =IFERROR(G4-F4,"-") -> -217.9545 | M4: =IFERROR(L4/F4,"-") -> -0.055423254
B5: 供汽量 | C5: 吨 | D5: =北海!D5 -> 0 | E5: =北海!E5 -> 29011 | F5: =[3]股份本部!G5 -> 29011 | G5: =北海!G5+天然气炉!D4 -> 35445 | H5: =北海!H5+天然气炉!F4 -> 35445 | I5: =IFERROR(H5/D5,"-") -> - | J5: =IFERROR(G5-E5,"-") -> 6434 | K5: =IFERROR(J5/E5,"-") -> 0.22177795 | L5: =IFERROR(G5-F5,"-") -> 6434 | M5: =IFERROR(L5/F5,"-") -> 0.22177795
B6: 供热量 | C6: 吉焦 | E6: =北海!E6+北海水炉!E4 -> 1548747.6 | F6: =[3]股份本部!G6 -> 1392347.6 | G6: =北海!G6+北海水炉!G4+主城区电锅炉!G6+天然气炉!D5 -> 1721380.2 | H6: =北海!H6+北海水炉!H4+主城区电锅炉!H6+天然气炉!F5 -> 1721380.2 | I6: =IFERROR(H6/D6,"-") -> - | J6: =IFERROR(G6-E6,"-") -> 172632.6 | K6: =IFERROR(J6/E6,"-") -> 0.11146594 | L6: =IFERROR(G6-F6,"-") -> 329032.6 | M6: =IFERROR(L6/F6,"-") -> 0.23631498
B7: 其中：高温水网供热量 | C7: 吉焦 | D7: =北海!D7+北海水炉!D4 -> 0 | E7: =北海!E7+北海水炉!E4 -> 1463116 | F7: =[3]股份本部!G7 -> 1306319 | G7: =北海!G7+北海水炉!G4 -> 1616316.4 | H7: =北海!H7+北海水炉!H4 -> 1616316.4 | I7: =IFERROR(H7/D7,"-") -> - | J7: =IFERROR(G7-E7,"-") -> 153200.4 | K7: =IFERROR(J7/E7,"-") -> 0.10470831 | L7: =IFERROR(G7-F7,"-") -> 309997.4 | M7: =IFERROR(L7/F7,"-") -> 0.23730605
B8: 关联交易量(蒸汽) | C8: 吨 | E8: ='[2]3.股份本部汇总表'!$M$16 -> -6183 | F8: =[3]股份本部!G8 -> 1684 | G8: =[5]售热量!$D$5 -> 1200 | H8: =[5]售热量!$D$5 -> 1200 | I8: =IFERROR(H8/D8,"-") -> - | J8: =IFERROR(G8-E8,"-") -> 7383 | K8: =IFERROR(J8/E8,"-") -> -1.1940805 | L8: =IFERROR(G8-F8,"-") -> -484 | M8: =IFERROR(L8/F8,"-") -> -0.28741093
B9: 关联交易量(高温水) | C9: 吉焦 | E9: ='[2]3.股份本部汇总表'!$M$17 -> 149928 | F9: =[3]股份本部!G9 -> 150679 | G9: =[5]售热量!$D$6 -> 198254 | H9: =[5]售热量!$D$6 -> 198254 | I9: =IFERROR(H9/D9,"-") -> - | J9: =IFERROR(G9-E9,"-") -> 48326 | K9: =IFERROR(J9/E9,"-") -> 0.32232805 | L9: =IFERROR(G9-F9,"-") -> 47575 | M9: =IFERROR(L9/F9,"-") -> 0.31573743
B10: 高温水销售量 | C10: 吉焦 | E10: ='[2]3.股份本部汇总表'!$M$25 -> 100500 | F10: =[3]股份本部!G10 -> 97005 | G10: =[5]售热量!$D$7 -> 104506 | H10: =[5]售热量!$D$7 -> 104506 | I10: =IFERROR(H10/D10,"-") -> - | J10: =IFERROR(G10-E10,"-") -> 4006 | K10: =IFERROR(J10/E10,"-") -> 0.039860697 | L10: =IFERROR(G10-F10,"-") -> 7501 | M10: =IFERROR(L10/F10,"-") -> 0.077325911
B11: 期末供暖收费面积 | C11: 平方米 | E11: ='[2]3.股份本部汇总表'!$M$19 -> 16943011 | F11: =[3]股份本部!G11 -> 16102552 | G11: =H11 -> 16314998 | H11: 16314998 | I11: =IFERROR(H11/D11,"-") -> - | J11: =IFERROR(G11-E11,"-") -> -628012.94 | K11: =IFERROR(J11/E11,"-") -> -0.037066196 | L11: =IFERROR(G11-F11,"-") -> 212445.54 | M11: =IFERROR(L11/F11,"-") -> 0.013193284
A12: 消耗指标 | B12: 生产耗原煤量 | C12: 吨 | D12: =北海!D12+北海水炉!D5 -> 0 | E12: =北海!E12+北海水炉!E5 -> 105279.22 | F12: =[3]股份本部!G12 -> 92166 | G12: =北海!G12+北海水炉!G5 -> 111116 | H12: =北海!H12+北海水炉!H5 -> 111116 | I12: =IFERROR(H12/D12,"-") -> - | J12: =IFERROR(G12-E12,"-") -> 5836.7778 | K12: =IFERROR(J12/E12,"-") -> 0.055440928 | L12: =IFERROR(G12-F12,"-") -> 18950 | M12: =IFERROR(L12/F12,"-") -> 0.20560727
B13: 锅炉耗柴油量 | C13: 吨 | D13: =北海!D24+北海水炉!D6 -> 0 | E13: =北海!E24+北海水炉!E6 -> 59 | F13: =[3]股份本部!G13 -> 58.5 | G13: =北海!G24+北海水炉!G6 -> 78.3 | H13: =北海!H24+北海水炉!H6 -> 78.3 | I13: =IFERROR(H13/D13,"-") -> - | J13: =IFERROR(G13-E13,"-") -> 19.3 | K13: =IFERROR(J13/E13,"-") -> 0.32711864 | L13: =IFERROR(G13-F13,"-") -> 19.8 | M13: =IFERROR(L13/F13,"-") -> 0.33846154
B14: 耗水量 | C14: 吨 | D14: =北海!D22+北海!D21+北海水炉!D9 -> 0 | E14: =北海!E22+北海!E21+北海水炉!E9 -> 193594 | F14: =[3]股份本部!G14 -> 221014 | G14: =北海!G22+北海!G21+北海水炉!G9+天然气炉!D8 -> 192052 | H14: =北海!H22+北海!H21+北海水炉!H9+天然气炉!F8 -> 192052 | I14: =IFERROR(H14/D14,"-") -> - | J14: =IFERROR(G14-E14,"-") -> -1542 | K14: =IFERROR(J14/E14,"-") -> -0.0079651229 | L14: =IFERROR(G14-F14,"-") -> -28962 | M14: =IFERROR(L14/F14,"-") -> -0.13104147
B15: 耗酸量 | C15: 吨 | D15: =北海!D14 -> 0 | E15: =北海!E14 -> 21 | F15: =[3]股份本部!G15 -> 14 | G15: =北海!G14 -> 6.4 | H15: =北海!H14 -> 6.4 | I15: =IFERROR(H15/D15,"-") -> - | J15: =IFERROR(G15-E15,"-") -> -14.6 | K15: =IFERROR(J15/E15,"-") -> -0.6952381 | L15: =IFERROR(G15-F15,"-") -> -7.6 | M15: =IFERROR(L15/F15,"-") -> -0.54285714
B16: 耗碱量 | C16: 吨 | D16: =北海!D13 -> 0 | E16: =北海!E13 -> 18 | F16: =[3]股份本部!G16 -> 18 | G16: =北海!G13 -> 9.7 | H16: =北海!H13 -> 9.7 | I16: =IFERROR(H16/D16,"-") -> - | J16: =IFERROR(G16-E16,"-") -> -8.3 | K16: =IFERROR(J16/E16,"-") -> -0.46111111 | L16: =IFERROR(G16-F16,"-") -> -8.3 | M16: =IFERROR(L16/F16,"-") -> -0.46111111
B17: 耗石灰石粉量 | C17: 吨 | D17: =北海!D25+北海水炉!D16 -> 0 | E17: =北海!E25+北海水炉!E16 -> 3089 | F17: =[3]股份本部!G17 -> 1891 | G17: =北海!G25+北海水炉!G16 -> 2779.29 | H17: =北海!H25+北海水炉!H16 -> 2779.29 | I17: =IFERROR(H17/D17,"-") -> - | J17: =IFERROR(G17-E17,"-") -> -309.71 | K17: =IFERROR(J17/E17,"-") -> -0.10026222 | L17: =IFERROR(G17-F17,"-") -> 888.29 | M17: =IFERROR(L17/F17,"-") -> 0.46974617
B18: 耗氨水量 | C18: 吨 | D18: =北海!D15+北海水炉!D17 -> 0 | E18: =北海!E15+北海水炉!E17 -> 595 | F18: =[3]股份本部!G18 -> 520.63 | G18: =北海!G15+北海水炉!G17 -> 631.54 | H18: =北海!H15+北海水炉!H17 -> 631.54 | I18: =IFERROR(H18/D18,"-") -> - | J18: =IFERROR(G18-E18,"-") -> 36.54 | K18: =IFERROR(J18/E18,"-") -> 0.061411765 | L18: =IFERROR(G18-F18,"-") -> 110.91 | M18: =IFERROR(L18/F18,"-") -> 0.21303037
B19: 耗阻垢剂量 | C19: 吨 | D19: =北海!D16+中水!E14 -> 0 | E19: =北海!E16 -> 1.2 | F19: =[3]股份本部!G19 -> 1.25 | G19: =北海!G16+中水!G14 -> 1.125 | H19: =北海!H16 -> 1.075 | I19: =IFERROR(H19/D19,"-") -> - | J19: =IFERROR(G19-E19,"-") -> -0.075 | K19: =IFERROR(J19/E19,"-") -> -0.0625 | L19: =IFERROR(G19-F19,"-") -> -0.125 | M19: =IFERROR(L19/F19,"-") -> -0.1
B20: 耗杀菌剂量 | C20: 吨 | D20: =北海!D17+中水!E16 -> 0 | E20: =北海!E17 -> 0 | F20: =[3]股份本部!G20 -> 0 | G20: =北海!G17+中水!G16 -> 0 | H20: =北海!H17+中水!H16 -> 0 | I20: =IFERROR(H20/D20,"-") -> - | J20: =IFERROR(G20-E20,"-") -> 0 | K20: =IFERROR(J20/E20,"-") -> - | L20: =IFERROR(G20-F20,"-") -> 0 | M20: =IFERROR(L20/F20,"-") -> -
B21: 外购电量 | C21: 万千瓦时 | D21: =北海!D26+北海水炉!D13 -> 0 | E21: =北海!E26+北海水炉!E13 -> 0 | F21: =北海!F26+北海水炉!F13 -> 0 | G21: =北海!G26+北海水炉!G13 -> 0 | H21: =北海!H26+北海水炉!H13 -> 0 | I21: =IFERROR(H21/D21,"-") -> - | J21: =IFERROR(G21-E21,"-") -> 0 | K21: =IFERROR(J21/E21,"-") -> - | L21: =IFERROR(G21-F21,"-") -> 0 | M21: =IFERROR(L21/F21,"-") -> -
B22: 耗标煤总量 | C22: 吨 | D22: =D23+D24 -> 0 | E22: =E23+E24 -> 71129 | F22: =[3]股份本部!G22 -> 62683.28 | G22: =G23+G24 -> 74474.8 | H22: =H23+H24 -> 74474.8 | I22: =IFERROR(H22/D22,"-") -> - | J22: =IFERROR(G22-E22,"-") -> 3345.7996 | K22: =IFERROR(J22/E22,"-") -> 0.047038474 | L22: =IFERROR(G22-F22,"-") -> 11791.52 | M22: =IFERROR(L22/F22,"-") -> 0.18811268
B23: 发电标准煤耗量 | C23: 吨 | D23: =北海!D8 -> 0 | E23: =北海!E8 -> 10967 | F23: =[3]股份本部!G23 -> 8517.6 | G23: =北海!G8 -> 9838.4525 | H23: =北海!H8 -> 9838.4525 | I23: =IFERROR(H23/D23,"-") -> - | J23: =IFERROR(G23-E23,"-") -> -1128.5475 | K23: =IFERROR(J23/E23,"-") -> -0.10290394 | L23: =IFERROR(G23-F23,"-") -> 1320.8525 | M23: =IFERROR(L23/F23,"-") -> 0.15507332
B24: 供热标准煤耗量 | C24: 吨 | D24: =北海!D9+北海水炉!D7 -> 0 | E24: =北海!E9+北海水炉!E7 -> 60162 | F24: =[3]股份本部!G24 -> 54165.68 | G24: =北海!G9+北海水炉!G7 -> 64636.347 | H24: =北海!H9+北海水炉!H7 -> 64636.347 | I24: =IFERROR(H24/D24,"-") -> - | J24: =IFERROR(G24-E24,"-") -> 4474.3471 | K24: =IFERROR(J24/E24,"-") -> 0.074371649 | L24: =IFERROR(G24-F24,"-") -> 10470.667 | M24: =IFERROR(L24/F24,"-") -> 0.19330815
B25: 其中：煤折标煤量 | C25: 吨 | D25: =北海!D11+北海水炉!D8 -> 0 | E25: =北海!E11+北海水炉!E8 -> 71043.031 | F25: =[3]股份本部!G25 -> 62598.04 | G25: =北海!G11+北海水炉!G8 -> 74360.706 | H25: =北海!H11+北海水炉!H8 -> 74360.706 | I25: =IFERROR(H25/D25,"-") -> - | J25: =IFERROR(G25-E25,"-") -> 3317.6752 | K25: =IFERROR(J25/E25,"-") -> 0.046699517 | L25: =IFERROR(G25-F25,"-") -> 11762.666 | M25: =IFERROR(L25/F25,"-") -> 0.1879079
A26: 单耗与效率 | B26: 综合厂用电率 | C26: % | D26: =(D3-D4)/D3 -> #DIV/0! | E26: =(E3-E4)/E3 -> 0.3100765 | F26: =[3]股份本部!G26 -> 0.32243275 | G26: =北海!G27/G3 -> 0.38858082 | H26: =北海!H27/H3 -> 0.38858082 | I26: - | J26: =IFERROR(G26-E26,"-") -> 0.078504328 | K26: - | L26: =IFERROR(G26-F26,"-") -> 0.066148072 | M26: -
B27: 发电煤耗率 | C27: 克/千瓦时 | D27: =D23*100/D3 -> #DIV/0! | E27: =E23*100/E3 -> 144.64521 | F27: =[3]股份本部!G27 -> 146.75599 | G27: =G23*100/G3 -> 161.94024 | H27: =H23*100/H3 -> 161.94024 | I27: =IFERROR(H27/D27,"-") -> - | J27: =IFERROR(G27-E27,"-") -> 17.295026 | K27: =IFERROR(J27/E27,"-") -> 0.11956861 | L27: =IFERROR(G27-F27,"-") -> 15.184253 | M27: =IFERROR(L27/F27,"-") -> 0.10346599
B28: 供电煤耗率 | C28: 克/千瓦时 | D28: =D23*100/(D3-北海!D29) -> #DIV/0! | E28: =E23*100/(E3-北海!E29) -> 151.87486 | F28: =[3]股份本部!G28 -> 153.66304 | G28: =G23*100/(G3-北海!G29) -> 172.05956 | H28: =H23*100/(H3-北海!H29) -> 172.05956 | I28: =IFERROR(H28/D28,"-") -> - | J28: =IFERROR(G28-E28,"-") -> 20.184698 | K28: =IFERROR(J28/E28,"-") -> 0.13290348 | L28: =IFERROR(G28-F28,"-") -> 18.396527 | M28: =IFERROR(L28/F28,"-") -> 0.11971992
B29: 供热煤耗率 | C29: 千克/吉焦 | D29: =D24*1000/(D6-主城区电锅炉!D6) -> #DIV/0! | E29: =E24*1000/E6 -> 38.845581 | F29: =[3]股份本部!G29 -> 38.913508 | G29: =G24*1000/(G6-主城区电锅炉!G6-天然气炉!D5) -> 37.558763 | H29: =H24*1000/(H6-主城区电锅炉!H6-天然气炉!F5) -> 37.558763 | I29: =IFERROR(H29/D29,"-") -> - | J29: =IFERROR(G29-E29,"-") -> -1.286818 | K29: =IFERROR(J29/E29,"-") -> -0.033126497 | L29: =IFERROR(G29-F29,"-") -> -1.3547447 | M29: =IFERROR(L29/F29,"-") -> -0.034814253
B30: 入炉煤低位发热量 | C30: 千焦/千克 | D30: =D22*29308/D12 -> #DIV/0! | E30: =E22*29308/E12 -> 19801.141 | F30: =[3]股份本部!G30 -> 19905.642 | G30: =('[6]26.1'!$E$40+'[6]26.1'!$E$43+北海水炉!G8)*29308/G12 -> 19613.409 | H30: =('[6]26.1'!$K$40+'[6]26.1'!$K$43+北海水炉!H8)*29308/H12 -> 19613.409 | I30: =IFERROR(H30/D30,"-") -> - | J30: =IFERROR(G30-E30,"-") -> -187.73184 | K30: =IFERROR(J30/E30,"-") -> -0.0094808596 | L30: =IFERROR(G30-F30,"-") -> -292.23228 | M30: =IFERROR(L30/F30,"-") -> -0.014680877
A31: 设备利用率 | B31: 发电设备利用率 | C31: % | D31: =D3/10/8760 -> 0 | E31: =E3/10/(DAY(DATE(2026,2,0))*24) -> 1.019086 | F31: =[3]股份本部!G31 -> 0.78009677 | G31: =G3/10/(DAY(DATE(2026,2,0))*24) -> 0.81658065 | H31: =H3/10/(DATEDIF(DATE(2026,1,1),DATE(2026,2,1),"D")*24) -> 0.81658065 | I31: - | J31: =IFERROR(G31-E31,"-") -> -0.20250538 | K31: - | L31: =IFERROR(G31-F31,"-") -> 0.036483871 | M31: -
B32: 供热设备利用率 | C32: % | D32: =D6*1000/1142.55/(8760*3600) -> 0 | E32: =E6*1000/1142.55/((DAY(DATE(2026,2,0))*24)*3600) -> 0.50609261 | F32: =[3]股份本部!G32 -> 0.45498494 | G32: =G6*1000/1142.55/((DAY(DATE(2026,2,0))*24)*3600) -> 0.56250469 | H32: =H6*1000/1142.55/((DATEDIF(DATE(2026,1,1),DATE(2026,2,1),"D")*24)*3600) -> 0.56250469 | I32: - | J32: =IFERROR(G32-E32,"-") -> 0.056412086 | K32: - | L32: =IFERROR(G32-F32,"-") -> 0.10751976 | M32: -

Sheet 北海
A1: 指标类别 | B1: 项 目 | C1: 计量单位 | D1: 本年计划 | E1: 本月计划 | F1: 上年同期 | G1: 本月实际 | H1: 本年累计 | I1: 年计划 完成率 | J1: 与月计划比较 | L1: 与上年同期比较
J2: 差异 | K2: ±% | L2: 差异 | M2: ±%
A3: 产销指标 | B3: 发电量 | C3: 万千瓦时 | E3: ='[2]5.北海热电厂（热电联产）表'!$M$7 -> 7582 | F3: =[3]北海!G3 -> 5803.92 | G3: ='[6]26.1'!$E$7/10000 -> 6075.36 | H3: ='[6]26.1'!$K$7/10000 -> 6075.36 | I3: =IFERROR(H3/D3,"-") -> - | J3: =IFERROR(G3-E3,"-") -> -1506.64 | K3: =IFERROR(J3/E3,"-") -> -0.19871274 | L3: =IFERROR(G3-F3,"-") -> 271.44 | M3: =IFERROR(L3/F3,"-") -> 0.046768391
B4: 售电量 | C4: 万千瓦时 | E4: ='[2]5.北海热电厂（热电联产）表'!$M$14 -> 5231 | F4: =[3]北海!G4 -> 3932.5461 | G4: ='[6]26.1'!$E$8/10000 -> 3714.5916 | H4: ='[6]26.1'!$K$8/10000 -> 3714.5916 | I4: =IFERROR(H4/D4,"-") -> - | J4: =IFERROR(G4-E4,"-") -> -1516.4084 | K4: =IFERROR(J4/E4,"-") -> -0.28988882 | L4: =IFERROR(G4-F4,"-") -> -217.9545 | M4: =IFERROR(L4/F4,"-") -> -0.055423254
B5: 供汽量 | C5: 吨 | E5: ='[2]5.北海热电厂（热电联产）表'!$M$9 -> 29011 | F5: =[3]北海!G5 -> 29011 | G5: ='[6]26.1'!$E$12 -> 35445 | H5: ='[6]26.1'!$K$12 -> 35445 | I5: =IFERROR(H5/D5,"-") -> - | J5: =IFERROR(G5-E5,"-") -> 6434 | K5: =IFERROR(J5/E5,"-") -> 0.22177795 | L5: =IFERROR(G5-F5,"-") -> 6434 | M5: =IFERROR(L5/F5,"-") -> 0.22177795
B6: 供热量 | C6: 吉焦 | E6: ='[2]5.北海热电厂（热电联产）表'!$M$8 -> 1196417.6 | F6: =[3]北海!G6 -> 962532.59 | G6: ='[6]26.1'!$E$9 -> 980229.19 | H6: ='[6]26.1'!$K$9 -> 980229.19 | I6: =IFERROR(H6/D6,"-") -> - | J6: =IFERROR(G6-E6,"-") -> -216188.4 | K6: =IFERROR(J6/E6,"-") -> -0.18069644 | L6: =IFERROR(G6-F6,"-") -> 17696.599 | M6: =IFERROR(L6/F6,"-") -> 0.018385454
B7: 其中：首站供热量 | C7: 吉焦 | E7: ='[2]5.北海热电厂（热电联产）表'!$M$10 -> 1110786 | F7: =[3]北海!G7 -> 876901 | G7: ='[6]26.1'!$E$11 -> 875606.4 | H7: ='[6]26.1'!$K$11 -> 875606.4 | I7: =IFERROR(H7/D7,"-") -> - | J7: =IFERROR(G7-E7,"-") -> -235179.6 | K7: =IFERROR(J7/E7,"-") -> -0.21172359 | L7: =IFERROR(G7-F7,"-") -> -1294.6 | M7: =IFERROR(L7/F7,"-") -> -0.0014763354
A8: 消耗指标 | B8: 发电耗标煤量 | C8: 吨 | E8: ='[2]5.北海热电厂（热电联产）表'!$M$30 -> 10967 | F8: =[3]北海!G8 -> 8517.6 | G8: ='[6]26.1'!$E$39 -> 9838.4525 | H8: ='[6]26.1'!$K$39 -> 9838.4525 | I8: =IFERROR(H8/D8,"-") -> - | J8: =IFERROR(G8-E8,"-") -> -1128.5475 | K8: =IFERROR(J8/E8,"-") -> -0.10290394 | L8: =IFERROR(G8-F8,"-") -> 1320.8525 | M8: =IFERROR(L8/F8,"-") -> 0.15507332
B9: 供热耗标煤量 | C9: 吨 | E9: ='[2]5.北海热电厂（热电联产）表'!$M$33 -> 46822 | F9: =[3]北海!G9 -> 37752.04 | G9: ='[6]26.1'!$E$42 -> 37010.429 | H9: ='[6]26.1'!$K$42 -> 37010.429 | I9: =IFERROR(H9/D9,"-") -> - | J9: =IFERROR(G9-E9,"-") -> -9811.5711 | K9: =IFERROR(J9/E9,"-") -> -0.20955045 | L9: =IFERROR(G9-F9,"-") -> -741.61112 | M9: =IFERROR(L9/F9,"-") -> -0.019644266
B10: 耗标煤总量 | C10: 吨 | D10: =SUM(D8:D9) -> 0 | E10: =SUM(E8:E9) -> 57789 | F10: =[3]北海!G10 -> 46269.64 | G10: =SUM(G8:G9) -> 46848.881 | H10: =SUM(H8:H9) -> 46848.881 | I10: =IFERROR(H10/D10,"-") -> - | J10: =IFERROR(G10-E10,"-") -> -10940.119 | K10: =IFERROR(J10/E10,"-") -> -0.18931144 | L10: =IFERROR(G10-F10,"-") -> 579.24136 | M10: =IFERROR(L10/F10,"-") -> 0.012518821
B11: 其中：煤折标煤量 | C11: 吨 | D11: =D10-1.4571*D24 -> 0 | E11: =E10-1.4571*E24 -> 57727.802 | F11: =F10-1.4571*F24 -> 46209.316 | G11: ='[6]26.1'!$E$40+'[6]26.1'!$E$43 -> 46747.902 | H11: ='[6]26.1'!$K$40+'[6]26.1'!$K$43 -> 46747.902 | I11: =IFERROR(H11/D11,"-") -> - | J11: =IFERROR(G11-E11,"-") -> -10979.9 | K11: =IFERROR(J11/E11,"-") -> -0.19020125 | L11: =IFERROR(G11-F11,"-") -> 538.58592 | M11: =IFERROR(L11/F11,"-") -> 0.011655354
